
|france| Friendly SyntaxError tracebacks - en Français
======================================================

Le but principal de friendly-traceback est de fournir des rétroactions plus
conviviales que les fameux **tracebacks** de Python lorsqu'une exception survient.
Ci-dessous, on peut voir quelques exemples, uniquement pour les
exceptions de type SyntaxError et des classes dérivées;
les autres sont couvertes dans une autre page.
Le but est de documenter ici tous les exemples possibles
tels qu'interprétés par friendly-traceback.

.. note::

     Le contenu de cette page a été généré par l'exécution de
     trb_syntax_french.py situé dans le répertoire ``tests/``.
     Ceci a besoin d'être fait de manière explicite lorsqu'on veut
     faire des corrections ou des ajouts, avant de faire la mise
     à jour du reste de la documentation avec Sphinx.
     Sous Windows, si Sphinx est installé sur votre ordinateur, il est
     plutôt suggéré d'exécuter make_trb.bat qui est au premier niveau
     du répertoire de fichier. Si vous faites ceci, la documentation pour
     toutes les langues sera automatiquement mise à jour.

Friendly version: 0.3.85
Python version: 3.8.4



(1) Using 'and' in import statement
-----------------------------------

.. code-block:: none


    Traceback (most recent call last):
      File "TESTS:\trb_syntax_common.py", line 49, in create_tracebacks
        __import__(name)
      File "TESTS:\syntax\and_in_import_statement.py", line 1
        from math import sin and cos
                             ^
    SyntaxError: invalid syntax
    
    Une exception de type `SyntaxError` se produit lorsque Python ne peut pas comprendre votre code.
    
    Python peut seulement comprendre le code du fichier
    'TESTS:\syntax\and_in_import_statement.py'
    jusqu'à l'endroit indiqué par ^.
    
    -->1: from math import sin and cos
                               ^

    Le mot clé Python `and` ne peut être utilisé que pour les expressions booléennes.
    Peut-être que vous vouliez écrire
    
    `from math import sin , cos`
    

(2) Annotated name cannot be global
-----------------------------------

.. code-block:: none


    Traceback (most recent call last):
      File "TESTS:\trb_syntax_common.py", line 49, in create_tracebacks
        __import__(name)
      File "TESTS:\syntax\annotated_name_global.py", line 4
        x:int = 1
        ^
    SyntaxError: annotated name 'x' can't be global
    
    Une exception de type `SyntaxError` se produit lorsque Python ne peut pas comprendre votre code.
    
    Python peut seulement comprendre le code du fichier
    'TESTS:\syntax\annotated_name_global.py'
    jusqu'à l'endroit indiqué par ^.
    
       1: # SyntaxError: annotated name 'x' can't be global
       2: def foo():
       3:     global x
    -->4:     x:int = 1
              ^

    L’objet nommé `x` est défini avec une annotation de type
    comme une variable locale. Il ne peut pas être déclaré variable globale.
    

(3) Incorrect use of 'from module import ... as ...
---------------------------------------------------

.. code-block:: none


    Traceback (most recent call last):
      File "TESTS:\trb_syntax_common.py", line 49, in create_tracebacks
        __import__(name)
      File "TESTS:\syntax\as_instead_of_comma_in_import.py", line 2
        from math import (sin, cos) as funcs
                                    ^
    SyntaxError: invalid syntax
    
    Une exception de type `SyntaxError` se produit lorsque Python ne peut pas comprendre votre code.
    
    Python peut seulement comprendre le code du fichier
    'TESTS:\syntax\as_instead_of_comma_in_import.py'
    jusqu'à l'endroit indiqué par ^.
    
       1: # issue 158
    -->2: from math import (sin, cos) as funcs
                                      ^

    Je suppose que vous essayez d’importer au moins un objet
    à partir du module `math` pour le renommer en utilisant le mot clé Python `as`;
    ce mot clé ne peut être utilisé que pour renommer un objet à la fois
    en utilisant une syntaxe bien définie.
    Je vous suggère de diviser une telle déclaration d’importation avec chaque objet
    renommé sur une ligne séparée comme suit:
    
        from math import objet_1 as nom_1
        from math import objet_2 as nom_2 # si nécessaire
    

(4) Name assigned prior to global declaration
---------------------------------------------

.. code-block:: none


    Traceback (most recent call last):
      File "TESTS:\trb_syntax_common.py", line 49, in create_tracebacks
        __import__(name)
      File "TESTS:\syntax\assign_name_before_global_1.py", line 7
        global p
        ^
    SyntaxError: name 'p' is assigned to before global declaration
    
    Une exception de type `SyntaxError` se produit lorsque Python ne peut pas comprendre votre code.
    
    Python peut seulement comprendre le code du fichier
    'TESTS:\syntax\assign_name_before_global_1.py'
    jusqu'à l'endroit indiqué par ^.
    
       3: 
       4: 
       5: def fn():
       6:     p = 1
    -->7:     global p
              ^

    Vous avez attribué une valeur à la variable `p`
    avant de la déclarer comme une variable globale.
    

(5) Name used prior to global declaration
-----------------------------------------

.. code-block:: none


    Traceback (most recent call last):
      File "TESTS:\trb_syntax_common.py", line 49, in create_tracebacks
        __import__(name)
      File "TESTS:\syntax\assign_name_before_global_2.py", line 7
        global r
        ^
    SyntaxError: name 'r' is used prior to global declaration
    
    Une exception de type `SyntaxError` se produit lorsque Python ne peut pas comprendre votre code.
    
    Python peut seulement comprendre le code du fichier
    'TESTS:\syntax\assign_name_before_global_2.py'
    jusqu'à l'endroit indiqué par ^.
    
       3: 
       4: 
       5: def fn():
       6:     print(r)
    -->7:     global r
              ^

    Vous avez utilisé la variable `r`
    avant de la déclarer comme une variable globale.
    

(6) Name used prior to nonlocal declaration
-------------------------------------------

.. code-block:: none


    Traceback (most recent call last):
      File "TESTS:\trb_syntax_common.py", line 49, in create_tracebacks
        __import__(name)
      File "TESTS:\syntax\assign_name_before_nonlocal_1.py", line 9
        nonlocal q
        ^
    SyntaxError: name 'q' is used prior to nonlocal declaration
    
        Avez-vous oublié d’ajouter `nonlocal` en premier ?
        
    Une exception de type `SyntaxError` se produit lorsque Python ne peut pas comprendre votre code.
    
    Python peut seulement comprendre le code du fichier
    'TESTS:\syntax\assign_name_before_nonlocal_1.py'
    jusqu'à l'endroit indiqué par ^.
    
        5:     q = 1
        6: 
        7:     def g():
        8:         print(q)
    --> 9:         nonlocal q
                   ^

    Vous avez utilisé la variable `q`
    avant de la déclarer comme variable non locale.
    

(7) Name assigned prior to nonlocal declaration
-----------------------------------------------

.. code-block:: none


    Traceback (most recent call last):
      File "TESTS:\trb_syntax_common.py", line 49, in create_tracebacks
        __import__(name)
      File "TESTS:\syntax\assign_name_before_nonlocal_2.py", line 9
        nonlocal s
        ^
    SyntaxError: name 's' is assigned to before nonlocal declaration
    
        Avez-vous oublié d’ajouter `nonlocal` ?
        
    Une exception de type `SyntaxError` se produit lorsque Python ne peut pas comprendre votre code.
    
    Python peut seulement comprendre le code du fichier
    'TESTS:\syntax\assign_name_before_nonlocal_2.py'
    jusqu'à l'endroit indiqué par ^.
    
        5:     s = 1
        6: 
        7:     def g():
        8:         s = 2
    --> 9:         nonlocal s
                   ^

    Vous avez attribué une valeur à la variable `s`
    avant de la déclarer comme variable non locale.
    

(8) Assign to conditional expression
------------------------------------

.. code-block:: none


    Traceback (most recent call last):
      File "TESTS:\trb_syntax_common.py", line 49, in create_tracebacks
        __import__(name)
      File "TESTS:\syntax\assign_to_conditional.py", line 3
        a if 1 else b = 1
        ^
    SyntaxError: cannot assign to conditional expression
    
        Vous ne pouvez assigner des objets qu’à des identifiants (noms de variables).
        
    Une exception de type `SyntaxError` se produit lorsque Python ne peut pas comprendre votre code.
    
    Python peut seulement comprendre le code du fichier
    'TESTS:\syntax\assign_to_conditional.py'
    jusqu'à l'endroit indiqué par ^.
    
       1: """Should raise SyntaxError: can't [cannot] assign to conditional expression"""
       2: 
    -->3: a if 1 else b = 1
          ^

    Du côté gauche d'un signe d'égalité, vous avez une
    expression conditionnelle au lieu du nom d'une variable.
    Une expression conditionnelle doit avoir la forme suivante:
    
        variable = objet if condition else autre_objet

(9) Assignment to keyword (__debug__)
-------------------------------------

.. code-block:: none


    Traceback (most recent call last):
      File "TESTS:\trb_syntax_common.py", line 49, in create_tracebacks
        __import__(name)
      File "TESTS:\syntax\assign_to_debug.py", line 4
        __debug__ = 1
        ^
    SyntaxError: cannot assign to __debug__
    
        Vous ne pouvez pas attribuer une valeur à `__debug__`.
    Une exception de type `SyntaxError` se produit lorsque Python ne peut pas comprendre votre code.
    
    Python peut seulement comprendre le code du fichier
    'TESTS:\syntax\assign_to_debug.py'
    jusqu'à l'endroit indiqué par ^.
    
       1: """Should raise SyntaxError: cannot assign to __debug__ in Py 3.8
       2:    and assignment to keyword before."""
       3: 
    -->4: __debug__ = 1
          ^

    `__debug__` est une constante dans python; vous ne pouvez pas lui assigner une valeur différente.
    
    

(10) Assignment to keyword (__debug__)
--------------------------------------

.. code-block:: none


    Traceback (most recent call last):
      File "TESTS:\trb_syntax_common.py", line 49, in create_tracebacks
        __import__(name)
      File "TESTS:\syntax\assign_to_debug2.py", line 4
        a.__debug__ = 1
        ^
    SyntaxError: cannot assign to __debug__
    
        Vous ne pouvez pas attribuer une valeur à `__debug__`.
    Une exception de type `SyntaxError` se produit lorsque Python ne peut pas comprendre votre code.
    
    Python peut seulement comprendre le code du fichier
    'TESTS:\syntax\assign_to_debug2.py'
    jusqu'à l'endroit indiqué par ^.
    
       1: """Should raise SyntaxError: cannot assign to __debug__ in Py 3.8
       2:    and assignment to keyword before."""
       3: 
    -->4: a.__debug__ = 1
          ^

    `__debug__` est une constante dans python; vous ne pouvez pas lui assigner une valeur différente.
    
    

(11) Assignment to Ellipsis symbol
----------------------------------

.. code-block:: none


    Traceback (most recent call last):
      File "TESTS:\trb_syntax_common.py", line 49, in create_tracebacks
        __import__(name)
      File "TESTS:\syntax\assign_to_ellipsis.py", line 4
        ... = 1
        ^
    SyntaxError: cannot assign to Ellipsis
    
        Vous ne pouvez pas attribuer une valeur au symbole 'ellipsis' [`...`].
        
    Une exception de type `SyntaxError` se produit lorsque Python ne peut pas comprendre votre code.
    
    Python peut seulement comprendre le code du fichier
    'TESTS:\syntax\assign_to_ellipsis.py'
    jusqu'à l'endroit indiqué par ^.
    
       1: """Should raise SyntaxError: cannot assign to Ellipsis in Py 3.8
       2:    and assignment to keyword before."""
       3: 
    -->4: ... = 1
          ^

    Le symbole `...` est une constante dans python; vous ne pouvez pas lui assigner une valeur différente.
    
    

(12) Cannot assign to f-string
------------------------------

.. code-block:: none


    Traceback (most recent call last):
      File "TESTS:\trb_syntax_common.py", line 49, in create_tracebacks
        __import__(name)
      File "TESTS:\syntax\assign_to_f_string.py", line 6
        f'{x}' = 42
        ^
    SyntaxError: cannot assign to f-string expression
    
        Vous ne pouvez assigner des objets qu’à des identifiants (noms de variables).
        
    Une exception de type `SyntaxError` se produit lorsque Python ne peut pas comprendre votre code.
    
    Python peut seulement comprendre le code du fichier
    'TESTS:\syntax\assign_to_f_string.py'
    jusqu'à l'endroit indiqué par ^.
    
       1: """Should raise
       2: Python < 3.8: SyntaxError: can't assign to literal
       3: Python >= 3.8: SyntaxError: cannot assign to f-string expression
       4: """
       5: 
    -->6: f'{x}' = 42
          ^

    Vous avez écrit une expression qui a la chaine de
    caractères formatés `f'{x}'`
    du côté gauche du signe d'égalité.
    Une telle chaîne ne doit apparaître que du côté droit d'un signe d’égalité.
    

(13) Cannot assign to function call: single = sign
--------------------------------------------------

.. code-block:: none


    Traceback (most recent call last):
      File "TESTS:\trb_syntax_common.py", line 49, in create_tracebacks
        __import__(name)
      File "TESTS:\syntax\assign_to_function_call_1.py", line 6
        len('a') = 3
        ^
    SyntaxError: cannot assign to function call
    
        Vous ne pouvez assigner des objets qu’à des identifiants (noms de variables).
        
    Une exception de type `SyntaxError` se produit lorsque Python ne peut pas comprendre votre code.
    
    Python peut seulement comprendre le code du fichier
    'TESTS:\syntax\assign_to_function_call_1.py'
    jusqu'à l'endroit indiqué par ^.
    
       1: """Should raise SyntaxError: can't assign to function call
       2: 
       3: Python 3.8: SyntaxError: cannot assign to function call
       4: """
       5: 
    -->6: len('a') = 3
          ^

    Vous avez écrit une expression comme
    
        len('a') = 3
    
    où `len('a')`, à la gauche du signe d'égalité est soit l'invocation
    d'une fonction, ou inclus une telle invocation,
    et n'est pas simplement le nom d'une variable.
    

(14) Cannot assign to function call: two = signs
------------------------------------------------

.. code-block:: none


    Traceback (most recent call last):
      File "TESTS:\trb_syntax_common.py", line 49, in create_tracebacks
        __import__(name)
      File "TESTS:\syntax\assign_to_function_call_2.py", line 6
        func(a, b=3) = 4
        ^
    SyntaxError: cannot assign to function call
    
        Vous ne pouvez assigner des objets qu’à des identifiants (noms de variables).
        
    Une exception de type `SyntaxError` se produit lorsque Python ne peut pas comprendre votre code.
    
    Python peut seulement comprendre le code du fichier
    'TESTS:\syntax\assign_to_function_call_2.py'
    jusqu'à l'endroit indiqué par ^.
    
       1: """Should raise SyntaxError: can't assign to function call
       2: 
       3: Python 3.8: SyntaxError: cannot assign to function call
       4: """
       5: 
    -->6: func(a, b=3) = 4
          ^

    Vous avez écrit une expression comme
    
        func(...) = une certaine valeur
    
    où `func(...)`, du côté gauche du signe d'égalité
    est une fonction et non le nom d’une variable.
    

(15) Assign to generator expression
-----------------------------------

.. code-block:: none


    Traceback (most recent call last):
      File "TESTS:\trb_syntax_common.py", line 49, in create_tracebacks
        __import__(name)
      File "TESTS:\syntax\assign_to_generator.py", line 3
        (x for x in x) = 1
        ^
    SyntaxError: cannot assign to generator expression
    
        Vous ne pouvez assigner des objets qu’à des identifiants (noms de variables).
        
    Une exception de type `SyntaxError` se produit lorsque Python ne peut pas comprendre votre code.
    
    Python peut seulement comprendre le code du fichier
    'TESTS:\syntax\assign_to_generator.py'
    jusqu'à l'endroit indiqué par ^.
    
       1: """Should raise SyntaxError: can't [cannot] assign to generator expression"""
       2: 
    -->3: (x for x in x) = 1
          ^

    Du côté gauche d'un signe d'égalité, vous avez une
    expression génératrice au lieu du nom d'une variable.
    

(16) Cannot assign to literal - 4
---------------------------------

.. code-block:: none


    Traceback (most recent call last):
      File "TESTS:\trb_syntax_common.py", line 49, in create_tracebacks
        __import__(name)
      File "TESTS:\syntax\assign_to_literal_dict.py", line 7
        {1 : 2, 2 : 4} = 5
        ^
    SyntaxError: cannot assign to dict display
    
        Vous ne pouvez assigner des objets qu’à des identifiants (noms de variables).
        
    Une exception de type `SyntaxError` se produit lorsque Python ne peut pas comprendre votre code.
    
    Python peut seulement comprendre le code du fichier
    'TESTS:\syntax\assign_to_literal_dict.py'
    jusqu'à l'endroit indiqué par ^.
    
       1: """Should raise SyntaxError:
       2: Python 3.8: cannot assign to dict display
       3: Python 3.6, 3.7: can't assign to literal
       4: 
       5:  """
       6: 
    -->7: {1 : 2, 2 : 4} = 5
          ^

    Vous avez écrit une expression comme
    
        {1 : 2, 2 : 4} = 5
    où `{1 : 2, 2 : 4}`, du côté gauche du signe d'égalité
    est ou inclut un objet de type `dict`
    et n'est pas simplement le nom d'une variable.
    
    

(17) Cannot assign to literal int
---------------------------------

.. code-block:: none


    Traceback (most recent call last):
      File "TESTS:\trb_syntax_common.py", line 49, in create_tracebacks
        __import__(name)
      File "TESTS:\syntax\assign_to_literal_int.py", line 3
        1 = a
        ^
    SyntaxError: cannot assign to literal
    
        Peut-être que vous vouliez plutôt écrire : `a = 1`
    Une exception de type `SyntaxError` se produit lorsque Python ne peut pas comprendre votre code.
    
    Python peut seulement comprendre le code du fichier
    'TESTS:\syntax\assign_to_literal_int.py'
    jusqu'à l'endroit indiqué par ^.
    
       1: """Should raise SyntaxError: can't assign to literal"""
       2: 
    -->3: 1 = a
          ^

    Vous avez écrit une expression comme
    
        1 = a
    où `1`, du côté gauche du signe d'égalité
    est ou inclut un objet de type `int`
    et n'est pas simplement le nom d'une variable.
    Peut-être que vous vouliez plutôt écrire :
    
        a = 1
    
    

(18) Cannot assign to literal int - 2
-------------------------------------

.. code-block:: none


    Traceback (most recent call last):
      File "TESTS:\trb_syntax_common.py", line 49, in create_tracebacks
        __import__(name)
      File "TESTS:\syntax\assign_to_literal_int_2.py", line 3
        1 = 2
        ^
    SyntaxError: cannot assign to literal
    
        Vous ne pouvez assigner des objets qu’à des identifiants (noms de variables).
        
    Une exception de type `SyntaxError` se produit lorsque Python ne peut pas comprendre votre code.
    
    Python peut seulement comprendre le code du fichier
    'TESTS:\syntax\assign_to_literal_int_2.py'
    jusqu'à l'endroit indiqué par ^.
    
       1: """Should raise SyntaxError: can't assign to literal"""
       2: 
    -->3: 1 = 2
          ^

    Vous avez écrit une expression comme
    
        1 = 2
    où `1`, du côté gauche du signe d'égalité
    est ou inclut un objet de type `int`
    et n'est pas simplement le nom d'une variable.
    
    

(19) Cannot assign to literal - 5
---------------------------------

.. code-block:: none


    Traceback (most recent call last):
      File "TESTS:\trb_syntax_common.py", line 49, in create_tracebacks
        __import__(name)
      File "TESTS:\syntax\assign_to_literal_int_3.py", line 4
        1 = a = b
        ^
    SyntaxError: cannot assign to literal
    
        Vous ne pouvez assigner des objets qu’à des identifiants (noms de variables).
        
    Une exception de type `SyntaxError` se produit lorsque Python ne peut pas comprendre votre code.
    
    Python peut seulement comprendre le code du fichier
    'TESTS:\syntax\assign_to_literal_int_3.py'
    jusqu'à l'endroit indiqué par ^.
    
       1: """Should raise SyntaxError: can't assign to literal
       2: or (Python 3.8) cannot assign to literal"""
       3: 
    -->4: 1 = a = b
          ^

    Vous avez écrit une expression comme
    
        ... = nom_de_variable
    où `...`, du côté gauche du signe d'égalité
    est ou inclut un objet 
    et n'est pas simplement le nom d'une variable.
    
    

(20) Cannot assign to literal - 3
---------------------------------

.. code-block:: none


    Traceback (most recent call last):
      File "TESTS:\trb_syntax_common.py", line 49, in create_tracebacks
        __import__(name)
      File "TESTS:\syntax\assign_to_literal_set.py", line 7
        {1, 2, 3} = 4
        ^
    SyntaxError: cannot assign to set display
    
        Vous ne pouvez assigner des objets qu’à des identifiants (noms de variables).
        
    Une exception de type `SyntaxError` se produit lorsque Python ne peut pas comprendre votre code.
    
    Python peut seulement comprendre le code du fichier
    'TESTS:\syntax\assign_to_literal_set.py'
    jusqu'à l'endroit indiqué par ^.
    
       1: """Should raise SyntaxError:
       2: Python 3.8: cannot assign to set display
       3: Python 3.6, 3.7: can't assign to literal
       4: 
       5:  """
       6: 
    -->7: {1, 2, 3} = 4
          ^

    Vous avez écrit une expression comme
    
        {1, 2, 3} = 4
    où `{1, 2, 3}`, du côté gauche du signe d'égalité
    est ou inclut un objet de type `set`
    et n'est pas simplement le nom d'une variable.
    
    

(21) Assign to keyword def
--------------------------

.. code-block:: none


    Traceback (most recent call last):
      File "TESTS:\trb_syntax_common.py", line 49, in create_tracebacks
        __import__(name)
      File "TESTS:\syntax\assign_to_keyword_def.py", line 3
        def = 2
            ^
    SyntaxError: invalid syntax
    
        Les mots clés Python ne peuvent pas être utilisés comme identifiants (noms de variables).
        
    Une exception de type `SyntaxError` se produit lorsque Python ne peut pas comprendre votre code.
    
    Python peut seulement comprendre le code du fichier
    'TESTS:\syntax\assign_to_keyword_def.py'
    jusqu'à l'endroit indiqué par ^.
    
       1: """ Should raise SyntaxError"""
       2: 
    -->3: def = 2
              ^

    Vous essayiez d’assigner une valeur au mot clé Python `def`.
    Ceci n’est pas permis.
    
    

(22) Assign to keyword else
---------------------------

.. code-block:: none


    Traceback (most recent call last):
      File "TESTS:\trb_syntax_common.py", line 49, in create_tracebacks
        __import__(name)
      File "TESTS:\syntax\assign_to_keyword_else.py", line 3
        else = 1
        ^
    SyntaxError: invalid syntax
    
        Les mots clés Python ne peuvent pas être utilisés comme identifiants (noms de variables).
        
    Une exception de type `SyntaxError` se produit lorsque Python ne peut pas comprendre votre code.
    
    Python peut seulement comprendre le code du fichier
    'TESTS:\syntax\assign_to_keyword_else.py'
    jusqu'à l'endroit indiqué par ^.
    
       1: """ Should raise SyntaxError"""
       2: 
    -->3: else = 1
          ^

    Vous essayiez d’assigner une valeur au mot clé Python `else`.
    Ceci n’est pas permis.
    
    

(23) Assignment to keyword (None)
---------------------------------

.. code-block:: none


    Traceback (most recent call last):
      File "TESTS:\trb_syntax_common.py", line 49, in create_tracebacks
        __import__(name)
      File "TESTS:\syntax\assign_to_keyword_none.py", line 4
        None = 1
        ^
    SyntaxError: cannot assign to None
    
        Vous ne pouvez pas attribuer une valeur à `None`.
    Une exception de type `SyntaxError` se produit lorsque Python ne peut pas comprendre votre code.
    
    Python peut seulement comprendre le code du fichier
    'TESTS:\syntax\assign_to_keyword_none.py'
    jusqu'à l'endroit indiqué par ^.
    
       1: """Should raise SyntaxError: cannot assign to None in Py 3.8
       2:    and can't assign to keyword before."""
       3: 
    -->4: None = 1
          ^

    `None` est une constante dans python; vous ne pouvez pas lui assigner une valeur différente.
    
    

(24) Assign to math operation
-----------------------------

.. code-block:: none


    Traceback (most recent call last):
      File "TESTS:\trb_syntax_common.py", line 49, in create_tracebacks
        __import__(name)
      File "TESTS:\syntax\assign_to_operation.py", line 4
        a + 1 = 2
        ^
    SyntaxError: cannot assign to operator
    
        Vous ne pouvez assigner des objets qu’à des identifiants (noms de variables).
        
    Une exception de type `SyntaxError` se produit lorsque Python ne peut pas comprendre votre code.
    
    Python peut seulement comprendre le code du fichier
    'TESTS:\syntax\assign_to_operation.py'
    jusqu'à l'endroit indiqué par ^.
    
       1: """Should raise SyntaxError: can't assign to operator
       2: or (Python 3.8) cannot assign to operator"""
       3: 
    -->4: a + 1 = 2
          ^

    Vous avez écrit une expression qui inclut des opérations mathématiques
    du côté gauche du signe d'égalité; ceci devrait être
    utilisé uniquement pour attribuer une valeur à une variable.
    

(25) def: missing parentheses
-----------------------------

.. code-block:: none


    Traceback (most recent call last):
      File "TESTS:\trb_syntax_common.py", line 49, in create_tracebacks
        __import__(name)
      File "TESTS:\syntax\async_def_missing_parens.py", line 1
        async def name:
                      ^
    SyntaxError: invalid syntax
    
        Avez-vous oublié d’ajouter des parenthèses ?
        
    Une exception de type `SyntaxError` se produit lorsque Python ne peut pas comprendre votre code.
    
    Python peut seulement comprendre le code du fichier
    'TESTS:\syntax\async_def_missing_parens.py'
    jusqu'à l'endroit indiqué par ^.
    
    -->1: async def name:
                        ^

    Vous avez peut-être oublié d’inclure des parenthèses.
    Vous avez peut-être voulu écrire 
    
        async def name():
    

(26) Augmented assignment to literal
------------------------------------

.. code-block:: none


    Traceback (most recent call last):
      File "TESTS:\trb_syntax_common.py", line 49, in create_tracebacks
        __import__(name)
      File "TESTS:\syntax\augmented_assignment_to_literal.py", line 1
        if "word" := True:
           ^
    SyntaxError: cannot use assignment expressions with literal
    
        Vous ne pouvez assigner des objets qu’à des identifiants (noms de variables).
        
    Une exception de type `SyntaxError` se produit lorsque Python ne peut pas comprendre votre code.
    
    Python peut seulement comprendre le code du fichier
    'TESTS:\syntax\augmented_assignment_to_literal.py'
    jusqu'à l'endroit indiqué par ^.
    
    -->1: if "word" := True:
             ^

    Vous ne pouvez pas utiliser l’opérateur d’affectation augmentée `:=`,
    parfois appelé l’opérateur morse, avec des littéraux comme `"word"`.
    Vous ne pouvez attribuer des objets qu’à des identifiants (noms de variables).
    

(27) Walrus/Named assignment depending on Python version
--------------------------------------------------------

.. code-block:: none


    Traceback (most recent call last):
      File "TESTS:\trb_syntax_common.py", line 49, in create_tracebacks
        __import__(name)
      File "TESTS:\syntax\augmented_assigment_with_true.py", line 4
        (True := 1)
         ^
    SyntaxError: cannot use assignment expressions with True
    
        Vous ne pouvez pas attribuer une valeur à `True`.
    Une exception de type `SyntaxError` se produit lorsque Python ne peut pas comprendre votre code.
    
    Python peut seulement comprendre le code du fichier
    'TESTS:\syntax\augmented_assigment_with_true.py'
    jusqu'à l'endroit indiqué par ^.
    
       1: """Should raise SyntaxError: invalid syntax
       2: or (Python 3.8) cannot use named assignment with True"""
       3: 
    -->4: (True := 1)
           ^

    `True` est une constante dans python; vous ne pouvez pas lui assigner une valeur différente.
    
    

(28) Backslash instead of slash
-------------------------------

.. code-block:: none


    Traceback (most recent call last):
      File "TESTS:\trb_syntax_common.py", line 49, in create_tracebacks
        __import__(name)
      File "TESTS:\syntax\backslash_instead_of_slash.py", line 1
        a = 3 \ 4.0
                   ^
    SyntaxError: unexpected character after line continuation character
    
        Voulez-vous diviser par 4.0 ?
        
    Une exception de type `SyntaxError` se produit lorsque Python ne peut pas comprendre votre code.
    
    Python peut seulement comprendre le code du fichier
    'TESTS:\syntax\backslash_instead_of_slash.py'
    jusqu'à l'endroit indiqué par ^.
    
    -->1: a = 3 \ 4.0
                     ^

    Vous utilisez le caractère de continuation `\` en dehors d'une chaîne de caractères,
    et il est suivi par au moins un autre caractère.
    Je suppose que vous vouliez diviser par le nombre 4.0
    et avez écrit \ au lieu de /.

(29) break outside loop
-----------------------

.. code-block:: none


    Traceback (most recent call last):
      File "TESTS:\trb_syntax_common.py", line 49, in create_tracebacks
        __import__(name)
      File "TESTS:\syntax\break_outside_loop.py", line 4
        break
        ^
    SyntaxError: 'break' outside loop
    
    Une exception de type `SyntaxError` se produit lorsque Python ne peut pas comprendre votre code.
    
    Python peut seulement comprendre le code du fichier
    'TESTS:\syntax\break_outside_loop.py'
    jusqu'à l'endroit indiqué par ^.
    
       1: """Should raise SyntaxError: 'break' outside loop"""
       2: 
       3: if True:
    -->4:     break
              ^

    Le mot-clé Python `break` ne peut être utilisé qu'à l'intérieur d'une boucle `for` ou à l'intérieur d'une boucle `while`.
    

(30) Cannot use star operator
-----------------------------

.. code-block:: none


    Traceback (most recent call last):
      File "TESTS:\trb_syntax_common.py", line 49, in create_tracebacks
        __import__(name)
      File "TESTS:\syntax\cannot_use_star.py", line 3
        *a
        ^
    SyntaxError: can't use starred expression here
    
    Une exception de type `SyntaxError` se produit lorsque Python ne peut pas comprendre votre code.
    
    Python peut seulement comprendre le code du fichier
    'TESTS:\syntax\cannot_use_star.py'
    jusqu'à l'endroit indiqué par ^.
    
       1: """Should raise SyntaxError: can't use starred expression here"""
       2: 
    -->3: *a
          ^

    L’opérateur astérisque `*` est interprété comme signifiant que
    le déballage itérable doit être utilisé pour attribuer un nom
    à chaque élément d’un itérable, ce qui n’a pas de sens ici.
    

(31) Cannot use double star operator
------------------------------------

.. code-block:: none


    Traceback (most recent call last):
      File "TESTS:\trb_syntax_common.py", line 49, in create_tracebacks
        __import__(name)
      File "<fstring>", line 1
        (**k)
         ^
    SyntaxError: invalid syntax
    
    Une exception de type `SyntaxError` se produit lorsque Python ne peut pas comprendre votre code.
    
    Python peut seulement comprendre le code du fichier
    '<fstring>'
    jusqu'à l'endroit indiqué par ^.
    
    -->1: (**k)
           ^

    L’opérateur double astérisque, `**` est probablement interprété comme signifiant
    qu'un déballage de `dict` doit être utilisé ce qui n'est soit par permis
    ou n’a pas de sens ici.
    

(32) Missing class name
-----------------------

.. code-block:: none


    Traceback (most recent call last):
      File "TESTS:\trb_syntax_common.py", line 49, in create_tracebacks
        __import__(name)
      File "TESTS:\syntax\class_missing_name.py", line 1
        class:
             ^
    SyntaxError: invalid syntax
    
        Une classe a besoin d’un nom.
        
    Une exception de type `SyntaxError` se produit lorsque Python ne peut pas comprendre votre code.
    
    Python peut seulement comprendre le code du fichier
    'TESTS:\syntax\class_missing_name.py'
    jusqu'à l'endroit indiqué par ^.
    
    -->1: class:
               ^

    Un énoncé `class` doit inclure un nom :
    
        class NomQuelconque:
            ...
    
    

(33) Missing () for tuples in comprehension
-------------------------------------------

.. code-block:: none


    Traceback (most recent call last):
      File "TESTS:\trb_syntax_common.py", line 49, in create_tracebacks
        __import__(name)
      File "TESTS:\syntax\comprehension_missing_tuple_paren.py", line 1
        x = [i, i**2 for i in range(10)]
                     ^
    SyntaxError: invalid syntax
    
        Avez-vous oublié d’ajouter des parenthèses ?
        
    Une exception de type `SyntaxError` se produit lorsque Python ne peut pas comprendre votre code.
    
    Python peut seulement comprendre le code du fichier
    'TESTS:\syntax\comprehension_missing_tuple_paren.py'
    jusqu'à l'endroit indiqué par ^.
    
    -->1: x = [i, i**2 for i in range(10)]
                       ^

    Je suppose que vous écriviez une compréhension ou une expression génératrice
    et vous avez oublié d’inclure des parenthèses autour des tuples.
    Voici un exemple: au lieu d’écrire
    
        [i, i**2 for i in range(10)]
    
    vous auriez besoin d’écrire
    
        [(i, i**2) for i in range(10)]
    
    

(34) Comprehension with condition (no else)
-------------------------------------------

.. code-block:: none


    Traceback (most recent call last):
      File "TESTS:\trb_syntax_common.py", line 49, in create_tracebacks
        __import__(name)
      File "TESTS:\syntax\comprehension_with_condition_no_else.py", line 1
        a = [f(x) if condition for x in sequence]
                               ^
    SyntaxError: invalid syntax
    
    Une exception de type `SyntaxError` se produit lorsque Python ne peut pas comprendre votre code.
    
    Python peut seulement comprendre le code du fichier
    'TESTS:\syntax\comprehension_with_condition_no_else.py'
    jusqu'à l'endroit indiqué par ^.
    
    -->1: a = [f(x) if condition for x in sequence]
                                 ^

    Je suppose que vous écriviez une compréhension ou une expression génératrice
    et avez utiliser le mauvais ordre pour une condition.
    L'ordre correct dépend de la présence ou non d'une clause `else`.
    Par exemple, le bon ordre pour une compréhension de liste avec
    une condition est
    
        [f(x) if condition else autre for x in séquence]  # 'if' avant 'for'
    
    ou, s'il n'y a pas de `else`
    
        [f(x) pour x in séquence si condition]  # 'if' après 'for'
    
    

(35) Comprehension with condition (with else)
---------------------------------------------

.. code-block:: none


    Traceback (most recent call last):
      File "TESTS:\trb_syntax_common.py", line 49, in create_tracebacks
        __import__(name)
      File "TESTS:\syntax\comprehension_with_condition_with_else.py", line 1
        a = [f(x) for x in sequence if condition else other]
                                                 ^
    SyntaxError: invalid syntax
    
    Une exception de type `SyntaxError` se produit lorsque Python ne peut pas comprendre votre code.
    
    Python peut seulement comprendre le code du fichier
    'TESTS:\syntax\comprehension_with_condition_with_else.py'
    jusqu'à l'endroit indiqué par ^.
    
    -->1: a = [f(x) for x in sequence if condition else other]
                                                   ^

    Je suppose que vous écriviez une compréhension ou une expression génératrice
    et avez utiliser le mauvais ordre pour une condition.
    L'ordre correct dépend de la présence ou non d'une clause `else`.
    Par exemple, le bon ordre pour une compréhension de liste avec
    une condition est
    
        [f(x) if condition else autre for x in séquence]  # 'if' avant 'for'
    
    ou, s'il n'y a pas de `else`
    
        [f(x) pour x in séquence si condition]  # 'if' après 'for'
    
    

(36) continue outside loop
--------------------------

.. code-block:: none


    Traceback (most recent call last):
      File "TESTS:\trb_syntax_common.py", line 49, in create_tracebacks
        __import__(name)
      File "TESTS:\syntax\continue_outside_loop.py", line 4
        continue
        ^
    SyntaxError: 'continue' not properly in loop
    
    Une exception de type `SyntaxError` se produit lorsque Python ne peut pas comprendre votre code.
    
    Python peut seulement comprendre le code du fichier
    'TESTS:\syntax\continue_outside_loop.py'
    jusqu'à l'endroit indiqué par ^.
    
       1: """Should raise SyntaxError: 'continue' outside loop"""
       2: 
       3: if True:
    -->4:     continue
              ^

    Le mot-clé Python `continue` ne peut être utilisé qu'à l'intérieur d'une boucle `for` ou à l'intérieur d'une boucle `while`.
    

(37) Copy/paste from interpreter
--------------------------------

.. code-block:: none


    Traceback (most recent call last):
      File "TESTS:\trb_syntax_common.py", line 49, in create_tracebacks
        __import__(name)
      File "TESTS:\syntax\copy_pasted_code.py", line 2
        >>> print("Hello World!")
        ^
    SyntaxError: invalid syntax
    
        Avez-vous utilisé le copier-coller ?
        
    Une exception de type `SyntaxError` se produit lorsque Python ne peut pas comprendre votre code.
    
    Python peut seulement comprendre le code du fichier
    'TESTS:\syntax\copy_pasted_code.py'
    jusqu'à l'endroit indiqué par ^.
    
       1: """Should raise SyntaxError: invalid syntax"""
    -->2: >>> print("Hello World!")
          ^

    On dirait que vous avez copié-collé le code d’un interprète interactif.
    L’invite Python, `>>>`, ne doit pas être incluse dans votre code.
    

(38) def: positional arg after kwargs
-------------------------------------

.. code-block:: none


    Traceback (most recent call last):
      File "TESTS:\trb_syntax_common.py", line 49, in create_tracebacks
        __import__(name)
      File "TESTS:\syntax\def_arg_after_kwarg.py", line 1
        def test(a, **kwargs, b):
                              ^
    SyntaxError: invalid syntax
    
        Les arguments positionnels doivent être avant les arguments nommés.
        
    Une exception de type `SyntaxError` se produit lorsque Python ne peut pas comprendre votre code.
    
    Python peut seulement comprendre le code du fichier
    'TESTS:\syntax\def_arg_after_kwarg.py'
    jusqu'à l'endroit indiqué par ^.
    
    -->1: def test(a, **kwargs, b):
                                ^

    Les arguments positionnels doivent être avant les arguments nommés.
    `b` est un argument positionnel qui apparaît après un ou plusieurs
    arguments nommés dans votre définition de fonction.
    

(39) def: named arguments must follow bare *
--------------------------------------------

.. code-block:: none


    Traceback (most recent call last):
      File "TESTS:\trb_syntax_common.py", line 49, in create_tracebacks
        __import__(name)
      File "TESTS:\syntax\def_bare_star_arg.py", line 4
        def f(*):
              ^
    SyntaxError: named arguments must follow bare *
    
        Avez-vous oublié d’ajouter quelque chose après `*` ?
        
    Une exception de type `SyntaxError` se produit lorsque Python ne peut pas comprendre votre code.
    
    Python peut seulement comprendre le code du fichier
    'TESTS:\syntax\def_bare_star_arg.py'
    jusqu'à l'endroit indiqué par ^.
    
       1: # SyntaxError: named arguments must follow bare *
       2: 
       3: 
    -->4: def f(*):
                ^

    En supposant que vous définissiez une fonction, vous avez besoin
    de remplacer `*` soit par `*arguments` ou
    par `*, argument=valeur`.
    

(40) def: misused as code block
-------------------------------

.. code-block:: none


    Traceback (most recent call last):
      File "TESTS:\trb_syntax_common.py", line 49, in create_tracebacks
        __import__(name)
      File "TESTS:\syntax\def_code_block.py", line 3
        def :
            ^
    SyntaxError: invalid syntax
    
        Une fonction a besoin d’un nom.
        
    Une exception de type `SyntaxError` se produit lorsque Python ne peut pas comprendre votre code.
    
    Python peut seulement comprendre le code du fichier
    'TESTS:\syntax\def_code_block.py'
    jusqu'à l'endroit indiqué par ^.
    
       1: """Should raise SyntaxError"""
       2: 
    -->3: def :
              ^

    Vous vouliez définir une fonction, mais vous avez fait des erreurs de syntaxe.
    La syntaxe correct est :
    
        def nom ( ... ):
    

(41) def: misused as code block - 2
-----------------------------------

.. code-block:: none


    Traceback (most recent call last):
      File "TESTS:\trb_syntax_common.py", line 49, in create_tracebacks
        __import__(name)
      File "TESTS:\syntax\def_code_block_2.py", line 2
        def :
            ^
    SyntaxError: invalid syntax
    
        Les fonctions et les méthodes ont besoin d’un nom.
        
    Une exception de type `SyntaxError` se produit lorsque Python ne peut pas comprendre votre code.
    
    Python peut seulement comprendre le code du fichier
    'TESTS:\syntax\def_code_block_2.py'
    jusqu'à l'endroit indiqué par ^.
    
       1: class A:
    -->2:     def :
                  ^

    Vous vouliez définir une fonction ou une méthode, mais vous avez fait des erreurs de syntaxe.
    La syntaxe correct est :
    
        def nom ( ... ):
    

(42) def: dict as argument
--------------------------

.. code-block:: none


    Traceback (most recent call last):
      File "TESTS:\trb_syntax_common.py", line 49, in create_tracebacks
        __import__(name)
      File "TESTS:\syntax\def_dict_as_arg.py", line 1
        def test({'a': 1}, y):  # dict as first argument
                 ^
    SyntaxError: invalid syntax
    
        Vous ne pouvez pas avoir des `dict` ou des `set` explicite comme arguments de fonction.
        
    Une exception de type `SyntaxError` se produit lorsque Python ne peut pas comprendre votre code.
    
    Python peut seulement comprendre le code du fichier
    'TESTS:\syntax\def_dict_as_arg.py'
    jusqu'à l'endroit indiqué par ^.
    
    -->1: def test({'a': 1}, y):  # dict as first argument
                   ^

    Vous ne pouvez pas avoir des `dict` ou des `set` explicite comme arguments de fonction.
    Vous ne pouvez utiliser que des identifiants (noms de variables) comme arguments de fonction.
    

(43) def: Keyword arg only once in function definition
------------------------------------------------------

.. code-block:: none


    Traceback (most recent call last):
      File "TESTS:\trb_syntax_common.py", line 49, in create_tracebacks
        __import__(name)
      File "TESTS:\syntax\def_duplicate_arg.py", line 4
        def f(aa=1, aa=2):
        ^
    SyntaxError: duplicate argument 'aa' in function definition
    
    Une exception de type `SyntaxError` se produit lorsque Python ne peut pas comprendre votre code.
    
    Python peut seulement comprendre le code du fichier
    'TESTS:\syntax\def_duplicate_arg.py'
    jusqu'à l'endroit indiqué par ^.
    
       1: """Should raise SyntaxError: duplicate argument 'aa' in function definition"""
       2: 
       3: 
    -->4: def f(aa
          ^

    Vous avez défini une fonction répétant l'argument nommé
    
        aa
    deux fois; chaque argument nommé ne doit apparaître qu'une seule fois dans une définition de fonction.
    

(44) def: semi-colon after colon
--------------------------------

.. code-block:: none


    Traceback (most recent call last):
      File "TESTS:\trb_syntax_common.py", line 49, in create_tracebacks
        __import__(name)
      File "TESTS:\syntax\def_extra_semi_colon.py", line 1
        def test():;
                   ^
    SyntaxError: invalid syntax
    
        Avez-vous écrit quelque chose par erreur après les deux points `:` ?
        
    Une exception de type `SyntaxError` se produit lorsque Python ne peut pas comprendre votre code.
    
    Python peut seulement comprendre le code du fichier
    'TESTS:\syntax\def_extra_semi_colon.py'
    jusqu'à l'endroit indiqué par ^.
    
    -->1: def test():;
                     ^

    Une définition de fonction doit se terminer par deux point, `:`.
    Un bloc de code doit venir après les deux points.
    Si vous supprimez `;`, cela pourrait possiblement résoudre le problème.
    

(45) def: extra comma
---------------------

.. code-block:: none


    Traceback (most recent call last):
      File "TESTS:\trb_syntax_common.py", line 49, in create_tracebacks
        __import__(name)
      File "TESTS:\syntax\def_extra_comma.py", line 1
        def test(a,,b):
                   ^
    SyntaxError: invalid syntax
    
        Voulez-vous écrire `,`?
        
    Une exception de type `SyntaxError` se produit lorsque Python ne peut pas comprendre votre code.
    
    Python peut seulement comprendre le code du fichier
    'TESTS:\syntax\def_extra_comma.py'
    jusqu'à l'endroit indiqué par ^.
    
    -->1: def test(a,,b):
                     ^

    Je soupçonne que vous avez écrit `,` par erreur.
    L’énoncé suivant ne contient aucune erreur de syntaxe :
    
        def test(a,b):

(46) def: unspecified keywords before /
---------------------------------------

.. code-block:: none


    Traceback (most recent call last):
      File "TESTS:\trb_syntax_common.py", line 49, in create_tracebacks
        __import__(name)
      File "TESTS:\syntax\def_forward_slash_1.py", line 1
        def test(a, **kwargs, /):
                              ^
    SyntaxError: invalid syntax
    
        Les arguments nommés doivent apparaître après le symbole `/`.
        
    Une exception de type `SyntaxError` se produit lorsque Python ne peut pas comprendre votre code.
    
    Python peut seulement comprendre le code du fichier
    'TESTS:\syntax\def_forward_slash_1.py'
    jusqu'à l'endroit indiqué par ^.
    
    -->1: def test(a, **kwargs, /):
                                ^

    `/` indique que les arguments précédents dans une définition de fonction
    sont des arguments positionnels.
    Vous avez quelques arguments nommés arbitraires qui apparaissent avant
    le symbole `/`.
    

(47) def: / before star
-----------------------

.. code-block:: none


    Traceback (most recent call last):
      File "TESTS:\trb_syntax_common.py", line 49, in create_tracebacks
        __import__(name)
      File "TESTS:\syntax\def_forward_slash_2.py", line 1
        def test(a, *, b, /):
                          ^
    SyntaxError: invalid syntax
    
        `*` doit apparaître après `/` dans une définition de fonction.
        
    Une exception de type `SyntaxError` se produit lorsque Python ne peut pas comprendre votre code.
    
    Python peut seulement comprendre le code du fichier
    'TESTS:\syntax\def_forward_slash_2.py'
    jusqu'à l'endroit indiqué par ^.
    
    -->1: def test(a, *, b, /):
                            ^

    `/` indique que les arguments précédents dans une définition de fonction
    sont des arguments positionnels.
    Toutefois, `*` indique que les arguments
    qui suivent doivent être des arguments nommés.
    Lorsqu’ils sont utilisés ensemble, `/` doit apparaître avant `*`.
    

(48) def: / before star arg
---------------------------

.. code-block:: none


    Traceback (most recent call last):
      File "TESTS:\trb_syntax_common.py", line 49, in create_tracebacks
        __import__(name)
      File "TESTS:\syntax\def_forward_slash_3.py", line 1
        def test(a, *arg, /):
                          ^
    SyntaxError: invalid syntax
    
        `*arg` doit apparaître après `/` dans une définition de fonction.
        
    Une exception de type `SyntaxError` se produit lorsque Python ne peut pas comprendre votre code.
    
    Python peut seulement comprendre le code du fichier
    'TESTS:\syntax\def_forward_slash_3.py'
    jusqu'à l'endroit indiqué par ^.
    
    -->1: def test(a, *arg, /):
                            ^

    `/` indique que les arguments précédents dans une définition de fonction
    sont des arguments positionnels.
    `*arg` doit apparaître après `/` dans une définition de fonction.
    

(49) def: / used twice
----------------------

.. code-block:: none


    Traceback (most recent call last):
      File "TESTS:\trb_syntax_common.py", line 49, in create_tracebacks
        __import__(name)
      File "TESTS:\syntax\def_forward_slash_4.py", line 1
        def test(a, /, b, /):
                          ^
    SyntaxError: invalid syntax
    
        Vous ne pouvez utiliser `/` qu’une seule fois dans une définition de fonction.
        
    Une exception de type `SyntaxError` se produit lorsque Python ne peut pas comprendre votre code.
    
    Python peut seulement comprendre le code du fichier
    'TESTS:\syntax\def_forward_slash_4.py'
    jusqu'à l'endroit indiqué par ^.
    
    -->1: def test(a, /, b, /):
                            ^

    Vous ne pouvez utiliser `/` qu’une seule fois dans une définition de fonction.
    

(50) def: non-identifier as a function name
-------------------------------------------

.. code-block:: none


    Traceback (most recent call last):
      File "TESTS:\trb_syntax_common.py", line 49, in create_tracebacks
        __import__(name)
      File "TESTS:\syntax\def_function_name_invalid.py", line 3
        def 2be():
            ^
    SyntaxError: invalid syntax
    
        Vous avez écrit un nom de fonction invalide.
        
    Une exception de type `SyntaxError` se produit lorsque Python ne peut pas comprendre votre code.
    
    Python peut seulement comprendre le code du fichier
    'TESTS:\syntax\def_function_name_invalid.py'
    jusqu'à l'endroit indiqué par ^.
    
       1: 
       2: 
    -->3: def 2be():
              ^

    Le nom d’une fonction doit être un identificateur Python valide,
    c’est-à-dire un nom qui commence par une lettre ou un caractère de soulignement, `_`,
    et qui ne contient que des lettres, des chiffres ou le caractère de soulignement.
    

(51) def: using a string as a function name
-------------------------------------------

.. code-block:: none


    Traceback (most recent call last):
      File "TESTS:\trb_syntax_common.py", line 49, in create_tracebacks
        __import__(name)
      File "TESTS:\syntax\def_function_name_string.py", line 3
        def "function"():
            ^
    SyntaxError: invalid syntax
    
        Le nom d’une fonction doit être un identificateur Python valide,
        c’est-à-dire un nom qui commence par une lettre ou un caractère de soulignement, `_`,
        et qui ne contient que des lettres, des chiffres ou le caractère de soulignement.
        Vous avez essayé d’utiliser une chaîne de caractères comme nom de fonction.
        
    Une exception de type `SyntaxError` se produit lorsque Python ne peut pas comprendre votre code.
    
    Python peut seulement comprendre le code du fichier
    'TESTS:\syntax\def_function_name_string.py'
    jusqu'à l'endroit indiqué par ^.
    
       1: 
       2: 
    -->3: def "function"():
              ^

    Le nom d’une fonction doit être un identificateur Python valide,
    c’est-à-dire un nom qui commence par une lettre ou un caractère de soulignement, `_`,
    et qui ne contient que des lettres, des chiffres ou le caractère de soulignement.
    Vous avez essayé d’utiliser une chaîne de caractères comme nom de fonction.
    

(52) def: keyword cannot be argument in def - 1
-----------------------------------------------

.. code-block:: none


    Traceback (most recent call last):
      File "TESTS:\trb_syntax_common.py", line 49, in create_tracebacks
        __import__(name)
      File "TESTS:\syntax\def_keyword_as_arg_1.py", line 5
        def f(None=1):
              ^
    SyntaxError: invalid syntax
    
    Une exception de type `SyntaxError` se produit lorsque Python ne peut pas comprendre votre code.
    
    Python peut seulement comprendre le code du fichier
    'TESTS:\syntax\def_keyword_as_arg_1.py'
    jusqu'à l'endroit indiqué par ^.
    
       1: """Should raise SyntaxError: invalid syntax
       2: """
       3: 
       4: 
    -->5: def f(None=1):
                ^

    Vous avez tenté d'utiliser le mot clé Python `None` comme argument
    dans la définition d'une fonction où un identificateur
    (nom de variable) était attendu.
    

(53) def: keyword cannot be argument in def - 2
-----------------------------------------------

.. code-block:: none


    Traceback (most recent call last):
      File "TESTS:\trb_syntax_common.py", line 49, in create_tracebacks
        __import__(name)
      File "TESTS:\syntax\def_keyword_as_arg_2.py", line 5
        def f(x, True):
                 ^
    SyntaxError: invalid syntax
    
    Une exception de type `SyntaxError` se produit lorsque Python ne peut pas comprendre votre code.
    
    Python peut seulement comprendre le code du fichier
    'TESTS:\syntax\def_keyword_as_arg_2.py'
    jusqu'à l'endroit indiqué par ^.
    
       1: """Should raise SyntaxError: invalid syntax
       2: """
       3: 
       4: 
    -->5: def f(x, True):
                   ^

    Vous avez tenté d'utiliser le mot clé Python `True` comme argument
    dans la définition d'une fonction où un identificateur
    (nom de variable) était attendu.
    

(54) def: keyword cannot be argument in def - 3
-----------------------------------------------

.. code-block:: none


    Traceback (most recent call last):
      File "TESTS:\trb_syntax_common.py", line 49, in create_tracebacks
        __import__(name)
      File "TESTS:\syntax\def_keyword_as_arg_3.py", line 5
        def f(*None):
               ^
    SyntaxError: invalid syntax
    
    Une exception de type `SyntaxError` se produit lorsque Python ne peut pas comprendre votre code.
    
    Python peut seulement comprendre le code du fichier
    'TESTS:\syntax\def_keyword_as_arg_3.py'
    jusqu'à l'endroit indiqué par ^.
    
       1: """Should raise SyntaxError: invalid syntax
       2: """
       3: 
       4: 
    -->5: def f(*None):
                 ^

    Vous avez tenté d'utiliser le mot clé Python `None` comme argument
    dans la définition d'une fonction où un identificateur
    (nom de variable) était attendu.
    

(55) def: keyword cannot be argument in def - 4
-----------------------------------------------

.. code-block:: none


    Traceback (most recent call last):
      File "TESTS:\trb_syntax_common.py", line 49, in create_tracebacks
        __import__(name)
      File "TESTS:\syntax\def_keyword_as_arg_4.py", line 5
        def f(**None):
                ^
    SyntaxError: invalid syntax
    
    Une exception de type `SyntaxError` se produit lorsque Python ne peut pas comprendre votre code.
    
    Python peut seulement comprendre le code du fichier
    'TESTS:\syntax\def_keyword_as_arg_4.py'
    jusqu'à l'endroit indiqué par ^.
    
       1: """Should raise SyntaxError: invalid syntax
       2: """
       3: 
       4: 
    -->5: def f(**None):
                  ^

    Vous avez tenté d'utiliser le mot clé Python `None` comme argument
    dans la définition d'une fonction où un identificateur
    (nom de variable) était attendu.
    

(56) def: Python keyword as function name
-----------------------------------------

.. code-block:: none


    Traceback (most recent call last):
      File "TESTS:\trb_syntax_common.py", line 49, in create_tracebacks
        __import__(name)
      File "TESTS:\syntax\def_keyword_as_name.py", line 3
        def pass():
            ^
    SyntaxError: invalid syntax
    
        Vous avez tenté d'utiliser le mot clé Python `{kwd}` comme nom de fonction.
        
    Une exception de type `SyntaxError` se produit lorsque Python ne peut pas comprendre votre code.
    
    Python peut seulement comprendre le code du fichier
    'TESTS:\syntax\def_keyword_as_name.py'
    jusqu'à l'endroit indiqué par ^.
    
       1: """Should raise SyntaxError: invalid syntax"""
       2: 
    -->3: def pass():
              ^

    Vous avez tenté d'utiliser le mot clé Python `pass` comme nom de fonction.
    Ceci n’est pas permis.
    
    

(57) def: list as argument - 1
------------------------------

.. code-block:: none


    Traceback (most recent call last):
      File "TESTS:\trb_syntax_common.py", line 49, in create_tracebacks
        __import__(name)
      File "TESTS:\syntax\def_list_as_arg_1.py", line 1
        def test([x], y):  # list as first argument
                 ^
    SyntaxError: invalid syntax
    
        Vous ne pouvez pas avoir de listes explicites comme arguments de fonction.
        
    Une exception de type `SyntaxError` se produit lorsque Python ne peut pas comprendre votre code.
    
    Python peut seulement comprendre le code du fichier
    'TESTS:\syntax\def_list_as_arg_1.py'
    jusqu'à l'endroit indiqué par ^.
    
    -->1: def test([x], y):  # list as first argument
                   ^

    Vous ne pouvez pas avoir de listes explicites comme arguments de fonction.
    Vous ne pouvez utiliser que des identifiants (noms de variables) comme arguments de fonction.
    

(58) def: list as argument - 2
------------------------------

.. code-block:: none


    Traceback (most recent call last):
      File "TESTS:\trb_syntax_common.py", line 49, in create_tracebacks
        __import__(name)
      File "TESTS:\syntax\def_list_as_arg_2.py", line 1
        def test(x, [y]):  # list as second argument, after comma
                    ^
    SyntaxError: invalid syntax
    
        Vous ne pouvez pas avoir de listes explicites comme arguments de fonction.
        
    Une exception de type `SyntaxError` se produit lorsque Python ne peut pas comprendre votre code.
    
    Python peut seulement comprendre le code du fichier
    'TESTS:\syntax\def_list_as_arg_2.py'
    jusqu'à l'endroit indiqué par ^.
    
    -->1: def test(x, [y]):  # list as second argument, after comma
                      ^

    Vous ne pouvez pas avoir de listes explicites comme arguments de fonction.
    Vous ne pouvez utiliser que des identifiants (noms de variables) comme arguments de fonction.
    

(59) def: missing colon
-----------------------

.. code-block:: none


    Traceback (most recent call last):
      File "TESTS:\trb_syntax_common.py", line 49, in create_tracebacks
        __import__(name)
      File "TESTS:\syntax\def_missing_colon.py", line 1
        def test()
                  ^
    SyntaxError: invalid syntax
    
        Avez-vous oublié d’ajouter les deux points `:` ?
        
    Une exception de type `SyntaxError` se produit lorsque Python ne peut pas comprendre votre code.
    
    Python peut seulement comprendre le code du fichier
    'TESTS:\syntax\def_missing_colon.py'
    jusqu'à l'endroit indiqué par ^.
    
    -->1: def test()
                    ^

    Une définition de fonction doit se terminer par deux point, `:`.
    

(60) def: missing comma between function args
---------------------------------------------

.. code-block:: none


    Traceback (most recent call last):
      File "TESTS:\trb_syntax_common.py", line 49, in create_tracebacks
        __import__(name)
      File "TESTS:\syntax\def_missing_comma.py", line 4
        def a(b, c d):
                   ^
    SyntaxError: invalid syntax
    
        Avez-vous oublié une virgule ?
        
    Une exception de type `SyntaxError` se produit lorsque Python ne peut pas comprendre votre code.
    
    Python peut seulement comprendre le code du fichier
    'TESTS:\syntax\def_missing_comma.py'
    jusqu'à l'endroit indiqué par ^.
    
       1: """Should raise SyntaxError: invalid syntax"""
       2: 
       3: 
    -->4: def a(b, c d):
                     ^

    Python indique que l’erreur est causée par `d` écrit tout juste après `c`.
    Il est également possible que vous ayez oublié une virgule entre les éléments d'un tuple,
    ou entre les arguments d'une fonction, avant la position indiquée par ^.
    Peut-être que vous vouliez plutôt
    
        def a(b, c, d):
    

(61) def: missing parentheses
-----------------------------

.. code-block:: none


    Traceback (most recent call last):
      File "TESTS:\trb_syntax_common.py", line 49, in create_tracebacks
        __import__(name)
      File "TESTS:\syntax\def_missing_parens.py", line 3
        def name:
                ^
    SyntaxError: invalid syntax
    
        Avez-vous oublié d’ajouter des parenthèses ?
        
    Une exception de type `SyntaxError` se produit lorsque Python ne peut pas comprendre votre code.
    
    Python peut seulement comprendre le code du fichier
    'TESTS:\syntax\def_missing_parens.py'
    jusqu'à l'endroit indiqué par ^.
    
       1: """Should raise SyntaxError"""
       2: 
    -->3: def name:
                  ^

    Vous avez peut-être oublié d’inclure des parenthèses.
    Vous avez peut-être voulu écrire 
    
        def name():
    

(62) def: missing parentheses around arguments
----------------------------------------------

.. code-block:: none


    Traceback (most recent call last):
      File "TESTS:\trb_syntax_common.py", line 49, in create_tracebacks
        __import__(name)
      File "TESTS:\syntax\def_missing_parens_2.py", line 2
        def name a, b:
                 ^
    SyntaxError: invalid syntax
    
        Avez-vous oublié d’ajouter des parenthèses ?
        
    Une exception de type `SyntaxError` se produit lorsque Python ne peut pas comprendre votre code.
    
    Python peut seulement comprendre le code du fichier
    'TESTS:\syntax\def_missing_parens_2.py'
    jusqu'à l'endroit indiqué par ^.
    
       1: 
    -->2: def name a, b:
                   ^

    Vous avez peut-être oublié d’inclure des parenthèses.
    Vous avez peut-être voulu écrire 
    
        def name (a, b):
    

(63) def: missing function name
-------------------------------

.. code-block:: none


    Traceback (most recent call last):
      File "TESTS:\trb_syntax_common.py", line 49, in create_tracebacks
        __import__(name)
      File "TESTS:\syntax\def_missing_name.py", line 3
        def ( arg )  :
            ^
    SyntaxError: invalid syntax
    
    Une exception de type `SyntaxError` se produit lorsque Python ne peut pas comprendre votre code.
    
    Python peut seulement comprendre le code du fichier
    'TESTS:\syntax\def_missing_name.py'
    jusqu'à l'endroit indiqué par ^.
    
       1: """Should raise SyntaxError"""
       2: 
    -->3: def ( arg )  :
              ^

    Vous avez oublié de nommer votre fonction.
    La syntaxe correct est :
    
        def nom ( ... ):
    

(64) def: name is parameter and global
--------------------------------------

.. code-block:: none


    Traceback (most recent call last):
      File "TESTS:\trb_syntax_common.py", line 49, in create_tracebacks
        __import__(name)
      File "TESTS:\syntax\def_name_is_parameter_and_global.py", line 6
        global x
        ^
    SyntaxError: name 'x' is parameter and global
    
    Une exception de type `SyntaxError` se produit lorsque Python ne peut pas comprendre votre code.
    
    Python peut seulement comprendre le code du fichier
    'TESTS:\syntax\def_name_is_parameter_and_global.py'
    jusqu'à l'endroit indiqué par ^.
    
       1: """Should raise SyntaxError: name 'x' is parameter and global
       2: """
       3: 
       4: 
       5: def f(x):
    -->6:     global x
              ^

    Vous avec inclus l'énoncé
    
            global x
    
    
    indiquant que `x` est une variable définie en dehors d'une fonction.
    Vous utilisez également le même `x` comme un argument pour cette
    fonction; un argument de fonction est une variable locale connue seulement
    à l'intérieur de cette fonction, ce qui est le contraire de ce que `global` sous-entendait.
    

(65) def: non-default argument follows default argument
-------------------------------------------------------

.. code-block:: none


    Traceback (most recent call last):
      File "TESTS:\trb_syntax_common.py", line 49, in create_tracebacks
        __import__(name)
      File "TESTS:\syntax\def_non_default_after_default.py", line 5
        def test(a=1, b):
                 ^
    SyntaxError: non-default argument follows default argument
    
    Une exception de type `SyntaxError` se produit lorsque Python ne peut pas comprendre votre code.
    
    Python peut seulement comprendre le code du fichier
    'TESTS:\syntax\def_non_default_after_default.py'
    jusqu'à l'endroit indiqué par ^.
    
       1: """Should raise SyntaxError: non-default argument follows default argument
       2: """
       3: 
       4: 
    -->5: def test(a=1, b):
                   ^

    Dans Python, vous pouvez définir les fonctions avec seulement des arguments de position
    
        def test(a, b, c): ...
    
    ou seulement des arguments nommés
    
        def test(a=1, b=2, c=3): ...
    
    ou une combinaison des deux
    
        def test(a, b, c=3): ...
    
    mais avec les arguments nommés apparaissant après tous les arguments positionnels.
    Selon Python, vous avez utilisé des arguments positionnels après des arguments nommés.
    

(66) Single number used as arg in function def
----------------------------------------------

.. code-block:: none


    Traceback (most recent call last):
      File "TESTS:\trb_syntax_common.py", line 49, in create_tracebacks
        __import__(name)
      File "TESTS:\syntax\def_number_as_arg.py", line 1
        def f(1):
              ^
    SyntaxError: invalid syntax
    
        Vous ne pouvez pas utiliser un nombre comme argument de fonction.
        
    Une exception de type `SyntaxError` se produit lorsque Python ne peut pas comprendre votre code.
    
    Python peut seulement comprendre le code du fichier
    'TESTS:\syntax\def_number_as_arg.py'
    jusqu'à l'endroit indiqué par ^.
    
    -->1: def f(1):
                ^

    Vous avez utilisé un nombre comme argument lors de la définition d’une fonction.
    Vous ne pouvez utiliser que des identificateurs (noms de variables) comme arguments de fonction.
    

(67) def: operator instead of comma
-----------------------------------

.. code-block:: none


    Traceback (most recent call last):
      File "TESTS:\trb_syntax_common.py", line 49, in create_tracebacks
        __import__(name)
      File "TESTS:\syntax\def_operator_instead_of_comma.py", line 1
        def test(a + b):
                   ^
    SyntaxError: invalid syntax
    
        Avez-vous oublié une virgule ?
        
    Une exception de type `SyntaxError` se produit lorsque Python ne peut pas comprendre votre code.
    
    Python peut seulement comprendre le code du fichier
    'TESTS:\syntax\def_operator_instead_of_comma.py'
    jusqu'à l'endroit indiqué par ^.
    
    -->1: def test(a + b):
                     ^

    Vous ne pouvez pas avoir d’opérateurs comme arguments de fonction.
    Je soupçonne que vous avez écrit `+` au lieu d’une virgule.
    L’énoncé suivant ne contient aucune erreur de syntaxe :
    
        def test(a , b):

(68) def: operator instead of equal
-----------------------------------

.. code-block:: none


    Traceback (most recent call last):
      File "TESTS:\trb_syntax_common.py", line 49, in create_tracebacks
        __import__(name)
      File "TESTS:\syntax\def_operator_instead_of_equal.py", line 1
        def test(a, b=3, c+None):
                          ^
    SyntaxError: invalid syntax
    
        Voulez-vous écrire un signe égal ?
        
    Une exception de type `SyntaxError` se produit lorsque Python ne peut pas comprendre votre code.
    
    Python peut seulement comprendre le code du fichier
    'TESTS:\syntax\def_operator_instead_of_equal.py'
    jusqu'à l'endroit indiqué par ^.
    
    -->1: def test(a, b=3, c+None):
                            ^

    Vous ne pouvez pas avoir d’opérateurs comme arguments de fonction.
    Je soupçonne que vous avez écrit `+` au lieu d’un signe d'égalité.
    L’énoncé suivant ne contient aucune erreur de syntaxe :
    
        def test(a, b=3, c=None):

(69) def: operator instead of name
----------------------------------

.. code-block:: none


    Traceback (most recent call last):
      File "TESTS:\trb_syntax_common.py", line 49, in create_tracebacks
        __import__(name)
      File "TESTS:\syntax\def_operator_instead_of_name.py", line 1
        def test(a, +, b):
                    ^
    SyntaxError: invalid syntax
    
        Vous ne pouvez pas utiliser `+` comme argument.
        
    Une exception de type `SyntaxError` se produit lorsque Python ne peut pas comprendre votre code.
    
    Python peut seulement comprendre le code du fichier
    'TESTS:\syntax\def_operator_instead_of_name.py'
    jusqu'à l'endroit indiqué par ^.
    
    -->1: def test(a, +, b):
                      ^

    Je soupçonne que vous avez écrit `+` par erreur.
    Si vous le remplacez par un nom de variable unique,
    le résultat n'aura aucun erreur de syntaxe.
    

(70) def: positional argument follows keyword argument
------------------------------------------------------

.. code-block:: none


    Traceback (most recent call last):
      File "TESTS:\trb_syntax_common.py", line 49, in create_tracebacks
        __import__(name)
      File "TESTS:\syntax\def_positional_after_keyword_arg.py", line 5
        test(a=1, b)
                  ^
    SyntaxError: positional argument follows keyword argument
    
    Une exception de type `SyntaxError` se produit lorsque Python ne peut pas comprendre votre code.
    
    Python peut seulement comprendre le code du fichier
    'TESTS:\syntax\def_positional_after_keyword_arg.py'
    jusqu'à l'endroit indiqué par ^.
    
       1: """Should raise SyntaxError: positional argument follows keyword argument
       2: """
       3: 
       4: 
    -->5: test(a=1, b)
                    ^

    Dans Python, vous pouvez invoquer les fonctions avec seulement des arguments de position
    
        test(1, 2, 3)
    
    ou seulement des arguments nommés
    
        test (a=1, b=2, c=3)
    
    ou une combinaison des deux
    
        test(1, 2, c=3)
    
    mais avec les arguments nommés apparaissant après tous les arguments positionnels.
    Selon Python, vous avez utilisé des arguments positionnels après des arguments nommés.
    

(71) def: semi-colon instead of colon
-------------------------------------

.. code-block:: none


    Traceback (most recent call last):
      File "TESTS:\trb_syntax_common.py", line 49, in create_tracebacks
        __import__(name)
      File "TESTS:\syntax\def_semi_colon_instead_of_colon.py", line 1
        def test();
                  ^
    SyntaxError: invalid syntax
    
        Avez-vous oublié d’ajouter les deux points `:` ?
        
    Une exception de type `SyntaxError` se produit lorsque Python ne peut pas comprendre votre code.
    
    Python peut seulement comprendre le code du fichier
    'TESTS:\syntax\def_semi_colon_instead_of_colon.py'
    jusqu'à l'endroit indiqué par ^.
    
    -->1: def test();
                    ^

    Une définition de fonction doit se terminer par deux point, `:`.
    Tu as écrit `;` au lieu de deux points, `:`.
    

(72) def: set as argument
-------------------------

.. code-block:: none


    Traceback (most recent call last):
      File "TESTS:\trb_syntax_common.py", line 49, in create_tracebacks
        __import__(name)
      File "TESTS:\syntax\def_set_as_arg.py", line 1
        def test(y, {'a', 'b'}):  # set as second argument, after comma
                    ^
    SyntaxError: invalid syntax
    
        Vous ne pouvez pas avoir des `dict` ou des `set` explicite comme arguments de fonction.
        
    Une exception de type `SyntaxError` se produit lorsque Python ne peut pas comprendre votre code.
    
    Python peut seulement comprendre le code du fichier
    'TESTS:\syntax\def_set_as_arg.py'
    jusqu'à l'endroit indiqué par ^.
    
    -->1: def test(y, {'a', 'b'}):  # set as second argument, after comma
                      ^

    Vous ne pouvez pas avoir des `dict` ou des `set` explicite comme arguments de fonction.
    Vous ne pouvez utiliser que des identifiants (noms de variables) comme arguments de fonction.
    

(73) def: ``*arg`` before /
---------------------------

.. code-block:: none


    Traceback (most recent call last):
      File "TESTS:\trb_syntax_common.py", line 49, in create_tracebacks
        __import__(name)
      File "TESTS:\syntax\def_star_arg_before_slash.py", line 1
        def test(a, *arg, /):
                          ^
    SyntaxError: invalid syntax
    
        `*arg` doit apparaître après `/` dans une définition de fonction.
        
    Une exception de type `SyntaxError` se produit lorsque Python ne peut pas comprendre votre code.
    
    Python peut seulement comprendre le code du fichier
    'TESTS:\syntax\def_star_arg_before_slash.py'
    jusqu'à l'endroit indiqué par ^.
    
    -->1: def test(a, *arg, /):
                            ^

    `/` indique que les arguments précédents dans une définition de fonction
    sont des arguments positionnels.
    `*arg` doit apparaître après `/` dans une définition de fonction.
    

(74) def: ``*`` used twice
--------------------------

.. code-block:: none


    Traceback (most recent call last):
      File "TESTS:\trb_syntax_common.py", line 49, in create_tracebacks
        __import__(name)
      File "TESTS:\syntax\def_star_used_only_once.py", line 1
        def test(a, *arg, *, b=1):
                          ^
    SyntaxError: invalid syntax
    
        Vous ne pouvez utiliser `*` qu’une seule fois dans une définition de fonction.
        
    Une exception de type `SyntaxError` se produit lorsque Python ne peut pas comprendre votre code.
    
    Python peut seulement comprendre le code du fichier
    'TESTS:\syntax\def_star_used_only_once.py'
    jusqu'à l'endroit indiqué par ^.
    
    -->1: def test(a, *arg, *, b=1):
                            ^

    Vous ne pouvez utiliser `*` qu’une seule fois dans une définition de fonction.
    Ce symbole doit soit être utilisé par lui-même, `..., *, ...`,
    ou soit sous la forme `..., *args ...`.
    

(75) Single string used as arg in function def
----------------------------------------------

.. code-block:: none


    Traceback (most recent call last):
      File "TESTS:\trb_syntax_common.py", line 49, in create_tracebacks
        __import__(name)
      File "TESTS:\syntax\def_string_as_arg.py", line 1
        def f("1"):
              ^
    SyntaxError: invalid syntax
    
        Vous ne pouvez pas utiliser les chaînes comme arguments de fonction.
        
    Une exception de type `SyntaxError` se produit lorsque Python ne peut pas comprendre votre code.
    
    Python peut seulement comprendre le code du fichier
    'TESTS:\syntax\def_string_as_arg.py'
    jusqu'à l'endroit indiqué par ^.
    
    -->1: def f("1"):
                ^

    Vous avez utilisé une chaîne comme argument lors de la définition d’une fonction.
    Vous ne pouvez utiliser que des identificateurs (noms de variables) comme arguments de fonction.
    

(76) def: tuple as function argument
------------------------------------

.. code-block:: none


    Traceback (most recent call last):
      File "TESTS:\trb_syntax_common.py", line 49, in create_tracebacks
        __import__(name)
      File "TESTS:\syntax\def_tuple_as_arg_1.py", line 1
        def test((a, b), c):
                 ^
    SyntaxError: invalid syntax
    
        Vous ne pouvez pas avoir des tuples explicites comme arguments de fonction.
        
    Une exception de type `SyntaxError` se produit lorsque Python ne peut pas comprendre votre code.
    
    Python peut seulement comprendre le code du fichier
    'TESTS:\syntax\def_tuple_as_arg_1.py'
    jusqu'à l'endroit indiqué par ^.
    
    -->1: def test((a, b), c):
                   ^

    Vous ne pouvez pas avoir des tuples explicites comme arguments de fonction.
    Vous ne pouvez utiliser que des identifiants (noms de variables) comme arguments de fonction.
    Assignez n’importe quel tuple à un paramètre et dépaquetez-le
    dans le corps de la fonction.
    

(77) def: tuple as function argument - 2
----------------------------------------

.. code-block:: none


    Traceback (most recent call last):
      File "TESTS:\trb_syntax_common.py", line 49, in create_tracebacks
        __import__(name)
      File "TESTS:\syntax\def_tuple_as_arg_2.py", line 1
        def test(a, (b, c)):
                    ^
    SyntaxError: invalid syntax
    
        Vous ne pouvez pas avoir des tuples explicites comme arguments de fonction.
        
    Une exception de type `SyntaxError` se produit lorsque Python ne peut pas comprendre votre code.
    
    Python peut seulement comprendre le code du fichier
    'TESTS:\syntax\def_tuple_as_arg_2.py'
    jusqu'à l'endroit indiqué par ^.
    
    -->1: def test(a, (b, c)):
                      ^

    Vous ne pouvez pas avoir des tuples explicites comme arguments de fonction.
    Vous ne pouvez utiliser que des identifiants (noms de variables) comme arguments de fonction.
    Assignez n’importe quel tuple à un paramètre et dépaquetez-le
    dans le corps de la fonction.
    

(78) Deleting constant/keyword
------------------------------

.. code-block:: none


    Traceback (most recent call last):
      File "TESTS:\trb_syntax_common.py", line 49, in create_tracebacks
        __import__(name)
      File "TESTS:\syntax\delete_constant_keyword.py", line 1
        del True
            ^
    SyntaxError: cannot delete True
    
    Une exception de type `SyntaxError` se produit lorsque Python ne peut pas comprendre votre code.
    
    Python peut seulement comprendre le code du fichier
    'TESTS:\syntax\delete_constant_keyword.py'
    jusqu'à l'endroit indiqué par ^.
    
    -->1: del True
              ^

    Vous ne pouvez pas supprimer la constante `True`.
    

(79) Cannot delete function call
--------------------------------

.. code-block:: none


    Traceback (most recent call last):
      File "TESTS:\trb_syntax_common.py", line 49, in create_tracebacks
        __import__(name)
      File "TESTS:\syntax\delete_function_call.py", line 5
        del f(a)
            ^
    SyntaxError: cannot delete function call
    
    Une exception de type `SyntaxError` se produit lorsque Python ne peut pas comprendre votre code.
    
    Python peut seulement comprendre le code du fichier
    'TESTS:\syntax\delete_function_call.py'
    jusqu'à l'endroit indiqué par ^.
    
       1: """Should raise SyntaxError: can't or cannot delete function call
       2: """
       3: 
       4: 
    -->5: del f(a)
              ^

    Vous avez tenté de supprimer un appel de fonction
    
        del f(a)
    au lieu de supprimer le nom de la fonction
    
        del f
    

(80) Deleting string literal
----------------------------

.. code-block:: none


    Traceback (most recent call last):
      File "TESTS:\trb_syntax_common.py", line 49, in create_tracebacks
        __import__(name)
      File "TESTS:\syntax\delete_string_literal.py", line 1
        del "Hello world!"
            ^
    SyntaxError: cannot delete literal
    
    Une exception de type `SyntaxError` se produit lorsque Python ne peut pas comprendre votre code.
    
    Python peut seulement comprendre le code du fichier
    'TESTS:\syntax\delete_string_literal.py'
    jusqu'à l'endroit indiqué par ^.
    
    -->1: del "Hello world!"
              ^

    Vous ne pouvez pas supprimer le littéral `"Hello world!"`.
    Vous ne pouvez supprimer que les noms d’objets, ou
    des items individuels dans un conteneur.
    

(81) Different operators in a row
---------------------------------

.. code-block:: none


    Traceback (most recent call last):
      File "TESTS:\trb_syntax_common.py", line 49, in create_tracebacks
        __import__(name)
      File "TESTS:\syntax\different_operators_in_a_row.py", line 1
        3 */ 4
           ^
    SyntaxError: invalid syntax
    
    Une exception de type `SyntaxError` se produit lorsque Python ne peut pas comprendre votre code.
    
    Python peut seulement comprendre le code du fichier
    'TESTS:\syntax\different_operators_in_a_row.py'
    jusqu'à l'endroit indiqué par ^.
    
    -->1: 3 */ 4
             ^

    Vous ne pouvez pas avoir ces deux opérateurs, `*` et `/`,
    qui se suivent. Peut-être avez-vous écrit l’un d’eux par erreur
    ou vous avez oublié d’écrire quelque chose entre les deux.
    

(82) Dot followed by parenthesis
--------------------------------

.. code-block:: none


    Traceback (most recent call last):
      File "TESTS:\trb_syntax_common.py", line 49, in create_tracebacks
        __import__(name)
      File "TESTS:\syntax\dot_before_paren.py", line 3
        print(len.('hello'))
                  ^
    SyntaxError: invalid syntax
    
    Une exception de type `SyntaxError` se produit lorsque Python ne peut pas comprendre votre code.
    
    Python peut seulement comprendre le code du fichier
    'TESTS:\syntax\dot_before_paren.py'
    jusqu'à l'endroit indiqué par ^.
    
       1: """Should raise SyntaxError: invalid syntax
       2: Reported by Hackinscience."""
    -->3: print(len.('hello'))
                    ^

    Vous ne pouvez pas avoir un point `.` suivi de `(`.
    Peut-être que vous devez remplacer le point par une virgule.
    

(83) Extra token
----------------

.. code-block:: none


    Traceback (most recent call last):
      File "TESTS:\trb_syntax_common.py", line 49, in create_tracebacks
        __import__(name)
      File "TESTS:\syntax\duplicate_token.py", line 1
        print(1 , , 2)
                  ^
    SyntaxError: invalid syntax
    
        Avez-vous écrit `,` deux fois par erreur ?
        
    Une exception de type `SyntaxError` se produit lorsque Python ne peut pas comprendre votre code.
    
    Python peut seulement comprendre le code du fichier
    'TESTS:\syntax\duplicate_token.py'
    jusqu'à l'endroit indiqué par ^.
    
    -->1: print(1 , , 2)
                    ^

    Je suppose que vous avez écrit `,` deux fois de suite par erreur.
    Si c’est le cas, vous devez supprimer le second.
    

(84) Write elif, not else if
----------------------------

.. code-block:: none


    Traceback (most recent call last):
      File "TESTS:\trb_syntax_common.py", line 49, in create_tracebacks
        __import__(name)
      File "TESTS:\syntax\else_if_instead_of_elif.py", line 5
        else if True:
             ^
    SyntaxError: invalid syntax
    
        Peut-être que vous vouliez plutôt `elif`.
        
    Une exception de type `SyntaxError` se produit lorsque Python ne peut pas comprendre votre code.
    
    Python peut seulement comprendre le code du fichier
    'TESTS:\syntax\else_if_instead_of_elif.py'
    jusqu'à l'endroit indiqué par ^.
    
       1: """Should raise SyntaxError"""
       2: 
       3: if False:
       4:     pass
    -->5: else if True:
               ^

    Vous avez écrit `else if`
    au lieu d'utiliser le mot-clé `elif`.
    
    

(85) Write elif, not elseif
---------------------------

.. code-block:: none


    Traceback (most recent call last):
      File "TESTS:\trb_syntax_common.py", line 49, in create_tracebacks
        __import__(name)
      File "TESTS:\syntax\elseif_instead_of_elif.py", line 5
        elseif True:
               ^
    SyntaxError: invalid syntax
    
        Peut-être que vous vouliez plutôt `elif`.
        
    Une exception de type `SyntaxError` se produit lorsque Python ne peut pas comprendre votre code.
    
    Python peut seulement comprendre le code du fichier
    'TESTS:\syntax\elseif_instead_of_elif.py'
    jusqu'à l'endroit indiqué par ^.
    
       1: """Should raise SyntaxError"""
       2: 
       3: if False:
       4:     pass
    -->5: elseif True:
                 ^

    Vous avez écrit `elseif`
    au lieu d'utiliser le mot-clé `elif`.
    
    

(86) EOL while scanning string literal
--------------------------------------

.. code-block:: none


    Traceback (most recent call last):
      File "TESTS:\trb_syntax_common.py", line 49, in create_tracebacks
        __import__(name)
      File "TESTS:\syntax\eol_string_literal.py", line 3
        alphabet = 'abc
                       ^
    SyntaxError: EOL while scanning string literal
    
        Avez-vous oublié d’ajouter un guillemet ?
        
    Une exception de type `SyntaxError` se produit lorsque Python ne peut pas comprendre votre code.
    
    Python peut seulement comprendre le code du fichier
    'TESTS:\syntax\eol_string_literal.py'
    jusqu'à l'endroit indiqué par ^.
    
       1: """Should raise SyntaxError: EOL while scanning string literal"""
       2: 
    -->3: alphabet = 'abc
                         ^

    Vous aviez commencé à écrire une chaîne de caractères
    avec un guillemet simple ou double, mais n'avez jamais
    terminé la chaîne avec un autre guillemet sur cette ligne.
    

(87) Used equal sign instead of colon
-------------------------------------

.. code-block:: none


    Traceback (most recent call last):
      File "TESTS:\trb_syntax_common.py", line 49, in create_tracebacks
        __import__(name)
      File "TESTS:\syntax\equal_sign_instead_of_colon.py", line 4
        ages = {'Alice'=22, 'Bob'=24}
                       ^
    SyntaxError: invalid syntax
    
    Une exception de type `SyntaxError` se produit lorsque Python ne peut pas comprendre votre code.
    
    Python peut seulement comprendre le code du fichier
    'TESTS:\syntax\equal_sign_instead_of_colon.py'
    jusqu'à l'endroit indiqué par ^.
    
       1: """Should raise SyntaxError: invalid syntax
       2: """
       3: 
    -->4: ages = {'Alice'=22, 'Bob'=24}
                         ^

    Il est possible que vous ayez utilisé un signe d'égalité `=` au lieu de deux points `:`
    pour attribuer des valeurs à une clé d'un dictionnaire
    avant ou exactement à la position indiquée par ^.
    

(88) Parens around multiple exceptions
--------------------------------------

.. code-block:: none


    Traceback (most recent call last):
      File "TESTS:\trb_syntax_common.py", line 49, in create_tracebacks
        __import__(name)
      File "TESTS:\syntax\except_multiple_exceptions.py", line 3
        except NameError, ValueError as err:
                        ^
    SyntaxError: invalid syntax
    
        Avez-vous oublié d’ajouter des parenthèses ?
        
    Une exception de type `SyntaxError` se produit lorsque Python ne peut pas comprendre votre code.
    
    Python peut seulement comprendre le code du fichier
    'TESTS:\syntax\except_multiple_exceptions.py'
    jusqu'à l'endroit indiqué par ^.
    
       1: try:
       2:     pass
    -->3: except NameError, ValueError as err:
                          ^

    Je suppose que vous vouliez utiliser un énoncé `except`
    avec plusieurs types d’exception. Si c’est le cas, vous devez
    les entourer de parenthèses.
    
    Si vous utilisez une console Friendly, vous pouvez
    utiliser la fonction `www()` qui ouvrira un navigateur à
    une place pertinente dans la documentation Python.
    

(89) Extra token
----------------

.. code-block:: none


    Traceback (most recent call last):
      File "TESTS:\trb_syntax_common.py", line 49, in create_tracebacks
        __import__(name)
      File "TESTS:\syntax\extra_token.py", line 1
        print(1 / 2) ==
                       ^
    SyntaxError: invalid syntax
    
        Avez-vous écrit `==` par erreur ?
        
    Une exception de type `SyntaxError` se produit lorsque Python ne peut pas comprendre votre code.
    
    Python peut seulement comprendre le code du fichier
    'TESTS:\syntax\extra_token.py'
    jusqu'à l'endroit indiqué par ^.
    
    -->1: print(1 / 2) ==
                         ^

    Je suppose que vous avez écrit `==` par erreur.
    Écrire simplement `print(1 / 2)` semble corriger l’erreur.
    

(90) Binary f-string not allowed
--------------------------------

.. code-block:: none


    Traceback (most recent call last):
      File "TESTS:\trb_syntax_common.py", line 49, in create_tracebacks
        __import__(name)
      File "TESTS:\syntax\f_string_binary.py", line 1
        greet = bf"Hello {name}"
                  ^
    SyntaxError: invalid syntax
    
        `bf` est un préfixe de chaîne illégal.
        
    Une exception de type `SyntaxError` se produit lorsque Python ne peut pas comprendre votre code.
    
    Python peut seulement comprendre le code du fichier
    'TESTS:\syntax\f_string_binary.py'
    jusqu'à l'endroit indiqué par ^.
    
    -->1: greet = bf"Hello {name}"
                    ^

    Je devine que vous vouliez une chaîne de caractères formatés (f-string) binaire;
    ceci n’est pas permis.
    

(91) f-string: unterminated string
----------------------------------

.. code-block:: none


    Traceback (most recent call last):
      File "TESTS:\trb_syntax_common.py", line 49, in create_tracebacks
        __import__(name)
      File "TESTS:\syntax\f_string_unterminated.py", line 4
        print(f"Bob is {age['Bob]} years old.")
              ^
    SyntaxError: f-string: unterminated string
    
        Avez-vous oublié d’ajouter un guillemet ?
        
    Une exception de type `SyntaxError` se produit lorsque Python ne peut pas comprendre votre code.
    
    Python peut seulement comprendre le code du fichier
    'TESTS:\syntax\f_string_unterminated.py'
    jusqu'à l'endroit indiqué par ^.
    
       1: """Should raise SyntaxError: f-string: unterminated string
       2: """
       3: 
    -->4: print(f"Bob is {age['Bob]} years old.")
                ^

    À l'intérieur de la chaîne `f"Bob is {age['Bob]} years old."`, qui est une chaîne de caractères préfixée de la lettre f,
    vous avez une autre chaîne de caractère qui débute soit avec un apostrophe (')
    ou des guillemets ("), mais n'est pas terminé par un autre caractère semblable.
    

(92) f-string with backslash
----------------------------

.. code-block:: none


    Traceback (most recent call last):
      File "TESTS:\trb_syntax_common.py", line 49, in create_tracebacks
        __import__(name)
      File "TESTS:\syntax\f_string_with_backslash.py", line 2
        print(f"{'\n'.join(names)}")
              ^
    SyntaxError: f-string expression part cannot include a backslash
    
    Une exception de type `SyntaxError` se produit lorsque Python ne peut pas comprendre votre code.
    
    Python peut seulement comprendre le code du fichier
    'TESTS:\syntax\f_string_with_backslash.py'
    jusqu'à l'endroit indiqué par ^.
    
       1: names = ['a', 'b']
    -->2: print(f"{'\n'.join(names)}")
                ^

    Vous avez écrit une chaîne de caractères formatés (f-string) dont le contenu `{...}`
    comprend une barre oblique inverse; ce n’est pas permis.
    Peut-être pouvez-vous remplacer la partie qui contient une barre oblique inverse par
    une variable. Par exemple, supposons que vous avez une chaîne comme suit :
    
        f"{... 'bonjour\n'...}"
    
    vous pourriez écrire ceci comme
    
        bonjour = 'bonjour\n'
        f"{... bonjour ...}"
    

(93) Missing terms in for statement
-----------------------------------

.. code-block:: none


    Traceback (most recent call last):
      File "TESTS:\trb_syntax_common.py", line 49, in create_tracebacks
        __import__(name)
      File "TESTS:\syntax\for_missing_terms.py", line 1
        for:
           ^
    SyntaxError: invalid syntax
    
        Une boucle `for` doit avoir plus de termes.
        
    Une exception de type `SyntaxError` se produit lorsque Python ne peut pas comprendre votre code.
    
    Python peut seulement comprendre le code du fichier
    'TESTS:\syntax\for_missing_terms.py'
    jusqu'à l'endroit indiqué par ^.
    
    -->1: for:
             ^

    Une boucle `for` est une itération sur une séquence :
    
        for élément in séquence:
            ...
    
    

(94) Not a chance!
------------------

.. code-block:: none


    Traceback (most recent call last):
      File "TESTS:\trb_syntax_common.py", line 49, in create_tracebacks
        __import__(name)
      File "TESTS:\syntax\future_braces.py", line 1
        from __future__ import braces
        ^
    SyntaxError: not a chance
    
    Une exception de type `SyntaxError` se produit lorsque Python ne peut pas comprendre votre code.
    
    Python peut seulement comprendre le code du fichier
    'TESTS:\syntax\future_braces.py'
    jusqu'à l'endroit indiqué par ^.
    
    -->1: from __future__ import braces
          ^

    Je soupçonne que vous avez écrit `from __future__ import braces`
    suivant une suggestion de quelqu’un d’autre. Ça ne marchera jamais.
    
    Contrairement à d’autres langages de programmation, les blocs de code Python sont définis par
    leur niveau d’indentation, et non pas en utilisant des accolades, comme `{...}`.
    

(95) Do not import * from __future__
------------------------------------

.. code-block:: none


    Traceback (most recent call last):
      File "TESTS:\trb_syntax_common.py", line 49, in create_tracebacks
        __import__(name)
      File "TESTS:\syntax\future_import_star.py", line 1
        from __future__ import *
        ^
    SyntaxError: future feature * is not defined
    
    Une exception de type `SyntaxError` se produit lorsque Python ne peut pas comprendre votre code.
    
    Python peut seulement comprendre le code du fichier
    'TESTS:\syntax\future_import_star.py'
    jusqu'à l'endroit indiqué par ^.
    
    -->1: from __future__ import *
          ^

    Lors de l’utilisation d’un énoncé `from __future__ import`,
    vous devez importer des noms spécifiques.
    
    Les valeurs disponibles sont `nested_scopes,
     generators,
     division,
     absolute_import,
     with_statement,
     print_function,
     unicode_literals,
     barry_as_FLUFL,
     generator_stop,
     annotations`.
    

(96) __future__ at beginning
----------------------------

.. code-block:: none


    Traceback (most recent call last):
      File "TESTS:\trb_syntax_common.py", line 49, in create_tracebacks
        __import__(name)
      File "TESTS:\syntax\future_must_be_first.py", line 3
        from __future__ import generators
        ^
    SyntaxError: from __future__ imports must occur at the beginning of the file
    
    Une exception de type `SyntaxError` se produit lorsque Python ne peut pas comprendre votre code.
    
    Python peut seulement comprendre le code du fichier
    'TESTS:\syntax\future_must_be_first.py'
    jusqu'à l'endroit indiqué par ^.
    
       1: 
       2: def fn():
    -->3:     from __future__ import generators
              ^

    Une instruction `from __future__ import` change la façon dont Python
    interprète le code dans un fichier.
    Une telle instruction doit apparaître au début du fichier.

(97) Typo in __future__
-----------------------

.. code-block:: none


    Traceback (most recent call last):
      File "TESTS:\trb_syntax_common.py", line 49, in create_tracebacks
        __import__(name)
      File "TESTS:\syntax\future_typo.py", line 1
        from __future__ import divisio
        ^
    SyntaxError: future feature divisio is not defined
    
        Vouliez-vous dire `division` ?
        
    Une exception de type `SyntaxError` se produit lorsque Python ne peut pas comprendre votre code.
    
    Python peut seulement comprendre le code du fichier
    'TESTS:\syntax\future_typo.py'
    jusqu'à l'endroit indiqué par ^.
    
    -->1: from __future__ import divisio
          ^

    Au lieu de `divisio`, peut-être que vous vouliez plutôt importer `division`.
    

(98) Unknown feature in __future__
----------------------------------

.. code-block:: none


    Traceback (most recent call last):
      File "TESTS:\trb_syntax_common.py", line 49, in create_tracebacks
        __import__(name)
      File "TESTS:\syntax\future_unknown.py", line 1
        from __future__ import something
        ^
    SyntaxError: future feature something is not defined
    
    Une exception de type `SyntaxError` se produit lorsque Python ne peut pas comprendre votre code.
    
    Python peut seulement comprendre le code du fichier
    'TESTS:\syntax\future_unknown.py'
    jusqu'à l'endroit indiqué par ^.
    
    -->1: from __future__ import something
          ^

    `something` n’est pas un attribut valide du module `__future__`.
    
    Les valeurs disponibles sont `nested_scopes,
     generators,
     division,
     absolute_import,
     with_statement,
     print_function,
     unicode_literals,
     barry_as_FLUFL,
     generator_stop,
     annotations`.
    

(99) Parenthesis around generator expression
--------------------------------------------

.. code-block:: none


    Traceback (most recent call last):
      File "TESTS:\trb_syntax_common.py", line 49, in create_tracebacks
        __import__(name)
      File "TESTS:\syntax\generator_expression_parens.py", line 6
        f(x for x in L, 1)
          ^
    SyntaxError: Generator expression must be parenthesized
    
    Une exception de type `SyntaxError` se produit lorsque Python ne peut pas comprendre votre code.
    
    Python peut seulement comprendre le code du fichier
    'TESTS:\syntax\generator_expression_parens.py'
    jusqu'à l'endroit indiqué par ^.
    
       2: def f(it, *varargs, **kwargs):
       3:     return list(it)
       4: 
       5: L = range(10)
    -->6: f(x for x in L, 1)
            ^

    Vous utilisez une expression de générateur, quelque chose de la forme
    
        x for x in objet
    
    Vous devez ajouter des parenthèses qui entourent cette expression.
    

(100) Space between names
-------------------------

.. code-block:: none


    Traceback (most recent call last):
      File "TESTS:\trb_syntax_common.py", line 49, in create_tracebacks
        __import__(name)
      File "TESTS:\syntax\hyphen_instead_of_underscore.py", line 4
        a-b = 2
        ^
    SyntaxError: cannot assign to operator
    
        Vouliez-vous dire `a_b` ?
        
    Une exception de type `SyntaxError` se produit lorsque Python ne peut pas comprendre votre code.
    
    Python peut seulement comprendre le code du fichier
    'TESTS:\syntax\hyphen_instead_of_underscore.py'
    jusqu'à l'endroit indiqué par ^.
    
       1: """Should raise SyntaxError: can't assign to operator
       2: or (Python 3.8) cannot assign to operator"""
       3: 
    -->4: a-b = 2
          ^

    Vous avez écrit une expression qui inclut des opérations mathématiques
    du côté gauche du signe d'égalité; ceci devrait être
    utilisé uniquement pour attribuer une valeur à une variable.
    Peut-être que vous vouliez plutôt écrire `a_b` au lieu de `a-b`.
    

(101) Missing condition in if statement
---------------------------------------

.. code-block:: none


    Traceback (most recent call last):
      File "TESTS:\trb_syntax_common.py", line 49, in create_tracebacks
        __import__(name)
      File "TESTS:\syntax\if_missing_condition.py", line 1
        if:
          ^
    SyntaxError: invalid syntax
    
        Vous avez oublié d’ajouter une condition.
        
    Une exception de type `SyntaxError` se produit lorsque Python ne peut pas comprendre votre code.
    
    Python peut seulement comprendre le code du fichier
    'TESTS:\syntax\if_missing_condition.py'
    jusqu'à l'endroit indiqué par ^.
    
    -->1: if:
            ^

    Un énoncé `if` doit inclure une condition :
    
        if condition:
            ...
    
    

(102) use j instead of i
------------------------

.. code-block:: none


    Traceback (most recent call last):
      File "TESTS:\trb_syntax_common.py", line 49, in create_tracebacks
        __import__(name)
      File "TESTS:\syntax\imaginary_i.py", line 3
        a = 3.0i
               ^
    SyntaxError: invalid syntax
    
        Vouliez-vous dire `3.0j` ?
        
    Une exception de type `SyntaxError` se produit lorsque Python ne peut pas comprendre votre code.
    
    Python peut seulement comprendre le code du fichier
    'TESTS:\syntax\imaginary_i.py'
    jusqu'à l'endroit indiqué par ^.
    
       1: # SyntaxError: invalid syntax
       2: 
    -->3: a = 3.0i
                 ^

    Les noms valides ne peuvent pas commencer par un chiffre.
    Peut-être pensiez-vous que `i` pouvait être utilisé pour représenter
    la racine carrée de `-1`. Dans Python, le symbole utilisé pour ceci est `j`
    et la partie imaginaire d'un nombre complexe a la forme `nombre`
    suivie immédiatement par `j` sans aucun espace entre les deux.
    Peut-être que vous vouliez écrire `3.0j`.
    

(103) Import inversion: import X from Y
---------------------------------------

.. code-block:: none


    Traceback (most recent call last):
      File "TESTS:\trb_syntax_common.py", line 49, in create_tracebacks
        __import__(name)
      File "TESTS:\syntax\import_from.py", line 3
        import pen from turtle
                   ^
    SyntaxError: invalid syntax
    
        Vouliez-vous dire `from turtle import pen` ?
        
    Une exception de type `SyntaxError` se produit lorsque Python ne peut pas comprendre votre code.
    
    Python peut seulement comprendre le code du fichier
    'TESTS:\syntax\import_from.py'
    jusqu'à l'endroit indiqué par ^.
    
       1: """Should raise SyntaxError: invalid syntax"""
       2: 
    -->3: import pen from turtle
                     ^

    Vous avez écrit quelque chose comme
        import pen from turtle
    au lieu de
        from turtle import pen
    
    

(104) IndentationError: expected an indented block
--------------------------------------------------

.. code-block:: none


    Traceback (most recent call last):
      File "TESTS:\trb_syntax_common.py", line 49, in create_tracebacks
        __import__(name)
      File "TESTS:\syntax\indentation_error_1.py", line 4
        pass
        ^
    IndentationError: expected an indented block
    
    Une exception de type `IndentationError` se produit lorsqu'une ligne de code
    n'est pas indentée (c'est-à-dire alignée verticalement avec les autres lignes)
    de la façon attendue.
    
    Python peut seulement comprendre le code du fichier
    'TESTS:\syntax\indentation_error_1.py'
    jusqu'à l'endroit indiqué par ^.
    
       1: '''Should raise IndentationError'''
       2: 
       3: if True:
    -->4: pass
          ^

    La ligne indiquée ci-dessus par --> devrait
    normalement commencer un nouveau bloc de code indenté.
    

(105) IndentationError: unexpected indent
-----------------------------------------

.. code-block:: none


    Traceback (most recent call last):
      File "TESTS:\trb_syntax_common.py", line 49, in create_tracebacks
        __import__(name)
      File "TESTS:\syntax\indentation_error_2.py", line 4
        pass
       ^
    IndentationError: unexpected indent
    
    Une exception de type `IndentationError` se produit lorsqu'une ligne de code
    n'est pas indentée (c'est-à-dire alignée verticalement avec les autres lignes)
    de la façon attendue.
    
    Python peut seulement comprendre le code du fichier
    'TESTS:\syntax\indentation_error_2.py'
    jusqu'à l'endroit indiqué par ^.
    
       1: '''Should raise IndentationError'''
       2: if True:
       3:     pass
    -->4:       pass
               ^

    La ligne indiquée ci-dessus par --> est plus indentée que prévu.
    

(106) IndentationError: unindent does not match ...
---------------------------------------------------

.. code-block:: none


    Traceback (most recent call last):
      File "TESTS:\trb_syntax_common.py", line 49, in create_tracebacks
        __import__(name)
      File "TESTS:\syntax\indentation_error_3.py", line 5
        pass
            ^
    IndentationError: unindent does not match any outer indentation level
    
    Une exception de type `IndentationError` se produit lorsqu'une ligne de code
    n'est pas indentée (c'est-à-dire alignée verticalement avec les autres lignes)
    de la façon attendue.
    
    Python peut seulement comprendre le code du fichier
    'TESTS:\syntax\indentation_error_3.py'
    jusqu'à l'endroit indiqué par ^.
    
       1: '''Should raise IndentationError'''
       2: 
       3: if True:
       4:       pass
    -->5:     pass
                  ^

    La ligne indiquée ci-dessus par --> est moins indentée que prévu.
    

(107) IndentationError: missing continuation line
-------------------------------------------------

.. code-block:: none


    Traceback (most recent call last):
      File "TESTS:\trb_syntax_common.py", line 49, in create_tracebacks
        __import__(name)
      File "TESTS:\syntax\indentation_error_4.py", line 6
        "c"
       ^
    IndentationError: unexpected indent
    
    Une exception de type `IndentationError` se produit lorsqu'une ligne de code
    n'est pas indentée (c'est-à-dire alignée verticalement avec les autres lignes)
    de la façon attendue.
    
    Python peut seulement comprendre le code du fichier
    'TESTS:\syntax\indentation_error_4.py'
    jusqu'à l'endroit indiqué par ^.
    
       2: 
       3: def f():
       4:      s = "a"\
       5:          "b"
    -->6:          "c"
                  ^

    La ligne indiquée ci-dessus par --> est plus indentée que prévu.
    
    Toutefois, la ligne 6, qui est identifiée comme ayant un problème,
    se compose d’une seule chaîne, ce qui est également le cas
    pour la ligne précédente.
    Peut-être que vous vouliez inclure un caractère de continuation, '\',
    à la fin de la ligne 5.
    

(108) Forgot 'o' for octal
--------------------------

.. code-block:: none


    Traceback (most recent call last):
      File "TESTS:\trb_syntax_common.py", line 49, in create_tracebacks
        __import__(name)
      File "TESTS:\syntax\integer_with_leading_zero_1.py", line 1
        x = 01
             ^
    SyntaxError: leading zeros in decimal integer literals are not permitted; use an 0o prefix for octal integers
    
        Vouliez-vous dire `0o1` ?
        
    Une exception de type `SyntaxError` se produit lorsque Python ne peut pas comprendre votre code.
    
    Python peut seulement comprendre le code du fichier
    'TESTS:\syntax\integer_with_leading_zero_1.py'
    jusqu'à l'endroit indiqué par ^.
    
    -->1: x = 01
               ^

    Peut-être que vous vouliez écrire le nombre octal `0o1`
    et oublié la lettre 'o', ou peut-être vous vouliez écrire
    un entier décimal et ne saviez pas qu’il ne pouvait pas commencer par des zéros.
    

(109) Integer with leading zeros
--------------------------------

.. code-block:: none


    Traceback (most recent call last):
      File "TESTS:\trb_syntax_common.py", line 49, in create_tracebacks
        __import__(name)
      File "TESTS:\syntax\integer_with_leading_zero_2.py", line 1
        x = 000_123_456
                      ^
    SyntaxError: leading zeros in decimal integer literals are not permitted; use an 0o prefix for octal integers
    
        Vouliez-vous dire `123_456` ?
        
    Une exception de type `SyntaxError` se produit lorsque Python ne peut pas comprendre votre code.
    
    Python peut seulement comprendre le code du fichier
    'TESTS:\syntax\integer_with_leading_zero_2.py'
    jusqu'à l'endroit indiqué par ^.
    
    -->1: x = 000_123_456
                        ^

    Peut-être que vous vouliez écrire l'entier décimal `123_456`
    et ne saviez pas qu’il ne pouvait pas commencer par des zéros.
    

(110) Invalid character in identifier
-------------------------------------

.. code-block:: none


    Traceback (most recent call last):
      File "TESTS:\trb_syntax_common.py", line 49, in create_tracebacks
        __import__(name)
      File "TESTS:\syntax\invalid_character_in_identifier.py", line 6
        🤖 = 'Reeborg'
        ^
    SyntaxError: invalid character in identifier
    
    Une exception de type `SyntaxError` se produit lorsque Python ne peut pas comprendre votre code.
    
    Python peut seulement comprendre le code du fichier
    'TESTS:\syntax\invalid_character_in_identifier.py'
    jusqu'à l'endroit indiqué par ^.
    
       1: """Should raise SyntaxError: invalid character in identifier
       2: """
       3: 
       4: # Robot-face character below
       5: 
    -->6: 🤖 = 'Reeborg'
          ^

    Python indique que vous avez utilisé le caractère unicode `🤖`
    ce qui n’est pas permis.
    

(111) Invalid hexadecimal number
--------------------------------

.. code-block:: none


    Traceback (most recent call last):
      File "TESTS:\trb_syntax_common.py", line 49, in create_tracebacks
        __import__(name)
      File "TESTS:\syntax\invalid_hexadecimal.py", line 3
        a = 0x123g4
                 ^
    SyntaxError: invalid syntax
    
        Avez-vous fait une erreur en écrivant un entier hexadécimal ?
        
    Une exception de type `SyntaxError` se produit lorsque Python ne peut pas comprendre votre code.
    
    Python peut seulement comprendre le code du fichier
    'TESTS:\syntax\invalid_hexadecimal.py'
    jusqu'à l'endroit indiqué par ^.
    
       1: """Should raise SyntaxError: invalid syntax"""
       2: 
    -->3: a = 0x123g4
                   ^

    On dirait que vous avez utilisé un caractère invalide ('g') dans un nombre hexadecimal.
    
    Les nombres hexadécimaux sont des entiers en base 16 qui utilisent les symboles `0` à `9`
    pour représenter les valeurs 0 à 9, et les lettres `a` à `f` (ou `A` à `F`)
    pour représenter les valeurs 10 à 15.
    Dans Python, les nombres hexadécimaux commencent par `0x` ou `0X`,
    suivi des caractères utilisés pour représenter la valeur du nombre.
    

(112) Valid names cannot begin with a number
--------------------------------------------

.. code-block:: none


    Traceback (most recent call last):
      File "TESTS:\trb_syntax_common.py", line 49, in create_tracebacks
        __import__(name)
      File "TESTS:\syntax\invalid_identifier.py", line 3
        36abc = 3
          ^
    SyntaxError: invalid syntax
    
        Les noms valides ne peuvent pas commencer par un chiffre.
        
    Une exception de type `SyntaxError` se produit lorsque Python ne peut pas comprendre votre code.
    
    Python peut seulement comprendre le code du fichier
    'TESTS:\syntax\invalid_identifier.py'
    jusqu'à l'endroit indiqué par ^.
    
       1: """Should raise SyntaxError: invalid syntax"""
       2: 
    -->3: 36abc = 3
            ^

    Les noms valides ne peuvent pas commencer par un chiffre.
    

(113) Valid names cannot begin with a number - 2
------------------------------------------------

.. code-block:: none


    Traceback (most recent call last):
      File "TESTS:\trb_syntax_common.py", line 49, in create_tracebacks
        __import__(name)
      File "TESTS:\syntax\invalid_identifier_2.py", line 3
        tau = 2pi
               ^
    SyntaxError: invalid syntax
    
        Peut-être avez-vous oublié un opérateur de multiplication, `2 * pi`.
        
    Une exception de type `SyntaxError` se produit lorsque Python ne peut pas comprendre votre code.
    
    Python peut seulement comprendre le code du fichier
    'TESTS:\syntax\invalid_identifier_2.py'
    jusqu'à l'endroit indiqué par ^.
    
       1: """Should raise SyntaxError: invalid syntax"""
       2: 
    -->3: tau = 2pi
                 ^

    Les noms valides ne peuvent pas commencer par un chiffre.
    Peut-être avez-vous oublié un opérateur de multiplication, `2 * pi`.
    
    

(114) Valid names cannot begin with a number - 3
------------------------------------------------

.. code-block:: none


    Traceback (most recent call last):
      File "TESTS:\trb_syntax_common.py", line 49, in create_tracebacks
        __import__(name)
      File "TESTS:\syntax\invalid_identifier_3.py", line 1
        3job  # could be entered in a repl
          ^
    SyntaxError: invalid syntax
    
        Peut-être avez-vous oublié un opérateur de multiplication, `3 * job`.
        
    Une exception de type `SyntaxError` se produit lorsque Python ne peut pas comprendre votre code.
    
    Python peut seulement comprendre le code du fichier
    'TESTS:\syntax\invalid_identifier_3.py'
    jusqu'à l'endroit indiqué par ^.
    
    -->1: 3job  # could be entered in a repl
            ^

    Les noms valides ne peuvent pas commencer par un chiffre.
    Peut-être avez-vous oublié un opérateur de multiplication, `3 * job`.
    
    [N.B.: `3j * ob` serait également valide
    puisque `3j` est un nombre complexe.]
    

(115) Valid names cannot begin with a number - 4
------------------------------------------------

.. code-block:: none


    Traceback (most recent call last):
      File "TESTS:\trb_syntax_common.py", line 49, in create_tracebacks
        __import__(name)
      File "TESTS:\syntax\invalid_identifier_4.py", line 1
        3job = 1
          ^
    SyntaxError: invalid syntax
    
        Les noms valides ne peuvent pas commencer par un chiffre.
        
    Une exception de type `SyntaxError` se produit lorsque Python ne peut pas comprendre votre code.
    
    Python peut seulement comprendre le code du fichier
    'TESTS:\syntax\invalid_identifier_4.py'
    jusqu'à l'endroit indiqué par ^.
    
    -->1: 3job = 1
            ^

    Les noms valides ne peuvent pas commencer par un chiffre.
    

(116) Valid names cannot begin with a number - 5
------------------------------------------------

.. code-block:: none


    Traceback (most recent call last):
      File "TESTS:\trb_syntax_common.py", line 49, in create_tracebacks
        __import__(name)
      File "TESTS:\syntax\invalid_identifier_5.py", line 1
        print(42java)
                 ^
    SyntaxError: invalid syntax
    
        Peut-être avez-vous oublié un opérateur de multiplication, `42 * java`.
        
    Une exception de type `SyntaxError` se produit lorsque Python ne peut pas comprendre votre code.
    
    Python peut seulement comprendre le code du fichier
    'TESTS:\syntax\invalid_identifier_5.py'
    jusqu'à l'endroit indiqué par ^.
    
    -->1: print(42java)
                   ^

    Les noms valides ne peuvent pas commencer par un chiffre.
    Peut-être avez-vous oublié un opérateur de multiplication, `42 * java`.
    
    [N.B.: `42j * ava` serait également valide
    puisque `42j` est un nombre complexe.]
    

(117) Keyword can't be an expression
------------------------------------

.. code-block:: none


    Traceback (most recent call last):
      File "TESTS:\trb_syntax_common.py", line 49, in create_tracebacks
        __import__(name)
      File "TESTS:\syntax\invalid_keyword_argument.py", line 7
        a = dict('key'=1)
                 ^
    SyntaxError: expression cannot contain assignment, perhaps you meant "=="?
    
    Une exception de type `SyntaxError` se produit lorsque Python ne peut pas comprendre votre code.
    
    Python peut seulement comprendre le code du fichier
    'TESTS:\syntax\invalid_keyword_argument.py'
    jusqu'à l'endroit indiqué par ^.
    
       1: """Should raise
       2: Python < 3.8: SyntaxError: keyword can't be an expression
       3: Python 3.8:  expression cannot contain assignment, perhaps you meant "=="?
       4: """
       5: 
       6: 
    -->7: a = dict('key'=1)
                   ^

    L'une des deux possibilités suivantes pourrait être la cause:
    
    1. Vous vouliez faire une comparaison avec `==` et vous avez écrit `=` à sa place.
    2. Vous avez invoqué une fonction avec un argument nommé:
    
            une_fonction (invalide=...)
    
    où `invalide` n'est pas un identifiant (nom de variable) valide dans Python
    soit parce qu'il commence par un chiffre, soit qu'il est une chaîne,
    ou qu'il contient un point, etc.
    
    

(118) Invalid octal number
--------------------------

.. code-block:: none


    Traceback (most recent call last):
      File "TESTS:\trb_syntax_common.py", line 49, in create_tracebacks
        __import__(name)
      File "TESTS:\syntax\invalid_octal.py", line 3
        b = 0O1876
               ^
    SyntaxError: invalid digit '8' in octal literal
    
        Avez-vous fait une erreur en écrivant un entier octal ?
        
    Une exception de type `SyntaxError` se produit lorsque Python ne peut pas comprendre votre code.
    
    Python peut seulement comprendre le code du fichier
    'TESTS:\syntax\invalid_octal.py'
    jusqu'à l'endroit indiqué par ^.
    
       1: 
       2: 
    -->3: b = 0O1876
                 ^

    On dirait que vous avez utilisé un caractère invalide ('8') dans un nombre octal.
    
    Les nombres octaux sont des entiers de base 8 qui n’utilisent que les symboles `0` à `7`
    pour représenter les valeurs.
    Dans Python, les nombres octaux commencent par `0o` ou `0O`,
    (le chiffre zéro suivi de la lettre `o`)
    suivi des caractères utilisés pour représenter la valeur de cet entier.
    

(119) Inverted operators 1
--------------------------

.. code-block:: none


    Traceback (most recent call last):
      File "TESTS:\trb_syntax_common.py", line 49, in create_tracebacks
        __import__(name)
      File "TESTS:\syntax\inverted_operators.py", line 1
        a =< 3
           ^
    SyntaxError: invalid syntax
    
        Avez-vous écrit des opérateurs dans un mauvais ordre ?
        
    Une exception de type `SyntaxError` se produit lorsque Python ne peut pas comprendre votre code.
    
    Python peut seulement comprendre le code du fichier
    'TESTS:\syntax\inverted_operators.py'
    jusqu'à l'endroit indiqué par ^.
    
    -->1: a =< 3
             ^

    On dirait que vous avez écrit deux opérateurs (`=` et `<`)
    dans le mauvais ordre: `=<` au lieu de `<=`.
    

(120) Inverted operators 2
--------------------------

.. code-block:: none


    Traceback (most recent call last):
      File "TESTS:\trb_syntax_common.py", line 49, in create_tracebacks
        __import__(name)
      File "TESTS:\syntax\inverted_operators_2.py", line 1
        a =<* 3
           ^
    SyntaxError: invalid syntax
    
        Avez-vous écrit des opérateurs dans un mauvais ordre ?
        
    Une exception de type `SyntaxError` se produit lorsque Python ne peut pas comprendre votre code.
    
    Python peut seulement comprendre le code du fichier
    'TESTS:\syntax\inverted_operators_2.py'
    jusqu'à l'endroit indiqué par ^.
    
    -->1: a =<* 3
             ^

    On dirait que vous avez écrit deux opérateurs (`=` et `<`)
    dans le mauvais ordre: `=<` au lieu de `<=`.
    
    Toutefois, un tel changement ne corrigerait pas
    toutes les erreurs de syntaxe dans le code que vous avez écrit.
    

(121) Keyword arg only once in function call
--------------------------------------------

.. code-block:: none


    Traceback (most recent call last):
      File "TESTS:\trb_syntax_common.py", line 49, in create_tracebacks
        __import__(name)
      File "TESTS:\syntax\keyword_arg_repeated.py", line 4
        f(ad=1, ad=2)
                ^
    SyntaxError: keyword argument repeated
    
    Une exception de type `SyntaxError` se produit lorsque Python ne peut pas comprendre votre code.
    
    Python peut seulement comprendre le code du fichier
    'TESTS:\syntax\keyword_arg_repeated.py'
    jusqu'à l'endroit indiqué par ^.
    
       1: """Should raise SyntaxError:  keyword argument repeated"""
       2: 
       3: 
    -->4: f(ad=1, ad=2)
                  ^

    Vous avez invoqué une fonction en répétant le même argument nommé (`ad`).
    Chaque argument de ce type ne peut apparaître qu'une seule fois.
    

(122) Keyword as attribute
--------------------------

.. code-block:: none


    Traceback (most recent call last):
      File "TESTS:\trb_syntax_common.py", line 49, in create_tracebacks
        __import__(name)
      File "TESTS:\syntax\keyword_as_attribute.py", line 12
        a.pass = 2
          ^
    SyntaxError: invalid syntax
    
        `pass` ne peut pas être utilisé comme n attribut.
        
        
    Une exception de type `SyntaxError` se produit lorsque Python ne peut pas comprendre votre code.
    
    Python peut seulement comprendre le code du fichier
    'TESTS:\syntax\keyword_as_attribute.py'
    jusqu'à l'endroit indiqué par ^.
    
        8: 
        9: a = A()
       10: 
       11: a.x = 1
    -->12: a.pass = 2
             ^

    Vous avez tenté d'utiliser le mot clé Python `pass` comme attribut.
    Ceci n’est pas permis.
    
    

(123) lambda with parentheses around arguments
----------------------------------------------

.. code-block:: none


    Traceback (most recent call last):
      File "TESTS:\trb_syntax_common.py", line 49, in create_tracebacks
        __import__(name)
      File "TESTS:\syntax\lambda_with_parens.py", line 2
        x = lambda (a, b): a + b
                   ^
    SyntaxError: invalid syntax
    
    Une exception de type `SyntaxError` se produit lorsque Python ne peut pas comprendre votre code.
    
    Python peut seulement comprendre le code du fichier
    'TESTS:\syntax\lambda_with_parens.py'
    jusqu'à l'endroit indiqué par ^.
    
       1: 
    -->2: x = lambda (a, b): a + b
                     ^

    `lambda` ne permet pas de parenthèses autour de ses arguments.
    Cela était permis dans Python 2, mais il ne l'est plus dans Python 3.
    

(124) lambda with tuple as argument
-----------------------------------

.. code-block:: none


    Traceback (most recent call last):
      File "TESTS:\trb_syntax_common.py", line 49, in create_tracebacks
        __import__(name)
      File "TESTS:\syntax\lambda_with_tuple_argument.py", line 2
        x = lambda a, (b, c): a + b + b
                      ^
    SyntaxError: invalid syntax
    
    Une exception de type `SyntaxError` se produit lorsque Python ne peut pas comprendre votre code.
    
    Python peut seulement comprendre le code du fichier
    'TESTS:\syntax\lambda_with_tuple_argument.py'
    jusqu'à l'endroit indiqué par ^.
    
       1: 
    -->2: x = lambda a, (b, c): a + b + b
                        ^

    Vous ne pouvez pas avoir des tuples explicites comme arguments.
    Attribuez n’importe quel tuple à un paramètre et dépaquetez-le
    dans le corps de la fonction.
    

(125) Assign to literal in for loop
-----------------------------------

.. code-block:: none


    Traceback (most recent call last):
      File "TESTS:\trb_syntax_common.py", line 49, in create_tracebacks
        __import__(name)
      File "TESTS:\syntax\literal_in_for_loop.py", line 1
        for "char" in "word":
            ^
    SyntaxError: cannot assign to literal
    
        Vous ne pouvez assigner des objets qu’à des identifiants (noms de variables).
        
    Une exception de type `SyntaxError` se produit lorsque Python ne peut pas comprendre votre code.
    
    Python peut seulement comprendre le code du fichier
    'TESTS:\syntax\literal_in_for_loop.py'
    jusqu'à l'endroit indiqué par ^.
    
    -->1: for "char" in "word":
              ^

    Une boucle for doit avoir la forme:
    
        for ... in séquence:
    
    où `...` doit contenir seulement des identifiants (noms de variables)
    et non pas des littéraux comme `"char"`.
    

(126) IndentationError/SyntaxError depending on version
-------------------------------------------------------

.. code-block:: none


    Traceback (most recent call last):
      File "TESTS:\trb_syntax_common.py", line 49, in create_tracebacks
        __import__(name)
      File "TESTS:\syntax\missing_code_block.py", line 4
    SyntaxError: unexpected EOF while parsing
    
    Une exception de type `SyntaxError` se produit lorsque Python ne peut pas comprendre votre code.
    
    Python peut seulement comprendre le code du fichier
    'TESTS:\syntax\missing_code_block.py'
    jusqu'à l'endroit indiqué par ^.
    
       1: '''Should raise SyntaxError: unexpected EOF while parsing'''
       2: 
       3: for i in range(10):
    -->4: 
          ^

    Python nous dit qu'il a atteint la fin du fichier
    et s'attendait à plus de contenu.
    
    

(127) Missing colon - if
------------------------

.. code-block:: none


    Traceback (most recent call last):
      File "TESTS:\trb_syntax_common.py", line 49, in create_tracebacks
        __import__(name)
      File "TESTS:\syntax\missing_colon_if.py", line 3
        if True
               ^
    SyntaxError: invalid syntax
    
        Avez-vous oublié d’ajouter les deux points `:` ?
        
    Une exception de type `SyntaxError` se produit lorsque Python ne peut pas comprendre votre code.
    
    Python peut seulement comprendre le code du fichier
    'TESTS:\syntax\missing_colon_if.py'
    jusqu'à l'endroit indiqué par ^.
    
       1: """Should raise SyntaxError"""
       2: 
    -->3: if True
                 ^

    Vous avez écrit un énoncé débutant avec
    `if` mais vous avez oublié d’ajouter deux points `:` à la fin.
    
    

(128) Missing colon - while
---------------------------

.. code-block:: none


    Traceback (most recent call last):
      File "TESTS:\trb_syntax_common.py", line 49, in create_tracebacks
        __import__(name)
      File "TESTS:\syntax\missing_colon_while.py", line 3
        while True  # a comment
                    ^
    SyntaxError: invalid syntax
    
        Avez-vous oublié d’ajouter les deux points `:` ?
        
    Une exception de type `SyntaxError` se produit lorsque Python ne peut pas comprendre votre code.
    
    Python peut seulement comprendre le code du fichier
    'TESTS:\syntax\missing_colon_while.py'
    jusqu'à l'endroit indiqué par ^.
    
       1: """Should raise SyntaxError"""
       2: 
    -->3: while True  # a comment
                      ^

    Vous vouliez débuter une boucle `while`
    mais vous avez oublié d’ajouter deux points `:` à la fin.
    
    

(129) Missing comma in a dict
-----------------------------

.. code-block:: none


    Traceback (most recent call last):
      File "TESTS:\trb_syntax_common.py", line 49, in create_tracebacks
        __import__(name)
      File "TESTS:\syntax\missing_comma_in_dict.py", line 5
        'c': 3,
        ^
    SyntaxError: invalid syntax
    
        Avez-vous oublié une virgule ?
        
    Une exception de type `SyntaxError` se produit lorsque Python ne peut pas comprendre votre code.
    
    Python peut seulement comprendre le code du fichier
    'TESTS:\syntax\missing_comma_in_dict.py'
    jusqu'à l'endroit indiqué par ^.
    
       2: 
       3: a = {'a': 1,
       4:      'b': 2
    -->5:      'c': 3,
               ^
       6: }

    Python indique que l’erreur est causée par `'c'` écrit tout juste après `2`.
    Il est également possible que vous ayez oublié une virgule entre les éléments d'un ensemble (set)
    ou un dict avant la position indiquée par ^.
    Peut-être que vous vouliez plutôt
    
        a = {'a': 1,
     'b': 2,
     'c': 3,
    }
    

(130) Missing comma between strings in a dict
---------------------------------------------

.. code-block:: none


    Traceback (most recent call last):
      File "TESTS:\trb_syntax_common.py", line 49, in create_tracebacks
        __import__(name)
      File "TESTS:\syntax\missing_comma_in_dict_2.py", line 4
        'c': '3',
           ^
    SyntaxError: invalid syntax
    
        Avez-vous oublié une virgule ?
        
    Une exception de type `SyntaxError` se produit lorsque Python ne peut pas comprendre votre code.
    
    Python peut seulement comprendre le code du fichier
    'TESTS:\syntax\missing_comma_in_dict_2.py'
    jusqu'à l'endroit indiqué par ^.
    
       1: 
       2: a = {'a': '1',
       3:      'b': '2'
    -->4:      'c': '3',
                  ^
       5: }

    Je crois que vous avez oublié une virgule entre deux chaînes de caractères
    lors de la définition d’un dictionnaire.
    
    ```
    a = {'a': '1',
         'b': '2'
          «,» 'c': '3',
    }
    ```

(131) Missing comma in a list
-----------------------------

.. code-block:: none


    Traceback (most recent call last):
      File "TESTS:\trb_syntax_common.py", line 49, in create_tracebacks
        __import__(name)
      File "TESTS:\syntax\missing_comma_in_list.py", line 3
        a = [1, 2  3]
                   ^
    SyntaxError: invalid syntax
    
        Avez-vous oublié quelque chose entre `2` et `3` ?
        
    Une exception de type `SyntaxError` se produit lorsque Python ne peut pas comprendre votre code.
    
    Python peut seulement comprendre le code du fichier
    'TESTS:\syntax\missing_comma_in_list.py'
    jusqu'à l'endroit indiqué par ^.
    
       1: """Should raise SyntaxError: invalid syntax"""
       2: 
    -->3: a = [1, 2  3]
                     ^

    Python indique que l’erreur est causée par `3` écrit tout juste après `2`.
    Il est également possible que vous ayez oublié une virgule entre les éléments d'une liste
    avant la position indiquée par ^.
    Peut-être que vous vouliez insérer un opérateur comme `+, -, *`
    entre `2` et `3`.
    Les lignes de code suivantes ne causeraient pas des `SyntaxError :
    
        a = [1, 2,  3]
        a = [1, 2 +  3]
        a = [1, 2 -  3]
        a = [1, 2 *  3]
    Remarque : ce ne sont là que quelques-uns des choix possibles et
    certains d’entre eux pourraient soulever d’autres types d’exceptions.
    

(132) Missing comma in a set
----------------------------

.. code-block:: none


    Traceback (most recent call last):
      File "TESTS:\trb_syntax_common.py", line 49, in create_tracebacks
        __import__(name)
      File "TESTS:\syntax\missing_comma_in_set.py", line 3
        a = {1, 2  3}
                   ^
    SyntaxError: invalid syntax
    
        Avez-vous oublié quelque chose entre `2` et `3` ?
        
    Une exception de type `SyntaxError` se produit lorsque Python ne peut pas comprendre votre code.
    
    Python peut seulement comprendre le code du fichier
    'TESTS:\syntax\missing_comma_in_set.py'
    jusqu'à l'endroit indiqué par ^.
    
       1: """Should raise SyntaxError: invalid syntax"""
       2: 
    -->3: a = {1, 2  3}
                     ^

    Python indique que l’erreur est causée par `3` écrit tout juste après `2`.
    Il est également possible que vous ayez oublié une virgule entre les éléments d'un ensemble (set)
    ou un dict avant la position indiquée par ^.
    Peut-être que vous vouliez insérer un opérateur comme `+, -, *`
    entre `2` et `3`.
    Les lignes de code suivantes ne causeraient pas des `SyntaxError :
    
        a = {1, 2,  3}
        a = {1, 2 +  3}
        a = {1, 2 -  3}
        a = {1, 2 *  3}
    Remarque : ce ne sont là que quelques-uns des choix possibles et
    certains d’entre eux pourraient soulever d’autres types d’exceptions.
    

(133) Missing comma in a tuple
------------------------------

.. code-block:: none


    Traceback (most recent call last):
      File "TESTS:\trb_syntax_common.py", line 49, in create_tracebacks
        __import__(name)
      File "TESTS:\syntax\missing_comma_in_tuple.py", line 3
        a = (1, 2  3)
                   ^
    SyntaxError: invalid syntax
    
        Avez-vous oublié quelque chose entre `2` et `3` ?
        
    Une exception de type `SyntaxError` se produit lorsque Python ne peut pas comprendre votre code.
    
    Python peut seulement comprendre le code du fichier
    'TESTS:\syntax\missing_comma_in_tuple.py'
    jusqu'à l'endroit indiqué par ^.
    
       1: """Should raise SyntaxError: invalid syntax"""
       2: 
    -->3: a = (1, 2  3)
                     ^

    Python indique que l’erreur est causée par `3` écrit tout juste après `2`.
    Il est également possible que vous ayez oublié une virgule entre les éléments d'un tuple,
    ou entre les arguments d'une fonction, avant la position indiquée par ^.
    Peut-être que vous vouliez insérer un opérateur comme `+, -, *`
    entre `2` et `3`.
    Les lignes de code suivantes ne causeraient pas des `SyntaxError :
    
        a = (1, 2,  3)
        a = (1, 2 +  3)
        a = (1, 2 -  3)
        a = (1, 2 *  3)
    Remarque : ce ne sont là que quelques-uns des choix possibles et
    certains d’entre eux pourraient soulever d’autres types d’exceptions.
    

(134) For loop missing 'in' operator
------------------------------------

.. code-block:: none


    Traceback (most recent call last):
      File "TESTS:\trb_syntax_common.py", line 49, in create_tracebacks
        __import__(name)
      File "TESTS:\syntax\missing_in_with_for.py", line 1
        for x range(4):
              ^
    SyntaxError: invalid syntax
    
        Avez-vous oublié d’écrire `in` ?
        
    Une exception de type `SyntaxError` se produit lorsque Python ne peut pas comprendre votre code.
    
    Python peut seulement comprendre le code du fichier
    'TESTS:\syntax\missing_in_with_for.py'
    jusqu'à l'endroit indiqué par ^.
    
    -->1: for x range(4):
                ^

    Il semble que vous avez oublié d’utiliser le mot clé `in »
    dans énoncé `for`. Peut-être que vous vouliez dire:
    
        for x in range(4):
    
    

(135) Missing parenthesis for range
-----------------------------------

.. code-block:: none


    Traceback (most recent call last):
      File "TESTS:\trb_syntax_common.py", line 49, in create_tracebacks
        __import__(name)
      File "TESTS:\syntax\missing_parens_for_range.py", line 1
        for i in range 3:
                       ^
    SyntaxError: invalid syntax
    
        Avez-vous oublié d’ajouter des parenthèses ?
        
    Une exception de type `SyntaxError` se produit lorsque Python ne peut pas comprendre votre code.
    
    Python peut seulement comprendre le code du fichier
    'TESTS:\syntax\missing_parens_for_range.py'
    jusqu'à l'endroit indiqué par ^.
    
    -->1: for i in range 3:
                         ^

    Il semble que vous avez oublié d’utiliser des parenthèses
    avec `range`. Peut-être que vous vouliez dire:
    
        for i in range( 3):
    
    

(136) Name is global and nonlocal
---------------------------------

.. code-block:: none


    Traceback (most recent call last):
      File "TESTS:\trb_syntax_common.py", line 49, in create_tracebacks
        __import__(name)
      File "TESTS:\syntax\name_is_global_and_nonlocal.py", line 7
        global xy
        ^
    SyntaxError: name 'xy' is nonlocal and global
    
    Une exception de type `SyntaxError` se produit lorsque Python ne peut pas comprendre votre code.
    
    Python peut seulement comprendre le code du fichier
    'TESTS:\syntax\name_is_global_and_nonlocal.py'
    jusqu'à l'endroit indiqué par ^.
    
       3: xy = 1
       4: 
       5: 
       6: def f():
    -->7:     global xy
              ^

    Vous avez utilisé `xy` comme étant une variable non locale et globale.
    Une variable peut être d'un seul type à la fois: soit globale, soit non locale, ou soit locale.
    

(137) Name is parameter and nonlocal
------------------------------------

.. code-block:: none


    Traceback (most recent call last):
      File "TESTS:\trb_syntax_common.py", line 49, in create_tracebacks
        __import__(name)
      File "TESTS:\syntax\name_is_param_and_nonlocal.py", line 5
        nonlocal x
        ^
    SyntaxError: name 'x' is parameter and nonlocal
    
    Une exception de type `SyntaxError` se produit lorsque Python ne peut pas comprendre votre code.
    
    Python peut seulement comprendre le code du fichier
    'TESTS:\syntax\name_is_param_and_nonlocal.py'
    jusqu'à l'endroit indiqué par ^.
    
       1: """Should raise SyntaxError: name 'x' is parameter and nonlocal"""
       2: 
       3: 
       4: def f(x):
    -->5:     nonlocal x
              ^

    Vous avez utilisé `x` comme paramètre pour une fonction
    avant de la déclarer également comme une variable non locale :
    `x` ne peut pas être les deux en même temps.
    

(138) nonlocal variable not found
---------------------------------

.. code-block:: none


    Traceback (most recent call last):
      File "TESTS:\trb_syntax_common.py", line 49, in create_tracebacks
        __import__(name)
      File "TESTS:\syntax\no_binding_for_nonlocal.py", line 5
        nonlocal ab
        ^
    SyntaxError: no binding for nonlocal 'ab' found
    
    Une exception de type `SyntaxError` se produit lorsque Python ne peut pas comprendre votre code.
    
    Python peut seulement comprendre le code du fichier
    'TESTS:\syntax\no_binding_for_nonlocal.py'
    jusqu'à l'endroit indiqué par ^.
    
       1: """Should raise SyntaxError: no binding for nonlocal 'ab' found"""
       2: 
       3: 
       4: def f():
    -->5:     nonlocal ab
              ^

    Vous avez déclaré la variable `ab` comme non locale
    mais elle n'existe pas ailleurs.
    

(139) nonlocal variable not found at module level
-------------------------------------------------

.. code-block:: none


    Traceback (most recent call last):
      File "TESTS:\trb_syntax_common.py", line 49, in create_tracebacks
        __import__(name)
      File "TESTS:\syntax\nonlocal_at_module.py", line 4
        nonlocal cd
        ^
    SyntaxError: nonlocal declaration not allowed at module level
    
    Une exception de type `SyntaxError` se produit lorsque Python ne peut pas comprendre votre code.
    
    Python peut seulement comprendre le code du fichier
    'TESTS:\syntax\nonlocal_at_module.py'
    jusqu'à l'endroit indiqué par ^.
    
       1: """Should raise SyntaxError:  nonlocal declaration not allowed at module level"""
       2: 
       3: 
    -->4: nonlocal cd
          ^

    Vous avez utilisé le mot clé nonlocal au niveau d'un module.
    Le mot clé nonlocal fait référence à une variable à l'intérieur d'une fonction
    qui a une valeur attribuée à l'extérieur de cette fonction.

(140) Same operator twice in a row
----------------------------------

.. code-block:: none


    Traceback (most recent call last):
      File "TESTS:\trb_syntax_common.py", line 49, in create_tracebacks
        __import__(name)
      File "TESTS:\syntax\operator_twice_in_a_row.py", line 1
        4****5
           ^
    SyntaxError: invalid syntax
    
    Une exception de type `SyntaxError` se produit lorsque Python ne peut pas comprendre votre code.
    
    Python peut seulement comprendre le code du fichier
    'TESTS:\syntax\operator_twice_in_a_row.py'
    jusqu'à l'endroit indiqué par ^.
    
    -->1: 4****5
             ^

    Vous ne pouvez pas écrire le même opérateur, `**`, deux fois de suite.
    Peut-être avez-vous écrit l’un d’eux par erreur
    ou vous avez oublié d’écrire quelque chose entre les deux.
    

(141) Using pip from interpreter
--------------------------------

.. code-block:: none


    Traceback (most recent call last):
      File "TESTS:\trb_syntax_common.py", line 49, in create_tracebacks
        __import__(name)
      File "TESTS:\syntax\pip_install_1.py", line 2
        pip install friendly
            ^
    SyntaxError: invalid syntax
    
        Pip ne peut pas être utilisé dans un interprète Python.
        
    Une exception de type `SyntaxError` se produit lorsque Python ne peut pas comprendre votre code.
    
    Python peut seulement comprendre le code du fichier
    'TESTS:\syntax\pip_install_1.py'
    jusqu'à l'endroit indiqué par ^.
    
       1: """Should raise SyntaxError: invalid syntax"""
    -->2: pip install friendly
              ^

    Il semble que vous essayez d’utiliser pip pour installer un module.
    `pip` est une commande qui doit être invoquée dans un terminal,
    pas dans un interprète Python.
    

(142) Using pip from interpreter 2
----------------------------------

.. code-block:: none


    Traceback (most recent call last):
      File "TESTS:\trb_syntax_common.py", line 49, in create_tracebacks
        __import__(name)
      File "TESTS:\syntax\pip_install_2.py", line 2
        python -m pip install friendly
                  ^
    SyntaxError: invalid syntax
    
        Pip ne peut pas être utilisé dans un interprète Python.
        
    Une exception de type `SyntaxError` se produit lorsque Python ne peut pas comprendre votre code.
    
    Python peut seulement comprendre le code du fichier
    'TESTS:\syntax\pip_install_2.py'
    jusqu'à l'endroit indiqué par ^.
    
       1: """Should raise SyntaxError: invalid syntax"""
    -->2: python -m pip install friendly
                    ^

    Il semble que vous essayez d’utiliser pip pour installer un module.
    `pip` est une commande qui doit être invoquée dans un terminal,
    pas dans un interprète Python.
    

(143) print is a function
-------------------------

.. code-block:: none


    Traceback (most recent call last):
      File "TESTS:\trb_syntax_common.py", line 49, in create_tracebacks
        __import__(name)
      File "TESTS:\syntax\print_is_a_function.py", line 2
        print 'hello'
              ^
    SyntaxError: Missing parentheses in call to 'print'. Did you mean print('hello')?
    
        Vouliez-vous dire `print('hello')` ?
        
    Une exception de type `SyntaxError` se produit lorsque Python ne peut pas comprendre votre code.
    
    Python peut seulement comprendre le code du fichier
    'TESTS:\syntax\print_is_a_function.py'
    jusqu'à l'endroit indiqué par ^.
    
       1: """Should raise SyntaxError: Missing parentheses in call to 'print' ..."""
    -->2: print 'hello'
                ^

    Peut-être que vous avez besoin d'écrire
    
         print('hello')
    
    Dans l'ancienne version de Python, `print` était un mot clé.
    Maintenant, `print` est une fonction; vous devez utiliser des parenthèses pour l'invoquer.
    

(144) print is a function 2
---------------------------

.. code-block:: none


    Traceback (most recent call last):
      File "TESTS:\trb_syntax_common.py", line 49, in create_tracebacks
        __import__(name)
      File "TESTS:\syntax\print_is_a_function_2.py", line 2
        print len('hello')
              ^
    SyntaxError: invalid syntax
    
        Vouliez-vous dire `print(len('hello'))` ?
        
    Une exception de type `SyntaxError` se produit lorsque Python ne peut pas comprendre votre code.
    
    Python peut seulement comprendre le code du fichier
    'TESTS:\syntax\print_is_a_function_2.py'
    jusqu'à l'endroit indiqué par ^.
    
       1: """Should raise SyntaxError: invalid syntax"""
    -->2: print len('hello')
                ^

    Dans l'ancienne version de Python, `print` était un mot clé.
    Maintenant, `print` est une fonction; vous devez utiliser des parenthèses pour l'invoquer.
    

(145) print is a function 3
---------------------------

.. code-block:: none


    Traceback (most recent call last):
      File "TESTS:\trb_syntax_common.py", line 49, in create_tracebacks
        __import__(name)
      File "TESTS:\syntax\print_is_a_function_3.py", line 1
        print """This is a very long string which results in a very long error message."""
              ^
    SyntaxError: Missing parentheses in call to 'print'. Did you mean print("""This is a very long string which results in a very long error message.""")?
    
        Vouliez-vous dire `print("""This is a very long st ... )` ?
        
    Une exception de type `SyntaxError` se produit lorsque Python ne peut pas comprendre votre code.
    
    Python peut seulement comprendre le code du fichier
    'TESTS:\syntax\print_is_a_function_3.py'
    jusqu'à l'endroit indiqué par ^.
    
    -->1: print """This is a very long string which results in a very long error message."""
                ^

    Peut-être que vous avez besoin d'écrire
    
         print("""This is a very long st ... )
    
    Dans l'ancienne version de Python, `print` était un mot clé.
    Maintenant, `print` est une fonction; vous devez utiliser des parenthèses pour l'invoquer.
    

(146) print is a function 4
---------------------------

.. code-block:: none


    Traceback (most recent call last):
      File "TESTS:\trb_syntax_common.py", line 49, in create_tracebacks
        __import__(name)
      File "TESTS:\syntax\print_is_a_function_4.py", line 2
        print len("""This is a long string
              ^
    SyntaxError: invalid syntax
    
        Vouliez-vous dire `print(...)` ?
        
    Une exception de type `SyntaxError` se produit lorsque Python ne peut pas comprendre votre code.
    
    Python peut seulement comprendre le code du fichier
    'TESTS:\syntax\print_is_a_function_4.py'
    jusqu'à l'endroit indiqué par ^.
    
       1: """Should raise SyntaxError: invalid syntax"""
    -->2: print len("""This is a long string
                ^
       3:           that spans multiple lines.""")

    Dans l'ancienne version de Python, `print` était un mot clé.
    Maintenant, `print` est une fonction; vous devez utiliser des parenthèses pour l'invoquer.
    

(147) print is a function 5
---------------------------

.. code-block:: none


    Traceback (most recent call last):
      File "TESTS:\trb_syntax_common.py", line 49, in create_tracebacks
        __import__(name)
      File "TESTS:\syntax\print_is_a_function_5.py", line 2
        print len('This is a long string that fits on a single line.')
              ^
    SyntaxError: invalid syntax
    
        Vouliez-vous dire `print(len('This ... line.'))` ?
        
    Une exception de type `SyntaxError` se produit lorsque Python ne peut pas comprendre votre code.
    
    Python peut seulement comprendre le code du fichier
    'TESTS:\syntax\print_is_a_function_5.py'
    jusqu'à l'endroit indiqué par ^.
    
       1: """Should raise SyntaxError: invalid syntax"""
    -->2: print len('This is a long string that fits on a single line.')
                ^

    Dans l'ancienne version de Python, `print` était un mot clé.
    Maintenant, `print` est une fonction; vous devez utiliser des parenthèses pour l'invoquer.
    

(148) Calling python from interpreter
-------------------------------------

.. code-block:: none


    Traceback (most recent call last):
      File "TESTS:\trb_syntax_common.py", line 49, in create_tracebacks
        __import__(name)
      File "TESTS:\syntax\python_interpreter.py", line 1
        python -i friendly
                  ^
    SyntaxError: invalid syntax
    
    Une exception de type `SyntaxError` se produit lorsque Python ne peut pas comprendre votre code.
    
    Python peut seulement comprendre le code du fichier
    'TESTS:\syntax\python_interpreter.py'
    jusqu'à l'endroit indiqué par ^.
    
    -->1: python -i friendly
                    ^

    Je suppose que vous essayez d’utiliser Python pour exécuter un programme.
    Vous devez le faire à partir d’un terminal et non d’un interprète Python.
    

(149) problem with assigning a variable to Python
-------------------------------------------------

.. code-block:: none


    Traceback (most recent call last):
      File "TESTS:\trb_syntax_common.py", line 49, in create_tracebacks
        __import__(name)
      File "TESTS:\syntax\python_not_interpreter.py", line 1
        python = a b
                   ^
    SyntaxError: invalid syntax
    
        Avez-vous oublié quelque chose entre `a` et `b` ?
        
    Une exception de type `SyntaxError` se produit lorsque Python ne peut pas comprendre votre code.
    
    Python peut seulement comprendre le code du fichier
    'TESTS:\syntax\python_not_interpreter.py'
    jusqu'à l'endroit indiqué par ^.
    
    -->1: python = a b
                     ^

    Python indique que l’erreur est causée par `b` écrit tout juste après `a`.
    Peut-être que vous vouliez insérer un opérateur comme `+; -; *; ,`
    entre `a` et `b`.
    Les lignes de code suivantes ne causeraient pas des `SyntaxError :
    
        python = a + b
        python = a - b
        python = a * b
        python = a, b
    Remarque : ce ne sont là que quelques-uns des choix possibles et
    certains d’entre eux pourraient soulever d’autres types d’exceptions.
    

(150) Quote inside a string
---------------------------

.. code-block:: none


    Traceback (most recent call last):
      File "TESTS:\trb_syntax_common.py", line 49, in create_tracebacks
        __import__(name)
      File "TESTS:\syntax\quote_inside_string.py", line 3
        message = 'don't'
                       ^
    SyntaxError: invalid syntax
    
        Vous avez peut-être un guillemet écrit au mauvais endroit.
        
    Une exception de type `SyntaxError` se produit lorsque Python ne peut pas comprendre votre code.
    
    Python peut seulement comprendre le code du fichier
    'TESTS:\syntax\quote_inside_string.py'
    jusqu'à l'endroit indiqué par ^.
    
       1: """Should raise SyntaxError: invalid syntax"""
       2: 
    -->3: message = 'don't'
                         ^

    Il semble y avoir un identificateur Python (nom de variable)
    immédiatement après une chaîne.
    Je soupçonne que vous essayiez d'utiliser un apostrophe ou un guillemet
    à l'intérieur d'une chaîne qui était délimitée par ces mêmes caractères.
    

(151) Raising multiple exceptions
---------------------------------

.. code-block:: none


    Traceback (most recent call last):
      File "TESTS:\trb_syntax_common.py", line 49, in create_tracebacks
        __import__(name)
      File "TESTS:\syntax\raise_multiple_exceptions.py", line 2
        raise X, Y
               ^
    SyntaxError: invalid syntax
    
    Une exception de type `SyntaxError` se produit lorsque Python ne peut pas comprendre votre code.
    
    Python peut seulement comprendre le code du fichier
    'TESTS:\syntax\raise_multiple_exceptions.py'
    jusqu'à l'endroit indiqué par ^.
    
       1: """Should raise SyntaxError: invalid syntax"""
    -->2: raise X, Y
                 ^

    Je crois que vous essayez de lever une exception en utilisant la syntaxe de Python 2.
    

(152) Cannot use return outside function
----------------------------------------

.. code-block:: none


    Traceback (most recent call last):
      File "TESTS:\trb_syntax_common.py", line 49, in create_tracebacks
        __import__(name)
      File "TESTS:\syntax\return_outside_function.py", line 3
        return
        ^
    SyntaxError: 'return' outside function
    
    Une exception de type `SyntaxError` se produit lorsque Python ne peut pas comprendre votre code.
    
    Python peut seulement comprendre le code du fichier
    'TESTS:\syntax\return_outside_function.py'
    jusqu'à l'endroit indiqué par ^.
    
       1: """Should raise SyntaxError: 'return' outside function"""
       2: 
    -->3: return
          ^

    Vous ne pouvez utiliser un énoncé `return` qu'à l’intérieur d’une fonction ou d’une méthode.
    

(153) Semi-colon instead of comma - 1
-------------------------------------

.. code-block:: none


    Traceback (most recent call last):
      File "TESTS:\trb_syntax_common.py", line 49, in create_tracebacks
        __import__(name)
      File "TESTS:\syntax\semi_colon_instead_of_comma_1.py", line 1
        a = [1, 2; 3]
                 ^
    SyntaxError: invalid syntax
    
        Avez-vous oublié une virgule ?
        
    Une exception de type `SyntaxError` se produit lorsque Python ne peut pas comprendre votre code.
    
    Python peut seulement comprendre le code du fichier
    'TESTS:\syntax\semi_colon_instead_of_comma_1.py'
    jusqu'à l'endroit indiqué par ^.
    
    -->1: a = [1, 2; 3]
                   ^

    Vous avez écrit un point-virgule, `;`, au lieu d'une virgule.
    
    

(154) Semi-colon instead of commas - 2
--------------------------------------

.. code-block:: none


    Traceback (most recent call last):
      File "TESTS:\trb_syntax_common.py", line 49, in create_tracebacks
        __import__(name)
      File "TESTS:\syntax\semi_colon_instead_of_comma_2.py", line 1
        a = [1; 2; 3]
              ^
    SyntaxError: invalid syntax
    
        Vouliez-vous écrire des virgules ?
        
    Une exception de type `SyntaxError` se produit lorsque Python ne peut pas comprendre votre code.
    
    Python peut seulement comprendre le code du fichier
    'TESTS:\syntax\semi_colon_instead_of_comma_2.py'
    jusqu'à l'endroit indiqué par ^.
    
    -->1: a = [1; 2; 3]
                ^

    Vous avez écrit des points-virgules, `;`, au lieu de virgules.
    
    

(155) Semi-colon instead of commas - 3
--------------------------------------

.. code-block:: none


    Traceback (most recent call last):
      File "TESTS:\trb_syntax_common.py", line 49, in create_tracebacks
        __import__(name)
      File "TESTS:\syntax\semi_colon_instead_of_comma_3.py", line 1
        a = [1; 2; 3];
              ^
    SyntaxError: invalid syntax
    
        Vouliez-vous écrire des virgules ?
        
    Une exception de type `SyntaxError` se produit lorsque Python ne peut pas comprendre votre code.
    
    Python peut seulement comprendre le code du fichier
    'TESTS:\syntax\semi_colon_instead_of_comma_3.py'
    jusqu'à l'endroit indiqué par ^.
    
    -->1: a = [1; 2; 3];
                ^

    Vous avez écrit des points-virgules, `;`, au lieu de virgules.
    
    

(156) Single = instead of double == with if
-------------------------------------------

.. code-block:: none


    Traceback (most recent call last):
      File "TESTS:\trb_syntax_common.py", line 49, in create_tracebacks
        __import__(name)
      File "TESTS:\syntax\single_equal_with_if.py", line 3
        if i % 2 = 0:
                 ^
    SyntaxError: invalid syntax
    
        Peut-être que vous aviez besoin de `==` au lieu de `=`.
        
    Une exception de type `SyntaxError` se produit lorsque Python ne peut pas comprendre votre code.
    
    Python peut seulement comprendre le code du fichier
    'TESTS:\syntax\single_equal_with_if.py'
    jusqu'à l'endroit indiqué par ^.
    
       1: """Should raise SyntaxError: invalid syntax"""
       2: for i in range(101):
    -->3:     if i % 2 = 0:
                       ^

    Vous avez utilisé un opérateur d’affectation `=` au lieu d’un opérateur d'égalité `==` 
    

(157) Single = instead of double == with elif
---------------------------------------------

.. code-block:: none


    Traceback (most recent call last):
      File "TESTS:\trb_syntax_common.py", line 49, in create_tracebacks
        __import__(name)
      File "TESTS:\syntax\single_equal_with_elif.py", line 5
        elif i % 2 = 0:
                   ^
    SyntaxError: invalid syntax
    
        Peut-être que vous aviez besoin de `==` au lieu de `=`.
        
    Une exception de type `SyntaxError` se produit lorsque Python ne peut pas comprendre votre code.
    
    Python peut seulement comprendre le code du fichier
    'TESTS:\syntax\single_equal_with_elif.py'
    jusqu'à l'endroit indiqué par ^.
    
       1: """Should raise SyntaxError: invalid syntax"""
       2: for i in range(101):
       3:     if False:
       4:         pass
    -->5:     elif i % 2 = 0:
                         ^

    Vous avez utilisé un opérateur d’affectation `=` au lieu d’un opérateur d'égalité `==` 
    

(158) Single = instead of double == with while
----------------------------------------------

.. code-block:: none


    Traceback (most recent call last):
      File "TESTS:\trb_syntax_common.py", line 49, in create_tracebacks
        __import__(name)
      File "TESTS:\syntax\single_equal_with_while.py", line 4
        while a = 1:
                ^
    SyntaxError: invalid syntax
    
        Peut-être que vous aviez besoin de `==` ou `:=` au lieu de `=`.
        
    Une exception de type `SyntaxError` se produit lorsque Python ne peut pas comprendre votre code.
    
    Python peut seulement comprendre le code du fichier
    'TESTS:\syntax\single_equal_with_while.py'
    jusqu'à l'endroit indiqué par ^.
    
       1: """Should raise SyntaxError: invalid syntax"""
       2: a = 1
       3: 
    -->4: while a = 1:
                  ^

    Vous avez utilisé un opérateur d’affectation `=`; vous vouliez peut-être utiliser 
    un opérateur d'égalité, `==`, ou l'opérateur `:=`.
    

(159) Space between operators 1
-------------------------------

.. code-block:: none


    Traceback (most recent call last):
      File "TESTS:\trb_syntax_common.py", line 49, in create_tracebacks
        __import__(name)
      File "TESTS:\syntax\space_between_operators_1.py", line 1
        a = 2 * * 5
                ^
    SyntaxError: invalid syntax
    
    Une exception de type `SyntaxError` se produit lorsque Python ne peut pas comprendre votre code.
    
    Python peut seulement comprendre le code du fichier
    'TESTS:\syntax\space_between_operators_1.py'
    jusqu'à l'endroit indiqué par ^.
    
    -->1: a = 2 * * 5
                  ^

    Vous ne pouvez pas écrire le même opérateur, `*`, deux fois de suite.
    Peut-être avez-vous écrit l’un d’eux par erreur
    ou vous avez oublié d’écrire quelque chose entre les deux.
    Ou peut-être avez-vous inclus un espace par erreur entre les deux opérateurs
    et vouliez écrire l'opérateur `**`.
    

(160) Space between operators 2
-------------------------------

.. code-block:: none


    Traceback (most recent call last):
      File "TESTS:\trb_syntax_common.py", line 49, in create_tracebacks
        __import__(name)
      File "TESTS:\syntax\space_between_operators_2.py", line 1
        a / = b
            ^
    SyntaxError: invalid syntax
    
    Une exception de type `SyntaxError` se produit lorsque Python ne peut pas comprendre votre code.
    
    Python peut seulement comprendre le code du fichier
    'TESTS:\syntax\space_between_operators_2.py'
    jusqu'à l'endroit indiqué par ^.
    
    -->1: a / = b
              ^

    Vous ne pouvez pas avoir ces deux opérateurs, `/` et `=`,
    qui se suivent. Peut-être avez-vous écrit l’un d’eux par erreur
    ou vous avez oublié d’écrire quelque chose entre les deux.
    Ou peut-être avez-vous inclus un espace par erreur entre les deux opérateurs
    et vouliez écrire l'opérateur `/=`.
    

(161) Space in variable name
----------------------------

.. code-block:: none


    Traceback (most recent call last):
      File "TESTS:\trb_syntax_common.py", line 49, in create_tracebacks
        __import__(name)
      File "TESTS:\syntax\space_in_variable_name.py", line 1
        my name = André
           ^
    SyntaxError: invalid syntax
    
        Vouliez-vous dire `my_name` ?
        
    Une exception de type `SyntaxError` se produit lorsque Python ne peut pas comprendre votre code.
    
    Python peut seulement comprendre le code du fichier
    'TESTS:\syntax\space_in_variable_name.py'
    jusqu'à l'endroit indiqué par ^.
    
    -->1: my name = André
             ^

    Vous ne pouvez pas avoir d’espaces dans les identifiants (noms de variables).
    

(162) Too many nested blocks
----------------------------

.. code-block:: none


    Traceback (most recent call last):
      File "TESTS:\trb_syntax_common.py", line 49, in create_tracebacks
        __import__(name)
      File "None", line None
    SyntaxError: too many statically nested blocks
    
        Sérieusement ?
        
    Une exception de type `SyntaxError` se produit lorsque Python ne peut pas comprendre votre code.
    
    Vous n'êtes pas sérieux !
    
    Dans le cas où il s’agit d’une erreur dans un vrai programme, s’il vous plaît
    songez à réduire le nombre de blocs de code imbriqués.
    

(163) Triple-equal sign
-----------------------

.. code-block:: none


    Traceback (most recent call last):
      File "TESTS:\trb_syntax_common.py", line 49, in create_tracebacks
        __import__(name)
      File "TESTS:\syntax\triple_equal.py", line 3
        x = y === z
                ^
    SyntaxError: invalid syntax
    
        Voulez-vous utiliser `is` au lieu de `===`?
        
    Une exception de type `SyntaxError` se produit lorsque Python ne peut pas comprendre votre code.
    
    Python peut seulement comprendre le code du fichier
    'TESTS:\syntax\triple_equal.py'
    jusqu'à l'endroit indiqué par ^.
    
       1: 
       2: 
    -->3: x = y === z
                  ^

    Vous avez écrit trois signes égaux de suite ce qui est utilisé dans certains
    langages de programmation, mais pas en Python. Pour vérifier si deux objets
    sont égaux, utilisent deux signes d'égalité, `==`; pour voir si deux noms représentent
    exactement le même objet, utilisez l’opérateur `is`.
    

(164) Unclosed bracket
----------------------

.. code-block:: none


    Traceback (most recent call last):
      File "TESTS:\trb_syntax_common.py", line 49, in create_tracebacks
        __import__(name)
      File "TESTS:\syntax\unclosed_bracket.py", line 7
        print(foo())
        ^
    SyntaxError: invalid syntax
    
    Une exception de type `SyntaxError` se produit lorsque Python ne peut pas comprendre votre code.
    
    Python peut seulement comprendre le code du fichier
    'TESTS:\syntax\unclosed_bracket.py'
    jusqu'à l'endroit indiqué par ^.
    
        3: 
        4: def foo():
        5:     return [1, 2, 3
        6: 
    --> 7: print(foo())
           ^

    Le symbole crochet `[` à la ligne 5 n'est pas fermé par le symbole correspondant.
    
        5:     return [1, 2, 3
                      ^
    

(165) Unclosed parenthesis - 1
------------------------------

.. code-block:: none


    Traceback (most recent call last):
      File "TESTS:\trb_syntax_common.py", line 49, in create_tracebacks
        __import__(name)
      File "TESTS:\syntax\unclosed_paren_1.py", line 3
        if x == 1:
                 ^
    SyntaxError: invalid syntax
    
    Une exception de type `SyntaxError` se produit lorsque Python ne peut pas comprendre votre code.
    
    Python peut seulement comprendre le code du fichier
    'TESTS:\syntax\unclosed_paren_1.py'
    jusqu'à l'endroit indiqué par ^.
    
       1: """Should raise SyntaxError: invalid syntax"""
       2: x = int('1'
    -->3: if x == 1:
                   ^
       4:     print('yes')

    Le symbole parenthèse `(` à la ligne 2 n'est pas fermé par le symbole correspondant.
    
        2: x = int('1'
                  ^
    

(166) Unclosed parenthesis - 2
------------------------------

.. code-block:: none


    Traceback (most recent call last):
      File "TESTS:\trb_syntax_common.py", line 49, in create_tracebacks
        __import__(name)
      File "TESTS:\syntax\unclosed_paren_2.py", line 3
        d = a*a
        ^
    SyntaxError: invalid syntax
    
    Une exception de type `SyntaxError` se produit lorsque Python ne peut pas comprendre votre code.
    
    Python peut seulement comprendre le code du fichier
    'TESTS:\syntax\unclosed_paren_2.py'
    jusqu'à l'endroit indiqué par ^.
    
       1: """Should raise SyntaxError: invalid syntax"""
       2: a = (b+c
    -->3: d = a*a
          ^

    Le symbole parenthèse `(` à la ligne 2 n'est pas fermé par le symbole correspondant.
    
        2: a = (b+c
               ^
    

(167) Unclosed parenthesis - 3
------------------------------

.. code-block:: none


    Traceback (most recent call last):
      File "TESTS:\trb_syntax_common.py", line 49, in create_tracebacks
        __import__(name)
      File "TESTS:\syntax\unclosed_paren_3.py", line 7
        if 2:
            ^
    SyntaxError: invalid syntax
    
    Une exception de type `SyntaxError` se produit lorsque Python ne peut pas comprendre votre code.
    
    Python peut seulement comprendre le code du fichier
    'TESTS:\syntax\unclosed_paren_3.py'
    jusqu'à l'endroit indiqué par ^.
    
       4:     if 1:
       5:         print(((123))
       6: 
    -->7: if 2:
              ^
       8:     print(123))

    Le symbole parenthèse `(` à la ligne 5 n'est pas fermé par le symbole correspondant.
    
        5:         print(((123))
                        ^
    Si cela est incorrect, veuillez signaler ce cas.
    

(168) Unclosed parenthesis - 4
------------------------------

.. code-block:: none


    Traceback (most recent call last):
      File "TESTS:\trb_syntax_common.py", line 49, in create_tracebacks
        __import__(name)
      File "TESTS:\syntax\unclosed_paren_4.py", line 4
        def test():
        ^
    SyntaxError: invalid syntax
    
    Une exception de type `SyntaxError` se produit lorsque Python ne peut pas comprendre votre code.
    
    Python peut seulement comprendre le code du fichier
    'TESTS:\syntax\unclosed_paren_4.py'
    jusqu'à l'endroit indiqué par ^.
    
       1: # equal number of ( and ) in file
       2: print('hello'
       3: 
    -->4: def
          ^

    Le symbole parenthèse `(` à la ligne 2 n'est pas fermé par le symbole correspondant.
    
        2: print('hello'
                ^
    

(169) Content passed continuation line character
------------------------------------------------

.. code-block:: none


    Traceback (most recent call last):
      File "TESTS:\trb_syntax_common.py", line 49, in create_tracebacks
        __import__(name)
      File "TESTS:\syntax\unexpected_after_continuation_character.py", line 5
        print(\t)
                 ^
    SyntaxError: unexpected character after line continuation character
    
    Une exception de type `SyntaxError` se produit lorsque Python ne peut pas comprendre votre code.
    
    Python peut seulement comprendre le code du fichier
    'TESTS:\syntax\unexpected_after_continuation_character.py'
    jusqu'à l'endroit indiqué par ^.
    
       1: """Should raise
       2: SyntaxError: unexpected character after line continuation character
       3: """
       4: 
    -->5: print(\t)
                   ^

    Vous utilisez le caractère de continuation `\` en dehors d'une chaîne de caractères,
    et il est suivi par au moins un autre caractère.
    Je suppose que vous avez oublié d’enfermer du contenu dans une chaîne de caractères.
    

(170) Unexpected EOF while parsing
----------------------------------

.. code-block:: none


    Traceback (most recent call last):
      File "TESTS:\trb_syntax_common.py", line 49, in create_tracebacks
        __import__(name)
      File "TESTS:\syntax\unexpected_eof.py", line 8
    SyntaxError: unexpected EOF while parsing
    
    Une exception de type `SyntaxError` se produit lorsque Python ne peut pas comprendre votre code.
    
    Python peut seulement comprendre le code du fichier
    'TESTS:\syntax\unexpected_eof.py'
    jusqu'à l'endroit indiqué par ^.
    
        3: 
        4: def foo():
        5:     return [1, 2, 3,
        6: 
        7: print(foo())
    --> 8: 
           ^

    Python nous dit qu'il a atteint la fin du fichier
    et s'attendait à plus de contenu.
    
    Je vais essayer de donner un peu plus d'informations.
    
    
    Le symbole crochet `[` à la ligne 5 n'est pas fermé par le symbole correspondant.
    
        5:     return [1, 2, 3,
                      ^
    

(171) Invalid character (unicode quote)
---------------------------------------

.. code-block:: none


    Traceback (most recent call last):
      File "TESTS:\trb_syntax_common.py", line 49, in create_tracebacks
        __import__(name)
      File "TESTS:\syntax\unicode_quote.py", line 3
        a = « hello »
            ^
    SyntaxError: invalid character in identifier
    
        Vouliez vous utiliser un guillemet normal, `'` ou `"` ?
        
    Une exception de type `SyntaxError` se produit lorsque Python ne peut pas comprendre votre code.
    
    Python peut seulement comprendre le code du fichier
    'TESTS:\syntax\unicode_quote.py'
    jusqu'à l'endroit indiqué par ^.
    
       1: """Should raise SyntaxError: invalid character in identifier for Python <=3.8
       2:    and  SyntaxError: invalid character '«' (U+00AB) in Python 3.9"""
    -->3: a = « hello »
              ^

    Avez-vous utilisé le copier-coller ?
    Python indique que vous avez utilisé le caractère unicode `«`
    ce qui n’est pas permis.
    Je soupçonne que vous avez utilisé un guillemet unicode
    au lieu d'un guillemet normal (simple ou double) pour une chaîne de caractères.
    

(172) Unmatched closing curly bracket
-------------------------------------

.. code-block:: none


    Traceback (most recent call last):
      File "TESTS:\trb_syntax_common.py", line 49, in create_tracebacks
        __import__(name)
      File "TESTS:\syntax\unmatched_closing_curly.py", line 6
        3, 4,}}
              ^
    SyntaxError: unmatched '}'
    
    Une exception de type `SyntaxError` se produit lorsque Python ne peut pas comprendre votre code.
    
    Python peut seulement comprendre le code du fichier
    'TESTS:\syntax\unmatched_closing_curly.py'
    jusqu'à l'endroit indiqué par ^.
    
       1: """Should raise SyntaxError: invalid syntax for Python < 3.8
       2:    otherwise, SyntaxError: unmatched ')'
       3: """
       4: a = {1,
       5:     2,
    -->6:     3, 4,}}
                    ^

    Le symbole accolade `}` à la ligne 6 n'a pas de symbole ouvrant qui lui correspond.
    

(173) Unmatched closing parenthesis
-----------------------------------

.. code-block:: none


    Traceback (most recent call last):
      File "TESTS:\trb_syntax_common.py", line 49, in create_tracebacks
        __import__(name)
      File "TESTS:\syntax\unmatched_closing_paren.py", line 6
        3, 4,))
              ^
    SyntaxError: unmatched ')'
    
    Une exception de type `SyntaxError` se produit lorsque Python ne peut pas comprendre votre code.
    
    Python peut seulement comprendre le code du fichier
    'TESTS:\syntax\unmatched_closing_paren.py'
    jusqu'à l'endroit indiqué par ^.
    
       1: """Should raise SyntaxError: invalid syntax for Python < 3.8
       2:    otherwise, SyntaxError: unmatched ')'
       3: """
       4: a = (1,
       5:     2,
    -->6:     3, 4,))
                    ^

    Le symbole parenthèse `)` à la ligne 6 n'a pas de symbole ouvrant qui lui correspond.
    

(174) Mismatched brackets - 1
-----------------------------

.. code-block:: none


    Traceback (most recent call last):
      File "TESTS:\trb_syntax_common.py", line 49, in create_tracebacks
        __import__(name)
      File "TESTS:\syntax\unmatched_closing_bracket_1.py", line 2
        x = (1, 2, 3]
                    ^
    SyntaxError: closing parenthesis ']' does not match opening parenthesis '('
    
    Une exception de type `SyntaxError` se produit lorsque Python ne peut pas comprendre votre code.
    
    Python peut seulement comprendre le code du fichier
    'TESTS:\syntax\unmatched_closing_bracket_1.py'
    jusqu'à l'endroit indiqué par ^.
    
       1: """Should raise SyntaxError: invalid syntax"""
    -->2: x = (1, 2, 3]
                      ^

    Le symbole crochet `]` à la ligne 2 ne correspond pas au symbole parenthèse `(` à la ligne 2.
    
        2: x = (1, 2, 3]
               ^       ^
    

(175) Mismatched brackets - 2
-----------------------------

.. code-block:: none


    Traceback (most recent call last):
      File "TESTS:\trb_syntax_common.py", line 49, in create_tracebacks
        __import__(name)
      File "TESTS:\syntax\unmatched_closing_bracket_2.py", line 4
        3]
         ^
    SyntaxError: closing parenthesis ']' does not match opening parenthesis '(' on line 2
    
    Une exception de type `SyntaxError` se produit lorsque Python ne peut pas comprendre votre code.
    
    Python peut seulement comprendre le code du fichier
    'TESTS:\syntax\unmatched_closing_bracket_2.py'
    jusqu'à l'endroit indiqué par ^.
    
       1: """Should raise SyntaxError: invalid syntax"""
       2: x = (1,
       3:      2,
    -->4:      3]
                ^

    Le symbole crochet `]` à la ligne 4 ne correspond pas au symbole parenthèse `(` à la ligne 2.
    
        2: x = (1,
               ^
        4:      3]
                 ^
    

(176) Unmatched brackets - 3
----------------------------

.. code-block:: none


    Traceback (most recent call last):
      File "TESTS:\trb_syntax_common.py", line 49, in create_tracebacks
        __import__(name)
      File "TESTS:\syntax\unmatched_closing_bracket_3.py", line 3
        3]]
          ^
    SyntaxError: unmatched ']'
    
    Une exception de type `SyntaxError` se produit lorsque Python ne peut pas comprendre votre code.
    
    Python peut seulement comprendre le code du fichier
    'TESTS:\syntax\unmatched_closing_bracket_3.py'
    jusqu'à l'endroit indiqué par ^.
    
       1: x = [1,
       2:      2,
    -->3:      3]]
                 ^

    Le symbole crochet `]` à la ligne 3 n'a pas de symbole ouvrant qui lui correspond.
    

(177) Unterminated triple quoted string
---------------------------------------

.. code-block:: none


    Traceback (most recent call last):
      File "TESTS:\trb_syntax_common.py", line 49, in create_tracebacks
        __import__(name)
      File "TESTS:\syntax\unterminated_triple_quote_string.py", line 4
        some_text = """In a land
    populated by weird animals,
    a ...
                                                                   ^
    SyntaxError: EOF while scanning triple-quoted string literal
    
    Une exception de type `SyntaxError` se produit lorsque Python ne peut pas comprendre votre code.
    
    Python ne peut pas comprendre le code du fichier
    'TESTS:\syntax\unterminated_triple_quote_string.py'
    
       1: some_text =

    Vous avez commencé à écrire une chaîne débutant avec des triples guillemets,
    sans inclure les triples guillemets nécessaires pour mettre fin à la chaîne.
    

(178) TabError
--------------

.. code-block:: none


    Traceback (most recent call last):
      File "TESTS:\trb_syntax_common.py", line 49, in create_tracebacks
        __import__(name)
      File "TESTS:\syntax\tab_error.py", line 7
        pass
            ^
    TabError: inconsistent use of tabs and spaces in indentation
    
    Une exception de type `TabError` indique que vous avez utilisé des espaces
    ainsi que des caractères de tabulation pour indenter votre code.
    Cela n’est pas autorisé dans Python.
    L’indentation de votre code signifie que le bloc de codes est aligné
    verticalement en insérant des espaces ou des tabulations au début des lignes.
    La recommandation de Python est de toujours utiliser des espaces
    pour indenter votre code.
    
    Python peut seulement comprendre le code du fichier
    'TESTS:\syntax\tab_error.py'
    jusqu'à l'endroit indiqué par ^.
    
       3: 
       4: 
       5: def test_tab_error():
       6:     if True:
    -->7: 	pass
               ^

(179) EOL unescaped backslash
-----------------------------

.. code-block:: none


    Traceback (most recent call last):
      File "TESTS:\trb_syntax_common.py", line 49, in create_tracebacks
        __import__(name)
      File "TESTS:\syntax\unescaped_backslash.py", line 1
        a = "abc\"
                  ^
    SyntaxError: EOL while scanning string literal
    
        Avez-vous oublié d’échapper un caractère barre oblique inverse ?
        
    Une exception de type `SyntaxError` se produit lorsque Python ne peut pas comprendre votre code.
    
    Python peut seulement comprendre le code du fichier
    'TESTS:\syntax\unescaped_backslash.py'
    jusqu'à l'endroit indiqué par ^.
    
    -->1: a = "abc\"
                    ^

    Vous aviez commencé à écrire une chaîne de caractères
    avec un guillemet simple ou double, mais n'avez jamais
    terminé la chaîne avec un autre guillemet sur cette ligne.
    Peut-être que vous vouliez écrire une barre oblique inverse, `\`
    comme le dernier caractère de la chaîne et vous oublié que vous
    deviez en écrire deux `\` d’affilée.
    

(180) Using the backquote character
-----------------------------------

.. code-block:: none


    Traceback (most recent call last):
      File "TESTS:\trb_syntax_common.py", line 49, in create_tracebacks
        __import__(name)
      File "TESTS:\syntax\use_backquote.py", line 3
        a = `1`
            ^
    SyntaxError: invalid syntax
    
        Vous ne devez pas utiliser le caractère accent grave.
        
    Une exception de type `SyntaxError` se produit lorsque Python ne peut pas comprendre votre code.
    
    Python peut seulement comprendre le code du fichier
    'TESTS:\syntax\use_backquote.py'
    jusqu'à l'endroit indiqué par ^.
    
       1: """Should raise SyntaxError: invalid syntax"""
       2: 
    -->3: a = `1`
              ^

    Vous utilisez le charactère d'accent grave.
    Soit que vous vouliez utiliser un apostrophe, ',
    ou que vous avez copié du code de Python 2;
    dans ce dernier cas, utilisez la fonction `repr(x)`.

(181) Walrus instead of equal
-----------------------------

.. code-block:: none


    Traceback (most recent call last):
      File "TESTS:\trb_syntax_common.py", line 49, in create_tracebacks
        __import__(name)
      File "TESTS:\syntax\walrus_instead_of_equal.py", line 1
        a := 3
          ^
    SyntaxError: invalid syntax
    
        Voulez-vous utiliser `=` ?
        
    Une exception de type `SyntaxError` se produit lorsque Python ne peut pas comprendre votre code.
    
    Python peut seulement comprendre le code du fichier
    'TESTS:\syntax\walrus_instead_of_equal.py'
    jusqu'à l'endroit indiqué par ^.
    
    -->1: a := 3
            ^

    Vous utilisez l’opérateur d’affectation augmentée `:=` là où
    l’opérateur d’affectation normal `=` était requis.
    

(182) Missing condition in while statement
------------------------------------------

.. code-block:: none


    Traceback (most recent call last):
      File "TESTS:\trb_syntax_common.py", line 49, in create_tracebacks
        __import__(name)
      File "TESTS:\syntax\while_missing_condition.py", line 1
        while:
             ^
    SyntaxError: invalid syntax
    
        Vous avez oublié d’ajouter une condition.
        
    Une exception de type `SyntaxError` se produit lorsque Python ne peut pas comprendre votre code.
    
    Python peut seulement comprendre le code du fichier
    'TESTS:\syntax\while_missing_condition.py'
    jusqu'à l'endroit indiqué par ^.
    
    -->1: while:
               ^

    Une boucle `while` doit inclure une condition :
    
        while condition:
            ...
    
    

(183) Would-be variable declaration
-----------------------------------

.. code-block:: none


    Traceback (most recent call last):
      File "TESTS:\trb_syntax_common.py", line 49, in create_tracebacks
        __import__(name)
      File "TESTS:\syntax\would_be_type_declaration_1.py", line 3
        if var start := begin < end:
               ^
    SyntaxError: invalid syntax
    
        Vous n’avez pas besoin de déclarer des variables dans Python.
        
    Une exception de type `SyntaxError` se produit lorsque Python ne peut pas comprendre votre code.
    
    Python peut seulement comprendre le code du fichier
    'TESTS:\syntax\would_be_type_declaration_1.py'
    jusqu'à l'endroit indiqué par ^.
    
       1: begin, end = 1, 2
       2: 
    -->3: if var start := begin < end:
                 ^

    Il semble que vous essayiez de déclarer que `start` est
    une variable utilisant le mot `var`.
    Si vous supprimez `var`, vous aurez une instruction Python valide.
    

(184) Would-be variable declaration - 2
---------------------------------------

.. code-block:: none


    Traceback (most recent call last):
      File "TESTS:\trb_syntax_common.py", line 49, in create_tracebacks
        __import__(name)
      File "TESTS:\syntax\would_be_type_declaration_2.py", line 5
        var start := begin < end
            ^
    SyntaxError: invalid syntax
    
        Vous n’avez pas besoin de déclarer des variables dans Python.
        
    Une exception de type `SyntaxError` se produit lorsque Python ne peut pas comprendre votre code.
    
    Python peut seulement comprendre le code du fichier
    'TESTS:\syntax\would_be_type_declaration_2.py'
    jusqu'à l'endroit indiqué par ^.
    
       2: end = 4
       3: 
       4: if (
    -->5:     var start := begin < end
                  ^
       6:    )

    Il semble que vous essayiez de déclarer que `start` est
    une variable utilisant le mot `var`.
    Toutefois, même si vous supprimez `var`, il y aurait encore
    au moins une autre erreur de syntaxe.
    
