

<!DOCTYPE html>
<html class="writer-html5" lang="en" >
<head>
  <meta charset="utf-8">
  
  <meta name="viewport" content="width=device-width, initial-scale=1.0">
  
  <title>Friendly tracebacks - in English &mdash; Friendly tracebacks 0.2.7a documentation</title>
  

  
  <link rel="stylesheet" href="_static/css/theme.css" type="text/css" />
  <link rel="stylesheet" href="_static/pygments.css" type="text/css" />
  <link rel="stylesheet" href="_static/custom.css" type="text/css" />

  
  
  
  

  
  <!--[if lt IE 9]>
    <script src="_static/js/html5shiv.min.js"></script>
  <![endif]-->
  
    
      <script type="text/javascript" id="documentation_options" data-url_root="./" src="_static/documentation_options.js"></script>
        <script src="_static/jquery.js"></script>
        <script src="_static/underscore.js"></script>
        <script src="_static/doctools.js"></script>
        <script src="_static/language_data.js"></script>
    
    <script type="text/javascript" src="_static/js/theme.js"></script>

    
    <link rel="index" title="Index" href="genindex.html" />
    <link rel="search" title="Search" href="search.html" />
    <link rel="next" title="Friendly SyntaxError tracebacks - in English" href="syntax_tracebacks_en_3.7.html" />
    <link rel="prev" title="Friendly SyntaxError tracebacks - in English" href="syntax_tracebacks_en_3.6.html" /> 
</head>

<body class="wy-body-for-nav">

   
  <div class="wy-grid-for-nav">
    
    <nav data-toggle="wy-nav-shift" class="wy-nav-side">
      <div class="wy-side-scroll">
        <div class="wy-side-nav-search" >
          

          
            <a href="index.html" class="icon icon-home" alt="Documentation Home"> Friendly tracebacks
          

          
          </a>

          
            
            
              <div class="version">
                0.2.7a
              </div>
            
          

          
<div role="search">
  <form id="rtd-search-form" class="wy-form" action="search.html" method="get">
    <input type="text" name="q" placeholder="Search docs" />
    <input type="hidden" name="check_keywords" value="yes" />
    <input type="hidden" name="area" value="default" />
  </form>
</div>

          
        </div>

        
        <div class="wy-menu wy-menu-vertical" data-spy="affix" role="navigation" aria-label="main navigation">
          
            
            
              
            
            
              <p class="caption"><span class="caption-text">Begin here</span></p>
<ul>
<li class="toctree-l1"><a class="reference internal" href="usage.html">Installation and basic usage</a></li>
<li class="toctree-l1"><a class="reference internal" href="repl.html">Console basics</a></li>
<li class="toctree-l1"><a class="reference internal" href="editor.html">Using with an editor or IDE</a></li>
<li class="toctree-l1"><a class="reference internal" href="mu.html">Using with Mu</a></li>
<li class="toctree-l1"><a class="reference internal" href="thonny.html">Using with Thonny</a></li>
<li class="toctree-l1"><a class="reference internal" href="tracebacks.html">Multiple tracebacks</a></li>
</ul>
<p class="caption"><span class="caption-text">Thoughts on design</span></p>
<ul>
<li class="toctree-l1"><a class="reference internal" href="design.html">Some thoughts on the design of Friendly-traceback</a></li>
<li class="toctree-l1"><a class="reference internal" href="themes.html">Themes and colours</a></li>
</ul>
<p class="caption"><span class="caption-text">Use in your project</span></p>
<ul>
<li class="toctree-l1"><a class="reference internal" href="api.html">Public API</a></li>
<li class="toctree-l1"><a class="reference internal" href="lies.html">Learn to lie</a></li>
<li class="toctree-l1"><a class="reference internal" href="formatter.html">Custom formatter</a></li>
<li class="toctree-l1"><a class="reference internal" href="usage_adv.html">Other details for advanced users</a></li>
<li class="toctree-l1"><a class="reference internal" href="plugins.html">Editor plugins</a></li>
</ul>
<p class="caption"><span class="caption-text">Contribute</span></p>
<ul>
<li class="toctree-l1"><a class="reference internal" href="suggest.html">Suggest an addition</a></li>
<li class="toctree-l1"><a class="reference internal" href="adding_exception.html">Developer: Add a new Exception case</a></li>
<li class="toctree-l1"><a class="reference internal" href="syntax_error.html">Developer: Add a new SyntaxError case</a></li>
<li class="toctree-l1"><a class="reference internal" href="translation_notes.html">Notes on translations - using gettext</a></li>
</ul>
<p class="caption"><span class="caption-text">All the tracebacks!</span></p>
<ul class="current">
<li class="toctree-l1"><a class="reference internal" href="all_tb.html">Why all the tracebacks?</a></li>
<li class="toctree-l1"><a class="reference internal" href="known.html">Generic information about various exceptions</a></li>
<li class="toctree-l1"><a class="reference internal" href="tracebacks_en_3.6.html">Friendly tracebacks - Python 3.6 in English</a></li>
<li class="toctree-l1"><a class="reference internal" href="syntax_tracebacks_en_3.6.html">SyntaxError - Python 3.6 in English</a></li>
<li class="toctree-l1 current"><a class="current reference internal" href="#">Friendly tracebacks - Python 3.7 in English</a><ul>
<li class="toctree-l2"><a class="reference internal" href="#arithmeticerror">ArithmeticError</a></li>
<li class="toctree-l2"><a class="reference internal" href="#attributeerror-class-attribute">AttributeError - class attribute</a></li>
<li class="toctree-l2"><a class="reference internal" href="#attributeerror-typo-in-module-attribute">AttributeError - typo in module attribute</a></li>
<li class="toctree-l2"><a class="reference internal" href="#attributeerror-typo-in-module-attribute-2">AttributeError - typo in module attribute 2</a></li>
<li class="toctree-l2"><a class="reference internal" href="#filenotfounderror">FileNotFoundError</a></li>
<li class="toctree-l2"><a class="reference internal" href="#importerror">ImportError</a></li>
<li class="toctree-l2"><a class="reference internal" href="#keyerror">KeyError</a></li>
<li class="toctree-l2"><a class="reference internal" href="#lookuperror">LookupError</a></li>
<li class="toctree-l2"><a class="reference internal" href="#indexerror-short-tuple">IndexError - short tuple</a></li>
<li class="toctree-l2"><a class="reference internal" href="#indexerror-long-list">IndexError - long list</a></li>
<li class="toctree-l2"><a class="reference internal" href="#modulenotfounderror">ModuleNotFoundError</a></li>
<li class="toctree-l2"><a class="reference internal" href="#nameerror-1">NameError - 1</a></li>
<li class="toctree-l2"><a class="reference internal" href="#nameerror-2">NameError - 2</a></li>
<li class="toctree-l2"><a class="reference internal" href="#nameerror-3">NameError - 3</a></li>
<li class="toctree-l2"><a class="reference internal" href="#nameerror-4">NameError - 4</a></li>
<li class="toctree-l2"><a class="reference internal" href="#overflowerror">OverflowError</a></li>
<li class="toctree-l2"><a class="reference internal" href="#recursionerror">RecursionError</a></li>
<li class="toctree-l2"><a class="reference internal" href="#typeerror-1-concatenate-two-different-types">TypeError - 1: concatenate two different types</a></li>
<li class="toctree-l2"><a class="reference internal" href="#typeerror-2-unsupported-operand-type-s-for">TypeError - 2: unsupported operand type(s) for +=</a></li>
<li class="toctree-l2"><a class="reference internal" href="#typeerror-3-unsupported-operand-type-s-for">TypeError - 3: unsupported operand type(s) for -=</a></li>
<li class="toctree-l2"><a class="reference internal" href="#typeerror-4-unsupported-operand-type-s-for">TypeError - 4: unsupported operand type(s) for <code class="docutils literal notranslate"><span class="pre">*=</span></code></a></li>
<li class="toctree-l2"><a class="reference internal" href="#typeerror-5-unsupported-operand-type-s-for">TypeError - 5: unsupported operand type(s) for //=</a></li>
<li class="toctree-l2"><a class="reference internal" href="#typeerror-6-unsupported-operand-type-s-for">TypeError - 6: unsupported operand type(s) for &amp;=</a></li>
<li class="toctree-l2"><a class="reference internal" href="#typeerror-7-unsupported-operand-type-s-for">TypeError - 7: unsupported operand type(s) for <code class="docutils literal notranslate"><span class="pre">**=</span></code></a></li>
<li class="toctree-l2"><a class="reference internal" href="#typeerror-8-unsupported-operand-type-s-for">TypeError - 8: unsupported operand type(s) for &gt;&gt;=</a></li>
<li class="toctree-l2"><a class="reference internal" href="#typeerror-9-unsupported-operand-type-s-for">TypeError - 9: unsupported operand type(s) for &#64;=</a></li>
<li class="toctree-l2"><a class="reference internal" href="#typeerror-10-comparison-between-incompatible-types">TypeError - 10: comparison between incompatible types</a></li>
<li class="toctree-l2"><a class="reference internal" href="#typeerror-11-bad-operand-type-for-unary">TypeError - 11: bad operand type for unary +</a></li>
<li class="toctree-l2"><a class="reference internal" href="#typeerror-12-object-does-not-support-item-assignment">TypeError - 12: object does not support item assignment</a></li>
<li class="toctree-l2"><a class="reference internal" href="#typeerror-13-wrong-number-of-positional-arguments">TypeError - 13: wrong number of positional arguments</a></li>
<li class="toctree-l2"><a class="reference internal" href="#typeerror-14-missing-positional-arguments">TypeError - 14: missing positional arguments</a></li>
<li class="toctree-l2"><a class="reference internal" href="#typeerror-15-list-object-is-not-callable">TypeError - 15: list object is not callable</a></li>
<li class="toctree-l2"><a class="reference internal" href="#typeerror-16-exception-derived-from-baseexception">TypeError - 16: exception derived from BaseException</a></li>
<li class="toctree-l2"><a class="reference internal" href="#unboundlocalerror-1-missing-global">UnboundLocalError - 1: missing global</a></li>
<li class="toctree-l2"><a class="reference internal" href="#unboundlocalerror-2-missing-nonlocal">UnboundLocalError - 2: missing nonlocal</a></li>
<li class="toctree-l2"><a class="reference internal" href="#unknown-exception">Unknown exception</a></li>
<li class="toctree-l2"><a class="reference internal" href="#zerodivisionerror-1">ZeroDivisionError - 1</a></li>
<li class="toctree-l2"><a class="reference internal" href="#zerodivisionerror-2">ZeroDivisionError - 2</a></li>
</ul>
</li>
<li class="toctree-l1"><a class="reference internal" href="syntax_tracebacks_en_3.7.html">SyntaxError - Python 3.7 in English</a></li>
<li class="toctree-l1"><a class="reference internal" href="tracebacks_en_3.8.html">Friendly tracebacks - Python 3.8 in English</a></li>
<li class="toctree-l1"><a class="reference internal" href="syntax_tracebacks_en_3.8.html">SyntaxError - Python 3.8 in English</a></li>
<li class="toctree-l1"><a class="reference internal" href="tracebacks_en_3.9.html">Friendly tracebacks - Python 3.9 in English</a></li>
<li class="toctree-l1"><a class="reference internal" href="syntax_tracebacks_en_3.9.html">SyntaxError - Python 3.9 in English</a></li>
<li class="toctree-l1"><a class="reference internal" href="tracebacks_en_3.10.html">Friendly tracebacks - Python 3.10 in English</a></li>
<li class="toctree-l1"><a class="reference internal" href="syntax_tracebacks_en_3.10.html">SyntaxError - Python 3.10 in English</a></li>
<li class="toctree-l1"><a class="reference internal" href="compare_exceptions.html">Comparing Exception messages between Python versions</a></li>
<li class="toctree-l1"><a class="reference internal" href="compare.html">Comparison between Python versions: SyntaxErrors</a></li>
</ul>
<p class="caption"><span class="caption-text">Markdown examples</span></p>
<ul>
<li class="toctree-l1"><a class="reference internal" href="tracebacks_markdown.html">Friendly tracebacks - markdown_docs format</a></li>
<li class="toctree-l1"><a class="reference internal" href="tracebacks_syntax_markdown.html">Syntax errors - markdown_docs format</a></li>
</ul>
<p class="caption"><span class="caption-text">En français</span></p>
<ul>
<li class="toctree-l1"><a class="reference internal" href="tracebacks_fr.html"> Friendly tracebacks - en Français</a></li>
<li class="toctree-l1"><a class="reference internal" href="syntax_tracebacks_fr.html"> Friendly SyntaxError tracebacks - en Français</a></li>
</ul>

            
          
        </div>
        
      </div>
    </nav>

    <section data-toggle="wy-nav-shift" class="wy-nav-content-wrap">

      
      <nav class="wy-nav-top" aria-label="top navigation">
        
          <i data-toggle="wy-nav-top" class="fa fa-bars"></i>
          <a href="index.html">Friendly tracebacks</a>
        
      </nav>


      <div class="wy-nav-content">
        
        <div class="rst-content style-external-links">
        
          















<div role="navigation" aria-label="breadcrumbs navigation">

  <ul class="wy-breadcrumbs">
    
      <li><a href="index.html" class="icon icon-home"></a> &raquo;</li>
        
      <li>Friendly tracebacks - in English</li>
    
    
      <li class="wy-breadcrumbs-aside">
        
            
            <a href="_sources/tracebacks_en_3.7.rst.txt" rel="nofollow"> View page source</a>
          
        
      </li>
    
  </ul>

  
  <div class="rst-breadcrumbs-buttons" role="navigation" aria-label="breadcrumb navigation">
      
        <a href="syntax_tracebacks_en_3.7.html" class="btn btn-neutral float-right" title="Friendly SyntaxError tracebacks - in English" accesskey="n">Next <span class="fa fa-arrow-circle-right"></span></a>
      
      
        <a href="syntax_tracebacks_en_3.6.html" class="btn btn-neutral float-left" title="Friendly SyntaxError tracebacks - in English" accesskey="p"><span class="fa fa-arrow-circle-left"></span> Previous</a>
      
  </div>
  
  <hr/>
</div>
          <div role="main" class="document" itemscope="itemscope" itemtype="http://schema.org/Article">
           <div itemprop="articleBody">
            
  <div class="section" id="friendly-tracebacks-in-english">
<h1>Friendly tracebacks - in English<a class="headerlink" href="#friendly-tracebacks-in-english" title="Permalink to this headline">¶</a></h1>
<p>Friendly-traceback aims to provide friendlier feedback when an exception
is raised than what is done by Python.
Below, we can find some examples. SyntaxError cases, as well as TabError and
IndentationError cases, are shown in a separate page.
Ideally, an example of each case handled by friendly-traceback
should be included here.</p>
<div class="admonition note">
<p class="admonition-title">Note</p>
<p>The content of this page is generated by running
trb_english.py located in the <code class="docutils literal notranslate"><span class="pre">tests/</span></code> directory.
This needs to be done explicitly, independently of updating the
documentation using Sphinx.</p>
</div>
<p>Friendly-traceback version: 0.2.7a
Python version: 3.7.8</p>
<div class="section" id="arithmeticerror">
<h2>ArithmeticError<a class="headerlink" href="#arithmeticerror" title="Permalink to this headline">¶</a></h2>
<div class="highlight-none notranslate"><div class="highlight"><pre><span></span>Traceback (most recent call last):
  File &quot;TESTS:\runtime\test_arithmetic_error.py&quot;, line 9, in test_arithmetic_error
    raise ArithmeticError(&#39;error&#39;)
ArithmeticError: error

`ArithmeticError` is the base class for those built-in exceptions
that are raised for various arithmetic errors.
It is unusual that you are seeing this exception;
normally, a more specific exception should have been raised.

Exception raised on line 9 of file TESTS:\runtime\test_arithmetic_error.py.

    7:         # Usually, a subclass such as ZeroDivisionError, etc., would
    8:         # likely be raised.
--&gt; 9:         raise ArithmeticError(&#39;error&#39;)
   10:     except Exception as e:
</pre></div>
</div>
</div>
<div class="section" id="attributeerror-class-attribute">
<h2>AttributeError - class attribute<a class="headerlink" href="#attributeerror-class-attribute" title="Permalink to this headline">¶</a></h2>
<div class="highlight-none notranslate"><div class="highlight"><pre><span></span>Traceback (most recent call last):
  File &quot;TESTS:\runtime\test_attribute_error.py&quot;, line 35, in test_attribute_error
    a.x  # Testing instance
AttributeError: &#39;A&#39; object has no attribute &#39;x&#39;

An `AttributeError` occurs when the code contains something like
    `object.x`
and `x` is not a method or attribute (variable) belonging to `object`.

    The object `a` has no attribute named `x`.

Exception raised on line 35 of file TESTS:\runtime\test_attribute_error.py.

   33:     try:
   34:         a = A()
--&gt;35:         a.x  # Testing instance
   36:     except Exception as e:

        a: &lt;A object&gt; from test_attribute_error.test_attribute_error
</pre></div>
</div>
</div>
<div class="section" id="attributeerror-typo-in-module-attribute">
<h2>AttributeError - typo in module attribute<a class="headerlink" href="#attributeerror-typo-in-module-attribute" title="Permalink to this headline">¶</a></h2>
<div class="highlight-none notranslate"><div class="highlight"><pre><span></span>Traceback (most recent call last):
  File &quot;TESTS:\runtime\test_attribute_error.py&quot;, line 66, in test_misspelled_module_attribute
    string.ascii_lowecase
AttributeError: module &#39;string&#39; has no attribute &#39;ascii_lowecase&#39;

    Did you mean `ascii_lowercase`?

An `AttributeError` occurs when the code contains something like
    `object.x`
and `x` is not a method or attribute (variable) belonging to `object`.

    Perhaps you meant to write `string.ascii_lowercase` instead of `string.ascii_lowecase`

Exception raised on line 66 of file TESTS:\runtime\test_attribute_error.py.

   64:
   65:     try:
--&gt;66:         string.ascii_lowecase
   67:     except Exception as e:

        string: &lt;module string&gt; from PYTHON_LIB:\string.py
</pre></div>
</div>
</div>
<div class="section" id="attributeerror-typo-in-module-attribute-2">
<h2>AttributeError - typo in module attribute 2<a class="headerlink" href="#attributeerror-typo-in-module-attribute-2" title="Permalink to this headline">¶</a></h2>
<div class="highlight-none notranslate"><div class="highlight"><pre><span></span>Traceback (most recent call last):
  File &quot;TESTS:\runtime\test_attribute_error.py&quot;, line 82, in test_misspelled_module_attribute_2
    math.cost
AttributeError: module &#39;math&#39; has no attribute &#39;cost&#39;

    Did you mean one of the following: `cos, cosh, acos`?

An `AttributeError` occurs when the code contains something like
    `object.x`
and `x` is not a method or attribute (variable) belonging to `object`.

    Instead of writing `math.cost`, perhaps you meant to write one of
    the following names which are attributes of module `math`:
    `cos, cosh, acos`

Exception raised on line 82 of file TESTS:\runtime\test_attribute_error.py.

   80:
   81:     try:
--&gt;82:         math.cost
   83:     except Exception as e:

        math: &lt;module math (builtin)&gt;
</pre></div>
</div>
</div>
<div class="section" id="filenotfounderror">
<h2>FileNotFoundError<a class="headerlink" href="#filenotfounderror" title="Permalink to this headline">¶</a></h2>
<div class="highlight-none notranslate"><div class="highlight"><pre><span></span>Traceback (most recent call last):
  File &quot;TESTS:\runtime\test_file_not_found_error.py&quot;, line 6, in test_file_not_found_error
    open(&quot;does_not_exist&quot;)
FileNotFoundError: [Errno 2] No such file or directory: &#39;does_not_exist&#39;

A `FileNotFoundError` exception indicates that you
are trying to open a file that cannot be found by Python.
This could be because you misspelled the name of the file.

    In your program, the name of the
    file that cannot be found is `does_not_exist`.

Exception raised on line 6 of file TESTS:\runtime\test_file_not_found_error.py.

   4: def test_file_not_found_error():
   5:     try:
--&gt;6:         open(&quot;does_not_exist&quot;)
   7:     except Exception as e:
</pre></div>
</div>
</div>
<div class="section" id="importerror">
<h2>ImportError<a class="headerlink" href="#importerror" title="Permalink to this headline">¶</a></h2>
<div class="highlight-none notranslate"><div class="highlight"><pre><span></span>Traceback (most recent call last):
  File &quot;TESTS:\runtime\test_import_error.py&quot;, line 6, in test_import_error
    from math import Pi
ImportError: cannot import name &#39;Pi&#39; from &#39;math&#39; (unknown location)

    Did you mean `pi`?

An `ImportError` exception indicates that a certain object could not
be imported from a module or package. Most often, this is
because the name of the object is not spelled correctly.

    Perhaps you meant to import `pi` (from `math`) instead of `Pi`

Exception raised on line 6 of file TESTS:\runtime\test_import_error.py.

   4: def test_import_error():
   5:     try:
--&gt;6:         from math import Pi
   7:     except Exception as e:
</pre></div>
</div>
</div>
<div class="section" id="keyerror">
<h2>KeyError<a class="headerlink" href="#keyerror" title="Permalink to this headline">¶</a></h2>
<div class="highlight-none notranslate"><div class="highlight"><pre><span></span>Traceback (most recent call last):
  File &quot;TESTS:\runtime\test_key_error.py&quot;, line 7, in test_key_error
    d[&quot;c&quot;]
KeyError: &#39;c&#39;

A `KeyError` is raised when a value is not found as a
key in a Python dict.

    In your program, the key that cannot be found is `&#39;c&#39;`.

Exception raised on line 7 of file TESTS:\runtime\test_key_error.py.

   5:     d = {&quot;a&quot;: 1, &quot;b&quot;: 2}
   6:     try:
--&gt;7:         d[&quot;c&quot;]
   8:     except Exception as e:

        d: {&#39;a&#39;: 1, &#39;b&#39;: 2}
</pre></div>
</div>
</div>
<div class="section" id="lookuperror">
<h2>LookupError<a class="headerlink" href="#lookuperror" title="Permalink to this headline">¶</a></h2>
<div class="highlight-none notranslate"><div class="highlight"><pre><span></span>Traceback (most recent call last):
  File &quot;TESTS:\runtime\test_lookup_error.py&quot;, line 10, in test_lookup_error
    raise LookupError(&quot;Fake message&quot;)
LookupError: Fake message

`LookupError` is the base class for the exceptions that are raised
when a key or index used on a mapping or sequence is invalid.
It can also be raised directly by codecs.lookup().

Exception raised on line 10 of file TESTS:\runtime\test_lookup_error.py.

    8:         # other than possibly codecs.lookup(), which is why we raise
    9:         # it directly here for our example.
--&gt;10:         raise LookupError(&quot;Fake message&quot;)
   11:     except Exception as e:
</pre></div>
</div>
</div>
<div class="section" id="indexerror-short-tuple">
<h2>IndexError - short tuple<a class="headerlink" href="#indexerror-short-tuple" title="Permalink to this headline">¶</a></h2>
<div class="highlight-none notranslate"><div class="highlight"><pre><span></span>Traceback (most recent call last):
  File &quot;TESTS:\runtime\test_index_error.py&quot;, line 8, in test_index_error1
    print(a[3], b[2])
IndexError: tuple index out of range

An `IndexError` occurs when you are try to get an item from a list,
a tuple, or a similar object (sequence), by using an index which
does not exists; typically, this is because the index you give
is greater than the length of the sequence.
Reminder: the first item of a sequence is at index 0.

Exception raised on line 8 of file TESTS:\runtime\test_index_error.py.

    6:     b = [1, 2, 3]
    7:     try:
--&gt; 8:         print(a[3], b[2])
                     ^^^^
    9:     except Exception as e:

        a: (1, 2, 3)
</pre></div>
</div>
</div>
<div class="section" id="indexerror-long-list">
<h2>IndexError - long list<a class="headerlink" href="#indexerror-long-list" title="Permalink to this headline">¶</a></h2>
<div class="highlight-none notranslate"><div class="highlight"><pre><span></span>Traceback (most recent call last):
  File &quot;TESTS:\runtime\test_index_error.py&quot;, line 22, in test_index_error2
    print(a[50], b[0])
IndexError: list index out of range

An `IndexError` occurs when you are try to get an item from a list,
a tuple, or a similar object (sequence), by using an index which
does not exists; typically, this is because the index you give
is greater than the length of the sequence.
Reminder: the first item of a sequence is at index 0.

Exception raised on line 22 of file TESTS:\runtime\test_index_error.py.

   20:     b = tuple(range(50))
   21:     try:
--&gt;22:         print(a[50], b[0])
                     ^^^^^
   23:     except Exception as e:

        a: [0, 1, 2, 3, 4, 5, 6, 7, 8, 9, 10, 11, 12, 13, 14, 15, 16, 17, 18, ...]
            len(a): 40
</pre></div>
</div>
</div>
<div class="section" id="modulenotfounderror">
<h2>ModuleNotFoundError<a class="headerlink" href="#modulenotfounderror" title="Permalink to this headline">¶</a></h2>
<div class="highlight-none notranslate"><div class="highlight"><pre><span></span>Traceback (most recent call last):
  File &quot;TESTS:\runtime\test_module_not_found_error.py&quot;, line 6, in test_module_not_found_error
    import Tkinter
ModuleNotFoundError: No module named &#39;Tkinter&#39;

    Did you mean `tkinter`?

A `ModuleNotFoundError` exception indicates that you
are trying to import a module that cannot be found by Python.
This could be because you misspelled the name of the module
or because it is not installed on your computer.

    The name of the module that could not be imported is `Tkinter`.
    `tkinter` is an existing module that has a similar name.

Exception raised on line 6 of file TESTS:\runtime\test_module_not_found_error.py.

   4: def test_module_not_found_error():
   5:     try:
--&gt;6:         import Tkinter
   7:     except Exception as e:
</pre></div>
</div>
</div>
<div class="section" id="nameerror-1">
<h2>NameError - 1<a class="headerlink" href="#nameerror-1" title="Permalink to this headline">¶</a></h2>
<div class="highlight-none notranslate"><div class="highlight"><pre><span></span>Traceback (most recent call last):
  File &quot;TESTS:\runtime\test_name_error.py&quot;, line 6, in test_name_error
    this = something
NameError: name &#39;something&#39; is not defined

A `NameError` exception indicates that a variable or
function name is not known to Python.
Most often, this is because there is a spelling mistake.
However, sometimes it is because the name is used
before being defined or given a value.

    In your program, `something` is an unknown name.
    I have no additional information for you.
Exception raised on line 6 of file TESTS:\runtime\test_name_error.py.

   4: def test_name_error():
   5:     try:
--&gt;6:         this = something
   7:     except Exception as e:
</pre></div>
</div>
</div>
<div class="section" id="nameerror-2">
<h2>NameError - 2<a class="headerlink" href="#nameerror-2" title="Permalink to this headline">¶</a></h2>
<div class="highlight-none notranslate"><div class="highlight"><pre><span></span>Traceback (most recent call last):
  File &quot;TESTS:\runtime\test_name_error.py&quot;, line 20, in test_name_error2
    x = babs(-1)
NameError: name &#39;babs&#39; is not defined

    Did you mean `abs`?
A `NameError` exception indicates that a variable or
function name is not known to Python.
Most often, this is because there is a spelling mistake.
However, sometimes it is because the name is used
before being defined or given a value.

    In your program, `babs` is an unknown name.
    Instead of writing `babs`, perhaps you meant one of the following:
    *   Local scope: `nabs`
    *   Global scope: `fabs`
    *   Python builtins: `abs`

Exception raised on line 20 of file TESTS:\runtime\test_name_error.py.

   18:     nabs = 1
   19:     try:
--&gt;20:         x = babs(-1)
   21:     except Exception as e:
</pre></div>
</div>
</div>
<div class="section" id="nameerror-3">
<h2>NameError - 3<a class="headerlink" href="#nameerror-3" title="Permalink to this headline">¶</a></h2>
<div class="highlight-none notranslate"><div class="highlight"><pre><span></span>Traceback (most recent call last):
  File &quot;TESTS:\runtime\test_name_error.py&quot;, line 35, in test_name_error3
    y = x
NameError: name &#39;x&#39; is not defined

    Did you use a colon instead of an equal sign?
A `NameError` exception indicates that a variable or
function name is not known to Python.
Most often, this is because there is a spelling mistake.
However, sometimes it is because the name is used
before being defined or given a value.

    In your program, `x` is an unknown name.
    A type hint found for `x` in the global scope.
    Perhaps you had used a colon instead of an equal sign and written

        x : 3

    instead of

        x = 3

Exception raised on line 35 of file TESTS:\runtime\test_name_error.py.

   33: def test_name_error3():
   34:     try:
--&gt;35:         y = x
   36:     except Exception as e:
</pre></div>
</div>
</div>
<div class="section" id="nameerror-4">
<h2>NameError - 4<a class="headerlink" href="#nameerror-4" title="Permalink to this headline">¶</a></h2>
<div class="highlight-none notranslate"><div class="highlight"><pre><span></span>Traceback (most recent call last):
  File &quot;TESTS:\runtime\test_name_error.py&quot;, line 48, in test_name_error4
    cost  # wrote from math import * above
NameError: name &#39;cost&#39; is not defined

    Did you mean `cos`?
A `NameError` exception indicates that a variable or
function name is not known to Python.
Most often, this is because there is a spelling mistake.
However, sometimes it is because the name is used
before being defined or given a value.

    In your program, `cost` is an unknown name.
    Instead of writing `cost`, perhaps you meant one of the following:
    *   Global scope: `cos`, `cosh`, `acos`

Exception raised on line 48 of file TESTS:\runtime\test_name_error.py.

   46: def test_name_error4():
   47:     try:
--&gt;48:         cost  # wrote from math import * above
   49:     except Exception as e:
</pre></div>
</div>
</div>
<div class="section" id="overflowerror">
<h2>OverflowError<a class="headerlink" href="#overflowerror" title="Permalink to this headline">¶</a></h2>
<div class="highlight-none notranslate"><div class="highlight"><pre><span></span>Traceback (most recent call last):
  File &quot;TESTS:\runtime\test_overflow_error.py&quot;, line 6, in test_overflow_error
    2.0 ** 1600
OverflowError: (34, &#39;Result too large&#39;)

An `OverflowError` is raised when the result of an arithmetic operation
is too large to be handled by the computer&#39;s processor.

Exception raised on line 6 of file TESTS:\runtime\test_overflow_error.py.

   4: def test_overflow_error():
   5:     try:
--&gt;6:         2.0 ** 1600
   7:     except Exception as e:
</pre></div>
</div>
</div>
<div class="section" id="recursionerror">
<h2>RecursionError<a class="headerlink" href="#recursionerror" title="Permalink to this headline">¶</a></h2>
<div class="highlight-none notranslate"><div class="highlight"><pre><span></span>Traceback (most recent call last):
  File &quot;TESTS:\runtime\test_recursion_error.py&quot;, line 8, in test_function_recursion_error
    a()

       ... More lines not shown. ...

  File &quot;TESTS:\runtime\test_recursion_error.py&quot;, line 6, in a
    return a()
  File &quot;TESTS:\runtime\test_recursion_error.py&quot;, line 6, in a
    return a()
RecursionError: maximum recursion depth exceeded

A `RecursionError` is raised when a function calls itself,
directly or indirectly, too many times.
It almost always indicates that you made an error in your code
and that your program would never stop.

Execution stopped on line 8 of file TESTS:\runtime\test_recursion_error.py.

    6:         return a()
    7:     try:
--&gt; 8:         a()
    9:     except Exception as e:

        a: &lt;function a&gt; from test_function_recursion_error

Exception raised on line 6 of file TESTS:\runtime\test_recursion_error.py.

   4: def test_function_recursion_error():
   5:     def a():
--&gt;6:         return a()
                     ^^^
   7:     try:

        a: &lt;function a&gt; from test_function_recursion_error
</pre></div>
</div>
</div>
<div class="section" id="typeerror-1-concatenate-two-different-types">
<h2>TypeError - 1: concatenate two different types<a class="headerlink" href="#typeerror-1-concatenate-two-different-types" title="Permalink to this headline">¶</a></h2>
<div class="highlight-none notranslate"><div class="highlight"><pre><span></span>Traceback (most recent call last):
  File &quot;TESTS:\runtime\test_type_error.py&quot;, line 38, in test_type_error1
    result = a_tuple + a_list
TypeError: can only concatenate tuple (not &quot;list&quot;) to tuple

A `TypeError` is usually caused by trying
to combine two incompatible types of objects,
by calling a function with the wrong type of object,
or by tring to do an operation not allowed on a given type of object.

    You tried to concatenate (add) two different types of objects:
    a `tuple` and a `list`

Exception raised on line 38 of file TESTS:\runtime\test_type_error.py.

   36:         a_tuple = (1, 2, 3)
   37:         a_list = [1, 2, 3]
--&gt;38:         result = a_tuple + a_list
                        ^^^^^^^^^^^^^^^^
   39:     except Exception as e:

        a_tuple: (1, 2, 3)
        a_list: [1, 2, 3]
</pre></div>
</div>
</div>
<div class="section" id="typeerror-2-unsupported-operand-type-s-for">
<h2>TypeError - 2: unsupported operand type(s) for +=<a class="headerlink" href="#typeerror-2-unsupported-operand-type-s-for" title="Permalink to this headline">¶</a></h2>
<div class="highlight-none notranslate"><div class="highlight"><pre><span></span>Traceback (most recent call last):
  File &quot;TESTS:\runtime\test_type_error.py&quot;, line 95, in test_type_error2
    b -= a
TypeError: unsupported operand type(s) for -=: &#39;list&#39; and &#39;tuple&#39;

A `TypeError` is usually caused by trying
to combine two incompatible types of objects,
by calling a function with the wrong type of object,
or by tring to do an operation not allowed on a given type of object.

    You tried to subtract two incompatible types of objects:
    a `list` and a `tuple`

Exception raised on line 95 of file TESTS:\runtime\test_type_error.py.

   93:         a = (1, 2)
   94:         b = [3, 4]
--&gt;95:         b -= a
   96:     except Exception as e:

        b: [3, 4]
        a: (1, 2)
</pre></div>
</div>
</div>
<div class="section" id="typeerror-3-unsupported-operand-type-s-for">
<h2>TypeError - 3: unsupported operand type(s) for -=<a class="headerlink" href="#typeerror-3-unsupported-operand-type-s-for" title="Permalink to this headline">¶</a></h2>
<div class="highlight-none notranslate"><div class="highlight"><pre><span></span>Traceback (most recent call last):
  File &quot;TESTS:\trb_common.py&quot;, line 163, in create_tracebacks
    result, message = getattr(mod, function)()
AttributeError: module &#39;test_type_error&#39; has no attribute &#39;test_type_error3&#39;

    Did you mean one of the following: `test_type_error13, test_type_error9, test_type_error8, test_type_error7, test_type_error6`?

An `AttributeError` occurs when the code contains something like
    `object.x`
and `x` is not a method or attribute (variable) belonging to `object`.

    Instead of writing `test_type_error.test_type_error3`, perhaps you meant to write one of
    the following names which are attributes of module `test_type_error`:
    `test_type_error13, test_type_error9, test_type_error8, test_type_error7, test_type_error6`

Exception raised on line 163 of file TESTS:\trb_common.py.

   161:                     mod = __import__(name)
   162:                     if function is not None:
--&gt;163:                         result, message = getattr(mod, function)()
                                                  ^^^^^^^^^^^^^^^^^^^^^^
   164:                         save_messages[function] = message

        mod: &lt;module test_type_error&gt; from TESTS:\runtime\test_type_error.py
        function: &#39;test_type_error3&#39;
</pre></div>
</div>
</div>
<div class="section" id="typeerror-4-unsupported-operand-type-s-for">
<h2>TypeError - 4: unsupported operand type(s) for <code class="docutils literal notranslate"><span class="pre">*=</span></code><a class="headerlink" href="#typeerror-4-unsupported-operand-type-s-for" title="Permalink to this headline">¶</a></h2>
<div class="highlight-none notranslate"><div class="highlight"><pre><span></span>Traceback (most recent call last):
  File &quot;TESTS:\runtime\test_type_error.py&quot;, line 124, in test_type_error4
    b *= a
TypeError: unsupported operand type(s) for *=: &#39;set&#39; and &#39;complex&#39;

A `TypeError` is usually caused by trying
to combine two incompatible types of objects,
by calling a function with the wrong type of object,
or by tring to do an operation not allowed on a given type of object.

    You tried to multiply two incompatible types of objects:
    a `set` and a complex number

Exception raised on line 124 of file TESTS:\runtime\test_type_error.py.

   122:         a = 1j
   123:         b = {2, 3}
--&gt;124:         b *= a
   125:     except Exception as e:

        b: {2, 3}
        a: 1j
</pre></div>
</div>
</div>
<div class="section" id="typeerror-5-unsupported-operand-type-s-for">
<h2>TypeError - 5: unsupported operand type(s) for //=<a class="headerlink" href="#typeerror-5-unsupported-operand-type-s-for" title="Permalink to this headline">¶</a></h2>
<div class="highlight-none notranslate"><div class="highlight"><pre><span></span>Traceback (most recent call last):
  File &quot;TESTS:\runtime\test_type_error.py&quot;, line 179, in test_type_error5
    b //= a
TypeError: unsupported operand type(s) for //=: &#39;float&#39; and &#39;dict&#39;

A `TypeError` is usually caused by trying
to combine two incompatible types of objects,
by calling a function with the wrong type of object,
or by tring to do an operation not allowed on a given type of object.

    You tried to divide two incompatible types of objects:
    a number (`float`) and a dictionary (`dict`)

Exception raised on line 179 of file TESTS:\runtime\test_type_error.py.

   177:         a = {1: 1, 2: 2}
   178:         b = 3.1416
--&gt;179:         b //= a
   180:     except Exception as e:

        b: 3.1416
        a: {1: 1, 2: 2}
</pre></div>
</div>
</div>
<div class="section" id="typeerror-6-unsupported-operand-type-s-for">
<h2>TypeError - 6: unsupported operand type(s) for &amp;=<a class="headerlink" href="#typeerror-6-unsupported-operand-type-s-for" title="Permalink to this headline">¶</a></h2>
<div class="highlight-none notranslate"><div class="highlight"><pre><span></span>Traceback (most recent call last):
  File &quot;TESTS:\runtime\test_type_error.py&quot;, line 208, in test_type_error6
    b &amp;= a
TypeError: unsupported operand type(s) for &amp;=: &#39;int&#39; and &#39;str&#39;

A `TypeError` is usually caused by trying
to combine two incompatible types of objects,
by calling a function with the wrong type of object,
or by tring to do an operation not allowed on a given type of object.

    You tried to perform the bitwise operation &amp;=
    on two incompatible types of objects:
    an integer (`int`) and a string (`str`)

Exception raised on line 208 of file TESTS:\runtime\test_type_error.py.

   206:         a = &quot;a&quot;
   207:         b = 2
--&gt;208:         b &amp;= a
   209:     except Exception as e:

        b: 2
        a: &#39;a&#39;
</pre></div>
</div>
</div>
<div class="section" id="typeerror-7-unsupported-operand-type-s-for">
<h2>TypeError - 7: unsupported operand type(s) for <code class="docutils literal notranslate"><span class="pre">**=</span></code><a class="headerlink" href="#typeerror-7-unsupported-operand-type-s-for" title="Permalink to this headline">¶</a></h2>
<div class="highlight-none notranslate"><div class="highlight"><pre><span></span>Traceback (most recent call last):
  File &quot;TESTS:\runtime\test_type_error.py&quot;, line 237, in test_type_error7
    a **= b
TypeError: unsupported operand type(s) for ** or pow(): &#39;dict&#39; and &#39;float&#39;

A `TypeError` is usually caused by trying
to combine two incompatible types of objects,
by calling a function with the wrong type of object,
or by tring to do an operation not allowed on a given type of object.

    You tried to exponentiate (raise to a power)
    using two incompatible types of objects:
    a dictionary (`dict`) and a number (`float`)

Exception raised on line 237 of file TESTS:\runtime\test_type_error.py.

   235:         a = {1: 1, 2: 2}
   236:         b = 3.1416
--&gt;237:         a **= b
   238:     except Exception as e:

        a: {1: 1, 2: 2}
        b: 3.1416
</pre></div>
</div>
</div>
<div class="section" id="typeerror-8-unsupported-operand-type-s-for">
<h2>TypeError - 8: unsupported operand type(s) for &gt;&gt;=<a class="headerlink" href="#typeerror-8-unsupported-operand-type-s-for" title="Permalink to this headline">¶</a></h2>
<div class="highlight-none notranslate"><div class="highlight"><pre><span></span>Traceback (most recent call last):
  File &quot;TESTS:\runtime\test_type_error.py&quot;, line 266, in test_type_error8
    a &gt;&gt;= b
TypeError: unsupported operand type(s) for &gt;&gt;=: &#39;str&#39; and &#39;int&#39;

A `TypeError` is usually caused by trying
to combine two incompatible types of objects,
by calling a function with the wrong type of object,
or by tring to do an operation not allowed on a given type of object.

    You tried to perform the bit shifting operation &gt;&gt;=
    on two incompatible types of objects:
    a string (`str`) and an integer (`int`)

Exception raised on line 266 of file TESTS:\runtime\test_type_error.py.

   264:         a = &quot;a&quot;
   265:         b = 42
--&gt;266:         a &gt;&gt;= b
   267:     except Exception as e:

        a: &#39;a&#39;
        b: 42
</pre></div>
</div>
</div>
<div class="section" id="typeerror-9-unsupported-operand-type-s-for">
<h2>TypeError - 9: unsupported operand type(s) for &#64;=<a class="headerlink" href="#typeerror-9-unsupported-operand-type-s-for" title="Permalink to this headline">¶</a></h2>
<div class="highlight-none notranslate"><div class="highlight"><pre><span></span>Traceback (most recent call last):
  File &quot;TESTS:\runtime\test_type_error.py&quot;, line 295, in test_type_error9
    a @= b
TypeError: unsupported operand type(s) for @=: &#39;str&#39; and &#39;int&#39;

A `TypeError` is usually caused by trying
to combine two incompatible types of objects,
by calling a function with the wrong type of object,
or by tring to do an operation not allowed on a given type of object.

    You tried to use the operator @=
    using two incompatible types of objects:
    a string (`str`) and an integer (`int`).
    This operator is normally used only
    for multiplication of matrices.

Exception raised on line 295 of file TESTS:\runtime\test_type_error.py.

   293:         a = &quot;a&quot;
   294:         b = 2
--&gt;295:         a @= b
   296:     except Exception as e:

        a: &#39;a&#39;
        b: 2
</pre></div>
</div>
</div>
<div class="section" id="typeerror-10-comparison-between-incompatible-types">
<h2>TypeError - 10: comparison between incompatible types<a class="headerlink" href="#typeerror-10-comparison-between-incompatible-types" title="Permalink to this headline">¶</a></h2>
<div class="highlight-none notranslate"><div class="highlight"><pre><span></span>Traceback (most recent call last):
  File &quot;TESTS:\runtime\test_type_error.py&quot;, line 311, in test_type_error10
    b &lt; a
TypeError: &#39;&lt;&#39; not supported between instances of &#39;int&#39; and &#39;str&#39;

A `TypeError` is usually caused by trying
to combine two incompatible types of objects,
by calling a function with the wrong type of object,
or by tring to do an operation not allowed on a given type of object.

    You tried to do an order comparison (&lt;)
    between two incompatible types of objects:
    an integer (`int`) and a string (`str`)

Exception raised on line 311 of file TESTS:\runtime\test_type_error.py.

   309:         a = &quot;a&quot;
   310:         b = 42
--&gt;311:         b &lt; a
   312:     except Exception as e:

        b: 42
        a: &#39;a&#39;
</pre></div>
</div>
</div>
<div class="section" id="typeerror-11-bad-operand-type-for-unary">
<h2>TypeError - 11: bad operand type for unary +<a class="headerlink" href="#typeerror-11-bad-operand-type-for-unary" title="Permalink to this headline">¶</a></h2>
<div class="highlight-none notranslate"><div class="highlight"><pre><span></span>Traceback (most recent call last):
  File &quot;TESTS:\runtime\test_type_error.py&quot;, line 363, in test_type_error11
    a =+ &quot;def&quot;
TypeError: bad operand type for unary +: &#39;str&#39;

    Perhaps you meant to write `+=` instead of `=+`
A `TypeError` is usually caused by trying
to combine two incompatible types of objects,
by calling a function with the wrong type of object,
or by tring to do an operation not allowed on a given type of object.

    You tried to use the unary operator &#39;+&#39;
    with the following type of object: a string (`str`).
    This operation is not defined for this type of object.

    Perhaps you meant to write `+=` instead of `=+`

Exception raised on line 363 of file TESTS:\runtime\test_type_error.py.

   361:     try:
   362:         a = &quot;abc&quot;
--&gt;363:         a =+ &quot;def&quot;
                   ^^^^^^^
   364:         print(a)
</pre></div>
</div>
</div>
<div class="section" id="typeerror-12-object-does-not-support-item-assignment">
<h2>TypeError - 12: object does not support item assignment<a class="headerlink" href="#typeerror-12-object-does-not-support-item-assignment" title="Permalink to this headline">¶</a></h2>
<div class="highlight-none notranslate"><div class="highlight"><pre><span></span>Traceback (most recent call last):
  File &quot;TESTS:\runtime\test_type_error.py&quot;, line 380, in test_type_error12
    a[0] = 0
TypeError: &#39;tuple&#39; object does not support item assignment

A `TypeError` is usually caused by trying
to combine two incompatible types of objects,
by calling a function with the wrong type of object,
or by tring to do an operation not allowed on a given type of object.

    In Python, some objects are known as immutable:
    once defined, their value cannot be changed.
    You tried change part of such an immutable object: a `tuple`,
    most likely by using an indexing operation.

Exception raised on line 380 of file TESTS:\runtime\test_type_error.py.

   378:     a = (1, 2, 3)
   379:     try:
--&gt;380:         a[0] = 0
   381:     except Exception as e:

        a[0]: 1
        a: (1, 2, 3)
</pre></div>
</div>
</div>
<div class="section" id="typeerror-13-wrong-number-of-positional-arguments">
<h2>TypeError - 13: wrong number of positional arguments<a class="headerlink" href="#typeerror-13-wrong-number-of-positional-arguments" title="Permalink to this headline">¶</a></h2>
<div class="highlight-none notranslate"><div class="highlight"><pre><span></span>Traceback (most recent call last):
  File &quot;TESTS:\runtime\test_type_error.py&quot;, line 413, in test_type_error13
    A().f(1)
TypeError: f() takes 1 positional argument but 2 were given

    Perhaps you forgot `self` when defining `f`.

A `TypeError` is usually caused by trying
to combine two incompatible types of objects,
by calling a function with the wrong type of object,
or by tring to do an operation not allowed on a given type of object.

    You apparently have called the function `f` with
    2 positional argument(s) while it requires 1
    such positional argument(s).
    Perhaps you forgot `self` when defining `f`.

Exception raised on line 413 of file TESTS:\runtime\test_type_error.py.

   411:
   412:     try:
--&gt;413:         A().f(1)
   414:     except Exception as e:

        A: &lt;class A&gt; from test_type_error.test_type_error13
</pre></div>
</div>
</div>
<div class="section" id="typeerror-14-missing-positional-arguments">
<h2>TypeError - 14: missing positional arguments<a class="headerlink" href="#typeerror-14-missing-positional-arguments" title="Permalink to this headline">¶</a></h2>
<div class="highlight-none notranslate"><div class="highlight"><pre><span></span>Traceback (most recent call last):
  File &quot;TESTS:\runtime\test_type_error.py&quot;, line 432, in test_type_error14
    fn(1)
TypeError: fn() missing 2 required positional arguments: &#39;b&#39; and &#39;c&#39;

A `TypeError` is usually caused by trying
to combine two incompatible types of objects,
by calling a function with the wrong type of object,
or by tring to do an operation not allowed on a given type of object.

    You apparently have called the function &#39;fn()&#39; with
    fewer positional arguments than it requires (2 missing).

Exception raised on line 432 of file TESTS:\runtime\test_type_error.py.

   430:
   431:     try:
--&gt;432:         fn(1)
   433:     except Exception as e:

        fn: &lt;function fn&gt; from test_type_error14
</pre></div>
</div>
</div>
<div class="section" id="typeerror-15-list-object-is-not-callable">
<h2>TypeError - 15: list object is not callable<a class="headerlink" href="#typeerror-15-list-object-is-not-callable" title="Permalink to this headline">¶</a></h2>
<div class="highlight-none notranslate"><div class="highlight"><pre><span></span>Traceback (most recent call last):
  File &quot;TESTS:\runtime\test_type_error.py&quot;, line 458, in test_type_error15
    _ = [1, 2](3, 4)
TypeError: &#39;list&#39; object is not callable

    Perhaps you had a missing comma before the tuple.

A `TypeError` is usually caused by trying
to combine two incompatible types of objects,
by calling a function with the wrong type of object,
or by tring to do an operation not allowed on a given type of object.

    I suspect that you had an object of this type, a `list`,
    followed by what looked like a tuple, &#39;(...)&#39;,
    which Python took as an indication of a function call.
    Perhaps you had a missing comma before the tuple.

Exception raised on line 458 of file TESTS:\runtime\test_type_error.py.

   456:
   457:     try:
--&gt;458:         _ = [1, 2](3, 4)
                    ^^^^^^^^^^^^
   459:     except Exception as e:
</pre></div>
</div>
</div>
<div class="section" id="typeerror-16-exception-derived-from-baseexception">
<h2>TypeError - 16: exception derived from BaseException<a class="headerlink" href="#typeerror-16-exception-derived-from-baseexception" title="Permalink to this headline">¶</a></h2>
<div class="highlight-none notranslate"><div class="highlight"><pre><span></span>Traceback (most recent call last):
  File &quot;TESTS:\runtime\test_type_error.py&quot;, line 471, in test_type_error16
    raise &quot;exception&quot;
TypeError: exceptions must derive from BaseException

A `TypeError` is usually caused by trying
to combine two incompatible types of objects,
by calling a function with the wrong type of object,
or by tring to do an operation not allowed on a given type of object.

    In Python 3, exceptions must be derived from BaseException.

Exception raised on line 471 of file TESTS:\runtime\test_type_error.py.

   469: def test_type_error16():
   470:     try:
--&gt;471:         raise &quot;exception&quot;
   472:     except Exception as e:
</pre></div>
</div>
</div>
<div class="section" id="unboundlocalerror-1-missing-global">
<h2>UnboundLocalError - 1: missing global<a class="headerlink" href="#unboundlocalerror-1-missing-global" title="Permalink to this headline">¶</a></h2>
<div class="highlight-none notranslate"><div class="highlight"><pre><span></span>Traceback (most recent call last):
  File &quot;TESTS:\runtime\test_unbound_local_error.py&quot;, line 27, in test_unbound_local_error_missing_global
    outer_missing_global()
  File &quot;TESTS:\runtime\test_unbound_local_error.py&quot;, line 11, in outer_missing_global
    inner()
  File &quot;TESTS:\runtime\test_unbound_local_error.py&quot;, line 9, in inner
    spam_missing_global += 1
UnboundLocalError: local variable &#39;spam_missing_global&#39; referenced before assignment

    Did you forget to add `global spam_missing_global`?

In Python, variables that are used inside a function are known as
local variables. Before they are used, they must be assigned a value.
A variable that is used before it is assigned a value is assumed to
be defined outside that function; it is known as a `global`
(or sometimes `nonlocal`) variable. You cannot assign a value to such
a global variable inside a function without first indicating to
Python that this is a global variable, otherwise you will see
an `UnboundLocalError`.

    The name `spam_missing_global` exists in the global scope.
    Perhaps the statement

        global spam_missing_global

    should have been included as the first line inside your function.

Execution stopped on line 27 of file TESTS:\runtime\test_unbound_local_error.py.

   25:
   26:     try:
--&gt;27:         outer_missing_global()
   28:     except Exception as e:

        global outer_missing_global: &lt;function outer_missing_global&gt;

Exception raised on line 9 of file TESTS:\runtime\test_unbound_local_error.py.

    7: def outer_missing_global():
    8:     def inner():
--&gt; 9:         spam_missing_global += 1

        global spam_missing_global: 1
</pre></div>
</div>
</div>
<div class="section" id="unboundlocalerror-2-missing-nonlocal">
<h2>UnboundLocalError - 2: missing nonlocal<a class="headerlink" href="#unboundlocalerror-2-missing-nonlocal" title="Permalink to this headline">¶</a></h2>
<div class="highlight-none notranslate"><div class="highlight"><pre><span></span>Traceback (most recent call last):
  File &quot;TESTS:\runtime\test_unbound_local_error.py&quot;, line 48, in test_unbound_local_error_missing_nonlocal
    outer_missing_nonlocal()
  File &quot;TESTS:\runtime\test_unbound_local_error.py&quot;, line 20, in outer_missing_nonlocal
    inner()
  File &quot;TESTS:\runtime\test_unbound_local_error.py&quot;, line 18, in inner
    spam_missing_nonlocal += 1
UnboundLocalError: local variable &#39;spam_missing_nonlocal&#39; referenced before assignment

    Did you forget to add `nonlocal spam_missing_nonlocal`?

In Python, variables that are used inside a function are known as
local variables. Before they are used, they must be assigned a value.
A variable that is used before it is assigned a value is assumed to
be defined outside that function; it is known as a `global`
(or sometimes `nonlocal`) variable. You cannot assign a value to such
a global variable inside a function without first indicating to
Python that this is a global variable, otherwise you will see
an `UnboundLocalError`.

    The name `spam_missing_nonlocal` exists in the nonlocal scope.
    Perhaps the statement

        nonlocal spam_missing_nonlocal

    should have been included as the first line inside your function.

Execution stopped on line 48 of file TESTS:\runtime\test_unbound_local_error.py.

   46:
   47:     try:
--&gt;48:         outer_missing_nonlocal()
   49:     except Exception as e:

        global outer_missing_nonlocal: &lt;function outer_missing_nonlocal&gt;

Exception raised on line 18 of file TESTS:\runtime\test_unbound_local_error.py.

   16:
   17:     def inner():
--&gt;18:         spam_missing_nonlocal += 1
</pre></div>
</div>
</div>
<div class="section" id="unknown-exception">
<h2>Unknown exception<a class="headerlink" href="#unknown-exception" title="Permalink to this headline">¶</a></h2>
<div class="highlight-none notranslate"><div class="highlight"><pre><span></span>Traceback (most recent call last):
  File &quot;TESTS:\runtime\test_unknown_error.py&quot;, line 10, in test_function_unknown_error
    raise MyException(&quot;Some informative message about an unknown exception.&quot;)
MyException: Some informative message about an unknown exception.

No information is available about this exception.

Exception raised on line 10 of file TESTS:\runtime\test_unknown_error.py.

    8: def test_function_unknown_error():
    9:     try:
--&gt;10:         raise MyException(&quot;Some informative message about an unknown exception.&quot;)
   11:     except Exception as e:

        global MyException: &lt;class test_unknown_error.MyException&gt;
</pre></div>
</div>
</div>
<div class="section" id="zerodivisionerror-1">
<h2>ZeroDivisionError - 1<a class="headerlink" href="#zerodivisionerror-1" title="Permalink to this headline">¶</a></h2>
<div class="highlight-none notranslate"><div class="highlight"><pre><span></span>Traceback (most recent call last):
  File &quot;TESTS:\runtime\test_zero_division_error.py&quot;, line 6, in test_zero_division_error
    1 / 0
ZeroDivisionError: division by zero

A `ZeroDivisionError` occurs when you are attempting to divide
a value by zero:
    `result = my_variable / 0.`
It can also happen if you calculate the remainder of a division
using the modulo operator `%`:
    `result = my_variable % 0`

Exception raised on line 6 of file TESTS:\runtime\test_zero_division_error.py.

   4: def test_zero_division_error():
   5:     try:
--&gt;6:         1 / 0
   7:     except Exception as e:
</pre></div>
</div>
</div>
<div class="section" id="zerodivisionerror-2">
<h2>ZeroDivisionError - 2<a class="headerlink" href="#zerodivisionerror-2" title="Permalink to this headline">¶</a></h2>
<div class="highlight-none notranslate"><div class="highlight"><pre><span></span>Traceback (most recent call last):
  File &quot;TESTS:\runtime\test_zero_division_error.py&quot;, line 21, in test_zero_division_error2
    1 % zero
ZeroDivisionError: integer division or modulo by zero

A `ZeroDivisionError` occurs when you are attempting to divide
a value by zero:
    `result = my_variable / 0.`
It can also happen if you calculate the remainder of a division
using the modulo operator `%`:
    `result = my_variable % 0`

Exception raised on line 21 of file TESTS:\runtime\test_zero_division_error.py.

   19:     zero = 0
   20:     try:
--&gt;21:         1 % zero
   22:     except Exception as e:

        zero: 0
</pre></div>
</div>
</div>
</div>


           </div>
           
          </div>
          <footer>
  
    <div class="rst-footer-buttons" role="navigation" aria-label="footer navigation">
      
        <a href="syntax_tracebacks_en_3.7.html" class="btn btn-neutral float-right" title="Friendly SyntaxError tracebacks - in English" accesskey="n" rel="next">Next <span class="fa fa-arrow-circle-right"></span></a>
      
      
        <a href="syntax_tracebacks_en_3.6.html" class="btn btn-neutral float-left" title="Friendly SyntaxError tracebacks - in English" accesskey="p" rel="prev"><span class="fa fa-arrow-circle-left"></span> Previous</a>
      
    </div>
  

  <hr/>

  <div role="contentinfo">
    <p>
        
        &copy; Copyright 2019, André Roberge

    </p>
  </div>
    
    
    
    Built with <a href="http://sphinx-doc.org/">Sphinx</a> using a
    
    <a href="https://github.com/rtfd/sphinx_rtd_theme">theme</a>
    
    provided by <a href="https://readthedocs.org">Read the Docs</a>. 

</footer>

        </div>
      </div>

    </section>

  </div>
  

  <script type="text/javascript">
      jQuery(function () {
          SphinxRtdTheme.Navigation.enable(true);
      });
  </script>

  
  
    
   

</body>
</html>