

<!DOCTYPE html>
<html class="writer-html5" lang="en" >
<head>
  <meta charset="utf-8">
  
  <meta name="viewport" content="width=device-width, initial-scale=1.0">
  
  <title>Friendly tracebacks - in English &mdash; Friendly tracebacks 0.1.12a documentation</title>
  

  
  <link rel="stylesheet" href="_static/css/theme.css" type="text/css" />
  <link rel="stylesheet" href="_static/pygments.css" type="text/css" />
  <link rel="stylesheet" href="_static/custom.css" type="text/css" />

  
  
  
  

  
  <!--[if lt IE 9]>
    <script src="_static/js/html5shiv.min.js"></script>
  <![endif]-->
  
    
      <script type="text/javascript" id="documentation_options" data-url_root="./" src="_static/documentation_options.js"></script>
        <script src="_static/jquery.js"></script>
        <script src="_static/underscore.js"></script>
        <script src="_static/doctools.js"></script>
        <script src="_static/language_data.js"></script>
    
    <script type="text/javascript" src="_static/js/theme.js"></script>

    
    <link rel="index" title="Index" href="genindex.html" />
    <link rel="search" title="Search" href="search.html" />
    <link rel="next" title="Friendly SyntaxError tracebacks - in English" href="syntax_tracebacks_en_3.10.html" />
    <link rel="prev" title="Friendly SyntaxError tracebacks - in English" href="syntax_tracebacks_en_3.9.html" /> 
</head>

<body class="wy-body-for-nav">

   
  <div class="wy-grid-for-nav">
    
    <nav data-toggle="wy-nav-shift" class="wy-nav-side">
      <div class="wy-side-scroll">
        <div class="wy-side-nav-search" >
          

          
            <a href="index.html" class="icon icon-home" alt="Documentation Home"> Friendly tracebacks
          

          
          </a>

          
            
            
              <div class="version">
                0.1.12a
              </div>
            
          

          
<div role="search">
  <form id="rtd-search-form" class="wy-form" action="search.html" method="get">
    <input type="text" name="q" placeholder="Search docs" />
    <input type="hidden" name="check_keywords" value="yes" />
    <input type="hidden" name="area" value="default" />
  </form>
</div>

          
        </div>

        
        <div class="wy-menu wy-menu-vertical" data-spy="affix" role="navigation" aria-label="main navigation">
          
            
            
              
            
            
              <p class="caption"><span class="caption-text">Begin here</span></p>
<ul>
<li class="toctree-l1"><a class="reference internal" href="usage.html">Installation and basic usage</a></li>
<li class="toctree-l1"><a class="reference internal" href="repl.html">Console basics</a></li>
<li class="toctree-l1"><a class="reference internal" href="editor.html">Using with an editor or IDE</a></li>
<li class="toctree-l1"><a class="reference internal" href="mu.html">Using with Mu</a></li>
<li class="toctree-l1"><a class="reference internal" href="thonny.html">Using with Thonny</a></li>
<li class="toctree-l1"><a class="reference internal" href="tracebacks.html">Multiple tracebacks</a></li>
</ul>
<p class="caption"><span class="caption-text">Thoughts on design</span></p>
<ul>
<li class="toctree-l1"><a class="reference internal" href="design.html">Some thoughts on the design of Friendly-traceback</a></li>
<li class="toctree-l1"><a class="reference internal" href="themes.html">Themes and colours</a></li>
</ul>
<p class="caption"><span class="caption-text">Use in your project</span></p>
<ul>
<li class="toctree-l1"><a class="reference internal" href="api.html">Public API</a></li>
<li class="toctree-l1"><a class="reference internal" href="lies.html">Learn to lie</a></li>
<li class="toctree-l1"><a class="reference internal" href="formatter.html">Custom formatter</a></li>
<li class="toctree-l1"><a class="reference internal" href="usage_adv.html">Other details for advanced users</a></li>
<li class="toctree-l1"><a class="reference internal" href="plugins.html">Editor plugins</a></li>
</ul>
<p class="caption"><span class="caption-text">Contribute</span></p>
<ul>
<li class="toctree-l1"><a class="reference internal" href="suggest.html">Suggest an addition</a></li>
<li class="toctree-l1"><a class="reference internal" href="adding_exception.html">Developer: Add a new Exception case</a></li>
<li class="toctree-l1"><a class="reference internal" href="syntax_error.html">Developer: Add a new SyntaxError case</a></li>
<li class="toctree-l1"><a class="reference internal" href="translation_notes.html">Notes on translations - using gettext</a></li>
</ul>
<p class="caption"><span class="caption-text">All the tracebacks!</span></p>
<ul class="current">
<li class="toctree-l1"><a class="reference internal" href="all_tb.html">Why all the tracebacks?</a></li>
<li class="toctree-l1"><a class="reference internal" href="known.html">Generic information about various exceptions</a></li>
<li class="toctree-l1"><a class="reference internal" href="tracebacks_en_3.6.html">Friendly tracebacks - Python 3.6 in English</a></li>
<li class="toctree-l1"><a class="reference internal" href="syntax_tracebacks_en_3.6.html">SyntaxError - Python 3.6 in English</a></li>
<li class="toctree-l1"><a class="reference internal" href="tracebacks_en_3.7.html">Friendly tracebacks - Python 3.7 in English</a></li>
<li class="toctree-l1"><a class="reference internal" href="syntax_tracebacks_en_3.7.html">SyntaxError - Python 3.7 in English</a></li>
<li class="toctree-l1"><a class="reference internal" href="tracebacks_en_3.8.html">Friendly tracebacks - Python 3.8 in English</a></li>
<li class="toctree-l1"><a class="reference internal" href="syntax_tracebacks_en_3.8.html">SyntaxError - Python 3.8 in English</a></li>
<li class="toctree-l1"><a class="reference internal" href="tracebacks_en_3.9.html">Friendly tracebacks - Python 3.9 in English</a></li>
<li class="toctree-l1"><a class="reference internal" href="syntax_tracebacks_en_3.9.html">SyntaxError - Python 3.9 in English</a></li>
<li class="toctree-l1 current"><a class="current reference internal" href="#">Friendly tracebacks - Python 3.10 in English</a><ul>
<li class="toctree-l2"><a class="reference internal" href="#arithmeticerror">ArithmeticError</a></li>
<li class="toctree-l2"><a class="reference internal" href="#attributeerror-class-attribute">AttributeError - class attribute</a></li>
<li class="toctree-l2"><a class="reference internal" href="#attributeerror-typo-in-module-attribute">AttributeError - typo in module attribute</a></li>
<li class="toctree-l2"><a class="reference internal" href="#attributeerror-typo-in-module-attribute-2">AttributeError - typo in module attribute 2</a></li>
<li class="toctree-l2"><a class="reference internal" href="#filenotfounderror">FileNotFoundError</a></li>
<li class="toctree-l2"><a class="reference internal" href="#importerror">ImportError</a></li>
<li class="toctree-l2"><a class="reference internal" href="#keyerror">KeyError</a></li>
<li class="toctree-l2"><a class="reference internal" href="#lookuperror">LookupError</a></li>
<li class="toctree-l2"><a class="reference internal" href="#indexerror-short-tuple">IndexError - short tuple</a></li>
<li class="toctree-l2"><a class="reference internal" href="#indexerror-long-list">IndexError - long list</a></li>
<li class="toctree-l2"><a class="reference internal" href="#modulenotfounderror">ModuleNotFoundError</a></li>
<li class="toctree-l2"><a class="reference internal" href="#nameerror-1">NameError - 1</a></li>
<li class="toctree-l2"><a class="reference internal" href="#nameerror-2">NameError - 2</a></li>
<li class="toctree-l2"><a class="reference internal" href="#nameerror-3">NameError - 3</a></li>
<li class="toctree-l2"><a class="reference internal" href="#nameerror-4">NameError - 4</a></li>
<li class="toctree-l2"><a class="reference internal" href="#overflowerror">OverflowError</a></li>
<li class="toctree-l2"><a class="reference internal" href="#recursionerror">RecursionError</a></li>
<li class="toctree-l2"><a class="reference internal" href="#typeerror-1-concatenate-two-different-types">TypeError - 1: concatenate two different types</a></li>
<li class="toctree-l2"><a class="reference internal" href="#typeerror-1a-concatenate-two-different-types">TypeError - 1a: concatenate two different types</a></li>
<li class="toctree-l2"><a class="reference internal" href="#typeerror-1b-concatenate-two-different-types">TypeError - 1b: concatenate two different types</a></li>
<li class="toctree-l2"><a class="reference internal" href="#typeerror-2-unsupported-operand-type-s-for">TypeError - 2: unsupported operand type(s) for +</a></li>
<li class="toctree-l2"><a class="reference internal" href="#typeerror-2a-unsupported-operand-type-s-for">TypeError - 2a: unsupported operand type(s) for +=</a></li>
<li class="toctree-l2"><a class="reference internal" href="#typeerror-3-unsupported-operand-type-s-for">TypeError - 3: unsupported operand type(s) for -</a></li>
<li class="toctree-l2"><a class="reference internal" href="#typeerror-3a-unsupported-operand-type-s-for">TypeError - 3a: unsupported operand type(s) for -=</a></li>
<li class="toctree-l2"><a class="reference internal" href="#typeerror-4-unsupported-operand-type-s-for">TypeError - 4: unsupported operand type(s) for *</a></li>
<li class="toctree-l2"><a class="reference internal" href="#typeerror-4a-unsupported-operand-type-s-for">TypeError - 4a: unsupported operand type(s) for <code class="docutils literal notranslate"><span class="pre">*=</span></code></a></li>
<li class="toctree-l2"><a class="reference internal" href="#typeerror-5-unsupported-operand-type-s-for">TypeError - 5: unsupported operand type(s) for /</a></li>
<li class="toctree-l2"><a class="reference internal" href="#typeerror-5a-unsupported-operand-type-s-for">TypeError - 5a: unsupported operand type(s) for /=</a></li>
<li class="toctree-l2"><a class="reference internal" href="#typeerror-5b-unsupported-operand-type-s-for">TypeError - 5b: unsupported operand type(s) for //</a></li>
<li class="toctree-l2"><a class="reference internal" href="#typeerror-5c-unsupported-operand-type-s-for">TypeError - 5c: unsupported operand type(s) for //=</a></li>
<li class="toctree-l2"><a class="reference internal" href="#typeerror-6-unsupported-operand-type-s-for">TypeError - 6: unsupported operand type(s) for &amp;</a></li>
<li class="toctree-l2"><a class="reference internal" href="#typeerror-6a-unsupported-operand-type-s-for">TypeError - 6a: unsupported operand type(s) for &amp;=</a></li>
<li class="toctree-l2"><a class="reference internal" href="#typeerror-7-unsupported-operand-type-s-for">TypeError - 7: unsupported operand type(s) for **</a></li>
<li class="toctree-l2"><a class="reference internal" href="#typeerror-7a-unsupported-operand-type-s-for">TypeError - 7a: unsupported operand type(s) for <code class="docutils literal notranslate"><span class="pre">**=</span></code></a></li>
<li class="toctree-l2"><a class="reference internal" href="#typeerror-8-unsupported-operand-type-s-for">TypeError - 8: unsupported operand type(s) for &gt;&gt;</a></li>
<li class="toctree-l2"><a class="reference internal" href="#typeerror-8a-unsupported-operand-type-s-for">TypeError - 8a: unsupported operand type(s) for &gt;&gt;=</a></li>
<li class="toctree-l2"><a class="reference internal" href="#typeerror-9-unsupported-operand-type-s-for">TypeError - 9: unsupported operand type(s) for &#64;</a></li>
<li class="toctree-l2"><a class="reference internal" href="#typeerror-9a-unsupported-operand-type-s-for">TypeError - 9a: unsupported operand type(s) for &#64;=</a></li>
<li class="toctree-l2"><a class="reference internal" href="#typeerror-10-comparison-between-incompatible-types">TypeError - 10: comparison between incompatible types</a></li>
<li class="toctree-l2"><a class="reference internal" href="#typeerror-11-bad-operand-type-for-unary">TypeError - 11: bad operand type for unary +</a></li>
<li class="toctree-l2"><a class="reference internal" href="#typeerror-11a-bad-operand-type-for-unary">TypeError - 11a: bad operand type for unary -</a></li>
<li class="toctree-l2"><a class="reference internal" href="#typeerror-11b-bad-operand-type-for-unary">TypeError - 11b: bad operand type for unary ~</a></li>
<li class="toctree-l2"><a class="reference internal" href="#typeerror-12-object-does-not-support-item-assignment">TypeError - 12: object does not support item assignment</a></li>
<li class="toctree-l2"><a class="reference internal" href="#typeerror-13-wrong-number-of-positional-arguments">TypeError - 13: wrong number of positional arguments</a></li>
<li class="toctree-l2"><a class="reference internal" href="#typeerror-13a-wrong-number-of-positional-arguments">TypeError - 13a: wrong number of positional arguments</a></li>
<li class="toctree-l2"><a class="reference internal" href="#typeerror-14-missing-positional-arguments">TypeError - 14: missing positional arguments</a></li>
<li class="toctree-l2"><a class="reference internal" href="#typeerror-15-tuple-object-is-not-callable">TypeError - 15: tuple object is not callable</a></li>
<li class="toctree-l2"><a class="reference internal" href="#typeerror-15a-list-object-is-not-callable">TypeError - 15a: list object is not callable</a></li>
<li class="toctree-l2"><a class="reference internal" href="#typeerror-16-exception-derived-from-baseexception">TypeError - 16: exception derived from BaseException</a></li>
<li class="toctree-l2"><a class="reference internal" href="#unboundlocalerror-1-missing-global">UnboundLocalError - 1: missing global</a></li>
<li class="toctree-l2"><a class="reference internal" href="#unboundlocalerror-2-missing-nonlocal">UnboundLocalError - 2: missing nonlocal</a></li>
<li class="toctree-l2"><a class="reference internal" href="#unknown-exception">Unknown exception</a></li>
<li class="toctree-l2"><a class="reference internal" href="#zerodivisionerror-1">ZeroDivisionError - 1</a></li>
<li class="toctree-l2"><a class="reference internal" href="#zerodivisionerror-2">ZeroDivisionError - 2</a></li>
</ul>
</li>
<li class="toctree-l1"><a class="reference internal" href="syntax_tracebacks_en_3.10.html">SyntaxError - Python 3.10 in English</a></li>
<li class="toctree-l1"><a class="reference internal" href="compare_exceptions.html">Comparing Exception messages between Python versions</a></li>
<li class="toctree-l1"><a class="reference internal" href="compare.html">Comparison between Python versions: SyntaxErrors</a></li>
</ul>
<p class="caption"><span class="caption-text">Markdown examples</span></p>
<ul>
<li class="toctree-l1"><a class="reference internal" href="tracebacks_markdown.html">Friendly tracebacks - markdown_docs format</a></li>
<li class="toctree-l1"><a class="reference internal" href="tracebacks_syntax_markdown.html">Syntax errors - markdown_docs format</a></li>
</ul>
<p class="caption"><span class="caption-text">En français</span></p>
<ul>
<li class="toctree-l1"><a class="reference internal" href="tracebacks_fr.html"> Friendly tracebacks - en Français</a></li>
<li class="toctree-l1"><a class="reference internal" href="syntax_tracebacks_fr.html"> Friendly SyntaxError tracebacks - en Français</a></li>
</ul>

            
          
        </div>
        
      </div>
    </nav>

    <section data-toggle="wy-nav-shift" class="wy-nav-content-wrap">

      
      <nav class="wy-nav-top" aria-label="top navigation">
        
          <i data-toggle="wy-nav-top" class="fa fa-bars"></i>
          <a href="index.html">Friendly tracebacks</a>
        
      </nav>


      <div class="wy-nav-content">
        
        <div class="rst-content style-external-links">
        
          















<div role="navigation" aria-label="breadcrumbs navigation">

  <ul class="wy-breadcrumbs">
    
      <li><a href="index.html" class="icon icon-home"></a> &raquo;</li>
        
      <li>Friendly tracebacks - in English</li>
    
    
      <li class="wy-breadcrumbs-aside">
        
            
            <a href="_sources/tracebacks_en_3.10.rst.txt" rel="nofollow"> View page source</a>
          
        
      </li>
    
  </ul>

  
  <div class="rst-breadcrumbs-buttons" role="navigation" aria-label="breadcrumb navigation">
      
        <a href="syntax_tracebacks_en_3.10.html" class="btn btn-neutral float-right" title="Friendly SyntaxError tracebacks - in English" accesskey="n">Next <span class="fa fa-arrow-circle-right"></span></a>
      
      
        <a href="syntax_tracebacks_en_3.9.html" class="btn btn-neutral float-left" title="Friendly SyntaxError tracebacks - in English" accesskey="p"><span class="fa fa-arrow-circle-left"></span> Previous</a>
      
  </div>
  
  <hr/>
</div>
          <div role="main" class="document" itemscope="itemscope" itemtype="http://schema.org/Article">
           <div itemprop="articleBody">
            
  <div class="section" id="friendly-tracebacks-in-english">
<h1>Friendly tracebacks - in English<a class="headerlink" href="#friendly-tracebacks-in-english" title="Permalink to this headline">¶</a></h1>
<p>Friendly-traceback aims to provide friendlier feedback when an exception
is raised than what is done by Python.
Below, we can find some examples. SyntaxError cases, as well as TabError and
IndentationError cases, are shown in a separate page.
Ideally, an example of each case handled by friendly-traceback
should be included here.</p>
<div class="admonition note">
<p class="admonition-title">Note</p>
<p>The content of this page is generated by running
C:Usersandregithubfriendly-tracebackteststrb_english.py located in the <code class="docutils literal notranslate"><span class="pre">tests/</span></code> directory.
This needs to be done explicitly, independently of updating the
documentation using Sphinx.</p>
</div>
<p>Friendly-traceback version: 0.1.12a
Python version: 3.10.0a1</p>
<div class="section" id="arithmeticerror">
<h2>ArithmeticError<a class="headerlink" href="#arithmeticerror" title="Permalink to this headline">¶</a></h2>
<div class="highlight-none notranslate"><div class="highlight"><pre><span></span>Traceback (most recent call last):
  File &quot;TESTS:\runtime\test_arithmetic_error.py&quot;, line 9, in test_arithmetic_error
    raise ArithmeticError
ArithmeticError:

`ArithmeticError` is the base class for those built-in exceptions
that are raised for various arithmetic errors.
It is unusual that you are seeing this exception;
normally, a more specific exception should have been raised.

Exception raised on line 9 of file TESTS:\runtime\test_arithmetic_error.py.

    8:         # likely be raised.
--&gt; 9:         raise ArithmeticError
   10:     except Exception as e:

    Known objects shown above:
        ArithmeticError: &lt;class &#39;ArithmeticError&#39;&gt;
        Exception: &lt;class &#39;Exception&#39;&gt;
        e: ArithmeticError()
</pre></div>
</div>
</div>
<div class="section" id="attributeerror-class-attribute">
<h2>AttributeError - class attribute<a class="headerlink" href="#attributeerror-class-attribute" title="Permalink to this headline">¶</a></h2>
<div class="highlight-none notranslate"><div class="highlight"><pre><span></span>Traceback (most recent call last):
  File &quot;TESTS:\runtime\test_attribute_error.py&quot;, line 35, in test_attribute_error
    a.x  # Testing instance
AttributeError: &#39;A&#39; object has no attribute &#39;x&#39;

An `AttributeError` occurs when the code contains something like
    `object.x`
and `x` is not a method or attribute (variable) belonging to `object`.

    The object `a` has no attribute named `x`.

Exception raised on line 35 of file TESTS:\runtime\test_attribute_error.py.

   34:         a = A()
--&gt;35:         a.x  # Testing instance
   36:     except Exception as e:

    Known objects shown above:
        a: &lt;test_attribute_error.test_attribute_error.&lt;locals&gt;.A object&gt;
        A: &lt;class &#39;test_attribute_error.test_attribute_error.&lt;locals&gt;.A&#39;&gt;
        Exception: &lt;class &#39;Exception&#39;&gt;
        e: AttributeError(&quot;&#39;A&#39; object has no attribute &#39;x&#39;&quot;)
</pre></div>
</div>
</div>
<div class="section" id="attributeerror-typo-in-module-attribute">
<h2>AttributeError - typo in module attribute<a class="headerlink" href="#attributeerror-typo-in-module-attribute" title="Permalink to this headline">¶</a></h2>
<div class="highlight-none notranslate"><div class="highlight"><pre><span></span>Traceback (most recent call last):
  File &quot;TESTS:\runtime\test_attribute_error.py&quot;, line 66, in test_misspelled_module_attribute
    string.ascii_lowecase
AttributeError: module &#39;string&#39; has no attribute &#39;ascii_lowecase&#39;

    Did you mean `ascii_lowercase`?

An `AttributeError` occurs when the code contains something like
    `object.x`
and `x` is not a method or attribute (variable) belonging to `object`.

    Perhaps you meant to write `string.ascii_lowercase` instead of `string.ascii_lowecase`

Exception raised on line 66 of file TESTS:\runtime\test_attribute_error.py.

   65:     try:
--&gt;66:         string.ascii_lowecase
   67:     except Exception as e:

    Known objects shown above:
        string: &lt;module &#39;string&#39;&gt; from PYTHON_LIB:\string.py
        Exception: &lt;class &#39;Exception&#39;&gt;
        e: AttributeError(&quot;module &#39;string&#39; has no attribute &#39;ascii_lowe...)
</pre></div>
</div>
</div>
<div class="section" id="attributeerror-typo-in-module-attribute-2">
<h2>AttributeError - typo in module attribute 2<a class="headerlink" href="#attributeerror-typo-in-module-attribute-2" title="Permalink to this headline">¶</a></h2>
<div class="highlight-none notranslate"><div class="highlight"><pre><span></span>Traceback (most recent call last):
  File &quot;TESTS:\runtime\test_attribute_error.py&quot;, line 82, in test_misspelled_module_attribute_2
    math.cost
AttributeError: module &#39;math&#39; has no attribute &#39;cost&#39;

    Did you mean one of the following: `cos, cosh, acos`?

An `AttributeError` occurs when the code contains something like
    `object.x`
and `x` is not a method or attribute (variable) belonging to `object`.

    Instead of writing `math.cost`, perhaps you meant to write one of
    the following names which are attributes of module `math`:
    `cos, cosh, acos`

Exception raised on line 82 of file TESTS:\runtime\test_attribute_error.py.

   81:     try:
--&gt;82:         math.cost
   83:     except Exception as e:

    Known objects shown above:
        math: &lt;module &#39;math&#39; (builtin)&gt;
        Exception: &lt;class &#39;Exception&#39;&gt;
        e: AttributeError(&quot;module &#39;math&#39; has no attribute &#39;cost&#39;&quot;)
</pre></div>
</div>
</div>
<div class="section" id="filenotfounderror">
<h2>FileNotFoundError<a class="headerlink" href="#filenotfounderror" title="Permalink to this headline">¶</a></h2>
<div class="highlight-none notranslate"><div class="highlight"><pre><span></span>Traceback (most recent call last):
  File &quot;TESTS:\runtime\test_file_not_found_error.py&quot;, line 6, in test_file_not_found_error
    open(&quot;does_not_exist&quot;)
FileNotFoundError: [Errno 2] No such file or directory: &#39;does_not_exist&#39;

A `FileNotFoundError` exception indicates that you
are trying to open a file that cannot be found by Python.
This could be because you misspelled the name of the file.

    In your program, the name of the
    file that cannot be found is `does_not_exist`.

Exception raised on line 6 of file TESTS:\runtime\test_file_not_found_error.py.

   5:     try:
--&gt;6:         open(&quot;does_not_exist&quot;)
   7:     except Exception as e:

    Known objects shown above:
        open: &lt;builtin function open&gt;
        Exception: &lt;class &#39;Exception&#39;&gt;
        e: FileNotFoundError(2, &#39;No such file or directory&#39;)
</pre></div>
</div>
</div>
<div class="section" id="importerror">
<h2>ImportError<a class="headerlink" href="#importerror" title="Permalink to this headline">¶</a></h2>
<div class="highlight-none notranslate"><div class="highlight"><pre><span></span>Traceback (most recent call last):
  File &quot;TESTS:\runtime\test_import_error.py&quot;, line 6, in test_import_error
    from math import Pi
ImportError: cannot import name &#39;Pi&#39; from &#39;math&#39; (unknown location)

    Did you mean `pi`?

An `ImportError` exception indicates that a certain object could not
be imported from a module or package. Most often, this is
because the name of the object is not spelled correctly.

    Perhaps you meant to import `pi` (from `math`) instead of `Pi`

Exception raised on line 6 of file TESTS:\runtime\test_import_error.py.

   5:     try:
--&gt;6:         from math import Pi
   7:     except Exception as e:

    Known objects shown above:
        Exception: &lt;class &#39;Exception&#39;&gt;
        e: ImportError(&quot;cannot import name &#39;Pi&#39; from &#39;math&#39; (unknown lo...)
</pre></div>
</div>
</div>
<div class="section" id="keyerror">
<h2>KeyError<a class="headerlink" href="#keyerror" title="Permalink to this headline">¶</a></h2>
<div class="highlight-none notranslate"><div class="highlight"><pre><span></span>Traceback (most recent call last):
  File &quot;TESTS:\runtime\test_key_error.py&quot;, line 7, in test_key_error
    d[&quot;c&quot;]
KeyError: &#39;c&#39;

A `KeyError` is raised when a value is not found as a
key in a Python dict.

    In your program, the key that cannot be found is `&#39;c&#39;`.

Exception raised on line 7 of file TESTS:\runtime\test_key_error.py.

   6:     try:
--&gt;7:         d[&quot;c&quot;]
   8:     except Exception as e:

    Known objects shown above:
        d: {&#39;a&#39;: 1, &#39;b&#39;: 2}
        Exception: &lt;class &#39;Exception&#39;&gt;
        e: KeyError(&#39;c&#39;)
</pre></div>
</div>
</div>
<div class="section" id="lookuperror">
<h2>LookupError<a class="headerlink" href="#lookuperror" title="Permalink to this headline">¶</a></h2>
<div class="highlight-none notranslate"><div class="highlight"><pre><span></span>Traceback (most recent call last):
  File &quot;TESTS:\runtime\test_lookup_error.py&quot;, line 10, in test_lookup_error
    raise LookupError(&quot;Fake message&quot;)
LookupError: Fake message

`LookupError` is the base class for the exceptions that are raised
when a key or index used on a mapping or sequence is invalid.
It can also be raised directly by codecs.lookup().

Exception raised on line 10 of file TESTS:\runtime\test_lookup_error.py.

    9:         # it directly here for our example.
--&gt;10:         raise LookupError(&quot;Fake message&quot;)
   11:     except Exception as e:

    Known objects shown above:
        LookupError: &lt;class &#39;LookupError&#39;&gt;
        Exception: &lt;class &#39;Exception&#39;&gt;
        e: LookupError(&#39;Fake message&#39;)
</pre></div>
</div>
</div>
<div class="section" id="indexerror-short-tuple">
<h2>IndexError - short tuple<a class="headerlink" href="#indexerror-short-tuple" title="Permalink to this headline">¶</a></h2>
<div class="highlight-none notranslate"><div class="highlight"><pre><span></span>Traceback (most recent call last):
  File &quot;TESTS:\runtime\test_index_error.py&quot;, line 8, in test_index_error1
    print(a[3], b[2])
IndexError: tuple index out of range

An `IndexError` occurs when you are try to get an item from a list,
a tuple, or a similar object (sequence), by using an index which
does not exists; typically, this is because the index you give
is greater than the length of the sequence.
Reminder: the first item of a sequence is at index 0.

Exception raised on line 8 of file TESTS:\runtime\test_index_error.py.

   7:     try:
--&gt;8:         print(a[3], b[2])
   9:     except Exception as e:

    Known objects shown above:
        print: &lt;builtin function print&gt;
        a: (1, 2, 3)
        b: [1, 2, 3]
        Exception: &lt;class &#39;Exception&#39;&gt;
        e: IndexError(&#39;tuple index out of range&#39;)
</pre></div>
</div>
</div>
<div class="section" id="indexerror-long-list">
<h2>IndexError - long list<a class="headerlink" href="#indexerror-long-list" title="Permalink to this headline">¶</a></h2>
<div class="highlight-none notranslate"><div class="highlight"><pre><span></span>Traceback (most recent call last):
  File &quot;TESTS:\runtime\test_index_error.py&quot;, line 22, in test_index_error2
    print(a[50], b[0])
IndexError: list index out of range

An `IndexError` occurs when you are try to get an item from a list,
a tuple, or a similar object (sequence), by using an index which
does not exists; typically, this is because the index you give
is greater than the length of the sequence.
Reminder: the first item of a sequence is at index 0.

Exception raised on line 22 of file TESTS:\runtime\test_index_error.py.

   21:     try:
--&gt;22:         print(a[50], b[0])
   23:     except Exception as e:

    Known objects shown above:
        print: &lt;builtin function print&gt;
        a: [0, 1, 2, 3, 4, 5, 6, 7, 8, 9, 10, 11, 12, 13, 14, 15, 16, 17, 18, ...]
            len(a): 40
        b: (0, 1, 2, 3, 4, 5, 6, 7, 8, 9, 10, 11, 12, 13, 14, 15, 16, 17, 18, ...)
            len(b): 50
        Exception: &lt;class &#39;Exception&#39;&gt;
        e: IndexError(&#39;list index out of range&#39;)
</pre></div>
</div>
</div>
<div class="section" id="modulenotfounderror">
<h2>ModuleNotFoundError<a class="headerlink" href="#modulenotfounderror" title="Permalink to this headline">¶</a></h2>
<div class="highlight-none notranslate"><div class="highlight"><pre><span></span>Traceback (most recent call last):
  File &quot;TESTS:\runtime\test_module_not_found_error.py&quot;, line 6, in test_module_not_found_error
    import Tkinter
ModuleNotFoundError: No module named &#39;Tkinter&#39;

    Did you mean `tkinter`?

A `ModuleNotFoundError` exception indicates that you
are trying to import a module that cannot be found by Python.
This could be because you misspelled the name of the module
or because it is not installed on your computer.

    The name of the module that could not be imported is `Tkinter`.
    `tkinter` is an existing module that has a similar name.

Exception raised on line 6 of file TESTS:\runtime\test_module_not_found_error.py.

   5:     try:
--&gt;6:         import Tkinter
   7:     except Exception as e:

    Known objects shown above:
        Exception: &lt;class &#39;Exception&#39;&gt;
        e: ModuleNotFoundError(&quot;No module named &#39;Tkinter&#39;&quot;)
</pre></div>
</div>
</div>
<div class="section" id="nameerror-1">
<h2>NameError - 1<a class="headerlink" href="#nameerror-1" title="Permalink to this headline">¶</a></h2>
<div class="highlight-none notranslate"><div class="highlight"><pre><span></span>Traceback (most recent call last):
  File &quot;TESTS:\runtime\test_name_error.py&quot;, line 6, in test_name_error
    this = something
NameError: name &#39;something&#39; is not defined

A `NameError` exception indicates that a variable or
function name is not known to Python.
Most often, this is because there is a spelling mistake.
However, sometimes it is because the name is used
before being defined or given a value.

    In your program, `something` is an unknown name.
    I have no additional information for you.
Exception raised on line 6 of file TESTS:\runtime\test_name_error.py.

   5:     try:
--&gt;6:         this = something
   7:     except Exception as e:

    Known objects shown above:
        Exception: &lt;class &#39;Exception&#39;&gt;
        e: NameError(&quot;name &#39;something&#39; is not defined&quot;)
</pre></div>
</div>
</div>
<div class="section" id="nameerror-2">
<h2>NameError - 2<a class="headerlink" href="#nameerror-2" title="Permalink to this headline">¶</a></h2>
<div class="highlight-none notranslate"><div class="highlight"><pre><span></span>Traceback (most recent call last):
  File &quot;TESTS:\runtime\test_name_error.py&quot;, line 20, in test_name_error2
    x = babs(-1)
NameError: name &#39;babs&#39; is not defined

    Did you mean `abs`?
A `NameError` exception indicates that a variable or
function name is not known to Python.
Most often, this is because there is a spelling mistake.
However, sometimes it is because the name is used
before being defined or given a value.

    In your program, `babs` is an unknown name.
    Instead of writing `babs`, perhaps you meant one of the following:
    *   Local scope: `nabs`
    *   Global scope: `fabs`
    *   Python builtins: `abs`

Exception raised on line 20 of file TESTS:\runtime\test_name_error.py.

   19:     try:
--&gt;20:         x = babs(-1)
   21:     except Exception as e:

    Known objects shown above:
        Exception: &lt;class &#39;Exception&#39;&gt;
        e: NameError(&quot;name &#39;babs&#39; is not defined&quot;)
</pre></div>
</div>
</div>
<div class="section" id="nameerror-3">
<h2>NameError - 3<a class="headerlink" href="#nameerror-3" title="Permalink to this headline">¶</a></h2>
<div class="highlight-none notranslate"><div class="highlight"><pre><span></span>Traceback (most recent call last):
  File &quot;TESTS:\runtime\test_name_error.py&quot;, line 35, in test_name_error3
    y = x
NameError: name &#39;x&#39; is not defined

    Did you use a colon instead of an equal sign?
A `NameError` exception indicates that a variable or
function name is not known to Python.
Most often, this is because there is a spelling mistake.
However, sometimes it is because the name is used
before being defined or given a value.

    In your program, `x` is an unknown name.
    A type hint found for `x` in the global scope.
    Perhaps you had used a colon instead of an equal sign and written

        x : 3

    instead of

        x = 3

Exception raised on line 35 of file TESTS:\runtime\test_name_error.py.

   34:     try:
--&gt;35:         y = x
   36:     except Exception as e:

    Known objects shown above:
        Exception: &lt;class &#39;Exception&#39;&gt;
        e: NameError(&quot;name &#39;x&#39; is not defined&quot;)
</pre></div>
</div>
</div>
<div class="section" id="nameerror-4">
<h2>NameError - 4<a class="headerlink" href="#nameerror-4" title="Permalink to this headline">¶</a></h2>
<div class="highlight-none notranslate"><div class="highlight"><pre><span></span>Traceback (most recent call last):
  File &quot;TESTS:\runtime\test_name_error.py&quot;, line 48, in test_name_error4
    cost  # wrote from math import * above
NameError: name &#39;cost&#39; is not defined

    Did you mean `cos`?
A `NameError` exception indicates that a variable or
function name is not known to Python.
Most often, this is because there is a spelling mistake.
However, sometimes it is because the name is used
before being defined or given a value.

    In your program, `cost` is an unknown name.
    Instead of writing `cost`, perhaps you meant one of the following:
    *   Global scope: `cos`, `cosh`, `acos`

Exception raised on line 48 of file TESTS:\runtime\test_name_error.py.

   47:     try:
--&gt;48:         cost  # wrote from math import * above
   49:     except Exception as e:

    Known objects shown above:
        Exception: &lt;class &#39;Exception&#39;&gt;
        e: NameError(&quot;name &#39;cost&#39; is not defined&quot;)
</pre></div>
</div>
</div>
<div class="section" id="overflowerror">
<h2>OverflowError<a class="headerlink" href="#overflowerror" title="Permalink to this headline">¶</a></h2>
<div class="highlight-none notranslate"><div class="highlight"><pre><span></span>Traceback (most recent call last):
  File &quot;TESTS:\runtime\test_overflow_error.py&quot;, line 6, in test_overflow_error
    2.0 ** 1600
OverflowError: (34, &#39;Result too large&#39;)

An `OverflowError` is raised when the result of an arithmetic operation
is too large to be handled by the computer&#39;s processor.

Exception raised on line 6 of file TESTS:\runtime\test_overflow_error.py.

   5:     try:
--&gt;6:         2.0 ** 1600
   7:     except Exception as e:

    Known objects shown above:
        Exception: &lt;class &#39;Exception&#39;&gt;
        e: OverflowError(34, &#39;Result too large&#39;)
</pre></div>
</div>
</div>
<div class="section" id="recursionerror">
<h2>RecursionError<a class="headerlink" href="#recursionerror" title="Permalink to this headline">¶</a></h2>
<div class="highlight-none notranslate"><div class="highlight"><pre><span></span>Traceback (most recent call last):
  File &quot;TESTS:\runtime\test_recursion_error.py&quot;, line 8, in test_function_recursion_error
    a()

       ... More lines not shown. ...

  File &quot;TESTS:\runtime\test_recursion_error.py&quot;, line 6, in a
    return a()
  File &quot;TESTS:\runtime\test_recursion_error.py&quot;, line 6, in a
    return a()
RecursionError: maximum recursion depth exceeded

A `RecursionError` is raised when a function calls itself,
directly or indirectly, too many times.
It almost always indicates that you made an error in your code
and that your program would never stop.

Execution stopped on line 8 of file TESTS:\runtime\test_recursion_error.py.

   7:     try:
--&gt;8:         a()
   9:     except Exception as e:

    Known objects shown above:
        a: &lt;function test_function_recursion_error.&lt;locals&gt;.a&gt;
        Exception: &lt;class &#39;Exception&#39;&gt;
        e: RecursionError(&#39;maximum recursion depth exceeded&#39;)

Exception raised on line 6 of file TESTS:\runtime\test_recursion_error.py.

   5:     def a():
--&gt;6:         return a()
   7:     try:

    Known objects shown above:
        a: &lt;function test_function_recursion_error.&lt;locals&gt;.a&gt;
</pre></div>
</div>
</div>
<div class="section" id="typeerror-1-concatenate-two-different-types">
<h2>TypeError - 1: concatenate two different types<a class="headerlink" href="#typeerror-1-concatenate-two-different-types" title="Permalink to this headline">¶</a></h2>
<div class="highlight-none notranslate"><div class="highlight"><pre><span></span>Traceback (most recent call last):
  File &quot;TESTS:\runtime\test_type_error.py&quot;, line 8, in test_type_error1
    result = a + one
TypeError: can only concatenate str (not &quot;int&quot;) to str

A `TypeError` is usually caused by trying
to combine two incompatible types of objects,
by calling a function with the wrong type of object,
or by tring to do an operation not allowed on a given type of object.

    You tried to concatenate (add) two different types of objects:
    a string (`str`) and an integer (`int`)

Exception raised on line 8 of file TESTS:\runtime\test_type_error.py.

   7:         one = 1
--&gt;8:         result = a + one
   9:     except Exception as e:

    Known objects shown above:
        one: 1
        a: &#39;a&#39;
        Exception: &lt;class &#39;Exception&#39;&gt;
        e: TypeError(&#39;can only concatenate str (not &quot;int&quot;) to str&#39;)
</pre></div>
</div>
</div>
<div class="section" id="typeerror-1a-concatenate-two-different-types">
<h2>TypeError - 1a: concatenate two different types<a class="headerlink" href="#typeerror-1a-concatenate-two-different-types" title="Permalink to this headline">¶</a></h2>
<div class="highlight-none notranslate"><div class="highlight"><pre><span></span>Traceback (most recent call last):
  File &quot;TESTS:\runtime\test_type_error.py&quot;, line 26, in test_type_error1a
    result = a + a_list
TypeError: can only concatenate str (not &quot;list&quot;) to str

A `TypeError` is usually caused by trying
to combine two incompatible types of objects,
by calling a function with the wrong type of object,
or by tring to do an operation not allowed on a given type of object.

    You tried to concatenate (add) two different types of objects:
    a string (`str`) and a `list`

Exception raised on line 26 of file TESTS:\runtime\test_type_error.py.

   25:         a_list = [1, 2, 3]
--&gt;26:         result = a + a_list
   27:     except Exception as e:

    Known objects shown above:
        a_list: [1, 2, 3]
        a: &#39;a&#39;
        Exception: &lt;class &#39;Exception&#39;&gt;
        e: TypeError(&#39;can only concatenate str (not &quot;list&quot;) to str&#39;)
</pre></div>
</div>
</div>
<div class="section" id="typeerror-1b-concatenate-two-different-types">
<h2>TypeError - 1b: concatenate two different types<a class="headerlink" href="#typeerror-1b-concatenate-two-different-types" title="Permalink to this headline">¶</a></h2>
<div class="highlight-none notranslate"><div class="highlight"><pre><span></span>Traceback (most recent call last):
  File &quot;TESTS:\runtime\test_type_error.py&quot;, line 44, in test_type_error1b
    result = a_tuple + a_list
TypeError: can only concatenate tuple (not &quot;list&quot;) to tuple

A `TypeError` is usually caused by trying
to combine two incompatible types of objects,
by calling a function with the wrong type of object,
or by tring to do an operation not allowed on a given type of object.

    You tried to concatenate (add) two different types of objects:
    a `tuple` and a `list`

Exception raised on line 44 of file TESTS:\runtime\test_type_error.py.

   43:         a_list = [1, 2, 3]
--&gt;44:         result = a_tuple + a_list
   45:     except Exception as e:

    Known objects shown above:
        a_list: [1, 2, 3]
        a_tuple: (1, 2, 3)
        Exception: &lt;class &#39;Exception&#39;&gt;
        e: TypeError(&#39;can only concatenate tuple (not &quot;list&quot;) to tuple&#39;)
</pre></div>
</div>
</div>
<div class="section" id="typeerror-2-unsupported-operand-type-s-for">
<h2>TypeError - 2: unsupported operand type(s) for +<a class="headerlink" href="#typeerror-2-unsupported-operand-type-s-for" title="Permalink to this headline">¶</a></h2>
<div class="highlight-none notranslate"><div class="highlight"><pre><span></span>Traceback (most recent call last):
  File &quot;TESTS:\runtime\test_type_error.py&quot;, line 60, in test_type_error2
    result = one + none
TypeError: unsupported operand type(s) for +: &#39;int&#39; and &#39;NoneType&#39;

A `TypeError` is usually caused by trying
to combine two incompatible types of objects,
by calling a function with the wrong type of object,
or by tring to do an operation not allowed on a given type of object.

    You tried to add two incompatible types of objects:
    an integer (`int`) and a variable equal to `None` (`NoneType`)

Exception raised on line 60 of file TESTS:\runtime\test_type_error.py.

   59:         none = None
--&gt;60:         result = one + none
   61:     except Exception as e:

    Known objects shown above:
        none: None
        one: 1
        Exception: &lt;class &#39;Exception&#39;&gt;
        e: TypeError(&quot;unsupported operand type(s) for +: &#39;int&#39; and &#39;Non...)
</pre></div>
</div>
</div>
<div class="section" id="typeerror-2a-unsupported-operand-type-s-for">
<h2>TypeError - 2a: unsupported operand type(s) for +=<a class="headerlink" href="#typeerror-2a-unsupported-operand-type-s-for" title="Permalink to this headline">¶</a></h2>
<div class="highlight-none notranslate"><div class="highlight"><pre><span></span>Traceback (most recent call last):
  File &quot;TESTS:\runtime\test_type_error.py&quot;, line 78, in test_type_error2a
    one += two
TypeError: unsupported operand type(s) for +=: &#39;int&#39; and &#39;str&#39;

A `TypeError` is usually caused by trying
to combine two incompatible types of objects,
by calling a function with the wrong type of object,
or by tring to do an operation not allowed on a given type of object.

    You tried to add two incompatible types of objects:
    an integer (`int`) and a string (`str`)

Exception raised on line 78 of file TESTS:\runtime\test_type_error.py.

   77:         two = &quot;two&quot;
--&gt;78:         one += two
   79:     except Exception as e:

    Known objects shown above:
        two: &#39;two&#39;
        one: 1
        Exception: &lt;class &#39;Exception&#39;&gt;
        e: TypeError(&quot;unsupported operand type(s) for +=: &#39;int&#39; and &#39;str&#39;&quot;)
</pre></div>
</div>
</div>
<div class="section" id="typeerror-3-unsupported-operand-type-s-for">
<h2>TypeError - 3: unsupported operand type(s) for -<a class="headerlink" href="#typeerror-3-unsupported-operand-type-s-for" title="Permalink to this headline">¶</a></h2>
<div class="highlight-none notranslate"><div class="highlight"><pre><span></span>Traceback (most recent call last):
  File &quot;TESTS:\runtime\test_type_error.py&quot;, line 94, in test_type_error3
    result = a - b
TypeError: unsupported operand type(s) for -: &#39;tuple&#39; and &#39;list&#39;

A `TypeError` is usually caused by trying
to combine two incompatible types of objects,
by calling a function with the wrong type of object,
or by tring to do an operation not allowed on a given type of object.

    You tried to subtract two incompatible types of objects:
    a `tuple` and a `list`

Exception raised on line 94 of file TESTS:\runtime\test_type_error.py.

   93:         b = [3, 4]
--&gt;94:         result = a - b
   95:     except Exception as e:

    Known objects shown above:
        b: [3, 4]
        a: (1, 2)
        Exception: &lt;class &#39;Exception&#39;&gt;
        e: TypeError(&quot;unsupported operand type(s) for -: &#39;tuple&#39; and &#39;l...)
</pre></div>
</div>
</div>
<div class="section" id="typeerror-3a-unsupported-operand-type-s-for">
<h2>TypeError - 3a: unsupported operand type(s) for -=<a class="headerlink" href="#typeerror-3a-unsupported-operand-type-s-for" title="Permalink to this headline">¶</a></h2>
<div class="highlight-none notranslate"><div class="highlight"><pre><span></span>Traceback (most recent call last):
  File &quot;TESTS:\runtime\test_type_error.py&quot;, line 110, in test_type_error3a
    b -= a
TypeError: unsupported operand type(s) for -=: &#39;list&#39; and &#39;tuple&#39;

A `TypeError` is usually caused by trying
to combine two incompatible types of objects,
by calling a function with the wrong type of object,
or by tring to do an operation not allowed on a given type of object.

    You tried to subtract two incompatible types of objects:
    a `list` and a `tuple`

Exception raised on line 110 of file TESTS:\runtime\test_type_error.py.

   109:         b = [3, 4]
--&gt;110:         b -= a
   111:     except Exception as e:

    Known objects shown above:
        b: [3, 4]
        a: (1, 2)
        Exception: &lt;class &#39;Exception&#39;&gt;
        e: TypeError(&quot;unsupported operand type(s) for -=: &#39;list&#39; and &#39;t...)
</pre></div>
</div>
</div>
<div class="section" id="typeerror-4-unsupported-operand-type-s-for">
<h2>TypeError - 4: unsupported operand type(s) for *<a class="headerlink" href="#typeerror-4-unsupported-operand-type-s-for" title="Permalink to this headline">¶</a></h2>
<div class="highlight-none notranslate"><div class="highlight"><pre><span></span>Traceback (most recent call last):
  File &quot;TESTS:\runtime\test_type_error.py&quot;, line 126, in test_type_error4
    result = a * b
TypeError: unsupported operand type(s) for *: &#39;complex&#39; and &#39;set&#39;

A `TypeError` is usually caused by trying
to combine two incompatible types of objects,
by calling a function with the wrong type of object,
or by tring to do an operation not allowed on a given type of object.

    You tried to multiply two incompatible types of objects:
    a complex number and a `set`

Exception raised on line 126 of file TESTS:\runtime\test_type_error.py.

   125:         b = {2, 3}
--&gt;126:         result = a * b
   127:     except Exception as e:

    Known objects shown above:
        b: {2, 3}
        a: 1j
        Exception: &lt;class &#39;Exception&#39;&gt;
        e: TypeError(&quot;unsupported operand type(s) for *: &#39;complex&#39; and ...)
</pre></div>
</div>
</div>
<div class="section" id="typeerror-4a-unsupported-operand-type-s-for">
<h2>TypeError - 4a: unsupported operand type(s) for <code class="docutils literal notranslate"><span class="pre">*=</span></code><a class="headerlink" href="#typeerror-4a-unsupported-operand-type-s-for" title="Permalink to this headline">¶</a></h2>
<div class="highlight-none notranslate"><div class="highlight"><pre><span></span>Traceback (most recent call last):
  File &quot;TESTS:\runtime\test_type_error.py&quot;, line 142, in test_type_error4a
    b *= a
TypeError: unsupported operand type(s) for *=: &#39;set&#39; and &#39;complex&#39;

A `TypeError` is usually caused by trying
to combine two incompatible types of objects,
by calling a function with the wrong type of object,
or by tring to do an operation not allowed on a given type of object.

    You tried to multiply two incompatible types of objects:
    a `set` and a complex number

Exception raised on line 142 of file TESTS:\runtime\test_type_error.py.

   141:         b = {2, 3}
--&gt;142:         b *= a
   143:     except Exception as e:

    Known objects shown above:
        b: {2, 3}
        a: 1j
        Exception: &lt;class &#39;Exception&#39;&gt;
        e: TypeError(&quot;unsupported operand type(s) for *=: &#39;set&#39; and &#39;co...)
</pre></div>
</div>
</div>
<div class="section" id="typeerror-5-unsupported-operand-type-s-for">
<h2>TypeError - 5: unsupported operand type(s) for /<a class="headerlink" href="#typeerror-5-unsupported-operand-type-s-for" title="Permalink to this headline">¶</a></h2>
<div class="highlight-none notranslate"><div class="highlight"><pre><span></span>Traceback (most recent call last):
  File &quot;TESTS:\runtime\test_type_error.py&quot;, line 158, in test_type_error5
    result = a / b
TypeError: unsupported operand type(s) for /: &#39;dict&#39; and &#39;float&#39;

A `TypeError` is usually caused by trying
to combine two incompatible types of objects,
by calling a function with the wrong type of object,
or by tring to do an operation not allowed on a given type of object.

    You tried to divide two incompatible types of objects:
    a dictionary (`dict`) and a number (`float`)

Exception raised on line 158 of file TESTS:\runtime\test_type_error.py.

   157:         b = 3.1416
--&gt;158:         result = a / b
   159:     except Exception as e:

    Known objects shown above:
        b: 3.1416
        a: {1: 1, 2: 2}
        Exception: &lt;class &#39;Exception&#39;&gt;
        e: TypeError(&quot;unsupported operand type(s) for /: &#39;dict&#39; and &#39;fl...)
</pre></div>
</div>
</div>
<div class="section" id="typeerror-5a-unsupported-operand-type-s-for">
<h2>TypeError - 5a: unsupported operand type(s) for /=<a class="headerlink" href="#typeerror-5a-unsupported-operand-type-s-for" title="Permalink to this headline">¶</a></h2>
<div class="highlight-none notranslate"><div class="highlight"><pre><span></span>Traceback (most recent call last):
  File &quot;TESTS:\runtime\test_type_error.py&quot;, line 174, in test_type_error5a
    b /= a
TypeError: unsupported operand type(s) for /=: &#39;float&#39; and &#39;dict&#39;

A `TypeError` is usually caused by trying
to combine two incompatible types of objects,
by calling a function with the wrong type of object,
or by tring to do an operation not allowed on a given type of object.

    You tried to divide two incompatible types of objects:
    a number (`float`) and a dictionary (`dict`)

Exception raised on line 174 of file TESTS:\runtime\test_type_error.py.

   173:         b = 3.1416
--&gt;174:         b /= a
   175:     except Exception as e:

    Known objects shown above:
        b: 3.1416
        a: {1: 1, 2: 2}
        Exception: &lt;class &#39;Exception&#39;&gt;
        e: TypeError(&quot;unsupported operand type(s) for /=: &#39;float&#39; and &#39;...)
</pre></div>
</div>
</div>
<div class="section" id="typeerror-5b-unsupported-operand-type-s-for">
<h2>TypeError - 5b: unsupported operand type(s) for //<a class="headerlink" href="#typeerror-5b-unsupported-operand-type-s-for" title="Permalink to this headline">¶</a></h2>
<div class="highlight-none notranslate"><div class="highlight"><pre><span></span>Traceback (most recent call last):
  File &quot;TESTS:\runtime\test_type_error.py&quot;, line 190, in test_type_error5b
    result = a // b
TypeError: unsupported operand type(s) for //: &#39;dict&#39; and &#39;int&#39;

A `TypeError` is usually caused by trying
to combine two incompatible types of objects,
by calling a function with the wrong type of object,
or by tring to do an operation not allowed on a given type of object.

    You tried to divide two incompatible types of objects:
    a dictionary (`dict`) and an integer (`int`)

Exception raised on line 190 of file TESTS:\runtime\test_type_error.py.

   189:         b = 1
--&gt;190:         result = a // b
   191:     except Exception as e:

    Known objects shown above:
        b: 1
        a: {1: 1, 2: 2}
        Exception: &lt;class &#39;Exception&#39;&gt;
        e: TypeError(&quot;unsupported operand type(s) for //: &#39;dict&#39; and &#39;int&#39;&quot;)
</pre></div>
</div>
</div>
<div class="section" id="typeerror-5c-unsupported-operand-type-s-for">
<h2>TypeError - 5c: unsupported operand type(s) for //=<a class="headerlink" href="#typeerror-5c-unsupported-operand-type-s-for" title="Permalink to this headline">¶</a></h2>
<div class="highlight-none notranslate"><div class="highlight"><pre><span></span>Traceback (most recent call last):
  File &quot;TESTS:\runtime\test_type_error.py&quot;, line 206, in test_type_error5c
    b //= a
TypeError: unsupported operand type(s) for //=: &#39;float&#39; and &#39;dict&#39;

A `TypeError` is usually caused by trying
to combine two incompatible types of objects,
by calling a function with the wrong type of object,
or by tring to do an operation not allowed on a given type of object.

    You tried to divide two incompatible types of objects:
    a number (`float`) and a dictionary (`dict`)

Exception raised on line 206 of file TESTS:\runtime\test_type_error.py.

   205:         b = 3.1416
--&gt;206:         b //= a
   207:     except Exception as e:

    Known objects shown above:
        b: 3.1416
        a: {1: 1, 2: 2}
        Exception: &lt;class &#39;Exception&#39;&gt;
        e: TypeError(&quot;unsupported operand type(s) for //=: &#39;float&#39; and ...)
</pre></div>
</div>
</div>
<div class="section" id="typeerror-6-unsupported-operand-type-s-for">
<h2>TypeError - 6: unsupported operand type(s) for &amp;<a class="headerlink" href="#typeerror-6-unsupported-operand-type-s-for" title="Permalink to this headline">¶</a></h2>
<div class="highlight-none notranslate"><div class="highlight"><pre><span></span>Traceback (most recent call last):
  File &quot;TESTS:\runtime\test_type_error.py&quot;, line 222, in test_type_error6
    result = a &amp; b
TypeError: unsupported operand type(s) for &amp;: &#39;str&#39; and &#39;int&#39;

A `TypeError` is usually caused by trying
to combine two incompatible types of objects,
by calling a function with the wrong type of object,
or by tring to do an operation not allowed on a given type of object.

    You tried to perform the bitwise operation &amp;
    on two incompatible types of objects:
    a string (`str`) and an integer (`int`)

Exception raised on line 222 of file TESTS:\runtime\test_type_error.py.

   221:         b = 2
--&gt;222:         result = a &amp; b
   223:     except Exception as e:

    Known objects shown above:
        b: 2
        a: &#39;a&#39;
        Exception: &lt;class &#39;Exception&#39;&gt;
        e: TypeError(&quot;unsupported operand type(s) for &amp;: &#39;str&#39; and &#39;int&#39;&quot;)
</pre></div>
</div>
</div>
<div class="section" id="typeerror-6a-unsupported-operand-type-s-for">
<h2>TypeError - 6a: unsupported operand type(s) for &amp;=<a class="headerlink" href="#typeerror-6a-unsupported-operand-type-s-for" title="Permalink to this headline">¶</a></h2>
<div class="highlight-none notranslate"><div class="highlight"><pre><span></span>Traceback (most recent call last):
  File &quot;TESTS:\runtime\test_type_error.py&quot;, line 238, in test_type_error6a
    b &amp;= a
TypeError: unsupported operand type(s) for &amp;=: &#39;int&#39; and &#39;str&#39;

A `TypeError` is usually caused by trying
to combine two incompatible types of objects,
by calling a function with the wrong type of object,
or by tring to do an operation not allowed on a given type of object.

    You tried to perform the bitwise operation &amp;=
    on two incompatible types of objects:
    an integer (`int`) and a string (`str`)

Exception raised on line 238 of file TESTS:\runtime\test_type_error.py.

   237:         b = 2
--&gt;238:         b &amp;= a
   239:     except Exception as e:

    Known objects shown above:
        b: 2
        a: &#39;a&#39;
        Exception: &lt;class &#39;Exception&#39;&gt;
        e: TypeError(&quot;unsupported operand type(s) for &amp;=: &#39;int&#39; and &#39;str&#39;&quot;)
</pre></div>
</div>
</div>
<div class="section" id="typeerror-7-unsupported-operand-type-s-for">
<h2>TypeError - 7: unsupported operand type(s) for **<a class="headerlink" href="#typeerror-7-unsupported-operand-type-s-for" title="Permalink to this headline">¶</a></h2>
<div class="highlight-none notranslate"><div class="highlight"><pre><span></span>Traceback (most recent call last):
  File &quot;TESTS:\runtime\test_type_error.py&quot;, line 254, in test_type_error7
    result = a ** b
TypeError: unsupported operand type(s) for ** or pow(): &#39;dict&#39; and &#39;float&#39;

A `TypeError` is usually caused by trying
to combine two incompatible types of objects,
by calling a function with the wrong type of object,
or by tring to do an operation not allowed on a given type of object.

    You tried to exponentiate (raise to a power)
    using two incompatible types of objects:
    a dictionary (`dict`) and a number (`float`)

Exception raised on line 254 of file TESTS:\runtime\test_type_error.py.

   253:         b = 3.1416
--&gt;254:         result = a ** b
   255:     except Exception as e:

    Known objects shown above:
        b: 3.1416
        a: {1: 1, 2: 2}
        Exception: &lt;class &#39;Exception&#39;&gt;
        e: TypeError(&quot;unsupported operand type(s) for ** or pow(): &#39;dic...)
</pre></div>
</div>
</div>
<div class="section" id="typeerror-7a-unsupported-operand-type-s-for">
<h2>TypeError - 7a: unsupported operand type(s) for <code class="docutils literal notranslate"><span class="pre">**=</span></code><a class="headerlink" href="#typeerror-7a-unsupported-operand-type-s-for" title="Permalink to this headline">¶</a></h2>
<div class="highlight-none notranslate"><div class="highlight"><pre><span></span>Traceback (most recent call last):
  File &quot;TESTS:\runtime\test_type_error.py&quot;, line 270, in test_type_error7a
    a **= b
TypeError: unsupported operand type(s) for ** or pow(): &#39;dict&#39; and &#39;float&#39;

A `TypeError` is usually caused by trying
to combine two incompatible types of objects,
by calling a function with the wrong type of object,
or by tring to do an operation not allowed on a given type of object.

    You tried to exponentiate (raise to a power)
    using two incompatible types of objects:
    a dictionary (`dict`) and a number (`float`)

Exception raised on line 270 of file TESTS:\runtime\test_type_error.py.

   269:         b = 3.1416
--&gt;270:         a **= b
   271:     except Exception as e:

    Known objects shown above:
        b: 3.1416
        a: {1: 1, 2: 2}
        Exception: &lt;class &#39;Exception&#39;&gt;
        e: TypeError(&quot;unsupported operand type(s) for ** or pow(): &#39;dic...)
</pre></div>
</div>
</div>
<div class="section" id="typeerror-8-unsupported-operand-type-s-for">
<h2>TypeError - 8: unsupported operand type(s) for &gt;&gt;<a class="headerlink" href="#typeerror-8-unsupported-operand-type-s-for" title="Permalink to this headline">¶</a></h2>
<div class="highlight-none notranslate"><div class="highlight"><pre><span></span>Traceback (most recent call last):
  File &quot;TESTS:\runtime\test_type_error.py&quot;, line 286, in test_type_error8
    result = a &gt;&gt; b
TypeError: unsupported operand type(s) for &gt;&gt;: &#39;str&#39; and &#39;int&#39;

A `TypeError` is usually caused by trying
to combine two incompatible types of objects,
by calling a function with the wrong type of object,
or by tring to do an operation not allowed on a given type of object.

    You tried to perform the bit shifting operation &gt;&gt;
    on two incompatible types of objects:
    a string (`str`) and an integer (`int`)

Exception raised on line 286 of file TESTS:\runtime\test_type_error.py.

   285:         b = 42
--&gt;286:         result = a &gt;&gt; b
   287:     except Exception as e:

    Known objects shown above:
        b: 42
        a: &#39;a&#39;
        Exception: &lt;class &#39;Exception&#39;&gt;
        e: TypeError(&quot;unsupported operand type(s) for &gt;&gt;: &#39;str&#39; and &#39;int&#39;&quot;)
</pre></div>
</div>
</div>
<div class="section" id="typeerror-8a-unsupported-operand-type-s-for">
<h2>TypeError - 8a: unsupported operand type(s) for &gt;&gt;=<a class="headerlink" href="#typeerror-8a-unsupported-operand-type-s-for" title="Permalink to this headline">¶</a></h2>
<div class="highlight-none notranslate"><div class="highlight"><pre><span></span>Traceback (most recent call last):
  File &quot;TESTS:\runtime\test_type_error.py&quot;, line 302, in test_type_error8a
    a &gt;&gt;= b
TypeError: unsupported operand type(s) for &gt;&gt;=: &#39;str&#39; and &#39;int&#39;

A `TypeError` is usually caused by trying
to combine two incompatible types of objects,
by calling a function with the wrong type of object,
or by tring to do an operation not allowed on a given type of object.

    You tried to perform the bit shifting operation &gt;&gt;=
    on two incompatible types of objects:
    a string (`str`) and an integer (`int`)

Exception raised on line 302 of file TESTS:\runtime\test_type_error.py.

   301:         b = 42
--&gt;302:         a &gt;&gt;= b
   303:     except Exception as e:

    Known objects shown above:
        b: 42
        a: &#39;a&#39;
        Exception: &lt;class &#39;Exception&#39;&gt;
        e: TypeError(&quot;unsupported operand type(s) for &gt;&gt;=: &#39;str&#39; and &#39;int&#39;&quot;)
</pre></div>
</div>
</div>
<div class="section" id="typeerror-9-unsupported-operand-type-s-for">
<h2>TypeError - 9: unsupported operand type(s) for &#64;<a class="headerlink" href="#typeerror-9-unsupported-operand-type-s-for" title="Permalink to this headline">¶</a></h2>
<div class="highlight-none notranslate"><div class="highlight"><pre><span></span>Traceback (most recent call last):
  File &quot;TESTS:\runtime\test_type_error.py&quot;, line 318, in test_type_error9
    result = a @ b
TypeError: unsupported operand type(s) for @: &#39;str&#39; and &#39;int&#39;

A `TypeError` is usually caused by trying
to combine two incompatible types of objects,
by calling a function with the wrong type of object,
or by tring to do an operation not allowed on a given type of object.

    You tried to use the operator @
    using two incompatible types of objects:
    a string (`str`) and an integer (`int`).
    This operator is normally used only
    for multiplication of matrices.

Exception raised on line 318 of file TESTS:\runtime\test_type_error.py.

   317:         b = 2
--&gt;318:         result = a @ b
   319:     except Exception as e:

    Known objects shown above:
        b: 2
        a: &#39;a&#39;
        Exception: &lt;class &#39;Exception&#39;&gt;
        e: TypeError(&quot;unsupported operand type(s) for @: &#39;str&#39; and &#39;int&#39;&quot;)
</pre></div>
</div>
</div>
<div class="section" id="typeerror-9a-unsupported-operand-type-s-for">
<h2>TypeError - 9a: unsupported operand type(s) for &#64;=<a class="headerlink" href="#typeerror-9a-unsupported-operand-type-s-for" title="Permalink to this headline">¶</a></h2>
<div class="highlight-none notranslate"><div class="highlight"><pre><span></span>Traceback (most recent call last):
  File &quot;TESTS:\runtime\test_type_error.py&quot;, line 334, in test_type_error9a
    a @= b
TypeError: unsupported operand type(s) for @=: &#39;str&#39; and &#39;int&#39;

A `TypeError` is usually caused by trying
to combine two incompatible types of objects,
by calling a function with the wrong type of object,
or by tring to do an operation not allowed on a given type of object.

    You tried to use the operator @=
    using two incompatible types of objects:
    a string (`str`) and an integer (`int`).
    This operator is normally used only
    for multiplication of matrices.

Exception raised on line 334 of file TESTS:\runtime\test_type_error.py.

   333:         b = 2
--&gt;334:         a @= b
   335:     except Exception as e:

    Known objects shown above:
        b: 2
        a: &#39;a&#39;
        Exception: &lt;class &#39;Exception&#39;&gt;
        e: TypeError(&quot;unsupported operand type(s) for @=: &#39;str&#39; and &#39;int&#39;&quot;)
</pre></div>
</div>
</div>
<div class="section" id="typeerror-10-comparison-between-incompatible-types">
<h2>TypeError - 10: comparison between incompatible types<a class="headerlink" href="#typeerror-10-comparison-between-incompatible-types" title="Permalink to this headline">¶</a></h2>
<div class="highlight-none notranslate"><div class="highlight"><pre><span></span>Traceback (most recent call last):
  File &quot;TESTS:\runtime\test_type_error.py&quot;, line 350, in test_type_error10
    b &lt; a
TypeError: &#39;&lt;&#39; not supported between instances of &#39;int&#39; and &#39;str&#39;

A `TypeError` is usually caused by trying
to combine two incompatible types of objects,
by calling a function with the wrong type of object,
or by tring to do an operation not allowed on a given type of object.

    You tried to do an order comparison (&lt;)
    between two incompatible types of objects:
    an integer (`int`) and a string (`str`)

Exception raised on line 350 of file TESTS:\runtime\test_type_error.py.

   349:         b = 42
--&gt;350:         b &lt; a
   351:     except Exception as e:

    Known objects shown above:
        b: 42
        a: &#39;a&#39;
        Exception: &lt;class &#39;Exception&#39;&gt;
        e: TypeError(&quot;&#39;&lt;&#39; not supported between instances of &#39;int&#39; and ...)
</pre></div>
</div>
</div>
<div class="section" id="typeerror-11-bad-operand-type-for-unary">
<h2>TypeError - 11: bad operand type for unary +<a class="headerlink" href="#typeerror-11-bad-operand-type-for-unary" title="Permalink to this headline">¶</a></h2>
<div class="highlight-none notranslate"><div class="highlight"><pre><span></span>Traceback (most recent call last):
  File &quot;TESTS:\runtime\test_type_error.py&quot;, line 364, in test_type_error11
    a = +&quot;abc&quot;
TypeError: bad operand type for unary +: &#39;str&#39;

A `TypeError` is usually caused by trying
to combine two incompatible types of objects,
by calling a function with the wrong type of object,
or by tring to do an operation not allowed on a given type of object.

    You tried to use the unary operator &#39;+&#39;
    with the following type of object: a string (`str`).
    This operation is not defined for this type of object.

Exception raised on line 364 of file TESTS:\runtime\test_type_error.py.

   363:     try:
--&gt;364:         a = +&quot;abc&quot;
   365:         print(a)

    Known objects shown above:
        print: &lt;builtin function print&gt;
</pre></div>
</div>
</div>
<div class="section" id="typeerror-11a-bad-operand-type-for-unary">
<h2>TypeError - 11a: bad operand type for unary -<a class="headerlink" href="#typeerror-11a-bad-operand-type-for-unary" title="Permalink to this headline">¶</a></h2>
<div class="highlight-none notranslate"><div class="highlight"><pre><span></span>Traceback (most recent call last):
  File &quot;TESTS:\runtime\test_type_error.py&quot;, line 379, in test_type_error11a
    a = -[1, 2, 3]
TypeError: bad operand type for unary -: &#39;list&#39;

A `TypeError` is usually caused by trying
to combine two incompatible types of objects,
by calling a function with the wrong type of object,
or by tring to do an operation not allowed on a given type of object.

    You tried to use the unary operator &#39;-&#39;
    with the following type of object: a `list`.
    This operation is not defined for this type of object.

Exception raised on line 379 of file TESTS:\runtime\test_type_error.py.

   378:     try:
--&gt;379:         a = -[1, 2, 3]
   380:         print(a)

    Known objects shown above:
        print: &lt;builtin function print&gt;
</pre></div>
</div>
</div>
<div class="section" id="typeerror-11b-bad-operand-type-for-unary">
<h2>TypeError - 11b: bad operand type for unary ~<a class="headerlink" href="#typeerror-11b-bad-operand-type-for-unary" title="Permalink to this headline">¶</a></h2>
<div class="highlight-none notranslate"><div class="highlight"><pre><span></span>Traceback (most recent call last):
  File &quot;TESTS:\runtime\test_type_error.py&quot;, line 394, in test_type_error11b
    a = ~(1, 2, 3)
TypeError: bad operand type for unary ~: &#39;tuple&#39;

A `TypeError` is usually caused by trying
to combine two incompatible types of objects,
by calling a function with the wrong type of object,
or by tring to do an operation not allowed on a given type of object.

    You tried to use the unary operator &#39;~&#39;
    with the following type of object: a `tuple`.
    This operation is not defined for this type of object.

Exception raised on line 394 of file TESTS:\runtime\test_type_error.py.

   393:     try:
--&gt;394:         a = ~(1, 2, 3)
   395:         print(a)

    Known objects shown above:
        print: &lt;builtin function print&gt;
</pre></div>
</div>
</div>
<div class="section" id="typeerror-12-object-does-not-support-item-assignment">
<h2>TypeError - 12: object does not support item assignment<a class="headerlink" href="#typeerror-12-object-does-not-support-item-assignment" title="Permalink to this headline">¶</a></h2>
<div class="highlight-none notranslate"><div class="highlight"><pre><span></span>Traceback (most recent call last):
  File &quot;TESTS:\runtime\test_type_error.py&quot;, line 410, in test_type_error12
    a[0] = 0
TypeError: &#39;tuple&#39; object does not support item assignment

A `TypeError` is usually caused by trying
to combine two incompatible types of objects,
by calling a function with the wrong type of object,
or by tring to do an operation not allowed on a given type of object.

    In Python, some objects are known as immutable:
    once defined, their value cannot be changed.
    You tried change part of such an immutable object: a `tuple`,
    most likely by using an indexing operation.

Exception raised on line 410 of file TESTS:\runtime\test_type_error.py.

   409:     try:
--&gt;410:         a[0] = 0
   411:     except Exception as e:

    Known objects shown above:
        a: (1, 2, 3)
        Exception: &lt;class &#39;Exception&#39;&gt;
        e: TypeError(&quot;&#39;tuple&#39; object does not support item assignment&quot;)
</pre></div>
</div>
</div>
<div class="section" id="typeerror-13-wrong-number-of-positional-arguments">
<h2>TypeError - 13: wrong number of positional arguments<a class="headerlink" href="#typeerror-13-wrong-number-of-positional-arguments" title="Permalink to this headline">¶</a></h2>
<div class="highlight-none notranslate"><div class="highlight"><pre><span></span>Traceback (most recent call last):
  File &quot;TESTS:\runtime\test_type_error.py&quot;, line 427, in test_type_error13
    fn(1)
TypeError: test_type_error13.&lt;locals&gt;.fn() takes 0 positional arguments but 1 was given

    Perhaps you forgot `self` when defining `test_type_error13.&lt;locals&gt;.fn`.

A `TypeError` is usually caused by trying
to combine two incompatible types of objects,
by calling a function with the wrong type of object,
or by tring to do an operation not allowed on a given type of object.

    You apparently have called the function `test_type_error13.&lt;locals&gt;.fn` with
    1 positional argument(s) while it requires 0
    such positional argument(s).
    Perhaps you forgot `self` when defining `test_type_error13.&lt;locals&gt;.fn`.

Exception raised on line 427 of file TESTS:\runtime\test_type_error.py.

   426:     try:
--&gt;427:         fn(1)
   428:     except Exception as e:

    Known objects shown above:
        fn: &lt;function test_type_error13.&lt;locals&gt;.fn&gt;
        Exception: &lt;class &#39;Exception&#39;&gt;
        e: TypeError(&#39;test_type_error13.&lt;locals&gt;.fn() takes 0 positiona...)
</pre></div>
</div>
</div>
<div class="section" id="typeerror-13a-wrong-number-of-positional-arguments">
<h2>TypeError - 13a: wrong number of positional arguments<a class="headerlink" href="#typeerror-13a-wrong-number-of-positional-arguments" title="Permalink to this headline">¶</a></h2>
<div class="highlight-none notranslate"><div class="highlight"><pre><span></span>Traceback (most recent call last):
  File &quot;TESTS:\runtime\test_type_error.py&quot;, line 446, in test_type_error13a
    A().f(1)
TypeError: test_type_error13a.&lt;locals&gt;.A.f() takes 1 positional argument but 2 were given

    Perhaps you forgot `self` when defining `test_type_error13a.&lt;locals&gt;.A.f`.

A `TypeError` is usually caused by trying
to combine two incompatible types of objects,
by calling a function with the wrong type of object,
or by tring to do an operation not allowed on a given type of object.

    You apparently have called the function `test_type_error13a.&lt;locals&gt;.A.f` with
    2 positional argument(s) while it requires 1
    such positional argument(s).
    Perhaps you forgot `self` when defining `test_type_error13a.&lt;locals&gt;.A.f`.

Exception raised on line 446 of file TESTS:\runtime\test_type_error.py.

   445:     try:
--&gt;446:         A().f(1)
   447:     except Exception as e:

    Known objects shown above:
        A: &lt;class &#39;test_type_error.test_type_error13a.&lt;locals&gt;.A&#39;&gt;
        Exception: &lt;class &#39;Exception&#39;&gt;
        e: TypeError(&#39;test_type_error13a.&lt;locals&gt;.A.f() takes 1 positio...)
</pre></div>
</div>
</div>
<div class="section" id="typeerror-14-missing-positional-arguments">
<h2>TypeError - 14: missing positional arguments<a class="headerlink" href="#typeerror-14-missing-positional-arguments" title="Permalink to this headline">¶</a></h2>
<div class="highlight-none notranslate"><div class="highlight"><pre><span></span>Traceback (most recent call last):
  File &quot;TESTS:\runtime\test_type_error.py&quot;, line 465, in test_type_error14
    fn(1)
TypeError: test_type_error14.&lt;locals&gt;.fn() missing 2 required positional arguments: &#39;b&#39; and &#39;c&#39;

A `TypeError` is usually caused by trying
to combine two incompatible types of objects,
by calling a function with the wrong type of object,
or by tring to do an operation not allowed on a given type of object.

    You apparently have called the function &#39;test_type_error14.&lt;locals&gt;.fn()&#39; with
    fewer positional arguments than it requires (2 missing).

Exception raised on line 465 of file TESTS:\runtime\test_type_error.py.

   464:     try:
--&gt;465:         fn(1)
   466:     except Exception as e:

    Known objects shown above:
        fn: &lt;function test_type_error14.&lt;locals&gt;.fn&gt;
        Exception: &lt;class &#39;Exception&#39;&gt;
        e: TypeError(&quot;test_type_error14.&lt;locals&gt;.fn() missing 2 require...)
</pre></div>
</div>
</div>
<div class="section" id="typeerror-15-tuple-object-is-not-callable">
<h2>TypeError - 15: tuple object is not callable<a class="headerlink" href="#typeerror-15-tuple-object-is-not-callable" title="Permalink to this headline">¶</a></h2>
<div class="highlight-none notranslate"><div class="highlight"><pre><span></span>Traceback (most recent call last):
  File &quot;TESTS:\runtime\test_type_error.py&quot;, line 480, in test_type_error15
    _ = (1, 2)(3, 4)
TypeError: &#39;tuple&#39; object is not callable

    Perhaps you had a missing comma between two tuples.

A `TypeError` is usually caused by trying
to combine two incompatible types of objects,
by calling a function with the wrong type of object,
or by tring to do an operation not allowed on a given type of object.

    I suspect that you had an object of this type, a `tuple`,
    followed by what looked like a tuple, &#39;(...)&#39;,
    which Python took as an indication of a function call.
    Perhaps you had a missing comma between two tuples.

Exception raised on line 480 of file TESTS:\runtime\test_type_error.py.

   479:     try:
--&gt;480:         _ = (1, 2)(3, 4)
   481:     except Exception as e:

    Known objects shown above:
        Exception: &lt;class &#39;Exception&#39;&gt;
        e: TypeError(&quot;&#39;tuple&#39; object is not callable&quot;)
</pre></div>
</div>
</div>
<div class="section" id="typeerror-15a-list-object-is-not-callable">
<h2>TypeError - 15a: list object is not callable<a class="headerlink" href="#typeerror-15a-list-object-is-not-callable" title="Permalink to this headline">¶</a></h2>
<div class="highlight-none notranslate"><div class="highlight"><pre><span></span>Traceback (most recent call last):
  File &quot;TESTS:\runtime\test_type_error.py&quot;, line 494, in test_type_error15a
    _ = [1, 2](3, 4)
TypeError: &#39;list&#39; object is not callable

    Perhaps you had a missing comma before the tuple.

A `TypeError` is usually caused by trying
to combine two incompatible types of objects,
by calling a function with the wrong type of object,
or by tring to do an operation not allowed on a given type of object.

    I suspect that you had an object of this type, a `list`,
    followed by what looked like a tuple, &#39;(...)&#39;,
    which Python took as an indication of a function call.
    Perhaps you had a missing comma before the tuple.

Exception raised on line 494 of file TESTS:\runtime\test_type_error.py.

   493:     try:
--&gt;494:         _ = [1, 2](3, 4)
   495:     except Exception as e:

    Known objects shown above:
        Exception: &lt;class &#39;Exception&#39;&gt;
        e: TypeError(&quot;&#39;list&#39; object is not callable&quot;)
</pre></div>
</div>
</div>
<div class="section" id="typeerror-16-exception-derived-from-baseexception">
<h2>TypeError - 16: exception derived from BaseException<a class="headerlink" href="#typeerror-16-exception-derived-from-baseexception" title="Permalink to this headline">¶</a></h2>
<div class="highlight-none notranslate"><div class="highlight"><pre><span></span>Traceback (most recent call last):
  File &quot;TESTS:\runtime\test_type_error.py&quot;, line 507, in test_type_error16
    raise &quot;exception&quot;
TypeError: exceptions must derive from BaseException

A `TypeError` is usually caused by trying
to combine two incompatible types of objects,
by calling a function with the wrong type of object,
or by tring to do an operation not allowed on a given type of object.

    In Python 3, exceptions must be derived from BaseException.

Exception raised on line 507 of file TESTS:\runtime\test_type_error.py.

   506:     try:
--&gt;507:         raise &quot;exception&quot;
   508:     except Exception as e:

    Known objects shown above:
        Exception: &lt;class &#39;Exception&#39;&gt;
        e: TypeError(&#39;exceptions must derive from BaseException&#39;)
</pre></div>
</div>
</div>
<div class="section" id="unboundlocalerror-1-missing-global">
<h2>UnboundLocalError - 1: missing global<a class="headerlink" href="#unboundlocalerror-1-missing-global" title="Permalink to this headline">¶</a></h2>
<div class="highlight-none notranslate"><div class="highlight"><pre><span></span>Traceback (most recent call last):
  File &quot;TESTS:\runtime\test_unbound_local_error.py&quot;, line 27, in test_unbound_local_error_missing_global
    outer_missing_global()
  File &quot;TESTS:\runtime\test_unbound_local_error.py&quot;, line 11, in outer_missing_global
    inner()
  File &quot;TESTS:\runtime\test_unbound_local_error.py&quot;, line 9, in inner
    spam_missing_global += 1
UnboundLocalError: local variable &#39;spam_missing_global&#39; referenced before assignment

    Did you forget to add `global spam_missing_global`?

In Python, variables that are used inside a function are known as
local variables. Before they are used, they must be assigned a value.
A variable that is used before it is assigned a value is assumed to
be defined outside that function; it is known as a `global`
(or sometimes `nonlocal`) variable. You cannot assign a value to such
a global variable inside a function without first indicating to
Python that this is a global variable, otherwise you will see
an `UnboundLocalError`.

    The name `spam_missing_global` exists in the global scope.
    Perhaps the statement

        global spam_missing_global

    should have been included as the first line inside your function.

Execution stopped on line 27 of file TESTS:\runtime\test_unbound_local_error.py.

   26:     try:
--&gt;27:         outer_missing_global()
   28:     except Exception as e:

    Known objects shown above:
        global outer_missing_global: &lt;function outer_missing_global&gt;
        Exception: &lt;class &#39;Exception&#39;&gt;
        e: UnboundLocalError(&quot;local variable &#39;spam_missing_global&#39; refe...)

Exception raised on line 9 of file TESTS:\runtime\test_unbound_local_error.py.

    8:     def inner():
--&gt; 9:         spam_missing_global += 1
   10:

    Known objects shown above:
        global spam_missing_global: 1
</pre></div>
</div>
</div>
<div class="section" id="unboundlocalerror-2-missing-nonlocal">
<h2>UnboundLocalError - 2: missing nonlocal<a class="headerlink" href="#unboundlocalerror-2-missing-nonlocal" title="Permalink to this headline">¶</a></h2>
<div class="highlight-none notranslate"><div class="highlight"><pre><span></span>Traceback (most recent call last):
  File &quot;TESTS:\runtime\test_unbound_local_error.py&quot;, line 48, in test_unbound_local_error_missing_nonlocal
    outer_missing_nonlocal()
  File &quot;TESTS:\runtime\test_unbound_local_error.py&quot;, line 20, in outer_missing_nonlocal
    inner()
  File &quot;TESTS:\runtime\test_unbound_local_error.py&quot;, line 18, in inner
    spam_missing_nonlocal += 1
UnboundLocalError: local variable &#39;spam_missing_nonlocal&#39; referenced before assignment

    Did you forget to add `nonlocal spam_missing_nonlocal`?

In Python, variables that are used inside a function are known as
local variables. Before they are used, they must be assigned a value.
A variable that is used before it is assigned a value is assumed to
be defined outside that function; it is known as a `global`
(or sometimes `nonlocal`) variable. You cannot assign a value to such
a global variable inside a function without first indicating to
Python that this is a global variable, otherwise you will see
an `UnboundLocalError`.

    The name `spam_missing_nonlocal` exists in the nonlocal scope.
    Perhaps the statement

        nonlocal spam_missing_nonlocal

    should have been included as the first line inside your function.

Execution stopped on line 48 of file TESTS:\runtime\test_unbound_local_error.py.

   47:     try:
--&gt;48:         outer_missing_nonlocal()
   49:     except Exception as e:

    Known objects shown above:
        global outer_missing_nonlocal: &lt;function outer_missing_nonlocal&gt;
        Exception: &lt;class &#39;Exception&#39;&gt;
        e: UnboundLocalError(&quot;local variable &#39;spam_missing_nonlocal&#39; re...)

Exception raised on line 18 of file TESTS:\runtime\test_unbound_local_error.py.

   17:     def inner():
--&gt;18:         spam_missing_nonlocal += 1
   19:
</pre></div>
</div>
</div>
<div class="section" id="unknown-exception">
<h2>Unknown exception<a class="headerlink" href="#unknown-exception" title="Permalink to this headline">¶</a></h2>
<div class="highlight-none notranslate"><div class="highlight"><pre><span></span>Traceback (most recent call last):
  File &quot;TESTS:\runtime\test_unknown_error.py&quot;, line 10, in test_function_unknown_error
    raise MyException(&quot;Some informative message about an unknown exception.&quot;)
MyException: Some informative message about an unknown exception.

No information is available about this exception.

Exception raised on line 10 of file TESTS:\runtime\test_unknown_error.py.

    9:     try:
--&gt;10:         raise MyException(&quot;Some informative message about an unknown exception.&quot;)
   11:     except Exception as e:

    Known objects shown above:
        global MyException: &lt;class &#39;test_unknown_error.MyException&#39;&gt;
        Exception: &lt;class &#39;Exception&#39;&gt;
        e: MyException(&#39;Some informative message about an unknown excep...)
</pre></div>
</div>
</div>
<div class="section" id="zerodivisionerror-1">
<h2>ZeroDivisionError - 1<a class="headerlink" href="#zerodivisionerror-1" title="Permalink to this headline">¶</a></h2>
<div class="highlight-none notranslate"><div class="highlight"><pre><span></span>Traceback (most recent call last):
  File &quot;TESTS:\runtime\test_zero_division_error.py&quot;, line 6, in test_zero_division_error
    1 / 0
ZeroDivisionError: division by zero

A `ZeroDivisionError` occurs when you are attempting to divide
a value by zero:
    `result = my_variable / 0.`
It can also happen if you calculate the remainder of a division
using the modulo operator `%`:
    `result = my_variable % 0`

Exception raised on line 6 of file TESTS:\runtime\test_zero_division_error.py.

   5:     try:
--&gt;6:         1 / 0
   7:     except Exception as e:

    Known objects shown above:
        Exception: &lt;class &#39;Exception&#39;&gt;
        e: ZeroDivisionError(&#39;division by zero&#39;)
</pre></div>
</div>
</div>
<div class="section" id="zerodivisionerror-2">
<h2>ZeroDivisionError - 2<a class="headerlink" href="#zerodivisionerror-2" title="Permalink to this headline">¶</a></h2>
<div class="highlight-none notranslate"><div class="highlight"><pre><span></span>Traceback (most recent call last):
  File &quot;TESTS:\runtime\test_zero_division_error.py&quot;, line 21, in test_zero_division_error2
    1 % zero
ZeroDivisionError: integer division or modulo by zero

A `ZeroDivisionError` occurs when you are attempting to divide
a value by zero:
    `result = my_variable / 0.`
It can also happen if you calculate the remainder of a division
using the modulo operator `%`:
    `result = my_variable % 0`

Exception raised on line 21 of file TESTS:\runtime\test_zero_division_error.py.

   20:     try:
--&gt;21:         1 % zero
   22:     except Exception as e:

    Known objects shown above:
        zero: 0
        Exception: &lt;class &#39;Exception&#39;&gt;
        e: ZeroDivisionError(&#39;integer division or modulo by zero&#39;)
</pre></div>
</div>
</div>
</div>


           </div>
           
          </div>
          <footer>
  
    <div class="rst-footer-buttons" role="navigation" aria-label="footer navigation">
      
        <a href="syntax_tracebacks_en_3.10.html" class="btn btn-neutral float-right" title="Friendly SyntaxError tracebacks - in English" accesskey="n" rel="next">Next <span class="fa fa-arrow-circle-right"></span></a>
      
      
        <a href="syntax_tracebacks_en_3.9.html" class="btn btn-neutral float-left" title="Friendly SyntaxError tracebacks - in English" accesskey="p" rel="prev"><span class="fa fa-arrow-circle-left"></span> Previous</a>
      
    </div>
  

  <hr/>

  <div role="contentinfo">
    <p>
        
        &copy; Copyright 2019, André Roberge

    </p>
  </div>
    
    
    
    Built with <a href="http://sphinx-doc.org/">Sphinx</a> using a
    
    <a href="https://github.com/rtfd/sphinx_rtd_theme">theme</a>
    
    provided by <a href="https://readthedocs.org">Read the Docs</a>. 

</footer>

        </div>
      </div>

    </section>

  </div>
  

  <script type="text/javascript">
      jQuery(function () {
          SphinxRtdTheme.Navigation.enable(true);
      });
  </script>

  
  
    
   

</body>
</html>