

<!DOCTYPE html>
<html class="writer-html5" lang="en" >
<head>
  <meta charset="utf-8" />
  
  <meta name="viewport" content="width=device-width, initial-scale=1.0" />
  
  <title>Friendly tracebacks - markdown_docs format &mdash; friendly-traceback 0.3.142 documentation</title>
  

  
  <link rel="stylesheet" href="_static/css/theme.css" type="text/css" />
  <link rel="stylesheet" href="_static/pygments.css" type="text/css" />
  <link rel="stylesheet" href="_static/custom.css" type="text/css" />

  
  

  
  

  

  
  <!--[if lt IE 9]>
    <script src="_static/js/html5shiv.min.js"></script>
  <![endif]-->
  
    
      <script type="text/javascript" id="documentation_options" data-url_root="./" src="_static/documentation_options.js"></script>
        <script src="_static/jquery.js"></script>
        <script src="_static/underscore.js"></script>
        <script src="_static/doctools.js"></script>
    
    <script type="text/javascript" src="_static/js/theme.js"></script>

    
    <link rel="index" title="Index" href="genindex.html" />
    <link rel="search" title="Search" href="search.html" />
    <link rel="next" title="Syntax errors - markdown_docs format" href="tracebacks_syntax_markdown.html" />
    <link rel="prev" title="Comparison between Python versions: SyntaxErrors" href="compare.html" /> 
</head>

<body class="wy-body-for-nav">

   
  <div class="wy-grid-for-nav">
    
    <nav data-toggle="wy-nav-shift" class="wy-nav-side">
      <div class="wy-side-scroll">
        <div class="wy-side-nav-search" >
          

          
            <a href="index.html" class="icon icon-home"> friendly-traceback
          

          
          </a>

          
            
            
              <div class="version">
                0.3.142
              </div>
            
          

          
<div role="search">
  <form id="rtd-search-form" class="wy-form" action="search.html" method="get">
    <input type="text" name="q" placeholder="Search docs" />
    <input type="hidden" name="check_keywords" value="yes" />
    <input type="hidden" name="area" value="default" />
  </form>
</div>

          
        </div>

        
        <div class="wy-menu wy-menu-vertical" data-spy="affix" role="navigation" aria-label="main navigation">
          
            
            
              
            
            
              <p class="caption"><span class="caption-text">Begin here</span></p>
<ul>
<li class="toctree-l1"><a class="reference internal" href="beginner.html">Useful information for beginners</a></li>
<li class="toctree-l1"><a class="reference internal" href="install.html">Installation</a></li>
<li class="toctree-l1"><a class="reference internal" href="usage.html">Basic usage</a></li>
</ul>
<p class="caption"><span class="caption-text">friendly console</span></p>
<ul>
<li class="toctree-l1"><a class="reference internal" href="repl.html">Console basics</a></li>
<li class="toctree-l1"><a class="reference internal" href="why.html">why()</a></li>
<li class="toctree-l1"><a class="reference internal" href="what.html">what()</a></li>
<li class="toctree-l1"><a class="reference internal" href="where.html">where()</a></li>
<li class="toctree-l1"><a class="reference internal" href="explain.html">explain()</a></li>
<li class="toctree-l1"><a class="reference internal" href="www.html">www()</a></li>
<li class="toctree-l1"><a class="reference internal" href="history.html">history() and back()</a></li>
<li class="toctree-l1"><a class="reference internal" href="friendly_object.html">Friendly object</a></li>
<li class="toctree-l1"><a class="reference internal" href="friendly_object.html#everything-about-the-friendly-console">Everything about the friendly console</a></li>
<li class="toctree-l1"><a class="reference internal" href="multiple_tracebacks.html">Multiple tracebacks</a></li>
<li class="toctree-l1"><a class="reference internal" href="repl_api.html">Everything about the friendly console</a></li>
<li class="toctree-l1"><a class="reference internal" href="about_warnings.html">One last thing</a></li>
</ul>
<p class="caption"><span class="caption-text">Why import *?</span></p>
<ul>
<li class="toctree-l1"><a class="reference internal" href="import_all.html">Why <code class="docutils literal notranslate"><span class="pre">import</span> <span class="pre">*</span></code>?</a></li>
</ul>
<p class="caption"><span class="caption-text">IDLE</span></p>
<ul>
<li class="toctree-l1"><a class="reference internal" href="idle.html">About IDLE</a></li>
<li class="toctree-l1"><a class="reference internal" href="idle_repl.html">IDLE’s shell</a></li>
<li class="toctree-l1"><a class="reference internal" href="idle_run.html">IDLE: using the editor</a></li>
</ul>
<p class="caption"><span class="caption-text">Mu</span></p>
<ul>
<li class="toctree-l1"><a class="reference internal" href="mu_about.html">About Mu</a></li>
<li class="toctree-l1"><a class="reference internal" href="mu_install.html">Using with Mu: installation</a></li>
<li class="toctree-l1"><a class="reference internal" href="mu_repl.html">Mu’s REPL</a></li>
<li class="toctree-l1"><a class="reference internal" href="mu_run.html">Mu: executing a program</a></li>
</ul>
<p class="caption"><span class="caption-text">Other consoles</span></p>
<ul>
<li class="toctree-l1"><a class="reference internal" href="pyrepl.html">Using another REPL</a></li>
<li class="toctree-l1"><a class="reference internal" href="vs_code_repl.html">Visual Studio Code’s terminal</a></li>
<li class="toctree-l1"><a class="reference internal" href="ipython_repl.html">IPython’s console</a></li>
<li class="toctree-l1"><a class="reference internal" href="other_repl.html">Other repl</a></li>
</ul>
<p class="caption"><span class="caption-text">Editors and Notebooks</span></p>
<ul>
<li class="toctree-l1"><a class="reference internal" href="install_thonny.html">Information for Thonny</a></li>
<li class="toctree-l1"><a class="reference internal" href="editor.html">Using with an editor or IDE</a></li>
<li class="toctree-l1"><a class="reference internal" href="jupyter.html">Jupyter notebooks</a></li>
<li class="toctree-l1"><a class="reference internal" href="vs_code.html">Visual Studio Code</a></li>
<li class="toctree-l1"><a class="reference internal" href="colab.html">Google’s colab</a></li>
</ul>
<p class="caption"><span class="caption-text">Thoughts on design</span></p>
<ul>
<li class="toctree-l1"><a class="reference internal" href="design.html">Some thoughts on the design of friendly</a></li>
<li class="toctree-l1"><a class="reference internal" href="themes.html">Themes and colours</a></li>
</ul>
<p class="caption"><span class="caption-text">Use in your project</span></p>
<ul>
<li class="toctree-l1"><a class="reference internal" href="api.html">Public API</a></li>
<li class="toctree-l1"><a class="reference internal" href="formatter.html">Custom formatter</a></li>
<li class="toctree-l1"><a class="reference internal" href="usage_adv.html">Other details for advanced users</a></li>
<li class="toctree-l1"><a class="reference internal" href="plugins.html">Editor plugins</a></li>
</ul>
<p class="caption"><span class="caption-text">Contribute</span></p>
<ul>
<li class="toctree-l1"><a class="reference internal" href="suggest.html">Suggest an addition</a></li>
<li class="toctree-l1"><a class="reference internal" href="translation_notes.html">Notes on translations - using gettext</a></li>
</ul>
<p class="caption"><span class="caption-text">All the tracebacks!</span></p>
<ul>
<li class="toctree-l1"><a class="reference internal" href="known.html">Generic information about various exceptions</a></li>
<li class="toctree-l1"><a class="reference internal" href="tracebacks_en_3.6.html">friendly tracebacks - Python 3.6 in English</a></li>
<li class="toctree-l1"><a class="reference internal" href="syntax_tracebacks_en_3.6.html">SyntaxError - Python 3.6 in English</a></li>
<li class="toctree-l1"><a class="reference internal" href="tracebacks_en_3.7.html">friendly tracebacks - Python 3.7 in English</a></li>
<li class="toctree-l1"><a class="reference internal" href="syntax_tracebacks_en_3.7.html">SyntaxError - Python 3.7 in English</a></li>
<li class="toctree-l1"><a class="reference internal" href="tracebacks_en_3.8.html">friendly tracebacks - Python 3.8 in English</a></li>
<li class="toctree-l1"><a class="reference internal" href="syntax_tracebacks_en_3.8.html">SyntaxError - Python 3.8 in English</a></li>
<li class="toctree-l1"><a class="reference internal" href="tracebacks_en_3.9.html">friendly tracebacks - Python 3.9 in English</a></li>
<li class="toctree-l1"><a class="reference internal" href="syntax_tracebacks_en_3.9.html">SyntaxError - Python 3.9 in English</a></li>
<li class="toctree-l1"><a class="reference internal" href="tracebacks_en_3.10.html">friendly tracebacks - Python 3.10 in English</a></li>
<li class="toctree-l1"><a class="reference internal" href="syntax_tracebacks_en_3.10.html">SyntaxError - Python 3.10 in English</a></li>
<li class="toctree-l1"><a class="reference internal" href="compare_exceptions.html">Comparing Exception messages between Python versions</a></li>
<li class="toctree-l1"><a class="reference internal" href="compare.html">Comparison between Python versions: SyntaxErrors</a></li>
</ul>
<p class="caption"><span class="caption-text">Markdown examples</span></p>
<ul class="current">
<li class="toctree-l1 current"><a class="current reference internal" href="#">Friendly tracebacks - markdown_docs format</a><ul>
<li class="toctree-l2"><a class="reference internal" href="#arithmeticerror">ArithmeticError</a><ul>
<li class="toctree-l3"><a class="reference internal" href="#generic">Generic</a></li>
</ul>
</li>
<li class="toctree-l2"><a class="reference internal" href="#assertionerror">AssertionError</a><ul>
<li class="toctree-l3"><a class="reference internal" href="#id1">Generic</a></li>
</ul>
</li>
<li class="toctree-l2"><a class="reference internal" href="#attributeerror">AttributeError</a><ul>
<li class="toctree-l3"><a class="reference internal" href="#attribute-from-other-module">Attribute from other module</a></li>
<li class="toctree-l3"><a class="reference internal" href="#builtin-function">Builtin function</a></li>
<li class="toctree-l3"><a class="reference internal" href="#builtin-module-with-no-file">Builtin module with no file</a></li>
<li class="toctree-l3"><a class="reference internal" href="#circular-import">Circular import</a></li>
<li class="toctree-l3"><a class="reference internal" href="#circular-import-b">Circular import b</a></li>
<li class="toctree-l3"><a class="reference internal" href="#id2">Generic</a></li>
<li class="toctree-l3"><a class="reference internal" href="#generic-different-frame">Generic different frame</a></li>
<li class="toctree-l3"><a class="reference internal" href="#generic-instance">Generic instance</a></li>
<li class="toctree-l3"><a class="reference internal" href="#module-attribute-typo">Module attribute typo</a></li>
<li class="toctree-l3"><a class="reference internal" href="#nonetype">Nonetype</a></li>
<li class="toctree-l3"><a class="reference internal" href="#object-attribute-typo">Object attribute typo</a></li>
<li class="toctree-l3"><a class="reference internal" href="#perhaps-comma">Perhaps comma</a></li>
<li class="toctree-l3"><a class="reference internal" href="#shadow-stdlib-module">Shadow stdlib module</a></li>
<li class="toctree-l3"><a class="reference internal" href="#tuple-by-accident">Tuple by accident</a></li>
<li class="toctree-l3"><a class="reference internal" href="#use-builtin">Use builtin</a></li>
<li class="toctree-l3"><a class="reference internal" href="#use-join-with-str">Use join with str</a></li>
<li class="toctree-l3"><a class="reference internal" href="#use-synonym">Use synonym</a></li>
<li class="toctree-l3"><a class="reference internal" href="#using-slots">Using slots</a></li>
</ul>
</li>
<li class="toctree-l2"><a class="reference internal" href="#filenotfounderror">FileNotFoundError</a><ul>
<li class="toctree-l3"><a class="reference internal" href="#id3">Generic</a></li>
</ul>
</li>
<li class="toctree-l2"><a class="reference internal" href="#importerror">ImportError</a><ul>
<li class="toctree-l3"><a class="reference internal" href="#id4">Circular import</a></li>
<li class="toctree-l3"><a class="reference internal" href="#simple-import-error">Simple import error</a></li>
</ul>
</li>
<li class="toctree-l2"><a class="reference internal" href="#indexerror">IndexError</a><ul>
<li class="toctree-l3"><a class="reference internal" href="#empty">Empty</a></li>
<li class="toctree-l3"><a class="reference internal" href="#long-list">Long list</a></li>
<li class="toctree-l3"><a class="reference internal" href="#short-tuple">Short tuple</a></li>
</ul>
</li>
<li class="toctree-l2"><a class="reference internal" href="#keyerror">KeyError</a><ul>
<li class="toctree-l3"><a class="reference internal" href="#chainmap">ChainMap</a></li>
<li class="toctree-l3"><a class="reference internal" href="#forgot-to-convert-to-string">Forgot to convert to string</a></li>
<li class="toctree-l3"><a class="reference internal" href="#generic-key-error">Generic key error</a></li>
<li class="toctree-l3"><a class="reference internal" href="#popitem-empty-chainmap">Popitem empty ChainMap</a></li>
<li class="toctree-l3"><a class="reference internal" href="#popitem-empty-dict">Popitem empty dict</a></li>
<li class="toctree-l3"><a class="reference internal" href="#similar-names">Similar names</a></li>
<li class="toctree-l3"><a class="reference internal" href="#string-by-mistake">String by mistake</a></li>
</ul>
</li>
<li class="toctree-l2"><a class="reference internal" href="#lookuperror">LookupError</a><ul>
<li class="toctree-l3"><a class="reference internal" href="#id5">Generic</a></li>
</ul>
</li>
<li class="toctree-l2"><a class="reference internal" href="#modulenotfounderror">ModuleNotFoundError</a><ul>
<li class="toctree-l3"><a class="reference internal" href="#need-to-install-module">Need to install module</a></li>
<li class="toctree-l3"><a class="reference internal" href="#not-a-package">Not a package</a></li>
<li class="toctree-l3"><a class="reference internal" href="#not-a-package-similar-name">Not a package similar name</a></li>
<li class="toctree-l3"><a class="reference internal" href="#object-not-module">Object not module</a></li>
<li class="toctree-l3"><a class="reference internal" href="#similar-object-not-module">Similar object not module</a></li>
<li class="toctree-l3"><a class="reference internal" href="#standard-library-module">Standard library module</a></li>
<li class="toctree-l3"><a class="reference internal" href="#no-curses">no curses</a></li>
</ul>
</li>
<li class="toctree-l2"><a class="reference internal" href="#nameerror">NameError</a><ul>
<li class="toctree-l3"><a class="reference internal" href="#annotated-variable">Annotated variable</a></li>
<li class="toctree-l3"><a class="reference internal" href="#custom-name">Custom name</a></li>
<li class="toctree-l3"><a class="reference internal" href="#free-variable-referenced">Free variable referenced</a></li>
<li class="toctree-l3"><a class="reference internal" href="#id6">Generic</a></li>
<li class="toctree-l3"><a class="reference internal" href="#missing-import">Missing import</a></li>
<li class="toctree-l3"><a class="reference internal" href="#synonym">Synonym</a></li>
</ul>
</li>
<li class="toctree-l2"><a class="reference internal" href="#oserror">OsError</a><ul>
<li class="toctree-l3"><a class="reference internal" href="#urllib-error">Urllib error</a></li>
</ul>
</li>
<li class="toctree-l2"><a class="reference internal" href="#overflowerror">OverflowError</a><ul>
<li class="toctree-l3"><a class="reference internal" href="#id7">Generic</a></li>
</ul>
</li>
<li class="toctree-l2"><a class="reference internal" href="#recursionerror">RecursionError</a><ul>
<li class="toctree-l3"><a class="reference internal" href="#id8">Generic</a></li>
</ul>
</li>
<li class="toctree-l2"><a class="reference internal" href="#typeerror">TypeError</a><ul>
<li class="toctree-l3"><a class="reference internal" href="#bad-type-for-unary-operator">Bad type for unary operator</a></li>
<li class="toctree-l3"><a class="reference internal" href="#builtin-has-no-len">Builtin has no len</a></li>
<li class="toctree-l3"><a class="reference internal" href="#can-only-concatenate">Can only concatenate</a></li>
<li class="toctree-l3"><a class="reference internal" href="#cannot-convert-dictionary-update-sequence">Cannot convert dictionary update sequence</a></li>
<li class="toctree-l3"><a class="reference internal" href="#cannot-multiply-by-non-int">Cannot multiply by non int</a></li>
<li class="toctree-l3"><a class="reference internal" href="#cannot-unpack-non-iterable-object">Cannot unpack non iterable object</a></li>
<li class="toctree-l3"><a class="reference internal" href="#comparison-not-supported">Comparison not supported</a></li>
<li class="toctree-l3"><a class="reference internal" href="#derive-from-baseexception">Derive from BaseException</a></li>
<li class="toctree-l3"><a class="reference internal" href="#indices-must-be-integers-or-slices">Indices must be integers or slices</a></li>
<li class="toctree-l3"><a class="reference internal" href="#not-an-integer">Not an integer</a></li>
<li class="toctree-l3"><a class="reference internal" href="#not-callable">Not callable</a></li>
<li class="toctree-l3"><a class="reference internal" href="#object-is-not-iterable">Object is not iterable</a></li>
<li class="toctree-l3"><a class="reference internal" href="#object-is-not-subscriptable">Object is not subscriptable</a></li>
<li class="toctree-l3"><a class="reference internal" href="#slice-indices-must-be-integers-or-none">Slice indices must be integers or None</a></li>
<li class="toctree-l3"><a class="reference internal" href="#too-few-positional-argument">Too few positional argument</a></li>
<li class="toctree-l3"><a class="reference internal" href="#too-many-positional-argument">Too many positional argument</a></li>
<li class="toctree-l3"><a class="reference internal" href="#tuple-no-item-assignment">Tuple no item assignment</a></li>
<li class="toctree-l3"><a class="reference internal" href="#unhachable-type">Unhachable type</a></li>
<li class="toctree-l3"><a class="reference internal" href="#unsupported-operand-types">Unsupported operand types</a></li>
<li class="toctree-l3"><a class="reference internal" href="#function-has-no-len">function has no len</a></li>
</ul>
</li>
<li class="toctree-l2"><a class="reference internal" href="#unboundlocalerror">UnboundLocalError</a><ul>
<li class="toctree-l3"><a class="reference internal" href="#missing-both">Missing both</a></li>
<li class="toctree-l3"><a class="reference internal" href="#missing-global">Missing global</a></li>
<li class="toctree-l3"><a class="reference internal" href="#missing-nonlocal">Missing nonlocal</a></li>
<li class="toctree-l3"><a class="reference internal" href="#typo-in-local">Typo in local</a></li>
</ul>
</li>
<li class="toctree-l2"><a class="reference internal" href="#unknownerror">UnknownError</a><ul>
<li class="toctree-l3"><a class="reference internal" href="#id9">Generic</a></li>
</ul>
</li>
<li class="toctree-l2"><a class="reference internal" href="#valueerror">ValueError</a><ul>
<li class="toctree-l3"><a class="reference internal" href="#date-invalid-month">Date invalid month</a></li>
<li class="toctree-l3"><a class="reference internal" href="#not-enough-values-to-unpack">Not enough values to unpack</a></li>
<li class="toctree-l3"><a class="reference internal" href="#too-many-values-to-unpack">Too many values to unpack</a></li>
</ul>
</li>
<li class="toctree-l2"><a class="reference internal" href="#zerodivisionerror">ZeroDivisionError</a><ul>
<li class="toctree-l3"><a class="reference internal" href="#complex-division">Complex division</a></li>
<li class="toctree-l3"><a class="reference internal" href="#division-by-zero-literal">Division by zero literal</a></li>
<li class="toctree-l3"><a class="reference internal" href="#division-operator">Division operator</a></li>
<li class="toctree-l3"><a class="reference internal" href="#divmod">Divmod</a></li>
<li class="toctree-l3"><a class="reference internal" href="#float-division">Float division</a></li>
<li class="toctree-l3"><a class="reference internal" href="#float-divmod">Float divmod</a></li>
<li class="toctree-l3"><a class="reference internal" href="#float-modulo">Float modulo</a></li>
<li class="toctree-l3"><a class="reference internal" href="#integer-division-operator">Integer division operator</a></li>
<li class="toctree-l3"><a class="reference internal" href="#mixed-operations">Mixed operations</a></li>
<li class="toctree-l3"><a class="reference internal" href="#modulo-operator">Modulo operator</a></li>
<li class="toctree-l3"><a class="reference internal" href="#raise-zero-negative-power">Raise zero negative power</a></li>
</ul>
</li>
</ul>
</li>
<li class="toctree-l1"><a class="reference internal" href="tracebacks_syntax_markdown.html">Syntax errors - markdown_docs format</a></li>
</ul>
<p class="caption"><span class="caption-text">En français</span></p>
<ul>
<li class="toctree-l1"><a class="reference internal" href="tracebacks_fr.html"> Friendly tracebacks - en Français</a></li>
<li class="toctree-l1"><a class="reference internal" href="syntax_tracebacks_fr.html"> Friendly SyntaxError tracebacks - en Français</a></li>
</ul>

            
          
        </div>
        
      </div>
    </nav>

    <section data-toggle="wy-nav-shift" class="wy-nav-content-wrap">

      
      <nav class="wy-nav-top" aria-label="top navigation">
        
          <i data-toggle="wy-nav-top" class="fa fa-bars"></i>
          <a href="index.html">friendly-traceback</a>
        
      </nav>


      <div class="wy-nav-content">
        
        <div class="rst-content style-external-links">
        
          

















<div role="navigation" aria-label="breadcrumbs navigation">

  <ul class="wy-breadcrumbs">
    
      <li><a href="index.html" class="icon icon-home"></a> &raquo;</li>
        
      <li>Friendly tracebacks - markdown_docs format</li>
    
    
      <li class="wy-breadcrumbs-aside">
        
          
            <a href="_sources/tracebacks_markdown.md.txt" rel="nofollow"> View page source</a>
          
        
      </li>
    
  </ul>

  
  <div class="rst-breadcrumbs-buttons" role="navigation" aria-label="breadcrumb navigation">
      
        <a href="tracebacks_syntax_markdown.html" class="btn btn-neutral float-right" title="Syntax errors - markdown_docs format" accesskey="n">Next <span class="fa fa-arrow-circle-right" aria-hidden="true"></span></a>
      
      
        <a href="compare.html" class="btn btn-neutral float-left" title="Comparison between Python versions: SyntaxErrors" accesskey="p"><span class="fa fa-arrow-circle-left" aria-hidden="true"></span> Previous</a>
      
  </div>
  
  <hr/>
</div>
          <div role="main" class="document" itemscope="itemscope" itemtype="http://schema.org/Article">
           <div itemprop="articleBody">
            
  <div class="section" id="friendly-tracebacks-markdown-docs-format">
<h1>Friendly tracebacks - markdown_docs format<a class="headerlink" href="#friendly-tracebacks-markdown-docs-format" title="Permalink to this headline">¶</a></h1>
<div class="admonition note">
<p class="admonition-title">Note</p>
<p>The content of this page is generated by running
trb_english_markdown.py located in the <code class="docutils literal notranslate"><span class="pre">tests/</span></code> directory.
This needs to be done explicitly, independently of updating the
documentation using Sphinx.
</p>
</div><p>Friendly version: 0.3.142
Python version: 3.8.10</p>
<hr class="docutils" />
<div class="section" id="arithmeticerror">
<h2>ArithmeticError<a class="headerlink" href="#arithmeticerror" title="Permalink to this headline">¶</a></h2>
<div class="section" id="generic">
<h3>Generic<a class="headerlink" href="#generic" title="Permalink to this headline">¶</a></h3>
<p>Traceback (most recent call last):
File “TESTS:\runtime\test_arithmetic_error.py”, line 9, in test_Generic
raise ArithmeticError(‘error’)
ArithmeticError: error</p>
<div class="highlight-default notranslate"><div class="highlight"><pre><span></span>`ArithmeticError` is the base class for those built-in exceptions
that are raised for various arithmetic errors.
It is unusual that you are seeing this exception;
normally, a more specific exception should have been raised.

Exception raised on line 9 of file TESTS:\runtime\test_arithmetic_error.py.

    7:         # Usually, a subclass such as ZeroDivisionError, etc., would
    8:         # likely be raised.
--&gt; 9:         raise ArithmeticError(&#39;error&#39;)
   10:     except ArithmeticError as e:

        ArithmeticError:  &lt;class ArithmeticError&gt;
</pre></div>
</div>
</div>
</div>
<hr class="docutils" />
<div class="section" id="assertionerror">
<h2>AssertionError<a class="headerlink" href="#assertionerror" title="Permalink to this headline">¶</a></h2>
<div class="section" id="id1">
<h3>Generic<a class="headerlink" href="#id1" title="Permalink to this headline">¶</a></h3>
<p>Traceback (most recent call last):
File “TESTS:\runtime\test_assertion_error.py”, line 8, in test_Generic
raise AssertionError(“Fake message”)
AssertionError: Fake message</p>
<div class="highlight-default notranslate"><div class="highlight"><pre><span></span>In Python, the keyword `assert` is used in statements of the form
`assert condition`, to confirm that `condition` is not `False`,
nor equivalent to `False` such as an empty list, etc.

If `condition` is `False` or equivalent, an `AssertionError` is raised.

Exception raised on line 8 of file TESTS:\runtime\test_assertion_error.py.

    6:         # We raise it explicitly, rather than with the keyword assert, since
    7:         # we don&#39;t want pytest to rewrite out test.
--&gt; 8:         raise AssertionError(&quot;Fake message&quot;)
    9:     except AssertionError as e:

        AssertionError:  &lt;class AssertionError&gt;
</pre></div>
</div>
</div>
</div>
<hr class="docutils" />
<div class="section" id="attributeerror">
<h2>AttributeError<a class="headerlink" href="#attributeerror" title="Permalink to this headline">¶</a></h2>
<div class="section" id="attribute-from-other-module">
<h3>Attribute from other module<a class="headerlink" href="#attribute-from-other-module" title="Permalink to this headline">¶</a></h3>
<p>Traceback (most recent call last):
File “TESTS:\runtime\test_attribute_error.py”, line 299, in test_Attribute_from_other_module
keyword.pi
AttributeError: module ‘keyword’ has no attribute ‘pi’</p>
<div class="highlight-default notranslate"><div class="highlight"><pre><span></span>    Did you mean one of the following modules: `math, cmath`?
An `AttributeError` occurs when the code contains something like
    `object.x`
and `x` is not a method or attribute (variable) belonging to `object`.

Instead of the module `keyword`, perhaps you wanted to use
the attribute `pi` of one of the following modules:
`math, cmath`.

Exception raised on line 299 of file TESTS:\runtime\test_attribute_error.py.

   297:     import cmath
   298:     try:
--&gt;299:         keyword.pi
   300:     except AttributeError as e:

        keyword:  &lt;module keyword&gt; from PYTHON_LIB:\keyword.py
</pre></div>
</div>
</div>
<div class="section" id="builtin-function">
<h3>Builtin function<a class="headerlink" href="#builtin-function" title="Permalink to this headline">¶</a></h3>
<p>Traceback (most recent call last):
File “TESTS:\runtime\test_attribute_error.py”, line 217, in test_Builtin_function
len.text
AttributeError: ‘builtin_function_or_method’ object has no attribute ‘text’</p>
<div class="highlight-default notranslate"><div class="highlight"><pre><span></span>    Did you mean `len(text)`?
    
An `AttributeError` occurs when the code contains something like
    `object.x`
and `x` is not a method or attribute (variable) belonging to `object`.

`len` is a function. Perhaps you meant to write
`len(text)`

Exception raised on line 217 of file TESTS:\runtime\test_attribute_error.py.

   215:     text = &#39;Hello world!&#39;
   216:     try:
--&gt;217:         len.text
   218:     except AttributeError as e:

        text:  &#39;Hello world!&#39;
        len:  &lt;builtin function len&gt;
</pre></div>
</div>
</div>
<div class="section" id="builtin-module-with-no-file">
<h3>Builtin module with no file<a class="headerlink" href="#builtin-module-with-no-file" title="Permalink to this headline">¶</a></h3>
<p>Traceback (most recent call last):
File “TESTS:\runtime\test_attribute_error.py”, line 234, in test_Builtin_module_with_no_file
sys.foo
AttributeError: module ‘sys’ has no attribute ‘foo’</p>
<div class="highlight-default notranslate"><div class="highlight"><pre><span></span>An `AttributeError` occurs when the code contains something like
    `object.x`
and `x` is not a method or attribute (variable) belonging to `object`.

Python tells us that no object with name `foo` is
found in module `sys`.

Exception raised on line 234 of file TESTS:\runtime\test_attribute_error.py.

   232: 
   233:     try:
--&gt;234:         sys.foo
   235:     except AttributeError as e:

        sys:  &lt;module sys (builtin)&gt;
</pre></div>
</div>
</div>
<div class="section" id="circular-import">
<h3>Circular import<a class="headerlink" href="#circular-import" title="Permalink to this headline">¶</a></h3>
<p>Traceback (most recent call last):
File “TESTS:\runtime\test_attribute_error.py”, line 329, in test_Circular_import
import my_turtle1
File “TESTS:\my_turtle1.py”, line 4, in <module>
a = my_turtle1.something
AttributeError: partially initialized module ‘my_turtle1’ has no attribute ‘something’ (most likely due to a circular import)</p>
<div class="highlight-default notranslate"><div class="highlight"><pre><span></span>    Did you give your program the same name as a Python module?
    
An `AttributeError` occurs when the code contains something like
    `object.x`
and `x` is not a method or attribute (variable) belonging to `object`.

I suspect that you used the name `my_turtle1.py` for your program
and that you also wanted to import a module with the same name
from Python&#39;s standard library.
If so, you should use a different name for your program.

Execution stopped on line 329 of file TESTS:\runtime\test_attribute_error.py.

   327:     stdlib_modules.names.append(&quot;my_turtle1&quot;)
   328:     try:
--&gt;329:        import my_turtle1
   330:     except AttributeError as e:

Exception raised on line 4 of file TESTS:\my_turtle1.py.

   2: import my_turtle1
   3: 
--&gt;4: a = my_turtle1.something
          ^^^^^^^^^^^^^^^^^^^^

        my_turtle1:  &lt;module my_turtle1&gt; from TESTS:\my_turtle1.py
</pre></div>
</div>
</div>
<div class="section" id="circular-import-b">
<h3>Circular import b<a class="headerlink" href="#circular-import-b" title="Permalink to this headline">¶</a></h3>
<p>Traceback (most recent call last):
File “TESTS:\runtime\test_attribute_error.py”, line 346, in test_Circular_import_b
import circular_c
File “TESTS:\circular_c.py”, line 4, in <module>
a = circular_c.something
AttributeError: partially initialized module ‘circular_c’ has no attribute ‘something’ (most likely due to a circular import)</p>
<div class="highlight-default notranslate"><div class="highlight"><pre><span></span>    You have a circular import.
    
An `AttributeError` occurs when the code contains something like
    `object.x`
and `x` is not a method or attribute (variable) belonging to `object`.

Python indicated that the module `{module}` was not fully imported.
This can occur if, during the execution of the code in module `circular_c`
an attempt is made to import the same module again.

Execution stopped on line 346 of file TESTS:\runtime\test_attribute_error.py.

   344: def test_Circular_import_b():
   345:     try:
--&gt;346:         import circular_c
   347:     except AttributeError as e:

Exception raised on line 4 of file TESTS:\circular_c.py.

   2: import circular_c
   3: 
--&gt;4: a = circular_c.something
          ^^^^^^^^^^^^^^^^^^^^

        circular_c:  &lt;module circular_c&gt; from TESTS:\circular_c.py
</pre></div>
</div>
</div>
<div class="section" id="id2">
<h3>Generic<a class="headerlink" href="#id2" title="Permalink to this headline">¶</a></h3>
<p>Traceback (most recent call last):
File “TESTS:\runtime\test_attribute_error.py”, line 24, in test_Generic
A.x  # testing type
AttributeError: type object ‘A’ has no attribute ‘x’</p>
<div class="highlight-default notranslate"><div class="highlight"><pre><span></span>An `AttributeError` occurs when the code contains something like
    `object.x`
and `x` is not a method or attribute (variable) belonging to `object`.

The object `A` has no attribute named `x`.

Exception raised on line 24 of file TESTS:\runtime\test_attribute_error.py.

   22: 
   23:     try:
--&gt;24:         A.x  # testing type
   25:     except AttributeError as e:

        A:  &lt;class A&gt; from test_attribute_error.test_Generic
</pre></div>
</div>
</div>
<div class="section" id="generic-different-frame">
<h3>Generic different frame<a class="headerlink" href="#generic-different-frame" title="Permalink to this headline">¶</a></h3>
<p>Traceback (most recent call last):
File “TESTS:\runtime\test_attribute_error.py”, line 47, in test_Generic_different_frame
a.attr
AttributeError: ‘A’ object has no attribute ‘attr’</p>
<div class="highlight-default notranslate"><div class="highlight"><pre><span></span>    Did you mean `attr2`?
    
An `AttributeError` occurs when the code contains something like
    `object.x`
and `x` is not a method or attribute (variable) belonging to `object`.

The object `a` has no attribute named `attr`.
Perhaps you meant to write `a.attr2` instead of `a.attr`

Exception raised on line 47 of file TESTS:\runtime\test_attribute_error.py.

   45:     a = f()
   46:     try:
--&gt;47:         a.attr
   48:     except AttributeError as e:

        a:  &lt;f.A object&gt; from test_attribute_error.test_Generic_different_frame
</pre></div>
</div>
</div>
<div class="section" id="generic-instance">
<h3>Generic instance<a class="headerlink" href="#generic-instance" title="Permalink to this headline">¶</a></h3>
<p>Traceback (most recent call last):
File “TESTS:\runtime\test_attribute_error.py”, line 65, in test_Generic_instance
a.x
AttributeError: ‘A’ object has no attribute ‘x’</p>
<div class="highlight-default notranslate"><div class="highlight"><pre><span></span>An `AttributeError` occurs when the code contains something like
    `object.x`
and `x` is not a method or attribute (variable) belonging to `object`.

The object `a` has no attribute named `x`.

Exception raised on line 65 of file TESTS:\runtime\test_attribute_error.py.

   63:     a = A()
   64:     try:
--&gt;65:         a.x
   66:     except AttributeError as e:

        a:  &lt;A object&gt; from test_attribute_error.test_Generic_instance
</pre></div>
</div>
</div>
<div class="section" id="module-attribute-typo">
<h3>Module attribute typo<a class="headerlink" href="#module-attribute-typo" title="Permalink to this headline">¶</a></h3>
<p>Traceback (most recent call last):
File “TESTS:\runtime\test_attribute_error.py”, line 142, in test_Module_attribute_typo
math.cost
AttributeError: module ‘math’ has no attribute ‘cost’</p>
<div class="highlight-default notranslate"><div class="highlight"><pre><span></span>    Did you mean `cos`?
    
An `AttributeError` occurs when the code contains something like
    `object.x`
and `x` is not a method or attribute (variable) belonging to `object`.

Instead of writing `math.cost`, perhaps you meant to write one of 
the following names which are attributes of module `math`:
`cos, cosh, acos`

Exception raised on line 142 of file TESTS:\runtime\test_attribute_error.py.

   140: 
   141:     try:
--&gt;142:         math.cost
   143:     except AttributeError as e:

        math:  &lt;module math (builtin)&gt;
</pre></div>
</div>
</div>
<div class="section" id="nonetype">
<h3>Nonetype<a class="headerlink" href="#nonetype" title="Permalink to this headline">¶</a></h3>
<p>Traceback (most recent call last):
File “TESTS:\runtime\test_attribute_error.py”, line 181, in test_Nonetype
a.b
AttributeError: ‘NoneType’ object has no attribute ‘b’</p>
<div class="highlight-default notranslate"><div class="highlight"><pre><span></span>An `AttributeError` occurs when the code contains something like
    `object.x`
and `x` is not a method or attribute (variable) belonging to `object`.

You are attempting to access the attribute `b`
for a variable whose value is `None`.
Exception raised on line 181 of file TESTS:\runtime\test_attribute_error.py.

   179:     a = None
   180:     try:
--&gt;181:         a.b
   182:     except AttributeError as e:

        a:  None
</pre></div>
</div>
</div>
<div class="section" id="object-attribute-typo">
<h3>Object attribute typo<a class="headerlink" href="#object-attribute-typo" title="Permalink to this headline">¶</a></h3>
<p>Traceback (most recent call last):
File “TESTS:\runtime\test_attribute_error.py”, line 81, in test_Object_attribute_typo
a.appendh(4)
AttributeError: ‘list’ object has no attribute ‘appendh’</p>
<div class="highlight-default notranslate"><div class="highlight"><pre><span></span>    Did you mean `append`?
    
An `AttributeError` occurs when the code contains something like
    `object.x`
and `x` is not a method or attribute (variable) belonging to `object`.

The object `a` has no attribute named `appendh`.
Perhaps you meant to write `a.append` instead of `a.appendh`

Exception raised on line 81 of file TESTS:\runtime\test_attribute_error.py.

   79:     try:
   80:         a = [1, 2, 3]
--&gt;81:         a.appendh(4)
               ^^^^^^^^^
   82:     except AttributeError as e:

        a:  [1, 2, 3]
</pre></div>
</div>
</div>
<div class="section" id="perhaps-comma">
<h3>Perhaps comma<a class="headerlink" href="#perhaps-comma" title="Permalink to this headline">¶</a></h3>
<p>Traceback (most recent call last):
File “TESTS:\runtime\test_attribute_error.py”, line 200, in test_Perhaps_comma
a = [abcd
AttributeError: ‘str’ object has no attribute ‘defg’</p>
<div class="highlight-default notranslate"><div class="highlight"><pre><span></span>    Did you mean to separate object names by a comma?
    
An `AttributeError` occurs when the code contains something like
    `object.x`
and `x` is not a method or attribute (variable) belonging to `object`.

`defg` is not an attribute of `abcd`.
However, both `abcd` and `defg` are known objects.
Perhaps you wrote a period to separate these two objects, 
instead of using a comma.

Exception raised on line 200 of file TESTS:\runtime\test_attribute_error.py.

   198:     # fmt: off
   199:     try:
--&gt;200:         a = [abcd
   201:         .defg]

        abcd:  &#39;hello&#39;
        defg:  &#39;world&#39;
</pre></div>
</div>
</div>
<div class="section" id="shadow-stdlib-module">
<h3>Shadow stdlib module<a class="headerlink" href="#shadow-stdlib-module" title="Permalink to this headline">¶</a></h3>
<p>Traceback (most recent call last):
File “TESTS:\runtime\test_attribute_error.py”, line 163, in test_Shadow_stdlib_module
turtle.Pen
AttributeError: module ‘turtle’ has no attribute ‘Pen’</p>
<div class="highlight-default notranslate"><div class="highlight"><pre><span></span>    Did you give your program the same name as a Python module?
    
An `AttributeError` occurs when the code contains something like
    `object.x`
and `x` is not a method or attribute (variable) belonging to `object`.

You imported a module named `turtle` from `TESTS:\turtle.py`.
There is also a module named `turtle` in Python&#39;s standard library.
Perhaps you need to rename your module.

Exception raised on line 163 of file TESTS:\runtime\test_attribute_error.py.

   161: 
   162:     try:
--&gt;163:         turtle.Pen
   164:     except AttributeError as e:

        turtle:  &lt;module turtle&gt; from TESTS:\turtle.py
</pre></div>
</div>
</div>
<div class="section" id="tuple-by-accident">
<h3>Tuple by accident<a class="headerlink" href="#tuple-by-accident" title="Permalink to this headline">¶</a></h3>
<p>Traceback (most recent call last):
File “TESTS:\runtime\test_attribute_error.py”, line 269, in test_Tuple_by_accident
something.upper()
AttributeError: ‘tuple’ object has no attribute ‘upper’</p>
<div class="highlight-default notranslate"><div class="highlight"><pre><span></span>    Did you write a comma by mistake?
    
An `AttributeError` occurs when the code contains something like
    `object.x`
and `x` is not a method or attribute (variable) belonging to `object`.

`something` is a tuple that contains a single item
which does have `&#39;upper&#39;` as an attribute.
Perhaps you added a trailing comma by mistake at the end of the line
where you defined `something`.

Exception raised on line 269 of file TESTS:\runtime\test_attribute_error.py.

   267:     something = &quot;abc&quot;,  # note trailing comma
   268:     try:
--&gt;269:         something.upper()
                ^^^^^^^^^^^^^^^
   270:     except AttributeError as e:

        something:  (&#39;abc&#39;,)
</pre></div>
</div>
</div>
<div class="section" id="use-builtin">
<h3>Use builtin<a class="headerlink" href="#use-builtin" title="Permalink to this headline">¶</a></h3>
<p>Traceback (most recent call last):
File “TESTS:\runtime\test_attribute_error.py”, line 97, in test_Use_builtin
a.length()
AttributeError: ‘list’ object has no attribute ‘length’</p>
<div class="highlight-default notranslate"><div class="highlight"><pre><span></span>    Did you mean `len(a)`?
    
An `AttributeError` occurs when the code contains something like
    `object.x`
and `x` is not a method or attribute (variable) belonging to `object`.

The object `a` has no attribute named `length`.
Perhaps you can use the Python builtin function `len` instead:
`len(a)`.
Exception raised on line 97 of file TESTS:\runtime\test_attribute_error.py.

   95:     try:
   96:         a = [1, 2, 3]
--&gt;97:         a.length()
               ^^^^^^^^
   98:     except AttributeError as e:

        a:  [1, 2, 3]
</pre></div>
</div>
</div>
<div class="section" id="use-join-with-str">
<h3>Use join with str<a class="headerlink" href="#use-join-with-str" title="Permalink to this headline">¶</a></h3>
<p>Traceback (most recent call last):
File “TESTS:\runtime\test_attribute_error.py”, line 313, in test_Use_join_with_str
a = [‘a’, ‘2’].join(‘abc’) + [‘b’, ‘3’].join(‘\n’)
AttributeError: ‘list’ object has no attribute ‘join’</p>
<div class="highlight-default notranslate"><div class="highlight"><pre><span></span>    Did you mean `&#39;abc&#39;.join([&#39;a&#39;, &#39;2&#39;])`?
    
An `AttributeError` occurs when the code contains something like
    `object.x`
and `x` is not a method or attribute (variable) belonging to `object`.

The object `[&#39;a&#39;, &#39;2&#39;]` has no attribute named `join`.
Perhaps you wanted something like `&#39;abc&#39;.join([&#39;a&#39;, &#39;2&#39;])`.

Exception raised on line 313 of file TESTS:\runtime\test_attribute_error.py.

   311: def test_Use_join_with_str():
   312:     try:
--&gt;313:         a = [&#39;a&#39;, &#39;2&#39;].join(&#39;abc&#39;) + [&#39;b&#39;, &#39;3&#39;].join(&#39;\n&#39;)
                    ^^^^^^^^^^^^^^^
   314:     except AttributeError as e:
</pre></div>
</div>
</div>
<div class="section" id="use-synonym">
<h3>Use synonym<a class="headerlink" href="#use-synonym" title="Permalink to this headline">¶</a></h3>
<p>Traceback (most recent call last):
File “TESTS:\runtime\test_attribute_error.py”, line 113, in test_Use_synonym
a.add(4)
AttributeError: ‘list’ object has no attribute ‘add’</p>
<div class="highlight-default notranslate"><div class="highlight"><pre><span></span>    Did you mean `append`?
    
An `AttributeError` occurs when the code contains something like
    `object.x`
and `x` is not a method or attribute (variable) belonging to `object`.

The object `a` has no attribute named `add`.
However, `a` has the following attributes with similar meanings:
`append, extend, insert`.

Exception raised on line 113 of file TESTS:\runtime\test_attribute_error.py.

   111:     try:
   112:         a = [1, 2, 3]
--&gt;113:         a.add(4)
                ^^^^^
   114:     except AttributeError as e:

        a:  [1, 2, 3]
</pre></div>
</div>
</div>
<div class="section" id="using-slots">
<h3>Using slots<a class="headerlink" href="#using-slots" title="Permalink to this headline">¶</a></h3>
<p>Traceback (most recent call last):
File “TESTS:\runtime\test_attribute_error.py”, line 254, in test_Using_slots
f.b = 1
AttributeError: ‘F’ object has no attribute ‘b’</p>
<div class="highlight-default notranslate"><div class="highlight"><pre><span></span>An `AttributeError` occurs when the code contains something like
    `object.x`
and `x` is not a method or attribute (variable) belonging to `object`.

The object `f` has no attribute named `b`.
Note that object `f` uses `__slots__` which prevents
the creation of new attributes.
The following are some of its known attributes:
`a`.
Exception raised on line 254 of file TESTS:\runtime\test_attribute_error.py.

   252:     f = F()
   253:     try:
--&gt;254:         f.b = 1
   255:     except AttributeError as e:

        f:  &lt;F object&gt; from test_attribute_error.test_Using_slots
</pre></div>
</div>
</div>
</div>
<hr class="docutils" />
<div class="section" id="filenotfounderror">
<h2>FileNotFoundError<a class="headerlink" href="#filenotfounderror" title="Permalink to this headline">¶</a></h2>
<div class="section" id="id3">
<h3>Generic<a class="headerlink" href="#id3" title="Permalink to this headline">¶</a></h3>
<p>Traceback (most recent call last):
File “TESTS:\runtime\test_file_not_found_error.py”, line 6, in test_Generic
open(“does_not_exist”)
FileNotFoundError: [Errno 2] No such file or directory: ‘does_not_exist’</p>
<div class="highlight-default notranslate"><div class="highlight"><pre><span></span>A `FileNotFoundError` exception indicates that you
are trying to open a file that cannot be found by Python.
This could be because you misspelled the name of the file.

In your program, the name of the
file that cannot be found is `does_not_exist`.

Exception raised on line 6 of file TESTS:\runtime\test_file_not_found_error.py.

   4: def test_Generic():
   5:     try:
--&gt;6:         open(&quot;does_not_exist&quot;)
   7:     except FileNotFoundError as e:

        open:  &lt;builtin function open&gt;
</pre></div>
</div>
</div>
</div>
<hr class="docutils" />
<div class="section" id="importerror">
<h2>ImportError<a class="headerlink" href="#importerror" title="Permalink to this headline">¶</a></h2>
<div class="section" id="id4">
<h3>Circular import<a class="headerlink" href="#id4" title="Permalink to this headline">¶</a></h3>
<p>Traceback (most recent call last):
File “TESTS:\runtime\test_import_error.py”, line 58, in test_Circular_import
import circular_a
File “TESTS:\circular_a.py”, line 2, in <module>
import circular_b
File “TESTS:\circular_b.py”, line 2, in <module>
from circular_a import a
ImportError: cannot import name ‘a’ from partially initialized module ‘circular_a’ (most likely due to a circular import) (C:\Users\andre\github\friendly-traceback\tests\circular_a.py)</p>
<div class="highlight-default notranslate"><div class="highlight"><pre><span></span>An `ImportError` exception indicates that a certain object could not
be imported from a module or package. Most often, this is
because the name of the object is not spelled correctly.

The object that could not be imported is `a`.
The module or package where it was 
expected to be found is `circular_a`.

The problem was likely caused by what is known as a &#39;circular import&#39;.
First, Python imported and started executing the code in file
   &#39;TESTS:\runtime\test_import_error.py&#39;.
which imports module `circular_a`.
During this process, the code in another file,
   &#39;TESTS:\circular_b.py&#39;
was executed. However in this last file, an attempt was made
to import the original module `circular_a`
a second time, before Python had completed the first import.

Execution stopped on line 58 of file TESTS:\runtime\test_import_error.py.

   56: def test_Circular_import():
   57:     try:
--&gt;58:         import circular_a
   59:     except ImportError as e:

Exception raised on line 2 of file TESTS:\circular_b.py.

   1: &quot;&quot;&quot;File used in for test_circular_import() in test_import_error.py&quot;&quot;&quot;
--&gt;2: from circular_a import a
</pre></div>
</div>
</div>
<div class="section" id="simple-import-error">
<h3>Simple import error<a class="headerlink" href="#simple-import-error" title="Permalink to this headline">¶</a></h3>
<p>Traceback (most recent call last):
File “TESTS:\runtime\test_import_error.py”, line 44, in test_Simple_import_error
from math import Pi
ImportError: cannot import name ‘Pi’ from ‘math’ (unknown location)</p>
<div class="highlight-default notranslate"><div class="highlight"><pre><span></span>    Did you mean `pi`?
    
An `ImportError` exception indicates that a certain object could not
be imported from a module or package. Most often, this is
because the name of the object is not spelled correctly.

Perhaps you meant to import `pi` (from `math`) instead of `Pi`

Exception raised on line 44 of file TESTS:\runtime\test_import_error.py.

   42: 
   43:     try:
--&gt;44:         from math import Pi
   45:     except ImportError as e:
</pre></div>
</div>
</div>
</div>
<hr class="docutils" />
<div class="section" id="indexerror">
<h2>IndexError<a class="headerlink" href="#indexerror" title="Permalink to this headline">¶</a></h2>
<div class="section" id="empty">
<h3>Empty<a class="headerlink" href="#empty" title="Permalink to this headline">¶</a></h3>
<p>Traceback (most recent call last):
File “TESTS:\runtime\test_index_error.py”, line 38, in test_Empty
c = a[1]
IndexError: list index out of range</p>
<div class="highlight-default notranslate"><div class="highlight"><pre><span></span>    `a` contains no item.
    
An `IndexError` occurs when you try to get an item from a list,
a tuple, or a similar object (sequence), and use an index which
does not exist; typically, this happens because the index you give
is greater than the length of the sequence.

You have tried to get the item with index `1` of `a`,
a `list` which contains no item.

Exception raised on line 38 of file TESTS:\runtime\test_index_error.py.

   36:     a = []
   37:     try:
--&gt;38:         c = a[1]
                   ^^^^
   39:     except IndexError as e:

        a:  []
</pre></div>
</div>
</div>
<div class="section" id="long-list">
<h3>Long list<a class="headerlink" href="#long-list" title="Permalink to this headline">¶</a></h3>
<p>Traceback (most recent call last):
File “TESTS:\runtime\test_index_error.py”, line 24, in test_Long_list
print(a[60], b[0])
IndexError: list index out of range</p>
<div class="highlight-default notranslate"><div class="highlight"><pre><span></span>An `IndexError` occurs when you try to get an item from a list,
a tuple, or a similar object (sequence), and use an index which
does not exist; typically, this happens because the index you give
is greater than the length of the sequence.

You have tried to get the item with index `60` of `a`,
a `list` of length `40`.
The valid index values of `a` are integers ranging from
`-40` to `39`.

Exception raised on line 24 of file TESTS:\runtime\test_index_error.py.

   22:     b = tuple(range(50))
   23:     try:
--&gt;24:         print(a[60], b[0])
                     ^^^^^
   25:     except IndexError as e:

        a:  [0, 1, 2, 3, 4, 5, 6, 7, 8, 9, 10, 11, 12, 13, 14, 15, 16, 17, 18, ...]
            len(a): 40
</pre></div>
</div>
</div>
<div class="section" id="short-tuple">
<h3>Short tuple<a class="headerlink" href="#short-tuple" title="Permalink to this headline">¶</a></h3>
<p>Traceback (most recent call last):
File “TESTS:\runtime\test_index_error.py”, line 8, in test_Short_tuple
print(a[3], b[2])
IndexError: tuple index out of range</p>
<div class="highlight-default notranslate"><div class="highlight"><pre><span></span>    Remember: the first item of a `tuple` is not at index 1 but at index 0.
    
An `IndexError` occurs when you try to get an item from a list,
a tuple, or a similar object (sequence), and use an index which
does not exist; typically, this happens because the index you give
is greater than the length of the sequence.

You have tried to get the item with index `3` of `a`,
a `tuple` of length `3`.
The valid index values of `a` are integers ranging from
`-3` to `2`.

Exception raised on line 8 of file TESTS:\runtime\test_index_error.py.

    6:     b = [1, 2, 3]
    7:     try:
--&gt; 8:         print(a[3], b[2])
                     ^^^^
    9:     except IndexError as e:

        a:  (1, 2, 3)
</pre></div>
</div>
</div>
</div>
<hr class="docutils" />
<div class="section" id="keyerror">
<h2>KeyError<a class="headerlink" href="#keyerror" title="Permalink to this headline">¶</a></h2>
<div class="section" id="chainmap">
<h3>ChainMap<a class="headerlink" href="#chainmap" title="Permalink to this headline">¶</a></h3>
<p>Traceback (most recent call last):
File “PYTHON_LIB:\collections_<em>init</em>_.py”, line 965, in pop
return self.maps[0].pop(key, *args)
KeyError: 42</p>
<div class="highlight-default notranslate"><div class="highlight"><pre><span></span><span class="n">During</span> <span class="n">handling</span> <span class="n">of</span> <span class="n">the</span> <span class="n">above</span> <span class="n">exception</span><span class="p">,</span> <span class="n">another</span> <span class="n">exception</span> <span class="n">occurred</span><span class="p">:</span>
</pre></div>
</div>
<p>Traceback (most recent call last):
File “TESTS:\runtime\test_key_error.py”, line 62, in test_ChainMap
d.pop(42)
File “PYTHON_LIB:\collections_<em>init</em>_.py”, line 967, in pop
raise KeyError(‘Key not found in the first mapping: {!r}’.format(key))
KeyError: ‘Key not found in the first mapping: 42’</p>
<div class="highlight-default notranslate"><div class="highlight"><pre><span></span>A `KeyError` is raised when a value is not found as a
key in a Python dict or in a similar object.

The key `42` cannot be found in `d`, an object of type `ChainMap`.

Execution stopped on line 62 of file TESTS:\runtime\test_key_error.py.

   60:     d = ChainMap({}, {})
   61:     try:
--&gt;62:         d.pop(42)
   63:     except KeyError as e:

        d:  ChainMap({}, {})
        d.pop:  &lt;bound method ChainMap.pop of ChainMap({}, {})&gt;
    
Exception raised on line 967 of file PYTHON_LIB:\collections\__init__.py.

   965:             return self.maps[0].pop(key, *args)
   966:         except KeyError:
--&gt;967:             raise KeyError(&#39;Key not found in the first mapping: {!r}&#39;.format(key))

        key:  42
        KeyError:  &lt;class KeyError&gt;
        format:  &lt;builtin function format&gt;
        &#39;Key not found in the first mapping: {!r}&#39;.format:  &lt;builtin method format of str object&gt;
</pre></div>
</div>
</div>
<div class="section" id="forgot-to-convert-to-string">
<h3>Forgot to convert to string<a class="headerlink" href="#forgot-to-convert-to-string" title="Permalink to this headline">¶</a></h3>
<p>Traceback (most recent call last):
File “TESTS:\runtime\test_key_error.py”, line 115, in test_Forgot_to_convert_to_string
print(squares[2])
KeyError: 2</p>
<div class="highlight-default notranslate"><div class="highlight"><pre><span></span>    Did you forget to convert `2` into a string?
    
A `KeyError` is raised when a value is not found as a
key in a Python dict or in a similar object.

The key `2` cannot be found in the dict `squares`.
`squares` contains a string key which is identical to `str(2)`.
Perhaps you forgot to convert the key into a string.

Exception raised on line 115 of file TESTS:\runtime\test_key_error.py.

   113:     squares = {&quot;1&quot;: 1, &quot;2&quot;: 4, &quot;3&quot;: 9}
   114:     try:
--&gt;115:         print(squares[2])
                      ^^^^^^^^^^
   116:     except KeyError as e:

        squares:  {&#39;1&#39;: 1, &#39;2&#39;: 4, &#39;3&#39;: 9}
</pre></div>
</div>
</div>
<div class="section" id="generic-key-error">
<h3>Generic key error<a class="headerlink" href="#generic-key-error" title="Permalink to this headline">¶</a></h3>
<p>Traceback (most recent call last):
File “TESTS:\runtime\test_key_error.py”, line 44, in test_Generic_key_error
d[“c”]
KeyError: ‘c’</p>
<div class="highlight-default notranslate"><div class="highlight"><pre><span></span>A `KeyError` is raised when a value is not found as a
key in a Python dict or in a similar object.

The key `&#39;c&#39;` cannot be found in the dict `d`.

Exception raised on line 44 of file TESTS:\runtime\test_key_error.py.

   42:     d = {&quot;a&quot;: 1, &quot;b&quot;: 2}
   43:     try:
--&gt;44:         d[&quot;c&quot;]
   45:     except KeyError as e:

        d:  {&#39;a&#39;: 1, &#39;b&#39;: 2}
</pre></div>
</div>
</div>
<div class="section" id="popitem-empty-chainmap">
<h3>Popitem empty ChainMap<a class="headerlink" href="#popitem-empty-chainmap" title="Permalink to this headline">¶</a></h3>
<p>Traceback (most recent call last):
File “PYTHON_LIB:\collections_<em>init</em>_.py”, line 958, in popitem
return self.maps[0].popitem()
KeyError: ‘popitem(): dictionary is empty’</p>
<div class="highlight-default notranslate"><div class="highlight"><pre><span></span><span class="n">During</span> <span class="n">handling</span> <span class="n">of</span> <span class="n">the</span> <span class="n">above</span> <span class="n">exception</span><span class="p">,</span> <span class="n">another</span> <span class="n">exception</span> <span class="n">occurred</span><span class="p">:</span>
</pre></div>
</div>
<p>Traceback (most recent call last):
File “TESTS:\runtime\test_key_error.py”, line 26, in test_Popitem_empty_ChainMap
alpha.popitem()
File “PYTHON_LIB:\collections_<em>init</em>_.py”, line 960, in popitem
raise KeyError(‘No keys found in the first mapping.’)
KeyError: ‘No keys found in the first mapping.’</p>
<div class="highlight-default notranslate"><div class="highlight"><pre><span></span>    `alpha` is an empty `ChainMap`.
    
A `KeyError` is raised when a value is not found as a
key in a Python dict or in a similar object.

You tried to retrieve an item from `alpha` which is an empty `ChainMap`.

Execution stopped on line 26 of file TESTS:\runtime\test_key_error.py.

   24:     alpha = ChainMap({}, {})
   25:     try:
--&gt;26:         alpha.popitem()
   27:     except KeyError as e:

        alpha:  ChainMap({}, {})
        alpha.popitem:  &lt;bound method ChainMap.popitem of ChainMap({}, {})&gt;
    
Exception raised on line 960 of file PYTHON_LIB:\collections\__init__.py.

   958:             return self.maps[0].popitem()
   959:         except KeyError:
--&gt;960:             raise KeyError(&#39;No keys found in the first mapping.&#39;)

        KeyError:  &lt;class KeyError&gt;
</pre></div>
</div>
</div>
<div class="section" id="popitem-empty-dict">
<h3>Popitem empty dict<a class="headerlink" href="#popitem-empty-dict" title="Permalink to this headline">¶</a></h3>
<p>Traceback (most recent call last):
File “TESTS:\runtime\test_key_error.py”, line 8, in test_Popitem_empty_dict
d.popitem()
KeyError: ‘popitem(): dictionary is empty’</p>
<div class="highlight-default notranslate"><div class="highlight"><pre><span></span>    `d` is an empty `dict`.
    
A `KeyError` is raised when a value is not found as a
key in a Python dict or in a similar object.

You tried to retrieve an item from `d` which is an empty `dict`.

Exception raised on line 8 of file TESTS:\runtime\test_key_error.py.

    6:     d = {}
    7:     try:
--&gt; 8:         d.popitem()
    9:     except KeyError as e:

        d:  {}
        d.popitem:  &lt;builtin method popitem of dict object&gt;
</pre></div>
</div>
</div>
<div class="section" id="similar-names">
<h3>Similar names<a class="headerlink" href="#similar-names" title="Permalink to this headline">¶</a></h3>
<p>Traceback (most recent call last):
File “TESTS:\runtime\test_key_error.py”, line 145, in test_Similar_names
a = second[“alpha”]
KeyError: ‘alpha’</p>
<div class="highlight-default notranslate"><div class="highlight"><pre><span></span>    Did you mean `&#39;alpha0&#39;`?
    
A `KeyError` is raised when a value is not found as a
key in a Python dict or in a similar object.

The key `&#39;alpha&#39;` cannot be found in the dict `second`.
`second` has some keys similar to `&#39;alpha&#39;` including:
`&#39;alpha0&#39;, &#39;alpha12&#39;, &#39;alpha11&#39;`.

Exception raised on line 145 of file TESTS:\runtime\test_key_error.py.

   143:     second = {&quot;alpha0&quot;: 1, &quot;alpha11&quot;: 2, &quot;alpha12&quot;: 3}
   144:     try:
--&gt;145:         a = second[&quot;alpha&quot;]
                    ^^^^^^^^^^^^^^^
   146:     except KeyError as e:

        second:  {&#39;alpha0&#39;: 1, &#39;alpha11&#39;: 2, &#39;alpha12&#39;: 3}
</pre></div>
</div>
</div>
<div class="section" id="string-by-mistake">
<h3>String by mistake<a class="headerlink" href="#string-by-mistake" title="Permalink to this headline">¶</a></h3>
<p>Traceback (most recent call last):
File “TESTS:\runtime\test_key_error.py”, line 98, in test_String_by_mistake
d[“(0, 0)”]
KeyError: ‘(0, 0)’</p>
<div class="highlight-default notranslate"><div class="highlight"><pre><span></span>    Did you convert `(0, 0)` into a string by mistake?
    
A `KeyError` is raised when a value is not found as a
key in a Python dict or in a similar object.

The key `&#39;(0, 0)&#39;` cannot be found in the dict `d`.
`&#39;(0, 0)&#39;` is a string.
There is a key of `d` whose string representation
is identical to `&#39;(0, 0)&#39;`.

Exception raised on line 98 of file TESTS:\runtime\test_key_error.py.

    96:     d = {(0, 0): &quot;origin&quot;}
    97:     try:
--&gt; 98:         d[&quot;(0, 0)&quot;]
    99:     except KeyError as e:

        d:  {(0, 0): &#39;origin&#39;}
</pre></div>
</div>
</div>
</div>
<hr class="docutils" />
<div class="section" id="lookuperror">
<h2>LookupError<a class="headerlink" href="#lookuperror" title="Permalink to this headline">¶</a></h2>
<div class="section" id="id5">
<h3>Generic<a class="headerlink" href="#id5" title="Permalink to this headline">¶</a></h3>
<p>Traceback (most recent call last):
File “TESTS:\runtime\test_lookup_error.py”, line 10, in test_Generic
raise LookupError(“Fake message”)
LookupError: Fake message</p>
<div class="highlight-default notranslate"><div class="highlight"><pre><span></span>`LookupError` is the base class for the exceptions that are raised
when a key or index used on a mapping or sequence is invalid.
It can also be raised directly by codecs.lookup().

Exception raised on line 10 of file TESTS:\runtime\test_lookup_error.py.

    8:         # other than possibly codecs.lookup(), which is why we raise
    9:         # it directly here for our example.
--&gt;10:         raise LookupError(&quot;Fake message&quot;)
   11:     except LookupError as e:

        LookupError:  &lt;class LookupError&gt;
</pre></div>
</div>
</div>
</div>
<hr class="docutils" />
<div class="section" id="modulenotfounderror">
<h2>ModuleNotFoundError<a class="headerlink" href="#modulenotfounderror" title="Permalink to this headline">¶</a></h2>
<div class="section" id="need-to-install-module">
<h3>Need to install module<a class="headerlink" href="#need-to-install-module" title="Permalink to this headline">¶</a></h3>
<p>Traceback (most recent call last):
File “TESTS:\runtime\test_module_not_found_error.py”, line 76, in test_Need_to_install_module
import alphabet
ModuleNotFoundError: No module named ‘alphabet’</p>
<div class="highlight-default notranslate"><div class="highlight"><pre><span></span>A `ModuleNotFoundError` exception indicates that you
are trying to import a module that cannot be found by Python.
This could be because you misspelled the name of the module
or because it is not installed on your computer.

No module named `alphabet` can be imported.
Perhaps you need to install it.

Exception raised on line 76 of file TESTS:\runtime\test_module_not_found_error.py.

   74: def test_Need_to_install_module():
   75:     try:
--&gt;76:         import alphabet
   77:     except ModuleNotFoundError as e:
</pre></div>
</div>
</div>
<div class="section" id="not-a-package">
<h3>Not a package<a class="headerlink" href="#not-a-package" title="Permalink to this headline">¶</a></h3>
<p>Traceback (most recent call last):
File “TESTS:\runtime\test_module_not_found_error.py”, line 22, in test_Not_a_package
import os.xxx
ModuleNotFoundError: No module named ‘os.xxx’; ‘os’ is not a package</p>
<div class="highlight-default notranslate"><div class="highlight"><pre><span></span>A `ModuleNotFoundError` exception indicates that you
are trying to import a module that cannot be found by Python.
This could be because you misspelled the name of the module
or because it is not installed on your computer.

`xxx` cannot be imported from `os`.

Exception raised on line 22 of file TESTS:\runtime\test_module_not_found_error.py.

   20: 
   21:     try:
--&gt;22:         import os.xxx
   23:     except ModuleNotFoundError as e:
</pre></div>
</div>
</div>
<div class="section" id="not-a-package-similar-name">
<h3>Not a package similar name<a class="headerlink" href="#not-a-package-similar-name" title="Permalink to this headline">¶</a></h3>
<p>Traceback (most recent call last):
File “TESTS:\runtime\test_module_not_found_error.py”, line 36, in test_Not_a_package_similar_name
import os.pathh
ModuleNotFoundError: No module named ‘os.pathh’; ‘os’ is not a package</p>
<div class="highlight-default notranslate"><div class="highlight"><pre><span></span>    Did you mean `import os.path`?
    
A `ModuleNotFoundError` exception indicates that you
are trying to import a module that cannot be found by Python.
This could be because you misspelled the name of the module
or because it is not installed on your computer.

Perhaps you meant `import os.path`.
`path` is a name similar to `pathh` and is a module that
can be imported from `os`.
Other objects with similar names that are part of
 `os` include `fspath`.

Exception raised on line 36 of file TESTS:\runtime\test_module_not_found_error.py.

   34: def test_Not_a_package_similar_name():
   35:     try:
--&gt;36:         import os.pathh
   37:     except ModuleNotFoundError as e:
</pre></div>
</div>
</div>
<div class="section" id="object-not-module">
<h3>Object not module<a class="headerlink" href="#object-not-module" title="Permalink to this headline">¶</a></h3>
<p>Traceback (most recent call last):
File “TESTS:\runtime\test_module_not_found_error.py”, line 49, in test_Object_not_module
import os.open
ModuleNotFoundError: No module named ‘os.open’; ‘os’ is not a package</p>
<div class="highlight-default notranslate"><div class="highlight"><pre><span></span>    Did you mean `from os import open`?
    
A `ModuleNotFoundError` exception indicates that you
are trying to import a module that cannot be found by Python.
This could be because you misspelled the name of the module
or because it is not installed on your computer.

`open` is not a separate module but an object that is part of `os`.

Exception raised on line 49 of file TESTS:\runtime\test_module_not_found_error.py.

   47: def test_Object_not_module():
   48:     try:
--&gt;49:         import os.open
   50:     except ModuleNotFoundError as e:

        open:  &lt;builtin function open&gt;
</pre></div>
</div>
</div>
<div class="section" id="similar-object-not-module">
<h3>Similar object not module<a class="headerlink" href="#similar-object-not-module" title="Permalink to this headline">¶</a></h3>
<p>Traceback (most recent call last):
File “TESTS:\runtime\test_module_not_found_error.py”, line 62, in test_Similar_object_not_module
import os.opend
ModuleNotFoundError: No module named ‘os.opend’; ‘os’ is not a package</p>
<div class="highlight-default notranslate"><div class="highlight"><pre><span></span>    Did you mean `from os import open`?
    
A `ModuleNotFoundError` exception indicates that you
are trying to import a module that cannot be found by Python.
This could be because you misspelled the name of the module
or because it is not installed on your computer.

Perhaps you meant `from os import open`.
`open` is a name similar to `opend` and is an object that
can be imported from `os`.
Other objects with similar names that are part of
 `os` include `popen, fdopen`.

Exception raised on line 62 of file TESTS:\runtime\test_module_not_found_error.py.

   60: def test_Similar_object_not_module():
   61:     try:
--&gt;62:         import os.opend
   63:     except ModuleNotFoundError as e:
</pre></div>
</div>
</div>
<div class="section" id="standard-library-module">
<h3>Standard library module<a class="headerlink" href="#standard-library-module" title="Permalink to this headline">¶</a></h3>
<p>Traceback (most recent call last):
File “TESTS:\runtime\test_module_not_found_error.py”, line 7, in test_Standard_library_module
import Tkinter
ModuleNotFoundError: No module named ‘Tkinter’</p>
<div class="highlight-default notranslate"><div class="highlight"><pre><span></span>    Did you mean `tkinter`?
    
A `ModuleNotFoundError` exception indicates that you
are trying to import a module that cannot be found by Python.
This could be because you misspelled the name of the module
or because it is not installed on your computer.

No module named `Tkinter` can be imported.
Perhaps you need to install it.
`tkinter` is an existing module that has a similar name.

Exception raised on line 7 of file TESTS:\runtime\test_module_not_found_error.py.

   5: def test_Standard_library_module():
   6:     try:
--&gt;7:         import Tkinter
   8:     except ModuleNotFoundError as e:
</pre></div>
</div>
</div>
<div class="section" id="no-curses">
<h3>no curses<a class="headerlink" href="#no-curses" title="Permalink to this headline">¶</a></h3>
<p>Traceback (most recent call last):
File “TESTS:\runtime\test_module_not_found_error.py”, line 92, in test_no_curses
import curses
File “PYTHON_LIB:\curses_<em>init</em>_.py”, line 13, in <module>
from _curses import *
ModuleNotFoundError: No module named ‘_curses’</p>
<div class="highlight-default notranslate"><div class="highlight"><pre><span></span>    The curses module is rarely installed with Python on Windows.
    
A `ModuleNotFoundError` exception indicates that you
are trying to import a module that cannot be found by Python.
This could be because you misspelled the name of the module
or because it is not installed on your computer.

You have tried to import the curses module.
The curses module is rarely installed with Python on Windows.

Execution stopped on line 92 of file TESTS:\runtime\test_module_not_found_error.py.

   90:     def test_no_curses():
   91:         try:
--&gt;92:             import curses
   93:         except ModuleNotFoundError as e:

Exception raised on line 13 of file PYTHON_LIB:\curses\__init__.py.

   11: &quot;&quot;&quot;
   12: 
--&gt;13: from _curses import *
   14: import os as _os
</pre></div>
</div>
</div>
</div>
<hr class="docutils" />
<div class="section" id="nameerror">
<h2>NameError<a class="headerlink" href="#nameerror" title="Permalink to this headline">¶</a></h2>
<div class="section" id="annotated-variable">
<h3>Annotated variable<a class="headerlink" href="#annotated-variable" title="Permalink to this headline">¶</a></h3>
<p>Traceback (most recent call last):
File “TESTS:\runtime\test_name_error.py”, line 24, in test_Annotated_variable
y = x
NameError: name ‘x’ is not defined</p>
<div class="highlight-default notranslate"><div class="highlight"><pre><span></span>    Did you use a colon instead of an equal sign?
    
A `NameError` exception indicates that a variable or
function name is not known to Python.
Most often, this is because there is a spelling mistake.
However, sometimes it is because the name is used
before being defined or given a value.

In your program, no object with the name `x` exists.
A type hint found for `x` in the global scope.
Perhaps you had used a colon instead of an equal sign and wrote

    x : 3

instead of

    x = 3

Exception raised on line 24 of file TESTS:\runtime\test_name_error.py.

   22: def test_Annotated_variable():
   23:     try:
--&gt;24:         y = x
                   ^
   25:     except NameError as e:
</pre></div>
</div>
</div>
<div class="section" id="custom-name">
<h3>Custom name<a class="headerlink" href="#custom-name" title="Permalink to this headline">¶</a></h3>
<p>Traceback (most recent call last):
File “TESTS:\runtime\test_name_error.py”, line 163, in test_Custom_name
python
NameError: name ‘python’ is not defined</p>
<div class="highlight-default notranslate"><div class="highlight"><pre><span></span>    You are already using Python!
A `NameError` exception indicates that a variable or
function name is not known to Python.
Most often, this is because there is a spelling mistake.
However, sometimes it is because the name is used
before being defined or given a value.

You are already using Python!
Exception raised on line 163 of file TESTS:\runtime\test_name_error.py.

   161: def test_Custom_name():
   162:     try:
--&gt;163:         python
                ^^^^^^
   164:     except NameError as e:
</pre></div>
</div>
</div>
<div class="section" id="free-variable-referenced">
<h3>Free variable referenced<a class="headerlink" href="#free-variable-referenced" title="Permalink to this headline">¶</a></h3>
<p>Traceback (most recent call last):
File “TESTS:\runtime\test_name_error.py”, line 149, in test_Free_variable_referenced
outer()
File “TESTS:\runtime\test_name_error.py”, line 145, in outer
inner()
File “TESTS:\runtime\test_name_error.py”, line 144, in inner
return var
NameError: free variable ‘var’ referenced before assignment in enclosing scope</p>
<div class="highlight-default notranslate"><div class="highlight"><pre><span></span>A `NameError` exception indicates that a variable or
function name is not known to Python.
Most often, this is because there is a spelling mistake.
However, sometimes it is because the name is used
before being defined or given a value.

In your program, `var` is an unknown name
that exists in an enclosing scope,
but has not yet been assigned a value.

Execution stopped on line 149 of file TESTS:\runtime\test_name_error.py.

   147: 
   148:     try:
--&gt;149:         outer()
   150:     except NameError as e:

        outer:  &lt;function outer&gt; from test_Free_variable_referenced
    
Exception raised on line 144 of file TESTS:\runtime\test_name_error.py.

   142:     def outer():
   143:         def inner():
--&gt;144:             return var
                           ^^^
   145:         inner()
</pre></div>
</div>
</div>
<div class="section" id="id6">
<h3>Generic<a class="headerlink" href="#id6" title="Permalink to this headline">¶</a></h3>
<p>Traceback (most recent call last):
File “TESTS:\runtime\test_name_error.py”, line 9, in test_Generic
this = something
NameError: name ‘something’ is not defined</p>
<div class="highlight-default notranslate"><div class="highlight"><pre><span></span>A `NameError` exception indicates that a variable or
function name is not known to Python.
Most often, this is because there is a spelling mistake.
However, sometimes it is because the name is used
before being defined or given a value.

In your program, no object with the name `something` exists.
I have no additional information for you.

Exception raised on line 9 of file TESTS:\runtime\test_name_error.py.

    7: def test_Generic():
    8:     try:
--&gt; 9:         this = something
                      ^^^^^^^^^
   10:     except NameError as e:
</pre></div>
</div>
</div>
<div class="section" id="missing-import">
<h3>Missing import<a class="headerlink" href="#missing-import" title="Permalink to this headline">¶</a></h3>
<p>Traceback (most recent call last):
File “TESTS:\runtime\test_name_error.py”, line 129, in test_Missing_import
unicodedata.something
NameError: name ‘unicodedata’ is not defined</p>
<div class="highlight-default notranslate"><div class="highlight"><pre><span></span>    Did you forget to import `unicodedata`?
    
A `NameError` exception indicates that a variable or
function name is not known to Python.
Most often, this is because there is a spelling mistake.
However, sometimes it is because the name is used
before being defined or given a value.

The name `unicodedata` is not defined in your program.
Perhaps you forgot to import `unicodedata` which is found
in Python&#39;s standard library.

Exception raised on line 129 of file TESTS:\runtime\test_name_error.py.

   127: 
   128:     try:
--&gt;129:         unicodedata.something
                ^^^^^^^^^^^
   130:     except NameError as e:
</pre></div>
</div>
</div>
<div class="section" id="synonym">
<h3>Synonym<a class="headerlink" href="#synonym" title="Permalink to this headline">¶</a></h3>
<p>Traceback (most recent call last):
File “TESTS:\runtime\test_name_error.py”, line 89, in test_Synonym
cost  # wrote from math import * above
NameError: name ‘cost’ is not defined</p>
<div class="highlight-default notranslate"><div class="highlight"><pre><span></span>    Did you mean `cos`?
    
A `NameError` exception indicates that a variable or
function name is not known to Python.
Most often, this is because there is a spelling mistake.
However, sometimes it is because the name is used
before being defined or given a value.

In your program, no object with the name `cost` exists.
Instead of writing `cost`, perhaps you meant one of the following:
*   Global scope: `cos`, `cosh`, `acos`

Exception raised on line 89 of file TESTS:\runtime\test_name_error.py.

   87: 
   88:     try:
--&gt;89:         cost  # wrote from math import * above
               ^^^^
   90:     except NameError as e:
</pre></div>
</div>
</div>
</div>
<hr class="docutils" />
<div class="section" id="oserror">
<h2>OsError<a class="headerlink" href="#oserror" title="Permalink to this headline">¶</a></h2>
<div class="section" id="urllib-error">
<h3>Urllib error<a class="headerlink" href="#urllib-error" title="Permalink to this headline">¶</a></h3>
<p>Traceback (most recent call last):
File “PYTHON_LIB:\urllib\request.py”, line 1354, in do_open
… More lines not shown. …
File “PYTHON_LIB:\socket.py”, line 787, in create_connection
for res in getaddrinfo(host, port, 0, SOCK_STREAM):
File “PYTHON_LIB:\socket.py”, line 918, in getaddrinfo
for res in _socket.getaddrinfo(host, port, family, type, proto, flags):
socket.gaierror: [Errno 11001] getaddrinfo failed</p>
<div class="highlight-default notranslate"><div class="highlight"><pre><span></span><span class="n">During</span> <span class="n">handling</span> <span class="n">of</span> <span class="n">the</span> <span class="n">above</span> <span class="n">exception</span><span class="p">,</span> <span class="n">another</span> <span class="n">exception</span> <span class="n">occurred</span><span class="p">:</span>
</pre></div>
</div>
<p>Traceback (most recent call last):
File “TESTS:\runtime\test_os_error.py”, line 7, in test_Urllib_error
request.urlopen(“http://does_not_exist”)
… More lines not shown. …
File “PYTHON_LIB:\urllib\request.py”, line 1383, in http_open
return self.do_open(http.client.HTTPConnection, req)
File “PYTHON_LIB:\urllib\request.py”, line 1357, in do_open
raise URLError(err)
URLError: &lt;urlopen error [Errno 11001] getaddrinfo failed&gt;</p>
<div class="highlight-default notranslate"><div class="highlight"><pre><span></span>An exception of type `URLError` is a subclass of `OSError`.
An `OSError` exception is usually raised by the Operating System
to indicate that an operation is not allowed or that
a resource is not available.

I suspect that you are trying to connect to a server and
that a connection cannot be made.

If that is the case, check for typos in the URL
and check your internet connectivity.

Execution stopped on line 7 of file TESTS:\runtime\test_os_error.py.

   5:     from urllib import request, error
   6:     try:
--&gt;7:         request.urlopen(&quot;http://does_not_exist&quot;)
   8:     except error.URLError as e:

        request:  &lt;module urllib.request&gt; from PYTHON_LIB:\urllib\request.py
        request.urlopen:  &lt;function urlopen&gt;
    
Exception raised on line 1357 of file PYTHON_LIB:\urllib\request.py.

   1355:                           encode_chunked=req.has_header(&#39;Transfer-encoding&#39;))
   1356:             except OSError as err: # timeout error
--&gt;1357:                 raise URLError(err)
   1358:             r = h.getresponse()

        global URLError:  &lt;class urllib.error.URLError&gt;
</pre></div>
</div>
</div>
</div>
<hr class="docutils" />
<div class="section" id="overflowerror">
<h2>OverflowError<a class="headerlink" href="#overflowerror" title="Permalink to this headline">¶</a></h2>
<div class="section" id="id7">
<h3>Generic<a class="headerlink" href="#id7" title="Permalink to this headline">¶</a></h3>
<p>Traceback (most recent call last):
File “TESTS:\runtime\test_overflow_error.py”, line 6, in test_Generic
2.0 ** 1600
OverflowError: (34, ‘Result too large’)</p>
<div class="highlight-default notranslate"><div class="highlight"><pre><span></span>An `OverflowError` is raised when the result of an arithmetic operation
is too large to be handled by the computer&#39;s processor.

Exception raised on line 6 of file TESTS:\runtime\test_overflow_error.py.

   4: def test_Generic():
   5:     try:
--&gt;6:         2.0 ** 1600
   7:     except OverflowError as e:
</pre></div>
</div>
</div>
</div>
<hr class="docutils" />
<div class="section" id="recursionerror">
<h2>RecursionError<a class="headerlink" href="#recursionerror" title="Permalink to this headline">¶</a></h2>
<div class="section" id="id8">
<h3>Generic<a class="headerlink" href="#id8" title="Permalink to this headline">¶</a></h3>
<p>Traceback (most recent call last):
File “TESTS:\runtime\test_recursion_error.py”, line 8, in test_Generic
a()
… More lines not shown. …
File “TESTS:\runtime\test_recursion_error.py”, line 6, in a
return a()
File “TESTS:\runtime\test_recursion_error.py”, line 6, in a
return a()
RecursionError: maximum recursion depth exceeded</p>
<div class="highlight-default notranslate"><div class="highlight"><pre><span></span>A `RecursionError` is raised when a function calls itself,
directly or indirectly, too many times.
It almost always indicates that you made an error in your code
and that your program would never stop.

Execution stopped on line 8 of file TESTS:\runtime\test_recursion_error.py.

    6:         return a()
    7:     try:
--&gt; 8:         a()
    9:     except RecursionError as e:

        a:  &lt;function a&gt; from test_Generic
    
Exception raised on line 6 of file TESTS:\runtime\test_recursion_error.py.

   4: def test_Generic():
   5:     def a():
--&gt;6:         return a()
                     ^^^
   7:     try:

        a:  &lt;function a&gt; from test_Generic
</pre></div>
</div>
</div>
</div>
<hr class="docutils" />
<div class="section" id="typeerror">
<h2>TypeError<a class="headerlink" href="#typeerror" title="Permalink to this headline">¶</a></h2>
<div class="section" id="bad-type-for-unary-operator">
<h3>Bad type for unary operator<a class="headerlink" href="#bad-type-for-unary-operator" title="Permalink to this headline">¶</a></h3>
<p>Traceback (most recent call last):
File “TESTS:\runtime\test_type_error.py”, line 371, in test_Bad_type_for_unary_operator
a =+ “def”
TypeError: bad operand type for unary +: ‘str’</p>
<div class="highlight-default notranslate"><div class="highlight"><pre><span></span>    Perhaps you meant to write `+=` instead of `=+`
A `TypeError` is usually caused by trying
to combine two incompatible types of objects,
by calling a function with the wrong type of object,
or by trying to do an operation not allowed on a given type of object.

You tried to use the unary operator &#39;+&#39;
with the following type of object: a string (`str`).
This operation is not defined for this type of object.

Perhaps you meant to write `+=` instead of `=+`

Exception raised on line 371 of file TESTS:\runtime\test_type_error.py.

   369:         # fmt: off
   370:         a = &quot;abc&quot;
--&gt;371:         a =+ &quot;def&quot;
                   ^^^^^^^
   372:         # fmt: on
</pre></div>
</div>
</div>
<div class="section" id="builtin-has-no-len">
<h3>Builtin has no len<a class="headerlink" href="#builtin-has-no-len" title="Permalink to this headline">¶</a></h3>
<p>Traceback (most recent call last):
File “TESTS:\runtime\test_type_error.py”, line 780, in test_Builtin_has_no_len
len(“Hello world”.split)
TypeError: object of type ‘builtin_function_or_method’ has no len()</p>
<div class="highlight-default notranslate"><div class="highlight"><pre><span></span>    Did you forget to call `&quot;Hello world&quot;.split`?
    
A `TypeError` is usually caused by trying
to combine two incompatible types of objects,
by calling a function with the wrong type of object,
or by trying to do an operation not allowed on a given type of object.

I suspect that you forgot to add parentheses to call `&quot;Hello world&quot;.split`.
You might have meant to write:
`len(&quot;Hello world&quot;.split())`

Exception raised on line 780 of file TESTS:\runtime\test_type_error.py.

   778: def test_Builtin_has_no_len():
   779:     try:
--&gt;780:         len(&quot;Hello world&quot;.split)
   781:     except TypeError as e:

        len:  &lt;builtin function len&gt;
        &quot;Hello world&quot;.split:  &lt;builtin method split of str object&gt;
</pre></div>
</div>
</div>
<div class="section" id="can-only-concatenate">
<h3>Can only concatenate<a class="headerlink" href="#can-only-concatenate" title="Permalink to this headline">¶</a></h3>
<p>Traceback (most recent call last):
File “TESTS:\runtime\test_type_error.py”, line 37, in test_Can_only_concatenate
result = a_tuple + a_list
TypeError: can only concatenate tuple (not “list”) to tuple</p>
<div class="highlight-default notranslate"><div class="highlight"><pre><span></span>A `TypeError` is usually caused by trying
to combine two incompatible types of objects,
by calling a function with the wrong type of object,
or by trying to do an operation not allowed on a given type of object.

You tried to concatenate (add) two different types of objects:
a `tuple` and a `list`.

Exception raised on line 37 of file TESTS:\runtime\test_type_error.py.

   35:         a_tuple = (1, 2, 3)
   36:         a_list = [1, 2, 3]
--&gt;37:         result = a_tuple + a_list
                        ^^^^^^^^^^^^^^^^
   38:     except TypeError as e:

        a_list:  [1, 2, 3]
        a_tuple:  (1, 2, 3)
</pre></div>
</div>
</div>
<div class="section" id="cannot-convert-dictionary-update-sequence">
<h3>Cannot convert dictionary update sequence<a class="headerlink" href="#cannot-convert-dictionary-update-sequence" title="Permalink to this headline">¶</a></h3>
<p>Traceback (most recent call last):
File “TESTS:\runtime\test_type_error.py”, line 766, in test_Cannot_convert_dictionary_update_sequence
dd.update([1, 2, 3])
TypeError: cannot convert dictionary update sequence element #0 to a sequence</p>
<div class="highlight-default notranslate"><div class="highlight"><pre><span></span>    Perhaps you need to use the `dict.fromkeys()` method.
    
A `TypeError` is usually caused by trying
to combine two incompatible types of objects,
by calling a function with the wrong type of object,
or by trying to do an operation not allowed on a given type of object.

`dict.update()` does not accept a sequence as an argument.
Instead of writing `dd.update([1, 2, 3])`
perhaps you should use the `dict.fromkeys()` method: `dd.update( dict.fromkeys([1, 2, 3]) )`.

Exception raised on line 766 of file TESTS:\runtime\test_type_error.py.

   764:     dd = {&quot;a&quot;: &quot;a&quot;}
   765:     try:
--&gt;766:         dd.update([1, 2, 3])
   767:     except TypeError as e:

        dd:  {&#39;a&#39;: &#39;a&#39;}
        dd.update:  &lt;builtin method update of dict object&gt;
</pre></div>
</div>
</div>
<div class="section" id="cannot-multiply-by-non-int">
<h3>Cannot multiply by non int<a class="headerlink" href="#cannot-multiply-by-non-int" title="Permalink to this headline">¶</a></h3>
<p>Traceback (most recent call last):
File “TESTS:\runtime\test_type_error.py”, line 570, in test_Cannot_multiply_by_non_int
“a” * “2”
TypeError: can’t multiply sequence by non-int of type ‘str’</p>
<div class="highlight-default notranslate"><div class="highlight"><pre><span></span>    Did you forget to convert `&quot;2&quot;` into an integer?
    
A `TypeError` is usually caused by trying
to combine two incompatible types of objects,
by calling a function with the wrong type of object,
or by trying to do an operation not allowed on a given type of object.

You can only multiply sequences, such as list, tuples,
 strings, etc., by integers.
Perhaps you forgot to convert `&quot;2&quot;` into an integer.

Exception raised on line 570 of file TESTS:\runtime\test_type_error.py.

   568: 
   569:     try:
--&gt;570:         &quot;a&quot; * &quot;2&quot;
   571:     except TypeError as e:
</pre></div>
</div>
</div>
<div class="section" id="cannot-unpack-non-iterable-object">
<h3>Cannot unpack non iterable object<a class="headerlink" href="#cannot-unpack-non-iterable-object" title="Permalink to this headline">¶</a></h3>
<p>Traceback (most recent call last):
File “TESTS:\runtime\test_type_error.py”, line 738, in test_Cannot_unpack_non_iterable_object
a, b = 42.0
TypeError: cannot unpack non-iterable float object</p>
<div class="highlight-default notranslate"><div class="highlight"><pre><span></span>A `TypeError` is usually caused by trying
to combine two incompatible types of objects,
by calling a function with the wrong type of object,
or by trying to do an operation not allowed on a given type of object.

Unpacking is a convenient way to assign a name,
to each item of an iterable.
An iterable is an object capable of returning its members one at a time.
Python containers (`list, tuple, dict`, etc.) are iterables,
but not objects of type `float`.

Exception raised on line 738 of file TESTS:\runtime\test_type_error.py.

   736: def test_Cannot_unpack_non_iterable_object():
   737:     try:
--&gt;738:         a, b = 42.0
   739:     except TypeError as e:
</pre></div>
</div>
</div>
<div class="section" id="comparison-not-supported">
<h3>Comparison not supported<a class="headerlink" href="#comparison-not-supported" title="Permalink to this headline">¶</a></h3>
<p>Traceback (most recent call last):
File “TESTS:\runtime\test_type_error.py”, line 320, in test_Comparison_not_supported
b &gt;= a
TypeError: ‘&gt;=’ not supported between instances of ‘int’ and ‘str’</p>
<div class="highlight-default notranslate"><div class="highlight"><pre><span></span>    Did you forget to convert the string `a` into an integer (`int`)?
    
A `TypeError` is usually caused by trying
to combine two incompatible types of objects,
by calling a function with the wrong type of object,
or by trying to do an operation not allowed on a given type of object.

You tried to do an order comparison (&gt;=)
between two incompatible types of objects:
an integer (`int`) and a string (`str`).
Perhaps you forgot to convert the string `a` into an integer (`int`).

Exception raised on line 320 of file TESTS:\runtime\test_type_error.py.

   318:         a = &quot;2&quot;
   319:         b = 42
--&gt;320:         b &gt;= a
   321:     except TypeError as e:

        a:  &#39;2&#39;
        b:  42
</pre></div>
</div>
</div>
<div class="section" id="derive-from-baseexception">
<h3>Derive from BaseException<a class="headerlink" href="#derive-from-baseexception" title="Permalink to this headline">¶</a></h3>
<p>Traceback (most recent call last):
File “TESTS:\runtime\test_type_error.py”, line 513, in test_Derive_from_BaseException
raise “exception”  # noqa
TypeError: exceptions must derive from BaseException</p>
<div class="highlight-default notranslate"><div class="highlight"><pre><span></span>A `TypeError` is usually caused by trying
to combine two incompatible types of objects,
by calling a function with the wrong type of object,
or by trying to do an operation not allowed on a given type of object.

In Python 3, exceptions must be derived from BaseException.

Exception raised on line 513 of file TESTS:\runtime\test_type_error.py.

   511: def test_Derive_from_BaseException():
   512:     try:
--&gt;513:         raise &quot;exception&quot;  # noqa
   514:     except TypeError as e:
</pre></div>
</div>
</div>
<div class="section" id="indices-must-be-integers-or-slices">
<h3>Indices must be integers or slices<a class="headerlink" href="#indices-must-be-integers-or-slices" title="Permalink to this headline">¶</a></h3>
<p>Traceback (most recent call last):
File “TESTS:\runtime\test_type_error.py”, line 652, in test_Indices_must_be_integers_or_slices
[1, 2, 3][“2”]
TypeError: list indices must be integers or slices, not str</p>
<div class="highlight-default notranslate"><div class="highlight"><pre><span></span>    Did you forget to convert `&quot;2&quot;` into an integer?
    
A `TypeError` is usually caused by trying
to combine two incompatible types of objects,
by calling a function with the wrong type of object,
or by trying to do an operation not allowed on a given type of object.

In the expression `[1, 2, 3][&quot;2&quot;]`
what is included between the square brackets, `[...]`,
must be either an integer or a slice
(`start:stop` or `start:stop:step`) 
and you have used a string (`str`) instead.

Perhaps you forgot to convert `&quot;2&quot;` into an integer.

Exception raised on line 652 of file TESTS:\runtime\test_type_error.py.

   650: 
   651:     try:
--&gt;652:         [1, 2, 3][&quot;2&quot;]
   653:     except TypeError as e:
</pre></div>
</div>
</div>
<div class="section" id="not-an-integer">
<h3>Not an integer<a class="headerlink" href="#not-an-integer" title="Permalink to this headline">¶</a></h3>
<p>Traceback (most recent call last):
File “TESTS:\runtime\test_type_error.py”, line 615, in test_Not_an_integer
range(c, d)
TypeError: ‘str’ object cannot be interpreted as an integer</p>
<div class="highlight-default notranslate"><div class="highlight"><pre><span></span>    Did you forget to convert `c, d` into integers?
    
A `TypeError` is usually caused by trying
to combine two incompatible types of objects,
by calling a function with the wrong type of object,
or by trying to do an operation not allowed on a given type of object.

You wrote an object of type `str` where an integer was expected.
Perhaps you forgot to convert `c, d` into integers.
Exception raised on line 615 of file TESTS:\runtime\test_type_error.py.

   613:     c, d = &quot;2&quot;, &quot;3&quot;
   614:     try:
--&gt;615:         range(c, d)
   616:     except TypeError as e:

        c:  &#39;2&#39;
        d:  &#39;3&#39;
        range:  &lt;class range&gt;
</pre></div>
</div>
</div>
<div class="section" id="not-callable">
<h3>Not callable<a class="headerlink" href="#not-callable" title="Permalink to this headline">¶</a></h3>
<p>Traceback (most recent call last):
File “TESTS:\runtime\test_type_error.py”, line 500, in test_Not_callable
_ = [1, 2](a + b)
TypeError: ‘list’ object is not callable</p>
<div class="highlight-default notranslate"><div class="highlight"><pre><span></span>    Did you mean `[1, 2][a + b]`?
    
A `TypeError` is usually caused by trying
to combine two incompatible types of objects,
by calling a function with the wrong type of object,
or by trying to do an operation not allowed on a given type of object.

Because of the surrounding parenthesis, `(a + b)` 
is interpreted by Python as indicating a function call for 
`[1, 2]`, which is an object of type `list`
which cannot be called.

However, `[1, 2]` is a sequence.
Perhaps you meant to use `[]` instead of `()` and write
`[1, 2][a + b]`

Exception raised on line 500 of file TESTS:\runtime\test_type_error.py.

   498:     try:
   499:         a, b = 3, 7
--&gt;500:         _ = [1, 2](a + b)
                    ^^^^^^^^^^^^^
   501:     except TypeError as e:

        a:  3
        b:  7
        a + b:  10
</pre></div>
</div>
</div>
<div class="section" id="object-is-not-iterable">
<h3>Object is not iterable<a class="headerlink" href="#object-is-not-iterable" title="Permalink to this headline">¶</a></h3>
<p>Traceback (most recent call last):
File “TESTS:\runtime\test_type_error.py”, line 724, in test_Object_is_not_iterable
list(42)
TypeError: ‘int’ object is not iterable</p>
<div class="highlight-default notranslate"><div class="highlight"><pre><span></span>A `TypeError` is usually caused by trying
to combine two incompatible types of objects,
by calling a function with the wrong type of object,
or by trying to do an operation not allowed on a given type of object.

An iterable is an object capable of returning its members one at a time.
Python containers (`list, tuple, dict`, etc.) are iterables.
An iterable is required here.

Exception raised on line 724 of file TESTS:\runtime\test_type_error.py.

   722: def test_Object_is_not_iterable():
   723:     try:
--&gt;724:         list(42)
   725:     except TypeError as e:

        list:  &lt;class list&gt;
</pre></div>
</div>
</div>
<div class="section" id="object-is-not-subscriptable">
<h3>Object is not subscriptable<a class="headerlink" href="#object-is-not-subscriptable" title="Permalink to this headline">¶</a></h3>
<p>Traceback (most recent call last):
File “TESTS:\runtime\test_type_error.py”, line 710, in test_Object_is_not_subscriptable
a = f[1]
TypeError: ‘function’ object is not subscriptable</p>
<div class="highlight-default notranslate"><div class="highlight"><pre><span></span>    Did you mean `f(1)`?
    
A `TypeError` is usually caused by trying
to combine two incompatible types of objects,
by calling a function with the wrong type of object,
or by trying to do an operation not allowed on a given type of object.

Subscriptable objects are typically containers from which
you can retrieve item using the notation `[...]`.

Perhaps you meant to write `f(1)`.

Exception raised on line 710 of file TESTS:\runtime\test_type_error.py.

   708: 
   709:     try:
--&gt;710:         a = f[1]
                    ^^^^
   711:     except TypeError as e:

        f:  &lt;function f&gt; from test_Object_is_not_subscriptable
</pre></div>
</div>
</div>
<div class="section" id="slice-indices-must-be-integers-or-none">
<h3>Slice indices must be integers or None<a class="headerlink" href="#slice-indices-must-be-integers-or-none" title="Permalink to this headline">¶</a></h3>
<p>Traceback (most recent call last):
File “TESTS:\runtime\test_type_error.py”, line 666, in test_Slice_indices_must_be_integers_or_None
[1, 2, 3][1.0:2.0]
TypeError: slice indices must be integers or None or have an <strong>index</strong> method</p>
<div class="highlight-default notranslate"><div class="highlight"><pre><span></span>A `TypeError` is usually caused by trying
to combine two incompatible types of objects,
by calling a function with the wrong type of object,
or by trying to do an operation not allowed on a given type of object.

When using a slice to extract a range of elements
from a sequence, that is something like
`[start:stop]` or `[start:stop:step]`
each of `start`, `stop`, `step` must be either an integer, `None`,
or possibly some other object having an `__index__` method.

Exception raised on line 666 of file TESTS:\runtime\test_type_error.py.

   664: def test_Slice_indices_must_be_integers_or_None():
   665:     try:
--&gt;666:         [1, 2, 3][1.0:2.0]
   667:     except TypeError as e:
</pre></div>
</div>
</div>
<div class="section" id="too-few-positional-argument">
<h3>Too few positional argument<a class="headerlink" href="#too-few-positional-argument" title="Permalink to this headline">¶</a></h3>
<p>Traceback (most recent call last):
File “TESTS:\runtime\test_type_error.py”, line 441, in test_Too_few_positional_argument
fn(1)
TypeError: fn() missing 2 required positional arguments: ‘b’ and ‘c’</p>
<div class="highlight-default notranslate"><div class="highlight"><pre><span></span>A `TypeError` is usually caused by trying
to combine two incompatible types of objects,
by calling a function with the wrong type of object,
or by trying to do an operation not allowed on a given type of object.

You apparently have called the function &#39;fn()&#39; with
fewer positional arguments than it requires (2 missing).

Exception raised on line 441 of file TESTS:\runtime\test_type_error.py.

   439: 
   440:     try:
--&gt;441:         fn(1)
   442:     except TypeError as e:

        fn:  &lt;function fn&gt; from test_Too_few_positional_argument
</pre></div>
</div>
</div>
<div class="section" id="too-many-positional-argument">
<h3>Too many positional argument<a class="headerlink" href="#too-many-positional-argument" title="Permalink to this headline">¶</a></h3>
<p>Traceback (most recent call last):
File “TESTS:\runtime\test_type_error.py”, line 422, in test_Too_many_positional_argument
A().f(1)
TypeError: f() takes 1 positional argument but 2 were given</p>
<div class="highlight-default notranslate"><div class="highlight"><pre><span></span>    Perhaps you forgot `self` when defining `f`.
    
A `TypeError` is usually caused by trying
to combine two incompatible types of objects,
by calling a function with the wrong type of object,
or by trying to do an operation not allowed on a given type of object.

You apparently have called the function `f` with
2 positional argument(s) while it requires 1
such positional argument(s).
Perhaps you forgot `self` when defining `f`.

Exception raised on line 422 of file TESTS:\runtime\test_type_error.py.

   420: 
   421:     try:
--&gt;422:         A().f(1)
   423:     except TypeError as e:

        A:  &lt;class A&gt; from test_type_error.test_Too_many_positional_argument
</pre></div>
</div>
</div>
<div class="section" id="tuple-no-item-assignment">
<h3>Tuple no item assignment<a class="headerlink" href="#tuple-no-item-assignment" title="Permalink to this headline">¶</a></h3>
<p>Traceback (most recent call last):
File “TESTS:\runtime\test_type_error.py”, line 389, in test_Tuple_no_item_assignment
a[0] = 0
TypeError: ‘tuple’ object does not support item assignment</p>
<div class="highlight-default notranslate"><div class="highlight"><pre><span></span>    Did you mean to use a list?
    
A `TypeError` is usually caused by trying
to combine two incompatible types of objects,
by calling a function with the wrong type of object,
or by trying to do an operation not allowed on a given type of object.

In Python, some objects are known as immutable:
once defined, their value cannot be changed.
You tried change part of such an immutable object: a `tuple`,
most likely by using an indexing operation.
Perhaps you meant to use a list instead.

Exception raised on line 389 of file TESTS:\runtime\test_type_error.py.

   387:     a = (1, 2, 3)
   388:     try:
--&gt;389:         a[0] = 0
   390:     except TypeError as e:

        a:  (1, 2, 3)
        a[0]:  1
</pre></div>
</div>
</div>
<div class="section" id="unhachable-type">
<h3>Unhachable type<a class="headerlink" href="#unhachable-type" title="Permalink to this headline">¶</a></h3>
<p>Traceback (most recent call last):
File “TESTS:\runtime\test_type_error.py”, line 683, in test_Unhachable_type
{[1, 2]: 1}
TypeError: unhashable type: ‘list’</p>
<div class="highlight-default notranslate"><div class="highlight"><pre><span></span>A `TypeError` is usually caused by trying
to combine two incompatible types of objects,
by calling a function with the wrong type of object,
or by trying to do an operation not allowed on a given type of object.

Only hashable objects can be used
as elements of `set` or keys of `dict`.
Hashable objects are objects that do not change value
once they have been created.Instead of using a `list`, consider using a `tuple`.

Exception raised on line 683 of file TESTS:\runtime\test_type_error.py.

   681: def test_Unhachable_type():
   682:     try:
--&gt;683:         {[1, 2]: 1}
   684:     except TypeError as e:
</pre></div>
</div>
</div>
<div class="section" id="unsupported-operand-types">
<h3>Unsupported operand types<a class="headerlink" href="#unsupported-operand-types" title="Permalink to this headline">¶</a></h3>
<p>Traceback (most recent call last):
File “TESTS:\runtime\test_type_error.py”, line 283, in test_Unsupported_operand_types
a &#64;= b
TypeError: unsupported operand type(s) for &#64;=: ‘str’ and ‘int’</p>
<div class="highlight-default notranslate"><div class="highlight"><pre><span></span>A `TypeError` is usually caused by trying
to combine two incompatible types of objects,
by calling a function with the wrong type of object,
or by trying to do an operation not allowed on a given type of object.

You tried to use the operator @=
using two incompatible types of objects:
a string (`str`) and an integer (`int`).
This operator is normally used only
for multiplication of matrices.

Exception raised on line 283 of file TESTS:\runtime\test_type_error.py.

   281:         a = &quot;a&quot;
   282:         b = 2
--&gt;283:         a @= b
   284:     except TypeError as e:

        a:  &#39;a&#39;
        b:  2
</pre></div>
</div>
</div>
<div class="section" id="function-has-no-len">
<h3>function has no len<a class="headerlink" href="#function-has-no-len" title="Permalink to this headline">¶</a></h3>
<p>Traceback (most recent call last):
File “TESTS:\runtime\test_type_error.py”, line 796, in test_function_has_no_len
len(bad)
TypeError: object of type ‘function’ has no len()</p>
<div class="highlight-default notranslate"><div class="highlight"><pre><span></span>    Did you forget to call `bad`?
    
A `TypeError` is usually caused by trying
to combine two incompatible types of objects,
by calling a function with the wrong type of object,
or by trying to do an operation not allowed on a given type of object.

I suspect that you forgot to add parentheses to call `bad`.
You might have meant to write:
`len(bad())`

Exception raised on line 796 of file TESTS:\runtime\test_type_error.py.

   794:         pass
   795:     try:
--&gt;796:         len(bad)
   797:     except TypeError as e:

        bad:  &lt;function bad&gt; from test_function_has_no_len
        len:  &lt;builtin function len&gt;
</pre></div>
</div>
</div>
</div>
<hr class="docutils" />
<div class="section" id="unboundlocalerror">
<h2>UnboundLocalError<a class="headerlink" href="#unboundlocalerror" title="Permalink to this headline">¶</a></h2>
<div class="section" id="missing-both">
<h3>Missing both<a class="headerlink" href="#missing-both" title="Permalink to this headline">¶</a></h3>
<p>Traceback (most recent call last):
File “TESTS:\runtime\test_unbound_local_error.py”, line 61, in test_Missing_both
outer_missing_both()
File “TESTS:\runtime\test_unbound_local_error.py”, line 22, in outer_missing_both
inner()
File “TESTS:\runtime\test_unbound_local_error.py”, line 21, in inner
spam_missing_both += 1
UnboundLocalError: local variable ‘spam_missing_both’ referenced before assignment</p>
<div class="highlight-default notranslate"><div class="highlight"><pre><span></span>    Did you forget to add either `global spam_missing_both` or 
    `nonlocal spam_missing_both`?
    
In Python, variables that are used inside a function are known as 
local variables. Before they are used, they must be assigned a value.
A variable that is used before it is assigned a value is assumed to
be defined outside that function; it is known as a `global`
(or sometimes `nonlocal`) variable. You cannot assign a value to such
a global variable inside a function without first indicating to
Python that this is a global variable, otherwise you will see
an `UnboundLocalError`.

The name `spam_missing_both` exists in both the global and nonlocal scope.
This can be rather confusing and is not recommended.
Depending on which variable you wanted to refer to, you needed to add either

    global spam_missing_both

or

    nonlocal spam_missing_both

as the first line inside your function.

Execution stopped on line 61 of file TESTS:\runtime\test_unbound_local_error.py.

   59: def test_Missing_both():
   60:     try:
--&gt;61:         outer_missing_both()
   62:     except UnboundLocalError as e:

        global outer_missing_both:  &lt;function outer_missing_both&gt;
    
Exception raised on line 21 of file TESTS:\runtime\test_unbound_local_error.py.

   19:     spam_missing_both = 2
   20:     def inner():
--&gt;21:         spam_missing_both += 1
   22:     inner()

        global spam_missing_both:  1
</pre></div>
</div>
</div>
<div class="section" id="missing-global">
<h3>Missing global<a class="headerlink" href="#missing-global" title="Permalink to this headline">¶</a></h3>
<p>Traceback (most recent call last):
File “TESTS:\runtime\test_unbound_local_error.py”, line 27, in test_Missing_global
outer_missing_global()
File “TESTS:\runtime\test_unbound_local_error.py”, line 10, in outer_missing_global
inner()
File “TESTS:\runtime\test_unbound_local_error.py”, line 9, in inner
spam_missing_global += 1
UnboundLocalError: local variable ‘spam_missing_global’ referenced before assignment</p>
<div class="highlight-default notranslate"><div class="highlight"><pre><span></span>    Did you forget to add `global spam_missing_global`?
    
In Python, variables that are used inside a function are known as 
local variables. Before they are used, they must be assigned a value.
A variable that is used before it is assigned a value is assumed to
be defined outside that function; it is known as a `global`
(or sometimes `nonlocal`) variable. You cannot assign a value to such
a global variable inside a function without first indicating to
Python that this is a global variable, otherwise you will see
an `UnboundLocalError`.

The name `spam_missing_global` exists in the global scope.
Perhaps the statement

    global spam_missing_global

should have been included as the first line inside your function.

Execution stopped on line 27 of file TESTS:\runtime\test_unbound_local_error.py.

   25: def test_Missing_global():
   26:     try:
--&gt;27:         outer_missing_global()
   28:     except UnboundLocalError as e:

        global outer_missing_global:  &lt;function outer_missing_global&gt;
    
Exception raised on line 9 of file TESTS:\runtime\test_unbound_local_error.py.

    7: def outer_missing_global():
    8:     def inner():
--&gt; 9:         spam_missing_global += 1
   10:     inner()

        global spam_missing_global:  1
</pre></div>
</div>
</div>
<div class="section" id="missing-nonlocal">
<h3>Missing nonlocal<a class="headerlink" href="#missing-nonlocal" title="Permalink to this headline">¶</a></h3>
<p>Traceback (most recent call last):
File “TESTS:\runtime\test_unbound_local_error.py”, line 44, in test_Missing_nonlocal
outer_missing_nonlocal()
File “TESTS:\runtime\test_unbound_local_error.py”, line 16, in outer_missing_nonlocal
inner()
File “TESTS:\runtime\test_unbound_local_error.py”, line 15, in inner
spam_missing_nonlocal += 1
UnboundLocalError: local variable ‘spam_missing_nonlocal’ referenced before assignment</p>
<div class="highlight-default notranslate"><div class="highlight"><pre><span></span>    Did you forget to add `nonlocal spam_missing_nonlocal`?
    
In Python, variables that are used inside a function are known as 
local variables. Before they are used, they must be assigned a value.
A variable that is used before it is assigned a value is assumed to
be defined outside that function; it is known as a `global`
(or sometimes `nonlocal`) variable. You cannot assign a value to such
a global variable inside a function without first indicating to
Python that this is a global variable, otherwise you will see
an `UnboundLocalError`.

The name `spam_missing_nonlocal` exists in the nonlocal scope.
Perhaps the statement

    nonlocal spam_missing_nonlocal

should have been included as the first line inside your function.

Execution stopped on line 44 of file TESTS:\runtime\test_unbound_local_error.py.

   42: def test_Missing_nonlocal():
   43:     try:
--&gt;44:         outer_missing_nonlocal()
   45:     except UnboundLocalError as e:

        global outer_missing_nonlocal:  &lt;function outer_missing_nonlocal&gt;
    
Exception raised on line 15 of file TESTS:\runtime\test_unbound_local_error.py.

   13:     spam_missing_nonlocal = 1
   14:     def inner():
--&gt;15:         spam_missing_nonlocal += 1
   16:     inner()
</pre></div>
</div>
</div>
<div class="section" id="typo-in-local">
<h3>Typo in local<a class="headerlink" href="#typo-in-local" title="Permalink to this headline">¶</a></h3>
<p>Traceback (most recent call last):
File “TESTS:\runtime\test_unbound_local_error.py”, line 97, in test_Typo_in_local
test2()
File “TESTS:\runtime\test_unbound_local_error.py”, line 94, in test2
alpha3 += 1
UnboundLocalError: local variable ‘alpha3’ referenced before assignment</p>
<div class="highlight-default notranslate"><div class="highlight"><pre><span></span>    Did you mean `alpha2`?
    
In Python, variables that are used inside a function are known as 
local variables. Before they are used, they must be assigned a value.
A variable that is used before it is assigned a value is assumed to
be defined outside that function; it is known as a `global`
(or sometimes `nonlocal`) variable. You cannot assign a value to such
a global variable inside a function without first indicating to
Python that this is a global variable, otherwise you will see
an `UnboundLocalError`.

Instead of writing `alpha3`, perhaps you meant one of the following:
*   Local scope: `alpha2`, `alpha1`

Execution stopped on line 97 of file TESTS:\runtime\test_unbound_local_error.py.

   95: 
   96:     try:
--&gt;97:         test2()
   98:     except UnboundLocalError as e:

        test2:  &lt;function test2&gt; from test_Typo_in_local
    
Exception raised on line 94 of file TESTS:\runtime\test_unbound_local_error.py.

   92:         alpha1 = 1
   93:         alpha2 = 1
--&gt;94:         alpha3 += 1
</pre></div>
</div>
</div>
</div>
<hr class="docutils" />
<div class="section" id="unknownerror">
<h2>UnknownError<a class="headerlink" href="#unknownerror" title="Permalink to this headline">¶</a></h2>
<div class="section" id="id9">
<h3>Generic<a class="headerlink" href="#id9" title="Permalink to this headline">¶</a></h3>
<p>Traceback (most recent call last):
File “TESTS:\runtime\test_unknown_error.py”, line 12, in test_Generic
raise MyException(“Some informative message about an unknown exception.”)
MyException: Some informative message about an unknown exception.</p>
<div class="highlight-default notranslate"><div class="highlight"><pre><span></span>No information is known about this exception.
Please report this example to https://github.com/aroberge/friendly/issues.
If you are using a REPL, use `www(&#39;bug&#39;)` to do so.

If you are using the Friendly console, use `www()` to
do an Internet search for this particular case.

Exception raised on line 12 of file TESTS:\runtime\test_unknown_error.py.

   10:     friendly_traceback.debug_helper.DEBUG = False
   11:     try:
--&gt;12:         raise MyException(&quot;Some informative message about an unknown exception.&quot;)
   13:     except Exception as e:

        global MyException:  &lt;class test_unknown_error.MyException&gt;
</pre></div>
</div>
</div>
</div>
<hr class="docutils" />
<div class="section" id="valueerror">
<h2>ValueError<a class="headerlink" href="#valueerror" title="Permalink to this headline">¶</a></h2>
<div class="section" id="date-invalid-month">
<h3>Date invalid month<a class="headerlink" href="#date-invalid-month" title="Permalink to this headline">¶</a></h3>
<p>Traceback (most recent call last):
File “TESTS:\runtime\test_value_error.py”, line 58, in test_Date_invalid_month
d = date(2021, 13, 1)
ValueError: month must be in 1..12</p>
<div class="highlight-default notranslate"><div class="highlight"><pre><span></span>    Did you specify an invalid month?
    
A `ValueError` indicates that a function or an operation
received an argument of the right type, but an inappropriate value.

I am guessing that you specify an invalid value for a month
in a `date` object. Valid values are integers, from 1 to 12.

Exception raised on line 58 of file TESTS:\runtime\test_value_error.py.

   56:     from datetime import date
   57:     try:
--&gt;58:         d = date(2021, 13, 1)
                   ^^^^^^^^^^^^^^^^^
   59:     except ValueError as e:

        date:  &lt;class datetime.date&gt;
</pre></div>
</div>
</div>
<div class="section" id="not-enough-values-to-unpack">
<h3>Not enough values to unpack<a class="headerlink" href="#not-enough-values-to-unpack" title="Permalink to this headline">¶</a></h3>
<p>Traceback (most recent call last):
File “TESTS:\runtime\test_value_error.py”, line 28, in test_Not_enough_values_to_unpack
a, b, c = d
ValueError: not enough values to unpack (expected 3, got 2)</p>
<div class="highlight-default notranslate"><div class="highlight"><pre><span></span>A `ValueError` indicates that a function or an operation
received an argument of the right type, but an inappropriate value.

Unpacking is a convenient way to assign a name,
to each item of an iterable.
In this instance, there are more names (3)
than the length of the iterable, a string (`str`) of length 2.

Exception raised on line 28 of file TESTS:\runtime\test_value_error.py.

   26:     d = &quot;ab&quot;
   27:     try:
--&gt;28:         a, b, c = d
   29:     except ValueError as e:

        d:  &#39;ab&#39;
</pre></div>
</div>
</div>
<div class="section" id="too-many-values-to-unpack">
<h3>Too many values to unpack<a class="headerlink" href="#too-many-values-to-unpack" title="Permalink to this headline">¶</a></h3>
<p>Traceback (most recent call last):
File “TESTS:\runtime\test_value_error.py”, line 43, in test_Too_many_values_to_unpack
a, b = c
ValueError: too many values to unpack (expected 2)</p>
<div class="highlight-default notranslate"><div class="highlight"><pre><span></span>A `ValueError` indicates that a function or an operation
received an argument of the right type, but an inappropriate value.

Unpacking is a convenient way to assign a name,
to each item of an iterable.
In this instance, there are fewer names (2)
than the length of the iterable, a `list` of length 3.

Exception raised on line 43 of file TESTS:\runtime\test_value_error.py.

   41:     c = [1, 2, 3]
   42:     try:
--&gt;43:         a, b = c
   44:     except ValueError as e:

        c:  [1, 2, 3]
</pre></div>
</div>
</div>
</div>
<hr class="docutils" />
<div class="section" id="zerodivisionerror">
<h2>ZeroDivisionError<a class="headerlink" href="#zerodivisionerror" title="Permalink to this headline">¶</a></h2>
<div class="section" id="complex-division">
<h3>Complex division<a class="headerlink" href="#complex-division" title="Permalink to this headline">¶</a></h3>
<p>Traceback (most recent call last):
File “TESTS:\runtime\test_zero_division_error.py”, line 155, in test_Complex_division
1 / zero
ZeroDivisionError: complex division by zero</p>
<div class="highlight-default notranslate"><div class="highlight"><pre><span></span>A `ZeroDivisionError` occurs when you are attempting to divide a value
by zero either directly or by using some other mathematical operation.

You are dividing by the following term

     zero

which is equal to zero.

Exception raised on line 155 of file TESTS:\runtime\test_zero_division_error.py.

   153:     zero = 0j
   154:     try:
--&gt;155:         1 / zero
   156:     except ZeroDivisionError as e:

        zero:  0j
</pre></div>
</div>
</div>
<div class="section" id="division-by-zero-literal">
<h3>Division by zero literal<a class="headerlink" href="#division-by-zero-literal" title="Permalink to this headline">¶</a></h3>
<p>Traceback (most recent call last):
File “TESTS:\runtime\test_zero_division_error.py”, line 199, in test_Division_by_zero_literal
1. / 0
ZeroDivisionError: float division by zero</p>
<div class="highlight-default notranslate"><div class="highlight"><pre><span></span>A `ZeroDivisionError` occurs when you are attempting to divide a value
by zero either directly or by using some other mathematical operation.

You are dividing by zero.

Exception raised on line 199 of file TESTS:\runtime\test_zero_division_error.py.

   197: 
   198:     try:
--&gt;199:         1. / 0
   200:     except ZeroDivisionError as e:
</pre></div>
</div>
</div>
<div class="section" id="division-operator">
<h3>Division operator<a class="headerlink" href="#division-operator" title="Permalink to this headline">¶</a></h3>
<p>Traceback (most recent call last):
File “TESTS:\runtime\test_zero_division_error.py”, line 17, in test_Division_operator
1 / zero
ZeroDivisionError: division by zero</p>
<div class="highlight-default notranslate"><div class="highlight"><pre><span></span>A `ZeroDivisionError` occurs when you are attempting to divide a value
by zero either directly or by using some other mathematical operation.

You are dividing by the following term

     zero

which is equal to zero.

Exception raised on line 17 of file TESTS:\runtime\test_zero_division_error.py.

   15: 
   16:     try:
--&gt;17:         1 / zero
   18:     except ZeroDivisionError as e:

        zero:  0
</pre></div>
</div>
</div>
<div class="section" id="divmod">
<h3>Divmod<a class="headerlink" href="#divmod" title="Permalink to this headline">¶</a></h3>
<p>Traceback (most recent call last):
File “TESTS:\runtime\test_zero_division_error.py”, line 82, in test_Divmod
divmod(1, zero)
ZeroDivisionError: integer division or modulo by zero</p>
<div class="highlight-default notranslate"><div class="highlight"><pre><span></span>A `ZeroDivisionError` occurs when you are attempting to divide a value
by zero either directly or by using some other mathematical operation.

The second argument of the `divmod()` function is zero.

Exception raised on line 82 of file TESTS:\runtime\test_zero_division_error.py.

   80:     zero = 0
   81:     try:
--&gt;82:         divmod(1, zero)
   83:     except ZeroDivisionError as e:

        zero:  0
        divmod:  &lt;builtin function divmod&gt;
</pre></div>
</div>
</div>
<div class="section" id="float-division">
<h3>Float division<a class="headerlink" href="#float-division" title="Permalink to this headline">¶</a></h3>
<p>Traceback (most recent call last):
File “TESTS:\runtime\test_zero_division_error.py”, line 125, in test_Float_division
1 / zero
ZeroDivisionError: float division by zero</p>
<div class="highlight-default notranslate"><div class="highlight"><pre><span></span>A `ZeroDivisionError` occurs when you are attempting to divide a value
by zero either directly or by using some other mathematical operation.

You are dividing by the following term

     zero

which is equal to zero.

Exception raised on line 125 of file TESTS:\runtime\test_zero_division_error.py.

   123:     zero = 0.
   124:     try:
--&gt;125:         1 / zero
   126:     except ZeroDivisionError as e:

        zero:  0.0
</pre></div>
</div>
</div>
<div class="section" id="float-divmod">
<h3>Float divmod<a class="headerlink" href="#float-divmod" title="Permalink to this headline">¶</a></h3>
<p>Traceback (most recent call last):
File “TESTS:\runtime\test_zero_division_error.py”, line 140, in test_Float_divmod
divmod(1, zero)
ZeroDivisionError: float divmod()</p>
<div class="highlight-default notranslate"><div class="highlight"><pre><span></span>A `ZeroDivisionError` occurs when you are attempting to divide a value
by zero either directly or by using some other mathematical operation.

The second argument of the `divmod()` function is equal to zero.

Exception raised on line 140 of file TESTS:\runtime\test_zero_division_error.py.

   138:     zero = 0.
   139:     try:
--&gt;140:         divmod(1, zero)
   141:     except ZeroDivisionError as e:

        zero:  0.0
        divmod:  &lt;builtin function divmod&gt;
</pre></div>
</div>
</div>
<div class="section" id="float-modulo">
<h3>Float modulo<a class="headerlink" href="#float-modulo" title="Permalink to this headline">¶</a></h3>
<p>Traceback (most recent call last):
File “TESTS:\runtime\test_zero_division_error.py”, line 110, in test_Float_modulo
1 % zero
ZeroDivisionError: float modulo</p>
<div class="highlight-default notranslate"><div class="highlight"><pre><span></span>A `ZeroDivisionError` occurs when you are attempting to divide a value
by zero either directly or by using some other mathematical operation.

Using the modulo operator, you are dividing by the following term

     zero

which is equal to zero.

Exception raised on line 110 of file TESTS:\runtime\test_zero_division_error.py.

   108: 
   109:     try:
--&gt;110:         1 % zero
   111:     except ZeroDivisionError as e:

        zero:  0.0
</pre></div>
</div>
</div>
<div class="section" id="integer-division-operator">
<h3>Integer division operator<a class="headerlink" href="#integer-division-operator" title="Permalink to this headline">¶</a></h3>
<p>Traceback (most recent call last):
File “TESTS:\runtime\test_zero_division_error.py”, line 42, in test_Integer_division_operator
1 // zero
ZeroDivisionError: integer division or modulo by zero</p>
<div class="highlight-default notranslate"><div class="highlight"><pre><span></span>A `ZeroDivisionError` occurs when you are attempting to divide a value
by zero either directly or by using some other mathematical operation.

You are dividing by the following term

     zero

which is equal to zero.

Exception raised on line 42 of file TESTS:\runtime\test_zero_division_error.py.

   40: 
   41:     try:
--&gt;42:         1 // zero
   43:     except ZeroDivisionError as e:

        zero:  0
</pre></div>
</div>
</div>
<div class="section" id="mixed-operations">
<h3>Mixed operations<a class="headerlink" href="#mixed-operations" title="Permalink to this headline">¶</a></h3>
<p>Traceback (most recent call last):
File “TESTS:\runtime\test_zero_division_error.py”, line 212, in test_Mixed_operations
a = divmod(8, 1 // 2)
ZeroDivisionError: integer division or modulo by zero</p>
<div class="highlight-default notranslate"><div class="highlight"><pre><span></span>A `ZeroDivisionError` occurs when you are attempting to divide a value
by zero either directly or by using some other mathematical operation.

The following mathematical expression includes a division by zero:

    divmod(8, 1 // 2)

Exception raised on line 212 of file TESTS:\runtime\test_zero_division_error.py.

   210: def test_Mixed_operations():
   211:     try:
--&gt;212:         a = divmod(8, 1 // 2)
                    ^^^^^^^^^^^^^^^^^
   213:     except ZeroDivisionError as e:

        divmod:  &lt;builtin function divmod&gt;
        1 // 2:  0
</pre></div>
</div>
</div>
<div class="section" id="modulo-operator">
<h3>Modulo operator<a class="headerlink" href="#modulo-operator" title="Permalink to this headline">¶</a></h3>
<p>Traceback (most recent call last):
File “TESTS:\runtime\test_zero_division_error.py”, line 67, in test_Modulo_operator
1 % zero
ZeroDivisionError: integer division or modulo by zero</p>
<div class="highlight-default notranslate"><div class="highlight"><pre><span></span>A `ZeroDivisionError` occurs when you are attempting to divide a value
by zero either directly or by using some other mathematical operation.

Using the modulo operator, you are dividing by the following term

     zero

which is equal to zero.

Exception raised on line 67 of file TESTS:\runtime\test_zero_division_error.py.

   65: 
   66:     try:
--&gt;67:         1 % zero
   68:     except ZeroDivisionError as e:

        zero:  0
</pre></div>
</div>
</div>
<div class="section" id="raise-zero-negative-power">
<h3>Raise zero negative power<a class="headerlink" href="#raise-zero-negative-power" title="Permalink to this headline">¶</a></h3>
<p>Traceback (most recent call last):
File “TESTS:\runtime\test_zero_division_error.py”, line 170, in test_Raise_zero_negative_power
zero ** -1
ZeroDivisionError: 0.0 cannot be raised to a negative power</p>
<div class="highlight-default notranslate"><div class="highlight"><pre><span></span>A `ZeroDivisionError` occurs when you are attempting to divide a value
by zero either directly or by using some other mathematical operation.

You are attempting to raise the number 0 to a negative power
which is equivalent to dividing by zero.

Exception raised on line 170 of file TESTS:\runtime\test_zero_division_error.py.

   168:     zero = 0
   169:     try:
--&gt;170:         zero ** -1
   171:     except ZeroDivisionError as e:

        zero:  0
</pre></div>
</div>
</div>
</div>
</div>


           </div>
           
          </div>
          <footer>
    <div class="rst-footer-buttons" role="navigation" aria-label="footer navigation">
        <a href="tracebacks_syntax_markdown.html" class="btn btn-neutral float-right" title="Syntax errors - markdown_docs format" accesskey="n" rel="next">Next <span class="fa fa-arrow-circle-right" aria-hidden="true"></span></a>
        <a href="compare.html" class="btn btn-neutral float-left" title="Comparison between Python versions: SyntaxErrors" accesskey="p" rel="prev"><span class="fa fa-arrow-circle-left" aria-hidden="true"></span> Previous</a>
    </div>

  <hr/>

  <div role="contentinfo">
    <p>
        &#169; Copyright André Roberge.

    </p>
  </div>
    
    
    
    Built with <a href="https://www.sphinx-doc.org/">Sphinx</a> using a
    
    <a href="https://github.com/readthedocs/sphinx_rtd_theme">theme</a>
    
    provided by <a href="https://readthedocs.org">Read the Docs</a>. 

</footer>
        </div>
      </div>

    </section>

  </div>
  

  <script type="text/javascript">
      jQuery(function () {
          SphinxRtdTheme.Navigation.enable(true);
      });
  </script>

  
  
    
   

</body>
</html>