

<!DOCTYPE html>
<html class="writer-html5" lang="en" >
<head>
  <meta charset="utf-8">
  
  <meta name="viewport" content="width=device-width, initial-scale=1.0">
  
  <title>Friendly tracebacks - in English &mdash; Friendly tracebacks 0.2.9a documentation</title>
  

  
  <link rel="stylesheet" href="_static/css/theme.css" type="text/css" />
  <link rel="stylesheet" href="_static/pygments.css" type="text/css" />
  <link rel="stylesheet" href="_static/custom.css" type="text/css" />

  
  
  
  

  
  <!--[if lt IE 9]>
    <script src="_static/js/html5shiv.min.js"></script>
  <![endif]-->
  
    
      <script type="text/javascript" id="documentation_options" data-url_root="./" src="_static/documentation_options.js"></script>
        <script src="_static/jquery.js"></script>
        <script src="_static/underscore.js"></script>
        <script src="_static/doctools.js"></script>
        <script src="_static/language_data.js"></script>
    
    <script type="text/javascript" src="_static/js/theme.js"></script>

    
    <link rel="index" title="Index" href="genindex.html" />
    <link rel="search" title="Search" href="search.html" />
    <link rel="next" title="Friendly SyntaxError tracebacks - in English" href="syntax_tracebacks_en_3.10.html" />
    <link rel="prev" title="Friendly SyntaxError tracebacks - in English" href="syntax_tracebacks_en_3.9.html" /> 
</head>

<body class="wy-body-for-nav">

   
  <div class="wy-grid-for-nav">
    
    <nav data-toggle="wy-nav-shift" class="wy-nav-side">
      <div class="wy-side-scroll">
        <div class="wy-side-nav-search" >
          

          
            <a href="index.html" class="icon icon-home" alt="Documentation Home"> Friendly tracebacks
          

          
          </a>

          
            
            
              <div class="version">
                0.2.9a
              </div>
            
          

          
<div role="search">
  <form id="rtd-search-form" class="wy-form" action="search.html" method="get">
    <input type="text" name="q" placeholder="Search docs" />
    <input type="hidden" name="check_keywords" value="yes" />
    <input type="hidden" name="area" value="default" />
  </form>
</div>

          
        </div>

        
        <div class="wy-menu wy-menu-vertical" data-spy="affix" role="navigation" aria-label="main navigation">
          
            
            
              
            
            
              <p class="caption"><span class="caption-text">Begin here</span></p>
<ul>
<li class="toctree-l1"><a class="reference internal" href="usage.html">Installation and basic usage</a></li>
<li class="toctree-l1"><a class="reference internal" href="repl.html">Console basics</a></li>
<li class="toctree-l1"><a class="reference internal" href="editor.html">Using with an editor or IDE</a></li>
<li class="toctree-l1"><a class="reference internal" href="mu.html">Using with Mu</a></li>
<li class="toctree-l1"><a class="reference internal" href="thonny.html">Using with Thonny</a></li>
<li class="toctree-l1"><a class="reference internal" href="ipython.html">IPython and Jupyter notebooks</a></li>
<li class="toctree-l1"><a class="reference internal" href="tracebacks.html">Multiple tracebacks</a></li>
</ul>
<p class="caption"><span class="caption-text">Thoughts on design</span></p>
<ul>
<li class="toctree-l1"><a class="reference internal" href="design.html">Some thoughts on the design of Friendly-traceback</a></li>
<li class="toctree-l1"><a class="reference internal" href="themes.html">Themes and colours</a></li>
</ul>
<p class="caption"><span class="caption-text">Use in your project</span></p>
<ul>
<li class="toctree-l1"><a class="reference internal" href="api.html">Public API</a></li>
<li class="toctree-l1"><a class="reference internal" href="lies.html">Learn to lie</a></li>
<li class="toctree-l1"><a class="reference internal" href="formatter.html">Custom formatter</a></li>
<li class="toctree-l1"><a class="reference internal" href="usage_adv.html">Other details for advanced users</a></li>
<li class="toctree-l1"><a class="reference internal" href="plugins.html">Editor plugins</a></li>
</ul>
<p class="caption"><span class="caption-text">Contribute</span></p>
<ul>
<li class="toctree-l1"><a class="reference internal" href="suggest.html">Suggest an addition</a></li>
<li class="toctree-l1"><a class="reference internal" href="adding_exception.html">Developer: Add a new Exception case</a></li>
<li class="toctree-l1"><a class="reference internal" href="syntax_error.html">Developer: Add a new SyntaxError case</a></li>
<li class="toctree-l1"><a class="reference internal" href="translation_notes.html">Notes on translations - using gettext</a></li>
</ul>
<p class="caption"><span class="caption-text">All the tracebacks!</span></p>
<ul class="current">
<li class="toctree-l1"><a class="reference internal" href="known.html">Generic information about various exceptions</a></li>
<li class="toctree-l1"><a class="reference internal" href="tracebacks_en_3.6.html">Friendly tracebacks - Python 3.6 in English</a></li>
<li class="toctree-l1"><a class="reference internal" href="syntax_tracebacks_en_3.6.html">SyntaxError - Python 3.6 in English</a></li>
<li class="toctree-l1"><a class="reference internal" href="tracebacks_en_3.7.html">Friendly tracebacks - Python 3.7 in English</a></li>
<li class="toctree-l1"><a class="reference internal" href="syntax_tracebacks_en_3.7.html">SyntaxError - Python 3.7 in English</a></li>
<li class="toctree-l1"><a class="reference internal" href="tracebacks_en_3.8.html">Friendly tracebacks - Python 3.8 in English</a></li>
<li class="toctree-l1"><a class="reference internal" href="syntax_tracebacks_en_3.8.html">SyntaxError - Python 3.8 in English</a></li>
<li class="toctree-l1"><a class="reference internal" href="tracebacks_en_3.9.html">Friendly tracebacks - Python 3.9 in English</a></li>
<li class="toctree-l1"><a class="reference internal" href="syntax_tracebacks_en_3.9.html">SyntaxError - Python 3.9 in English</a></li>
<li class="toctree-l1 current"><a class="current reference internal" href="#">Friendly tracebacks - Python 3.10 in English</a><ul>
<li class="toctree-l2"><a class="reference internal" href="#arithmeticerror">ArithmeticError</a><ul>
<li class="toctree-l3"><a class="reference internal" href="#generic">Generic</a></li>
</ul>
</li>
<li class="toctree-l2"><a class="reference internal" href="#attributeerror">AttributeError</a><ul>
<li class="toctree-l3"><a class="reference internal" href="#builtin-function">Builtin function</a></li>
<li class="toctree-l3"><a class="reference internal" href="#builtin-module-with-no-file">Builtin module with no file</a></li>
<li class="toctree-l3"><a class="reference internal" href="#id1">Generic</a></li>
<li class="toctree-l3"><a class="reference internal" href="#module-attribute-typo">Module attribute typo</a></li>
<li class="toctree-l3"><a class="reference internal" href="#nonetype">Nonetype</a></li>
<li class="toctree-l3"><a class="reference internal" href="#object-attribute-typo">Object attribute typo</a></li>
<li class="toctree-l3"><a class="reference internal" href="#perhaps-comma">Perhaps comma</a></li>
<li class="toctree-l3"><a class="reference internal" href="#shadow-stdlib-module">Shadow stdlib module</a></li>
<li class="toctree-l3"><a class="reference internal" href="#use-builtin">Use builtin</a></li>
<li class="toctree-l3"><a class="reference internal" href="#use-synonym">Use synonym</a></li>
</ul>
</li>
<li class="toctree-l2"><a class="reference internal" href="#filenotfounderror">FileNotFoundError</a><ul>
<li class="toctree-l3"><a class="reference internal" href="#id2">Generic</a></li>
</ul>
</li>
<li class="toctree-l2"><a class="reference internal" href="#importerror">ImportError</a><ul>
<li class="toctree-l3"><a class="reference internal" href="#circular-import">Circular import</a></li>
<li class="toctree-l3"><a class="reference internal" href="#simple-import-error">Simple import error</a></li>
</ul>
</li>
<li class="toctree-l2"><a class="reference internal" href="#indexerror">IndexError</a><ul>
<li class="toctree-l3"><a class="reference internal" href="#long-list">Long list</a></li>
<li class="toctree-l3"><a class="reference internal" href="#short-tuple">Short tuple</a></li>
</ul>
</li>
<li class="toctree-l2"><a class="reference internal" href="#keyerror">KeyError</a><ul>
<li class="toctree-l3"><a class="reference internal" href="#id3">Generic</a></li>
</ul>
</li>
<li class="toctree-l2"><a class="reference internal" href="#lookuperror">LookupError</a><ul>
<li class="toctree-l3"><a class="reference internal" href="#id4">Generic</a></li>
</ul>
</li>
<li class="toctree-l2"><a class="reference internal" href="#modulenotfounderror">ModuleNotFoundError</a><ul>
<li class="toctree-l3"><a class="reference internal" href="#not-a-package">Not a package</a></li>
<li class="toctree-l3"><a class="reference internal" href="#standard-library-module">Standard library module</a></li>
</ul>
</li>
<li class="toctree-l2"><a class="reference internal" href="#nameerror">NameError</a><ul>
<li class="toctree-l3"><a class="reference internal" href="#annotated-variable">Annotated variable</a></li>
<li class="toctree-l3"><a class="reference internal" href="#id5">Generic</a></li>
<li class="toctree-l3"><a class="reference internal" href="#synonym">Synonym</a></li>
</ul>
</li>
<li class="toctree-l2"><a class="reference internal" href="#overflowerror">OverflowError</a><ul>
<li class="toctree-l3"><a class="reference internal" href="#id6">Generic</a></li>
</ul>
</li>
<li class="toctree-l2"><a class="reference internal" href="#recursionerror">RecursionError</a><ul>
<li class="toctree-l3"><a class="reference internal" href="#id7">Generic</a></li>
</ul>
</li>
<li class="toctree-l2"><a class="reference internal" href="#typeerror">TypeError</a><ul>
<li class="toctree-l3"><a class="reference internal" href="#bad-type-for-unary-operator">Bad type for unary operator</a></li>
<li class="toctree-l3"><a class="reference internal" href="#can-only-concatenate">Can only concatenate</a></li>
<li class="toctree-l3"><a class="reference internal" href="#cannot-multiply-by-non-int">Cannot multiply by non int</a></li>
<li class="toctree-l3"><a class="reference internal" href="#comparison-not-supported">Comparison not supported</a></li>
<li class="toctree-l3"><a class="reference internal" href="#derive-from-baseexception">Derive from BaseException</a></li>
<li class="toctree-l3"><a class="reference internal" href="#not-an-integer">Not an integer</a></li>
<li class="toctree-l3"><a class="reference internal" href="#not-callable">Not callable</a></li>
<li class="toctree-l3"><a class="reference internal" href="#too-few-positional-argument">Too few positional argument</a></li>
<li class="toctree-l3"><a class="reference internal" href="#too-many-positional-argument">Too many positional argument</a></li>
<li class="toctree-l3"><a class="reference internal" href="#tuple-no-item-assignment">Tuple no item assignment</a></li>
<li class="toctree-l3"><a class="reference internal" href="#unsupported-operand-types">Unsupported operand types</a></li>
</ul>
</li>
<li class="toctree-l2"><a class="reference internal" href="#unboundlocalerror">UnboundLocalError</a><ul>
<li class="toctree-l3"><a class="reference internal" href="#missing-global">Missing global</a></li>
<li class="toctree-l3"><a class="reference internal" href="#missing-nonlocal">Missing nonlocal</a></li>
</ul>
</li>
<li class="toctree-l2"><a class="reference internal" href="#unknownerror">UnknownError</a><ul>
<li class="toctree-l3"><a class="reference internal" href="#id8">Generic</a></li>
</ul>
</li>
<li class="toctree-l2"><a class="reference internal" href="#valueerror">ValueError</a><ul>
<li class="toctree-l3"><a class="reference internal" href="#not-enough-values-to-unpack">Not enough values to unpack</a></li>
<li class="toctree-l3"><a class="reference internal" href="#too-many-values-to-unpack">Too many values to unpack</a></li>
</ul>
</li>
<li class="toctree-l2"><a class="reference internal" href="#zerodivisionerror">ZeroDivisionError</a><ul>
<li class="toctree-l3"><a class="reference internal" href="#division-operator">Division operator</a></li>
<li class="toctree-l3"><a class="reference internal" href="#modulo-operator">Modulo operator</a></li>
</ul>
</li>
</ul>
</li>
<li class="toctree-l1"><a class="reference internal" href="syntax_tracebacks_en_3.10.html">SyntaxError - Python 3.10 in English</a></li>
<li class="toctree-l1"><a class="reference internal" href="compare_exceptions.html">Comparing Exception messages between Python versions</a></li>
<li class="toctree-l1"><a class="reference internal" href="compare.html">Comparison between Python versions: SyntaxErrors</a></li>
</ul>
<p class="caption"><span class="caption-text">Markdown examples</span></p>
<ul>
<li class="toctree-l1"><a class="reference internal" href="tracebacks_markdown.html">Friendly tracebacks - markdown_docs format</a></li>
<li class="toctree-l1"><a class="reference internal" href="tracebacks_syntax_markdown.html">Syntax errors - markdown_docs format</a></li>
</ul>
<p class="caption"><span class="caption-text">En français</span></p>
<ul>
<li class="toctree-l1"><a class="reference internal" href="tracebacks_fr.html"> Friendly tracebacks - en Français</a></li>
<li class="toctree-l1"><a class="reference internal" href="syntax_tracebacks_fr.html"> Friendly SyntaxError tracebacks - en Français</a></li>
</ul>

            
          
        </div>
        
      </div>
    </nav>

    <section data-toggle="wy-nav-shift" class="wy-nav-content-wrap">

      
      <nav class="wy-nav-top" aria-label="top navigation">
        
          <i data-toggle="wy-nav-top" class="fa fa-bars"></i>
          <a href="index.html">Friendly tracebacks</a>
        
      </nav>


      <div class="wy-nav-content">
        
        <div class="rst-content style-external-links">
        
          















<div role="navigation" aria-label="breadcrumbs navigation">

  <ul class="wy-breadcrumbs">
    
      <li><a href="index.html" class="icon icon-home"></a> &raquo;</li>
        
      <li>Friendly tracebacks - in English</li>
    
    
      <li class="wy-breadcrumbs-aside">
        
            
            <a href="_sources/tracebacks_en_3.10.rst.txt" rel="nofollow"> View page source</a>
          
        
      </li>
    
  </ul>

  
  <div class="rst-breadcrumbs-buttons" role="navigation" aria-label="breadcrumb navigation">
      
        <a href="syntax_tracebacks_en_3.10.html" class="btn btn-neutral float-right" title="Friendly SyntaxError tracebacks - in English" accesskey="n">Next <span class="fa fa-arrow-circle-right"></span></a>
      
      
        <a href="syntax_tracebacks_en_3.9.html" class="btn btn-neutral float-left" title="Friendly SyntaxError tracebacks - in English" accesskey="p"><span class="fa fa-arrow-circle-left"></span> Previous</a>
      
  </div>
  
  <hr/>
</div>
          <div role="main" class="document" itemscope="itemscope" itemtype="http://schema.org/Article">
           <div itemprop="articleBody">
            
  <div class="section" id="friendly-tracebacks-in-english">
<h1>Friendly tracebacks - in English<a class="headerlink" href="#friendly-tracebacks-in-english" title="Permalink to this headline">¶</a></h1>
<p>Friendly-traceback aims to provide friendlier feedback when an exception
is raised than what is done by Python.
Below, we can find some examples. SyntaxError cases, as well as TabError and
IndentationError cases, are shown in a separate page.
Ideally, an example of each case handled by friendly-traceback
should be included here.</p>
<div class="admonition note">
<p class="admonition-title">Note</p>
<p>The content of this page is generated by running
C:Usersandregithubfriendly-tracebackteststrb_english.py located in the <code class="docutils literal notranslate"><span class="pre">tests/</span></code> directory.
This needs to be done explicitly, independently of updating the
documentation using Sphinx.</p>
</div>
<p>Friendly-traceback version: 0.2.9a
Python version: 3.10.0a3</p>
<div class="section" id="arithmeticerror">
<h2>ArithmeticError<a class="headerlink" href="#arithmeticerror" title="Permalink to this headline">¶</a></h2>
<div class="section" id="generic">
<h3>Generic<a class="headerlink" href="#generic" title="Permalink to this headline">¶</a></h3>
<div class="highlight-none notranslate"><div class="highlight"><pre><span></span>Traceback (most recent call last):
  File &quot;TESTS:\runtime\test_arithmetic_error.py&quot;, line 9, in test_Generic
    raise ArithmeticError(&#39;error&#39;)
ArithmeticError: error

`ArithmeticError` is the base class for those built-in exceptions
that are raised for various arithmetic errors.
It is unusual that you are seeing this exception;
normally, a more specific exception should have been raised.

Exception raised on line 9 of file TESTS:\runtime\test_arithmetic_error.py.

    7:         # Usually, a subclass such as ZeroDivisionError, etc., would
    8:         # likely be raised.
--&gt; 9:         raise ArithmeticError(&#39;error&#39;)
   10:     except Exception as e:

        ArithmeticError: &lt;class ArithmeticError&gt;
</pre></div>
</div>
</div>
</div>
<div class="section" id="attributeerror">
<h2>AttributeError<a class="headerlink" href="#attributeerror" title="Permalink to this headline">¶</a></h2>
<div class="section" id="builtin-function">
<h3>Builtin function<a class="headerlink" href="#builtin-function" title="Permalink to this headline">¶</a></h3>
<div class="highlight-none notranslate"><div class="highlight"><pre><span></span>Traceback (most recent call last):
  File &quot;TESTS:\runtime\test_attribute_error.py&quot;, line 188, in test_Builtin_function
    len.text
AttributeError: &#39;builtin_function_or_method&#39; object has no attribute &#39;text&#39;

    Did you mean `len(text)`?

An `AttributeError` occurs when the code contains something like
    `object.x`
and `x` is not a method or attribute (variable) belonging to `object`.

    `len` is a function. Perhaps you meant to write
    `len(text)`

Exception raised on line 188 of file TESTS:\runtime\test_attribute_error.py.

   186:     text = &#39;Hello world!&#39;
   187:     try:
--&gt;188:         len.text
   189:     except Exception as e:

        text: &#39;Hello world!&#39;
        len: &lt;builtin function len&gt;
</pre></div>
</div>
</div>
<div class="section" id="builtin-module-with-no-file">
<h3>Builtin module with no file<a class="headerlink" href="#builtin-module-with-no-file" title="Permalink to this headline">¶</a></h3>
<div class="highlight-none notranslate"><div class="highlight"><pre><span></span>Traceback (most recent call last):
  File &quot;TESTS:\runtime\test_attribute_error.py&quot;, line 205, in test_Builtin_module_with_no_file
    sys.foo
AttributeError: module &#39;sys&#39; has no attribute &#39;foo&#39;

An `AttributeError` occurs when the code contains something like
    `object.x`
and `x` is not a method or attribute (variable) belonging to `object`.

    Python tells us that no object with name `foo` is
    found in module `sys`.

Exception raised on line 205 of file TESTS:\runtime\test_attribute_error.py.

   203:
   204:     try:
--&gt;205:         sys.foo
   206:     except Exception as e:

        sys: &lt;module sys (builtin)&gt;
</pre></div>
</div>
</div>
<div class="section" id="id1">
<h3>Generic<a class="headerlink" href="#id1" title="Permalink to this headline">¶</a></h3>
<div class="highlight-none notranslate"><div class="highlight"><pre><span></span>Traceback (most recent call last):
  File &quot;TESTS:\runtime\test_attribute_error.py&quot;, line 36, in test_Generic
    a.x  # Testing instance
AttributeError: &#39;A&#39; object has no attribute &#39;x&#39;

An `AttributeError` occurs when the code contains something like
    `object.x`
and `x` is not a method or attribute (variable) belonging to `object`.

    The object `a` has no attribute named `x`.

Exception raised on line 36 of file TESTS:\runtime\test_attribute_error.py.

   34:     try:
   35:         a = A()
--&gt;36:         a.x  # Testing instance
   37:     except Exception as e:

        a: &lt;A object&gt; from test_attribute_error.test_Generic
</pre></div>
</div>
</div>
<div class="section" id="module-attribute-typo">
<h3>Module attribute typo<a class="headerlink" href="#module-attribute-typo" title="Permalink to this headline">¶</a></h3>
<div class="highlight-none notranslate"><div class="highlight"><pre><span></span>Traceback (most recent call last):
  File &quot;TESTS:\runtime\test_attribute_error.py&quot;, line 113, in test_Module_attribute_typo
    math.cost
AttributeError: module &#39;math&#39; has no attribute &#39;cost&#39;

    Did you mean one of the following: `cos, cosh, acos`?

An `AttributeError` occurs when the code contains something like
    `object.x`
and `x` is not a method or attribute (variable) belonging to `object`.

    Instead of writing `math.cost`, perhaps you meant to write one of
    the following names which are attributes of module `math`:
    `cos, cosh, acos`

Exception raised on line 113 of file TESTS:\runtime\test_attribute_error.py.

   111:
   112:     try:
--&gt;113:         math.cost
   114:     except Exception as e:

        math: &lt;module math (builtin)&gt;
</pre></div>
</div>
</div>
<div class="section" id="nonetype">
<h3>Nonetype<a class="headerlink" href="#nonetype" title="Permalink to this headline">¶</a></h3>
<div class="highlight-none notranslate"><div class="highlight"><pre><span></span>Traceback (most recent call last):
  File &quot;TESTS:\runtime\test_attribute_error.py&quot;, line 152, in test_Nonetype
    a.b
AttributeError: &#39;NoneType&#39; object has no attribute &#39;b&#39;

An `AttributeError` occurs when the code contains something like
    `object.x`
and `x` is not a method or attribute (variable) belonging to `object`.

    You are attempting to access the attribute `b`
    for a variable whose value is `None`.
Exception raised on line 152 of file TESTS:\runtime\test_attribute_error.py.

   150:     a = None
   151:     try:
--&gt;152:         a.b
   153:     except Exception as e:

        a: None
</pre></div>
</div>
</div>
<div class="section" id="object-attribute-typo">
<h3>Object attribute typo<a class="headerlink" href="#object-attribute-typo" title="Permalink to this headline">¶</a></h3>
<div class="highlight-none notranslate"><div class="highlight"><pre><span></span>Traceback (most recent call last):
  File &quot;TESTS:\runtime\test_attribute_error.py&quot;, line 52, in test_Object_attribute_typo
    a.appendh(4)
AttributeError: &#39;list&#39; object has no attribute &#39;appendh&#39;

    Did you mean `append`?

An `AttributeError` occurs when the code contains something like
    `object.x`
and `x` is not a method or attribute (variable) belonging to `object`.

    Perhaps you meant to write `a.append` instead of `a.appendh`

Exception raised on line 52 of file TESTS:\runtime\test_attribute_error.py.

   50:     try:
   51:         a = [1, 2, 3]
--&gt;52:         a.appendh(4)
               ^^^^^^^^^
   53:     except Exception as e:

        a: [1, 2, 3]
</pre></div>
</div>
</div>
<div class="section" id="perhaps-comma">
<h3>Perhaps comma<a class="headerlink" href="#perhaps-comma" title="Permalink to this headline">¶</a></h3>
<div class="highlight-none notranslate"><div class="highlight"><pre><span></span>Traceback (most recent call last):
  File &quot;TESTS:\runtime\test_attribute_error.py&quot;, line 171, in test_Perhaps_comma
    a = [abcd
AttributeError: &#39;str&#39; object has no attribute &#39;defg&#39;

    Did you mean to separate object names by a comma?

An `AttributeError` occurs when the code contains something like
    `object.x`
and `x` is not a method or attribute (variable) belonging to `object`.

    `defg` is not an attribute of `abcd`.
    However, both `abcd` and `defg` are known objects.
    Perhaps you wrote a period to separate these two objects,
    instead of using a comma.

Exception raised on line 171 of file TESTS:\runtime\test_attribute_error.py.

   169:     # fmt: off
   170:     try:
--&gt;171:         a = [abcd
   172:         .defg]

        abcd: &#39;hello&#39;
        defg: &#39;world&#39;
</pre></div>
</div>
</div>
<div class="section" id="shadow-stdlib-module">
<h3>Shadow stdlib module<a class="headerlink" href="#shadow-stdlib-module" title="Permalink to this headline">¶</a></h3>
<div class="highlight-none notranslate"><div class="highlight"><pre><span></span>Traceback (most recent call last):
  File &quot;TESTS:\runtime\test_attribute_error.py&quot;, line 134, in test_Shadow_stdlib_module
    turtle.Pen
AttributeError: module &#39;turtle&#39; has no attribute &#39;Pen&#39;

    Did you give your program the same name as a Python module?

An `AttributeError` occurs when the code contains something like
    `object.x`
and `x` is not a method or attribute (variable) belonging to `object`.

    You imported a module named `turtle` from `TESTS:\turtle.py`.
    There is also a module named `turtle` in Python&#39;s standard library.
    Perhaps you need to rename your module.

Exception raised on line 134 of file TESTS:\runtime\test_attribute_error.py.

   132:
   133:     try:
--&gt;134:         turtle.Pen
   135:     except Exception as e:

        turtle: &lt;module turtle&gt; from TESTS:\turtle.py
</pre></div>
</div>
</div>
<div class="section" id="use-builtin">
<h3>Use builtin<a class="headerlink" href="#use-builtin" title="Permalink to this headline">¶</a></h3>
<div class="highlight-none notranslate"><div class="highlight"><pre><span></span>Traceback (most recent call last):
  File &quot;TESTS:\runtime\test_attribute_error.py&quot;, line 68, in test_Use_builtin
    a.length()
AttributeError: &#39;list&#39; object has no attribute &#39;length&#39;

    Did you mean `len(a)`?

An `AttributeError` occurs when the code contains something like
    `object.x`
and `x` is not a method or attribute (variable) belonging to `object`.

    The object `a` has no attribute named `length`.
    Perhaps you can use the Python builtin function `len` instead:
    `len(a)`.
Exception raised on line 68 of file TESTS:\runtime\test_attribute_error.py.

   66:     try:
   67:         a = [1, 2, 3]
--&gt;68:         a.length()
               ^^^^^^^^
   69:     except Exception as e:

        a: [1, 2, 3]
</pre></div>
</div>
</div>
<div class="section" id="use-synonym">
<h3>Use synonym<a class="headerlink" href="#use-synonym" title="Permalink to this headline">¶</a></h3>
<div class="highlight-none notranslate"><div class="highlight"><pre><span></span>Traceback (most recent call last):
  File &quot;TESTS:\runtime\test_attribute_error.py&quot;, line 84, in test_Use_synonym
    a.add(4)
AttributeError: &#39;list&#39; object has no attribute &#39;add&#39;

    Did you mean `append`?

An `AttributeError` occurs when the code contains something like
    `object.x`
and `x` is not a method or attribute (variable) belonging to `object`.

    The object `a` has no attribute named `add`.
    However, `a` has the following attributes with similar meanings:
    `append, extend, insert`.

Exception raised on line 84 of file TESTS:\runtime\test_attribute_error.py.

   82:     try:
   83:         a = [1, 2, 3]
--&gt;84:         a.add(4)
               ^^^^^
   85:     except Exception as e:

        a: [1, 2, 3]
</pre></div>
</div>
</div>
</div>
<div class="section" id="filenotfounderror">
<h2>FileNotFoundError<a class="headerlink" href="#filenotfounderror" title="Permalink to this headline">¶</a></h2>
<div class="section" id="id2">
<h3>Generic<a class="headerlink" href="#id2" title="Permalink to this headline">¶</a></h3>
<div class="highlight-none notranslate"><div class="highlight"><pre><span></span>Traceback (most recent call last):
  File &quot;TESTS:\runtime\test_file_not_found_error.py&quot;, line 6, in test_Generic
    open(&quot;does_not_exist&quot;)
FileNotFoundError: [Errno 2] No such file or directory: &#39;does_not_exist&#39;

A `FileNotFoundError` exception indicates that you
are trying to open a file that cannot be found by Python.
This could be because you misspelled the name of the file.

    In your program, the name of the
    file that cannot be found is `does_not_exist`.

Exception raised on line 6 of file TESTS:\runtime\test_file_not_found_error.py.

   4: def test_Generic():
   5:     try:
--&gt;6:         open(&quot;does_not_exist&quot;)
   7:     except Exception as e:

        open: &lt;builtin function open&gt;
</pre></div>
</div>
</div>
</div>
<div class="section" id="importerror">
<h2>ImportError<a class="headerlink" href="#importerror" title="Permalink to this headline">¶</a></h2>
<div class="section" id="circular-import">
<h3>Circular import<a class="headerlink" href="#circular-import" title="Permalink to this headline">¶</a></h3>
<div class="highlight-none notranslate"><div class="highlight"><pre><span></span>Traceback (most recent call last):
  File &quot;TESTS:\runtime\test_import_error.py&quot;, line 20, in test_Circular_import
    import circular_a
  File &quot;TESTS:\circular_a.py&quot;, line 2, in &lt;module&gt;
    import circular_b
  File &quot;TESTS:\circular_b.py&quot;, line 2, in &lt;module&gt;
    from circular_a import a
ImportError: cannot import name &#39;a&#39; from partially initialized module &#39;circular_a&#39; (most likely due to a circular import) (C:\Users\andre\github\friendly-traceback\tests\circular_a.py)

An `ImportError` exception indicates that a certain object could not
be imported from a module or package. Most often, this is
because the name of the object is not spelled correctly.

    The object that could not be imported is `a`.
    The module or package where it was
    expected to be found is `circular_a`.

    The problem was likely caused by what is known as a &#39;circular import&#39;.
    First, Python imported and started executing the code in file
       &#39;TESTS:\runtime\test_import_error.py&#39;.
    which imports module `circular_a`.
    During this process, the code in another file,
       &#39;TESTS:\circular_b.py&#39;
    was executed. However in this last file, an attempt was made
    to import the original module `circular_a`
    a second time, before Python had completed the first import.

Execution stopped on line 20 of file TESTS:\runtime\test_import_error.py.

   18: def test_Circular_import():
   19:     try:
--&gt;20:         import circular_a
   21:     except Exception as e:

Exception raised on line 2 of file TESTS:\circular_b.py.

   1: &quot;&quot;&quot;File used in for test_circular_import() in test_import_error.py&quot;&quot;&quot;
--&gt;2: from circular_a import a
</pre></div>
</div>
</div>
<div class="section" id="simple-import-error">
<h3>Simple import error<a class="headerlink" href="#simple-import-error" title="Permalink to this headline">¶</a></h3>
<div class="highlight-none notranslate"><div class="highlight"><pre><span></span>Traceback (most recent call last):
  File &quot;TESTS:\runtime\test_import_error.py&quot;, line 6, in test_Simple_import_error
    from math import Pi
ImportError: cannot import name &#39;Pi&#39; from &#39;math&#39; (unknown location)

    Did you mean `pi`?

An `ImportError` exception indicates that a certain object could not
be imported from a module or package. Most often, this is
because the name of the object is not spelled correctly.

    Perhaps you meant to import `pi` (from `math`) instead of `Pi`

Exception raised on line 6 of file TESTS:\runtime\test_import_error.py.

   4: def test_Simple_import_error():
   5:     try:
--&gt;6:         from math import Pi
   7:     except Exception as e:
</pre></div>
</div>
</div>
</div>
<div class="section" id="indexerror">
<h2>IndexError<a class="headerlink" href="#indexerror" title="Permalink to this headline">¶</a></h2>
<div class="section" id="long-list">
<h3>Long list<a class="headerlink" href="#long-list" title="Permalink to this headline">¶</a></h3>
<div class="highlight-none notranslate"><div class="highlight"><pre><span></span>Traceback (most recent call last):
  File &quot;TESTS:\runtime\test_index_error.py&quot;, line 22, in test_Long_list
    print(a[50], b[0])
IndexError: list index out of range

An `IndexError` occurs when you are try to get an item from a list,
a tuple, or a similar object (sequence), by using an index which
does not exists; typically, this is because the index you give
is greater than the length of the sequence.
Reminder: the first item of a sequence is at index 0.

Exception raised on line 22 of file TESTS:\runtime\test_index_error.py.

   20:     b = tuple(range(50))
   21:     try:
--&gt;22:         print(a[50], b[0])
                     ^^^^^
   23:     except Exception as e:

        a: [0, 1, 2, 3, 4, 5, 6, 7, 8, 9, 10, 11, 12, 13, 14, 15, 16, 17, 18, ...]
            len(a): 40
</pre></div>
</div>
</div>
<div class="section" id="short-tuple">
<h3>Short tuple<a class="headerlink" href="#short-tuple" title="Permalink to this headline">¶</a></h3>
<div class="highlight-none notranslate"><div class="highlight"><pre><span></span>Traceback (most recent call last):
  File &quot;TESTS:\runtime\test_index_error.py&quot;, line 8, in test_Short_tuple
    print(a[3], b[2])
IndexError: tuple index out of range

An `IndexError` occurs when you are try to get an item from a list,
a tuple, or a similar object (sequence), by using an index which
does not exists; typically, this is because the index you give
is greater than the length of the sequence.
Reminder: the first item of a sequence is at index 0.

Exception raised on line 8 of file TESTS:\runtime\test_index_error.py.

    6:     b = [1, 2, 3]
    7:     try:
--&gt; 8:         print(a[3], b[2])
                     ^^^^
    9:     except Exception as e:

        a: (1, 2, 3)
</pre></div>
</div>
</div>
</div>
<div class="section" id="keyerror">
<h2>KeyError<a class="headerlink" href="#keyerror" title="Permalink to this headline">¶</a></h2>
<div class="section" id="id3">
<h3>Generic<a class="headerlink" href="#id3" title="Permalink to this headline">¶</a></h3>
<div class="highlight-none notranslate"><div class="highlight"><pre><span></span>Traceback (most recent call last):
  File &quot;TESTS:\runtime\test_key_error.py&quot;, line 7, in test_Generic
    d[&quot;c&quot;]
KeyError: &#39;c&#39;

A `KeyError` is raised when a value is not found as a
key in a Python dict.

    In your program, the key that cannot be found is `&#39;c&#39;`.

Exception raised on line 7 of file TESTS:\runtime\test_key_error.py.

   5:     d = {&quot;a&quot;: 1, &quot;b&quot;: 2}
   6:     try:
--&gt;7:         d[&quot;c&quot;]
   8:     except Exception as e:

        d: {&#39;a&#39;: 1, &#39;b&#39;: 2}
</pre></div>
</div>
</div>
</div>
<div class="section" id="lookuperror">
<h2>LookupError<a class="headerlink" href="#lookuperror" title="Permalink to this headline">¶</a></h2>
<div class="section" id="id4">
<h3>Generic<a class="headerlink" href="#id4" title="Permalink to this headline">¶</a></h3>
<div class="highlight-none notranslate"><div class="highlight"><pre><span></span>Traceback (most recent call last):
  File &quot;TESTS:\runtime\test_lookup_error.py&quot;, line 10, in test_Generic
    raise LookupError(&quot;Fake message&quot;)
LookupError: Fake message

`LookupError` is the base class for the exceptions that are raised
when a key or index used on a mapping or sequence is invalid.
It can also be raised directly by codecs.lookup().

Exception raised on line 10 of file TESTS:\runtime\test_lookup_error.py.

    8:         # other than possibly codecs.lookup(), which is why we raise
    9:         # it directly here for our example.
--&gt;10:         raise LookupError(&quot;Fake message&quot;)
   11:     except Exception as e:

        LookupError: &lt;class LookupError&gt;
</pre></div>
</div>
</div>
</div>
<div class="section" id="modulenotfounderror">
<h2>ModuleNotFoundError<a class="headerlink" href="#modulenotfounderror" title="Permalink to this headline">¶</a></h2>
<div class="section" id="not-a-package">
<h3>Not a package<a class="headerlink" href="#not-a-package" title="Permalink to this headline">¶</a></h3>
<div class="highlight-none notranslate"><div class="highlight"><pre><span></span>Traceback (most recent call last):
  File &quot;TESTS:\runtime\test_module_not_found_error.py&quot;, line 41, in test_Not_a_package
    import os.pathh
ModuleNotFoundError: No module named &#39;os.pathh&#39;; &#39;os&#39; is not a package

    Did you mean `import os.path`?

A `ModuleNotFoundError` exception indicates that you
are trying to import a module that cannot be found by Python.
This could be because you misspelled the name of the module
or because it is not installed on your computer.

    Perhaps you meant `import os.path`.
    `path` is a name similar to `pathh` and is a module that
    can be imported from `os`.
    Other objects with similar names that are part of
     `os` include `fspath`.

Exception raised on line 41 of file TESTS:\runtime\test_module_not_found_error.py.

   39:
   40:     try:
--&gt;41:         import os.pathh
   42:     except Exception as e:
</pre></div>
</div>
</div>
<div class="section" id="standard-library-module">
<h3>Standard library module<a class="headerlink" href="#standard-library-module" title="Permalink to this headline">¶</a></h3>
<div class="highlight-none notranslate"><div class="highlight"><pre><span></span>Traceback (most recent call last):
  File &quot;TESTS:\runtime\test_module_not_found_error.py&quot;, line 6, in test_Standard_library_module
    import Tkinter
ModuleNotFoundError: No module named &#39;Tkinter&#39;

    Did you mean `tkinter`?

A `ModuleNotFoundError` exception indicates that you
are trying to import a module that cannot be found by Python.
This could be because you misspelled the name of the module
or because it is not installed on your computer.

    The name of the module that could not be imported is `Tkinter`.
    `tkinter` is an existing module that has a similar name.

Exception raised on line 6 of file TESTS:\runtime\test_module_not_found_error.py.

   4: def test_Standard_library_module():
   5:     try:
--&gt;6:         import Tkinter
   7:     except Exception as e:
</pre></div>
</div>
</div>
</div>
<div class="section" id="nameerror">
<h2>NameError<a class="headerlink" href="#nameerror" title="Permalink to this headline">¶</a></h2>
<div class="section" id="annotated-variable">
<h3>Annotated variable<a class="headerlink" href="#annotated-variable" title="Permalink to this headline">¶</a></h3>
<div class="highlight-none notranslate"><div class="highlight"><pre><span></span>Traceback (most recent call last):
  File &quot;TESTS:\runtime\test_name_error.py&quot;, line 21, in test_Annotated_variable
    y = x
NameError: name &#39;x&#39; is not defined

    Did you use a colon instead of an equal sign?

A `NameError` exception indicates that a variable or
function name is not known to Python.
Most often, this is because there is a spelling mistake.
However, sometimes it is because the name is used
before being defined or given a value.

    In your program, `x` is an unknown name.
    A type hint found for `x` in the global scope.
    Perhaps you had used a colon instead of an equal sign and written

        x : 3

    instead of

        x = 3

Exception raised on line 21 of file TESTS:\runtime\test_name_error.py.

   19: def test_Annotated_variable():
   20:     try:
--&gt;21:         y = x
   22:     except Exception as e:
</pre></div>
</div>
</div>
<div class="section" id="id5">
<h3>Generic<a class="headerlink" href="#id5" title="Permalink to this headline">¶</a></h3>
<div class="highlight-none notranslate"><div class="highlight"><pre><span></span>Traceback (most recent call last):
  File &quot;TESTS:\runtime\test_name_error.py&quot;, line 6, in test_Generic
    this = something
NameError: name &#39;something&#39; is not defined

A `NameError` exception indicates that a variable or
function name is not known to Python.
Most often, this is because there is a spelling mistake.
However, sometimes it is because the name is used
before being defined or given a value.

    In your program, `something` is an unknown name.
    I have no additional information for you.
Exception raised on line 6 of file TESTS:\runtime\test_name_error.py.

   4: def test_Generic():
   5:     try:
--&gt;6:         this = something
   7:     except Exception as e:
</pre></div>
</div>
</div>
<div class="section" id="synonym">
<h3>Synonym<a class="headerlink" href="#synonym" title="Permalink to this headline">¶</a></h3>
<div class="highlight-none notranslate"><div class="highlight"><pre><span></span>Traceback (most recent call last):
  File &quot;TESTS:\runtime\test_name_error.py&quot;, line 46, in test_Synonym
    cost  # wrote from math import * above
NameError: name &#39;cost&#39; is not defined

    Did you mean `cos`?

A `NameError` exception indicates that a variable or
function name is not known to Python.
Most often, this is because there is a spelling mistake.
However, sometimes it is because the name is used
before being defined or given a value.

    In your program, `cost` is an unknown name.
    Instead of writing `cost`, perhaps you meant one of the following:
    *   Global scope: `cos`, `cosh`, `acos`

Exception raised on line 46 of file TESTS:\runtime\test_name_error.py.

   44:
   45:     try:
--&gt;46:         cost  # wrote from math import * above
   47:     except Exception as e:
</pre></div>
</div>
</div>
</div>
<div class="section" id="overflowerror">
<h2>OverflowError<a class="headerlink" href="#overflowerror" title="Permalink to this headline">¶</a></h2>
<div class="section" id="id6">
<h3>Generic<a class="headerlink" href="#id6" title="Permalink to this headline">¶</a></h3>
<div class="highlight-none notranslate"><div class="highlight"><pre><span></span>Traceback (most recent call last):
  File &quot;TESTS:\runtime\test_overflow_error.py&quot;, line 6, in test_Generic
    2.0 ** 1600
OverflowError: (34, &#39;Result too large&#39;)

An `OverflowError` is raised when the result of an arithmetic operation
is too large to be handled by the computer&#39;s processor.

Exception raised on line 6 of file TESTS:\runtime\test_overflow_error.py.

   4: def test_Generic():
   5:     try:
--&gt;6:         2.0 ** 1600
   7:     except Exception as e:
</pre></div>
</div>
</div>
</div>
<div class="section" id="recursionerror">
<h2>RecursionError<a class="headerlink" href="#recursionerror" title="Permalink to this headline">¶</a></h2>
<div class="section" id="id7">
<h3>Generic<a class="headerlink" href="#id7" title="Permalink to this headline">¶</a></h3>
<div class="highlight-none notranslate"><div class="highlight"><pre><span></span>Traceback (most recent call last):
  File &quot;TESTS:\runtime\test_recursion_error.py&quot;, line 8, in test_Generic
    a()

       ... More lines not shown. ...

  File &quot;TESTS:\runtime\test_recursion_error.py&quot;, line 6, in a
    return a()
  File &quot;TESTS:\runtime\test_recursion_error.py&quot;, line 6, in a
    return a()
RecursionError: maximum recursion depth exceeded

A `RecursionError` is raised when a function calls itself,
directly or indirectly, too many times.
It almost always indicates that you made an error in your code
and that your program would never stop.

Execution stopped on line 8 of file TESTS:\runtime\test_recursion_error.py.

    6:         return a()
    7:     try:
--&gt; 8:         a()
    9:     except Exception as e:

        a: &lt;function a&gt; from test_Generic

Exception raised on line 6 of file TESTS:\runtime\test_recursion_error.py.

   4: def test_Generic():
   5:     def a():
--&gt;6:         return a()
                     ^^^
   7:     try:

        a: &lt;function a&gt; from test_Generic
</pre></div>
</div>
</div>
</div>
<div class="section" id="typeerror">
<h2>TypeError<a class="headerlink" href="#typeerror" title="Permalink to this headline">¶</a></h2>
<div class="section" id="bad-type-for-unary-operator">
<h3>Bad type for unary operator<a class="headerlink" href="#bad-type-for-unary-operator" title="Permalink to this headline">¶</a></h3>
<div class="highlight-none notranslate"><div class="highlight"><pre><span></span>Traceback (most recent call last):
  File &quot;TESTS:\runtime\test_type_error.py&quot;, line 348, in test_Bad_type_for_unary_operator
    a =+ &quot;def&quot;
TypeError: bad operand type for unary +: &#39;str&#39;

    Perhaps you meant to write `+=` instead of `=+`
A `TypeError` is usually caused by trying
to combine two incompatible types of objects,
by calling a function with the wrong type of object,
or by trying to do an operation not allowed on a given type of object.

    You tried to use the unary operator &#39;+&#39;
    with the following type of object: a string (`str`).
    This operation is not defined for this type of object.

    Perhaps you meant to write `+=` instead of `=+`

Exception raised on line 348 of file TESTS:\runtime\test_type_error.py.

   346:         # fmt: off
   347:         a = &quot;abc&quot;
--&gt;348:         a =+ &quot;def&quot;
                   ^^^^^^^
   349:         # fmt: on
</pre></div>
</div>
</div>
<div class="section" id="can-only-concatenate">
<h3>Can only concatenate<a class="headerlink" href="#can-only-concatenate" title="Permalink to this headline">¶</a></h3>
<div class="highlight-none notranslate"><div class="highlight"><pre><span></span>Traceback (most recent call last):
  File &quot;TESTS:\runtime\test_type_error.py&quot;, line 36, in test_Can_only_concatenate
    result = a_tuple + a_list
TypeError: can only concatenate tuple (not &quot;list&quot;) to tuple

A `TypeError` is usually caused by trying
to combine two incompatible types of objects,
by calling a function with the wrong type of object,
or by trying to do an operation not allowed on a given type of object.

    You tried to concatenate (add) two different types of objects:
    a `tuple` and a `list`

Exception raised on line 36 of file TESTS:\runtime\test_type_error.py.

   34:         a_tuple = (1, 2, 3)
   35:         a_list = [1, 2, 3]
--&gt;36:         result = a_tuple + a_list
                        ^^^^^^^^^^^^^^^^
   37:     except Exception as e:

        a_tuple: (1, 2, 3)
        a_list: [1, 2, 3]
</pre></div>
</div>
</div>
<div class="section" id="cannot-multiply-by-non-int">
<h3>Cannot multiply by non int<a class="headerlink" href="#cannot-multiply-by-non-int" title="Permalink to this headline">¶</a></h3>
<div class="highlight-none notranslate"><div class="highlight"><pre><span></span>Traceback (most recent call last):
  File &quot;TESTS:\runtime\test_type_error.py&quot;, line 557, in test_Cannot_multiply_by_non_int
    &quot;a&quot; * &quot;2&quot;
TypeError: can&#39;t multiply sequence by non-int of type &#39;str&#39;

    Did you forget to convert `&quot;2&quot;` into an integer?

A `TypeError` is usually caused by trying
to combine two incompatible types of objects,
by calling a function with the wrong type of object,
or by trying to do an operation not allowed on a given type of object.

    You can only multiply sequences, such as list, tuples,
     strings, etc., by integers.
    Perhaps you forgot to convert `&quot;2&quot;` into an integer.

Exception raised on line 557 of file TESTS:\runtime\test_type_error.py.

   555:
   556:     try:
--&gt;557:         &quot;a&quot; * &quot;2&quot;
   558:     except Exception as e:
</pre></div>
</div>
</div>
<div class="section" id="comparison-not-supported">
<h3>Comparison not supported<a class="headerlink" href="#comparison-not-supported" title="Permalink to this headline">¶</a></h3>
<div class="highlight-none notranslate"><div class="highlight"><pre><span></span>Traceback (most recent call last):
  File &quot;TESTS:\runtime\test_type_error.py&quot;, line 298, in test_Comparison_not_supported
    b &lt; a
TypeError: &#39;&lt;&#39; not supported between instances of &#39;int&#39; and &#39;str&#39;

A `TypeError` is usually caused by trying
to combine two incompatible types of objects,
by calling a function with the wrong type of object,
or by trying to do an operation not allowed on a given type of object.

    You tried to do an order comparison (&lt;)
    between two incompatible types of objects:
    an integer (`int`) and a string (`str`)

Exception raised on line 298 of file TESTS:\runtime\test_type_error.py.

   296:         a = &quot;a&quot;
   297:         b = 42
--&gt;298:         b &lt; a
   299:     except Exception as e:

        b: 42
        a: &#39;a&#39;
</pre></div>
</div>
</div>
<div class="section" id="derive-from-baseexception">
<h3>Derive from BaseException<a class="headerlink" href="#derive-from-baseexception" title="Permalink to this headline">¶</a></h3>
<div class="highlight-none notranslate"><div class="highlight"><pre><span></span>Traceback (most recent call last):
  File &quot;TESTS:\runtime\test_type_error.py&quot;, line 488, in test_Derive_from_BaseException
    raise &quot;exception&quot;
TypeError: exceptions must derive from BaseException

A `TypeError` is usually caused by trying
to combine two incompatible types of objects,
by calling a function with the wrong type of object,
or by trying to do an operation not allowed on a given type of object.

    In Python 3, exceptions must be derived from BaseException.

Exception raised on line 488 of file TESTS:\runtime\test_type_error.py.

   486: def test_Derive_from_BaseException():
   487:     try:
--&gt;488:         raise &quot;exception&quot;
   489:     except Exception as e:
</pre></div>
</div>
</div>
<div class="section" id="not-an-integer">
<h3>Not an integer<a class="headerlink" href="#not-an-integer" title="Permalink to this headline">¶</a></h3>
<div class="highlight-none notranslate"><div class="highlight"><pre><span></span>Traceback (most recent call last):
  File &quot;TESTS:\runtime\test_type_error.py&quot;, line 605, in test_Not_an_integer
    range(c, d)
TypeError: &#39;str&#39; object cannot be interpreted as an integer

    Did you forget to convert `c, d` into integers?

A `TypeError` is usually caused by trying
to combine two incompatible types of objects,
by calling a function with the wrong type of object,
or by trying to do an operation not allowed on a given type of object.

    You wrote an object of type `str` where an integer was expected.
    Perhaps you forgot to convert `c, d` into integers.
Exception raised on line 605 of file TESTS:\runtime\test_type_error.py.

   603:     c, d = &quot;2&quot;, &quot;3&quot;
   604:     try:
--&gt;605:         range(c, d)
   606:     except Exception as e:

        c: &#39;2&#39;
        d: &#39;3&#39;
        range: &lt;class range&gt;
</pre></div>
</div>
</div>
<div class="section" id="not-callable">
<h3>Not callable<a class="headerlink" href="#not-callable" title="Permalink to this headline">¶</a></h3>
<div class="highlight-none notranslate"><div class="highlight"><pre><span></span>Traceback (most recent call last):
  File &quot;TESTS:\runtime\test_type_error.py&quot;, line 475, in test_Not_callable
    _ = [1, 2](3 + 4)
TypeError: &#39;list&#39; object is not callable

    Did you mean `[1, 2][3 + 4]`?

A `TypeError` is usually caused by trying
to combine two incompatible types of objects,
by calling a function with the wrong type of object,
or by trying to do an operation not allowed on a given type of object.

    Because of the surrounding parenthesis, `(3 + 4)`
    is interpreted by Python as indicating a function call for
    `[1, 2]`, which is an object of type `list`
    which cannot be called.

    However, `[1, 2]` is a sequence.
    Perhaps you meant to use `[]` instead of `()` and write
    `[1, 2][3 + 4]`

Exception raised on line 475 of file TESTS:\runtime\test_type_error.py.

   473:
   474:     try:
--&gt;475:         _ = [1, 2](3 + 4)
                    ^^^^^^^^^^^^^
   476:     except Exception as e:
</pre></div>
</div>
</div>
<div class="section" id="too-few-positional-argument">
<h3>Too few positional argument<a class="headerlink" href="#too-few-positional-argument" title="Permalink to this headline">¶</a></h3>
<div class="highlight-none notranslate"><div class="highlight"><pre><span></span>Traceback (most recent call last):
  File &quot;TESTS:\runtime\test_type_error.py&quot;, line 418, in test_Too_few_positional_argument
    fn(1)
TypeError: test_Too_few_positional_argument.&lt;locals&gt;.fn() missing 2 required positional arguments: &#39;b&#39; and &#39;c&#39;

A `TypeError` is usually caused by trying
to combine two incompatible types of objects,
by calling a function with the wrong type of object,
or by trying to do an operation not allowed on a given type of object.

    You apparently have called the function &#39;test_Too_few_positional_argument.&lt;locals&gt;.fn()&#39; with
    fewer positional arguments than it requires (2 missing).

Exception raised on line 418 of file TESTS:\runtime\test_type_error.py.

   416:
   417:     try:
--&gt;418:         fn(1)
   419:     except Exception as e:

        fn: &lt;function fn&gt; from test_Too_few_positional_argument
</pre></div>
</div>
</div>
<div class="section" id="too-many-positional-argument">
<h3>Too many positional argument<a class="headerlink" href="#too-many-positional-argument" title="Permalink to this headline">¶</a></h3>
<div class="highlight-none notranslate"><div class="highlight"><pre><span></span>Traceback (most recent call last):
  File &quot;TESTS:\runtime\test_type_error.py&quot;, line 399, in test_Too_many_positional_argument
    A().f(1)
TypeError: test_Too_many_positional_argument.&lt;locals&gt;.A.f() takes 1 positional argument but 2 were given

    Perhaps you forgot `self` when defining `A.f`.

A `TypeError` is usually caused by trying
to combine two incompatible types of objects,
by calling a function with the wrong type of object,
or by trying to do an operation not allowed on a given type of object.

    You apparently have called the function `A.f` with
    2 positional argument(s) while it requires 1
    such positional argument(s).
    Perhaps you forgot `self` when defining `A.f`.

Exception raised on line 399 of file TESTS:\runtime\test_type_error.py.

   397:
   398:     try:
--&gt;399:         A().f(1)
   400:     except Exception as e:

        A: &lt;class A&gt; from test_type_error.test_Too_many_positional_argument
</pre></div>
</div>
</div>
<div class="section" id="tuple-no-item-assignment">
<h3>Tuple no item assignment<a class="headerlink" href="#tuple-no-item-assignment" title="Permalink to this headline">¶</a></h3>
<div class="highlight-none notranslate"><div class="highlight"><pre><span></span>Traceback (most recent call last):
  File &quot;TESTS:\runtime\test_type_error.py&quot;, line 366, in test_Tuple_no_item_assignment
    a[0] = 0
TypeError: &#39;tuple&#39; object does not support item assignment

    Did you mean to use a list?

A `TypeError` is usually caused by trying
to combine two incompatible types of objects,
by calling a function with the wrong type of object,
or by trying to do an operation not allowed on a given type of object.

    In Python, some objects are known as immutable:
    once defined, their value cannot be changed.
    You tried change part of such an immutable object: a `tuple`,
    most likely by using an indexing operation.
    Perhaps you meant to use a list instead.

Exception raised on line 366 of file TESTS:\runtime\test_type_error.py.

   364:     a = (1, 2, 3)
   365:     try:
--&gt;366:         a[0] = 0
   367:     except Exception as e:

        a[0]: 1
        a: (1, 2, 3)
</pre></div>
</div>
</div>
<div class="section" id="unsupported-operand-types">
<h3>Unsupported operand types<a class="headerlink" href="#unsupported-operand-types" title="Permalink to this headline">¶</a></h3>
<div class="highlight-none notranslate"><div class="highlight"><pre><span></span>Traceback (most recent call last):
  File &quot;TESTS:\runtime\test_type_error.py&quot;, line 282, in test_Unsupported_operand_types
    a @= b
TypeError: unsupported operand type(s) for @=: &#39;str&#39; and &#39;int&#39;

A `TypeError` is usually caused by trying
to combine two incompatible types of objects,
by calling a function with the wrong type of object,
or by trying to do an operation not allowed on a given type of object.

    You tried to use the operator @=
    using two incompatible types of objects:
    a string (`str`) and an integer (`int`).
    This operator is normally used only
    for multiplication of matrices.

Exception raised on line 282 of file TESTS:\runtime\test_type_error.py.

   280:         a = &quot;a&quot;
   281:         b = 2
--&gt;282:         a @= b
   283:     except Exception as e:

        a: &#39;a&#39;
        b: 2
</pre></div>
</div>
</div>
</div>
<div class="section" id="unboundlocalerror">
<h2>UnboundLocalError<a class="headerlink" href="#unboundlocalerror" title="Permalink to this headline">¶</a></h2>
<div class="section" id="missing-global">
<h3>Missing global<a class="headerlink" href="#missing-global" title="Permalink to this headline">¶</a></h3>
<div class="highlight-none notranslate"><div class="highlight"><pre><span></span>Traceback (most recent call last):
  File &quot;TESTS:\runtime\test_unbound_local_error.py&quot;, line 27, in test_Missing_global
    outer_missing_global()
  File &quot;TESTS:\runtime\test_unbound_local_error.py&quot;, line 11, in outer_missing_global
    inner()
  File &quot;TESTS:\runtime\test_unbound_local_error.py&quot;, line 9, in inner
    spam_missing_global += 1
UnboundLocalError: local variable &#39;spam_missing_global&#39; referenced before assignment

    Did you forget to add `global spam_missing_global`?

In Python, variables that are used inside a function are known as
local variables. Before they are used, they must be assigned a value.
A variable that is used before it is assigned a value is assumed to
be defined outside that function; it is known as a `global`
(or sometimes `nonlocal`) variable. You cannot assign a value to such
a global variable inside a function without first indicating to
Python that this is a global variable, otherwise you will see
an `UnboundLocalError`.

    The name `spam_missing_global` exists in the global scope.
    Perhaps the statement

        global spam_missing_global

    should have been included as the first line inside your function.

Execution stopped on line 27 of file TESTS:\runtime\test_unbound_local_error.py.

   25:
   26:     try:
--&gt;27:         outer_missing_global()
   28:     except Exception as e:

        global outer_missing_global: &lt;function outer_missing_global&gt;

Exception raised on line 9 of file TESTS:\runtime\test_unbound_local_error.py.

    7: def outer_missing_global():
    8:     def inner():
--&gt; 9:         spam_missing_global += 1

        global spam_missing_global: 1
</pre></div>
</div>
</div>
<div class="section" id="missing-nonlocal">
<h3>Missing nonlocal<a class="headerlink" href="#missing-nonlocal" title="Permalink to this headline">¶</a></h3>
<div class="highlight-none notranslate"><div class="highlight"><pre><span></span>Traceback (most recent call last):
  File &quot;TESTS:\runtime\test_unbound_local_error.py&quot;, line 48, in test_Missing_nonlocal
    outer_missing_nonlocal()
  File &quot;TESTS:\runtime\test_unbound_local_error.py&quot;, line 20, in outer_missing_nonlocal
    inner()
  File &quot;TESTS:\runtime\test_unbound_local_error.py&quot;, line 18, in inner
    spam_missing_nonlocal += 1
UnboundLocalError: local variable &#39;spam_missing_nonlocal&#39; referenced before assignment

    Did you forget to add `nonlocal spam_missing_nonlocal`?

In Python, variables that are used inside a function are known as
local variables. Before they are used, they must be assigned a value.
A variable that is used before it is assigned a value is assumed to
be defined outside that function; it is known as a `global`
(or sometimes `nonlocal`) variable. You cannot assign a value to such
a global variable inside a function without first indicating to
Python that this is a global variable, otherwise you will see
an `UnboundLocalError`.

    The name `spam_missing_nonlocal` exists in the nonlocal scope.
    Perhaps the statement

        nonlocal spam_missing_nonlocal

    should have been included as the first line inside your function.

Execution stopped on line 48 of file TESTS:\runtime\test_unbound_local_error.py.

   46:
   47:     try:
--&gt;48:         outer_missing_nonlocal()
   49:     except Exception as e:

        global outer_missing_nonlocal: &lt;function outer_missing_nonlocal&gt;

Exception raised on line 18 of file TESTS:\runtime\test_unbound_local_error.py.

   16:
   17:     def inner():
--&gt;18:         spam_missing_nonlocal += 1
</pre></div>
</div>
</div>
</div>
<div class="section" id="unknownerror">
<h2>UnknownError<a class="headerlink" href="#unknownerror" title="Permalink to this headline">¶</a></h2>
<div class="section" id="id8">
<h3>Generic<a class="headerlink" href="#id8" title="Permalink to this headline">¶</a></h3>
<div class="highlight-none notranslate"><div class="highlight"><pre><span></span>Traceback (most recent call last):
  File &quot;TESTS:\runtime\test_unknown_error.py&quot;, line 10, in test_Generic
    raise MyException(&quot;Some informative message about an unknown exception.&quot;)
MyException: Some informative message about an unknown exception.

No information is available about this exception.

Exception raised on line 10 of file TESTS:\runtime\test_unknown_error.py.

    8: def test_Generic():
    9:     try:
--&gt;10:         raise MyException(&quot;Some informative message about an unknown exception.&quot;)
   11:     except Exception as e:

        global MyException: &lt;class test_unknown_error.MyException&gt;
</pre></div>
</div>
</div>
</div>
<div class="section" id="valueerror">
<h2>ValueError<a class="headerlink" href="#valueerror" title="Permalink to this headline">¶</a></h2>
<div class="section" id="not-enough-values-to-unpack">
<h3>Not enough values to unpack<a class="headerlink" href="#not-enough-values-to-unpack" title="Permalink to this headline">¶</a></h3>
<div class="highlight-none notranslate"><div class="highlight"><pre><span></span>Traceback (most recent call last):
  File &quot;TESTS:\runtime\test_value_error.py&quot;, line 28, in test_Not_enough_values_to_unpack
    a, b, c = d
ValueError: not enough values to unpack (expected 3, got 2)

A `ValueError` indicates that a function or an operation
received an argument of the right type, but an inappropriate value.

    Unpacking is a convenient way to assign a name,
    to each item of an iterable.
    In this instance, there are more names (3)
    than the length of the iterable, a string (`str`) of length 2.

Exception raised on line 28 of file TESTS:\runtime\test_value_error.py.

   26:     d = &quot;ab&quot;
   27:     try:
--&gt;28:         a, b, c = d
   29:     except Exception as e:

        d: &#39;ab&#39;
</pre></div>
</div>
</div>
<div class="section" id="too-many-values-to-unpack">
<h3>Too many values to unpack<a class="headerlink" href="#too-many-values-to-unpack" title="Permalink to this headline">¶</a></h3>
<div class="highlight-none notranslate"><div class="highlight"><pre><span></span>Traceback (most recent call last):
  File &quot;TESTS:\runtime\test_value_error.py&quot;, line 43, in test_Too_many_values_to_unpack
    a, b = c
ValueError: too many values to unpack (expected 2)

A `ValueError` indicates that a function or an operation
received an argument of the right type, but an inappropriate value.

    Unpacking is a convenient way to assign a name,
    to each item of an iterable.
    In this instance, there are fewer names (2)
    than the length of the iterable, a `list` of length 3.

Exception raised on line 43 of file TESTS:\runtime\test_value_error.py.

   41:     c = [1, 2, 3]
   42:     try:
--&gt;43:         a, b = c
   44:     except Exception as e:

        c: [1, 2, 3]
</pre></div>
</div>
</div>
</div>
<div class="section" id="zerodivisionerror">
<h2>ZeroDivisionError<a class="headerlink" href="#zerodivisionerror" title="Permalink to this headline">¶</a></h2>
<div class="section" id="division-operator">
<h3>Division operator<a class="headerlink" href="#division-operator" title="Permalink to this headline">¶</a></h3>
<div class="highlight-none notranslate"><div class="highlight"><pre><span></span>Traceback (most recent call last):
  File &quot;TESTS:\runtime\test_zero_division_error.py&quot;, line 6, in test_Division_operator
    1 / 0
ZeroDivisionError: division by zero

A `ZeroDivisionError` occurs when you are attempting to divide
a value by zero:
    `result = my_variable / 0.`
It can also happen if you calculate the remainder of a division
using the modulo operator `%`:
    `result = my_variable % 0`

Exception raised on line 6 of file TESTS:\runtime\test_zero_division_error.py.

   4: def test_Division_operator():
   5:     try:
--&gt;6:         1 / 0
   7:     except Exception as e:
</pre></div>
</div>
</div>
<div class="section" id="modulo-operator">
<h3>Modulo operator<a class="headerlink" href="#modulo-operator" title="Permalink to this headline">¶</a></h3>
<div class="highlight-none notranslate"><div class="highlight"><pre><span></span>Traceback (most recent call last):
  File &quot;TESTS:\runtime\test_zero_division_error.py&quot;, line 21, in test_Modulo_operator
    1 % zero
ZeroDivisionError: integer division or modulo by zero

A `ZeroDivisionError` occurs when you are attempting to divide
a value by zero:
    `result = my_variable / 0.`
It can also happen if you calculate the remainder of a division
using the modulo operator `%`:
    `result = my_variable % 0`

Exception raised on line 21 of file TESTS:\runtime\test_zero_division_error.py.

   19:     zero = 0
   20:     try:
--&gt;21:         1 % zero
   22:     except Exception as e:

        zero: 0
</pre></div>
</div>
</div>
</div>
</div>


           </div>
           
          </div>
          <footer>
  
    <div class="rst-footer-buttons" role="navigation" aria-label="footer navigation">
      
        <a href="syntax_tracebacks_en_3.10.html" class="btn btn-neutral float-right" title="Friendly SyntaxError tracebacks - in English" accesskey="n" rel="next">Next <span class="fa fa-arrow-circle-right"></span></a>
      
      
        <a href="syntax_tracebacks_en_3.9.html" class="btn btn-neutral float-left" title="Friendly SyntaxError tracebacks - in English" accesskey="p" rel="prev"><span class="fa fa-arrow-circle-left"></span> Previous</a>
      
    </div>
  

  <hr/>

  <div role="contentinfo">
    <p>
        
        &copy; Copyright 2019, André Roberge

    </p>
  </div>
    
    
    
    Built with <a href="http://sphinx-doc.org/">Sphinx</a> using a
    
    <a href="https://github.com/rtfd/sphinx_rtd_theme">theme</a>
    
    provided by <a href="https://readthedocs.org">Read the Docs</a>. 

</footer>

        </div>
      </div>

    </section>

  </div>
  

  <script type="text/javascript">
      jQuery(function () {
          SphinxRtdTheme.Navigation.enable(true);
      });
  </script>

  
  
    
   

</body>
</html>